<robot name = "robot">
    <link name="link0">
        <inertial>
            <origin xyz="0 0 1" rpy="0 0 0"/>
            <mass value="1" />
            <inertia ixx="100" ixy="0" ixz="0" iyy="100" iyz="0" izz="100" />
        </inertial>
        <visual>
            <origin xyz="0 0 1" rpy="0 0 0"/>
            <geometry>
                <box size="0.4351852751821821 0.9174341156007925 0.1573579145027979" />
            </geometry>
            <material name="Cyan">
                <color rgba="0 1.0 1.0 1.0"/>
            </material>
        </visual>
        <collision>
            <origin xyz="0 0 1" rpy="0 0 0"/>
            <geometry>
                <box size="0.4351852751821821 0.9174341156007925 0.1573579145027979" />
            </geometry>
        </collision>
    </link>
    <joint name="link0_link1" type="revolute">
       <parent link="link0"/>
       <child  link="link1"/>
       <origin rpy="0 0 0" xyz="-0.1711342027495404 0.0656131195806868 1.078678957251399" />
     <axis xyz="1 0 0"/>
       <limit effort="0.0" lower="-3.14159" upper="3.14159" velocity="0.0"/>
    </joint>
    <link name="link1">
        <inertial>
            <origin xyz="-0.07773376643336158 -0.0005466973622577841 0.49834016551200533" rpy="0 0 0"/>
            <mass value="1" />
            <inertia ixx="100" ixy="0" ixz="0" iyy="100" iyz="0" izz="100" />
        </inertial>
        <visual>
            <origin xyz="-0.07773376643336158 -0.0005466973622577841 0.49834016551200533" rpy="0 0 0"/>
            <geometry>
                <box size="0.6353337224786972 0.04190842119896809 0.9966803310240107" />
            </geometry>
            <material name="Cyan">
                <color rgba="0 1.0 1.0 1.0"/>
            </material>
        </visual>
        <collision>
            <origin xyz="-0.07773376643336158 -0.0005466973622577841 0.49834016551200533" rpy="0 0 0"/>
            <geometry>
                <box size="0.6353337224786972 0.04190842119896809 0.9966803310240107" />
            </geometry>
        </collision>
    </link>
    <joint name="link0_link2" type="revolute">
       <parent link="link0"/>
       <child  link="link2"/>
       <origin rpy="0 0 0" xyz="-0.02668269672880843 -0.45871705780039623 0.9928816051156955" />
     <axis xyz="1 0 0"/>
       <limit effort="0.0" lower="-3.14159" upper="3.14159" velocity="0.0"/>
    </joint>
    <link name="link2">
        <inertial>
            <origin xyz="0.1633646981186054 -0.019453394099509413 0.26057951265997076" rpy="0 0 0"/>
            <mass value="1" />
            <inertia ixx="100" ixy="0" ixz="0" iyy="100" iyz="0" izz="100" />
        </inertial>
        <visual>
            <origin xyz="0.1633646981186054 -0.019453394099509413 0.26057951265997076" rpy="0 0 0"/>
            <geometry>
                <box size="0.5369914469841163 0.03890678819901883 0.843106902574607" />
            </geometry>
            <material name="Cyan">
                <color rgba="0 1.0 1.0 1.0"/>
            </material>
        </visual>
        <collision>
            <origin xyz="0.1633646981186054 -0.019453394099509413 0.26057951265997076" rpy="0 0 0"/>
            <geometry>
                <box size="0.5369914469841163 0.03890678819901883 0.843106902574607" />
            </geometry>
        </collision>
    </link>
</robot>