<robot name = "robot">
    <link name="link0">
        <inertial>
            <origin xyz="0 0 1" rpy="0 0 0"/>
            <mass value="1" />
            <inertia ixx="100" ixy="0" ixz="0" iyy="100" iyz="0" izz="100" />
        </inertial>
        <visual>
            <origin xyz="0 0 1" rpy="0 0 0"/>
            <geometry>
                <box size="0.6564853263014581 0.4916610821415073 0.8486402688663145" />
            </geometry>
            <material name="Cyan">
                <color rgba="0.0 1.0 1.0 1.0"/>
            </material>
        </visual>
        <collision>
            <origin xyz="0 0 1" rpy="0 0 0"/>
            <geometry>
                <box size="0.6564853263014581 0.4916610821415073 0.8486402688663145" />
            </geometry>
        </collision>
    </link>
    <joint name="link0_link1" type="revolute">
       <parent link="link0"/>
       <child  link="link1"/>
       <origin rpy="0 0 0" xyz="-0.32824266315072903 -0.13753631229885302 1.1184863729997614" />
     <axis xyz="1 0 0"/>
       <limit effort="0.0" lower="-3.14159" upper="3.14159" velocity="0.0"/>
    </joint>
    <link name="link1">
        <inertial>
            <origin xyz="-0.3668032846340895 -0.09515365502945078 -0.09012497199917288" rpy="0 0 0"/>
            <mass value="1" />
            <inertia ixx="100" ixy="0" ixz="0" iyy="100" iyz="0" izz="100" />
        </inertial>
        <visual>
            <origin xyz="-0.3668032846340895 -0.09515365502945078 -0.09012497199917288" rpy="0 0 0"/>
            <geometry>
                <box size="0.733606569268179 0.5383597411341061 0.4435690598908625" />
            </geometry>
            <material name="Green">
                <color rgba="0.0 1.0 0.0 1.0"/>
            </material>
        </visual>
        <collision>
            <origin xyz="-0.3668032846340895 -0.09515365502945078 -0.09012497199917288" rpy="0 0 0"/>
            <geometry>
                <box size="0.733606569268179 0.5383597411341061 0.4435690598908625" />
            </geometry>
        </collision>
    </link>
    <joint name="link1_link2" type="revolute">
       <parent link="link1"/>
       <child  link="link2"/>
       <origin rpy="0 0 0" xyz="-0.3084370652987756 -0.11814555642189843 0.13165955794625836" />
     <axis xyz="0 0 1"/>
       <limit effort="0.0" lower="-3.14159" upper="3.14159" velocity="0.0"/>
    </joint>
    <link name="link2">
        <inertial>
            <origin xyz="0.41889030270993355 0.2257803805477169 0.4681306760264999" rpy="0 0 0"/>
            <mass value="1" />
            <inertia ixx="100" ixy="0" ixz="0" iyy="100" iyz="0" izz="100" />
        </inertial>
        <visual>
            <origin xyz="0.41889030270993355 0.2257803805477169 0.4681306760264999" rpy="0 0 0"/>
            <geometry>
                <box size="0.9479925079158558 0.48639573920435175 0.9362613520529998" />
            </geometry>
            <material name="Green">
                <color rgba="0.0 1.0 0.0 1.0"/>
            </material>
        </visual>
        <collision>
            <origin xyz="0.41889030270993355 0.2257803805477169 0.4681306760264999" rpy="0 0 0"/>
            <geometry>
                <box size="0.9479925079158558 0.48639573920435175 0.9362613520529998" />
            </geometry>
        </collision>
    </link>
    <joint name="link1_link3" type="revolute">
       <parent link="link1"/>
       <child  link="link3"/>
       <origin rpy="0 0 0" xyz="-0.5336739118662208 -0.32762678381651744 0.13165955794625836" />
     <axis xyz="0 1 0"/>
       <limit effort="0.0" lower="-3.14159" upper="3.14159" velocity="0.0"/>
    </joint>
    <link name="link3">
        <inertial>
            <origin xyz="-0.11182016819847733 -0.01587286675672447 0.3962703159568972" rpy="0 0 0"/>
            <mass value="1" />
            <inertia ixx="100" ixy="0" ixz="0" iyy="100" iyz="0" izz="100" />
        </inertial>
        <visual>
            <origin xyz="-0.11182016819847733 -0.01587286675672447 0.3962703159568972" rpy="0 0 0"/>
            <geometry>
                <box size="0.5755103904457288 0.11132213096837007 0.7925406319137944" />
            </geometry>
            <material name="Green">
                <color rgba="0.0 1.0 0.0 1.0"/>
            </material>
        </visual>
        <collision>
            <origin xyz="-0.11182016819847733 -0.01587286675672447 0.3962703159568972" rpy="0 0 0"/>
            <geometry>
                <box size="0.5755103904457288 0.11132213096837007 0.7925406319137944" />
            </geometry>
        </collision>
    </link>
    <joint name="link3_link4" type="revolute">
       <parent link="link3"/>
       <child  link="link4"/>
       <origin rpy="0 0 0" xyz="0.17593502702438707 -0.04038848335410877 0.7649457939980326" />
     <axis xyz="0 1 0"/>
       <limit effort="0.0" lower="-3.14159" upper="3.14159" velocity="0.0"/>
    </joint>
    <link name="link4">
        <inertial>
            <origin xyz="0.13219922678070284 0.3734633520602399 -0.35036550501849306" rpy="0 0 0"/>
            <mass value="1" />
            <inertia ixx="100" ixy="0" ixz="0" iyy="100" iyz="0" izz="100" />
        </inertial>
        <visual>
            <origin xyz="0.13219922678070284 0.3734633520602399 -0.35036550501849306" rpy="0 0 0"/>
            <geometry>
                <box size="0.2643984535614057 0.8704023757885155 0.9203674470060442" />
            </geometry>
            <material name="Green">
                <color rgba="0.0 1.0 0.0 1.0"/>
            </material>
        </visual>
        <collision>
            <origin xyz="0.13219922678070284 0.3734633520602399 -0.35036550501849306" rpy="0 0 0"/>
            <geometry>
                <box size="0.2643984535614057 0.8704023757885155 0.9203674470060442" />
            </geometry>
        </collision>
    </link>
    <joint name="link2_link5" type="revolute">
       <parent link="link2"/>
       <child  link="link5"/>
       <origin rpy="0 0 0" xyz="0.3058818962989716 0.06186409159268008 0.9362613520529998" />
     <axis xyz="0 0 1"/>
       <limit effort="0.0" lower="-3.14159" upper="3.14159" velocity="0.0"/>
    </joint>
    <link name="link5">
        <inertial>
            <origin xyz="0.02846723248758582 0.08920603515273418 0.2698717467590299" rpy="0 0 0"/>
            <mass value="1" />
            <inertia ixx="100" ixy="0" ixz="0" iyy="100" iyz="0" izz="100" />
        </inertial>
        <visual>
            <origin xyz="0.02846723248758582 0.08920603515273418 0.2698717467590299" rpy="0 0 0"/>
            <geometry>
                <box size="0.9833200532929315 0.7697377178028628 0.5397434935180598" />
            </geometry>
            <material name="Green">
                <color rgba="0.0 1.0 0.0 1.0"/>
            </material>
        </visual>
        <collision>
            <origin xyz="0.02846723248758582 0.08920603515273418 0.2698717467590299" rpy="0 0 0"/>
            <geometry>
                <box size="0.9833200532929315 0.7697377178028628 0.5397434935180598" />
            </geometry>
        </collision>
    </link>
    <joint name="link3_link6" type="revolute">
       <parent link="link3"/>
       <child  link="link6"/>
       <origin rpy="0 0 0" xyz="-0.23734636774460127 -0.05278614260945215 0.7925406319137944" />
     <axis xyz="1 0 0"/>
       <limit effort="0.0" lower="-3.14159" upper="3.14159" velocity="0.0"/>
    </joint>
    <link name="link6">
        <inertial>
            <origin xyz="0.011017295233693073 -0.07011541333477102 0.19351424423357388" rpy="0 0 0"/>
            <mass value="1" />
            <inertia ixx="100" ixy="0" ixz="0" iyy="100" iyz="0" izz="100" />
        </inertial>
        <visual>
            <origin xyz="0.011017295233693073 -0.07011541333477102 0.19351424423357388" rpy="0 0 0"/>
            <geometry>
                <box size="0.04788748707875368 0.24901450353760257 0.38702848846714777" />
            </geometry>
            <material name="Green">
                <color rgba="0.0 1.0 0.0 1.0"/>
            </material>
        </visual>
        <collision>
            <origin xyz="0.011017295233693073 -0.07011541333477102 0.19351424423357388" rpy="0 0 0"/>
            <geometry>
                <box size="0.04788748707875368 0.24901450353760257 0.38702848846714777" />
            </geometry>
        </collision>
    </link>
    <joint name="link2_link7" type="revolute">
       <parent link="link2"/>
       <child  link="link7"/>
       <origin rpy="0 0 0" xyz="0.8928865566678614 0.3596978281491711 0.8310049630431271" />
     <axis xyz="0 1 0"/>
       <limit effort="0.0" lower="-3.14159" upper="3.14159" velocity="0.0"/>
    </joint>
    <link name="link7">
        <inertial>
            <origin xyz="0.009166230040151824 0.09178218011801981 -0.3220263690839931" rpy="0 0 0"/>
            <mass value="1" />
            <inertia ixx="100" ixy="0" ixz="0" iyy="100" iyz="0" izz="100" />
        </inertial>
        <visual>
            <origin xyz="0.009166230040151824 0.09178218011801981 -0.3220263690839931" rpy="0 0 0"/>
            <geometry>
                <box size="0.018332460080303647 0.4032605944097706 0.7508935592706599" />
            </geometry>
            <material name="Green">
                <color rgba="0.0 1.0 0.0 1.0"/>
            </material>
        </visual>
        <collision>
            <origin xyz="0.009166230040151824 0.09178218011801981 -0.3220263690839931" rpy="0 0 0"/>
            <geometry>
                <box size="0.018332460080303647 0.4032605944097706 0.7508935592706599" />
            </geometry>
        </collision>
    </link>
    <joint name="link5_link8" type="revolute">
       <parent link="link5"/>
       <child  link="link8"/>
       <origin rpy="0 0 0" xyz="-0.46319279415887993 0.12788899368978368 0.47244796343430395" />
     <axis xyz="0 0 1"/>
       <limit effort="0.0" lower="-3.14159" upper="3.14159" velocity="0.0"/>
    </joint>
    <link name="link8">
        <inertial>
            <origin xyz="-0.22099019651925422 -0.2604472209994649 -0.2942313054752193" rpy="0 0 0"/>
            <mass value="1" />
            <inertia ixx="100" ixy="0" ixz="0" iyy="100" iyz="0" izz="100" />
        </inertial>
        <visual>
            <origin xyz="-0.22099019651925422 -0.2604472209994649 -0.2942313054752193" rpy="0 0 0"/>
            <geometry>
                <box size="0.44198039303850845 0.9972787753878978 0.7239814790713621" />
            </geometry>
            <material name="Green">
                <color rgba="0.0 1.0 0.0 1.0"/>
            </material>
        </visual>
        <collision>
            <origin xyz="-0.22099019651925422 -0.2604472209994649 -0.2942313054752193" rpy="0 0 0"/>
            <geometry>
                <box size="0.44198039303850845 0.9972787753878978 0.7239814790713621" />
            </geometry>
        </collision>
    </link>
    <joint name="link6_link9" type="revolute">
       <parent link="link6"/>
       <child  link="link9"/>
       <origin rpy="0 0 0" xyz="0.008421222860406963 -0.1946226651035723 0.11698326256800586" />
     <axis xyz="0 1 0"/>
       <limit effort="0.0" lower="-3.14159" upper="3.14159" velocity="0.0"/>
    </joint>
    <link name="link9">
        <inertial>
            <origin xyz="-0.12371638595247987 -0.3958721896572858 0.028761033664091853" rpy="0 0 0"/>
            <mass value="1" />
            <inertia ixx="100" ixy="0" ixz="0" iyy="100" iyz="0" izz="100" />
        </inertial>
        <visual>
            <origin xyz="-0.12371638595247987 -0.3958721896572858 0.028761033664091853" rpy="0 0 0"/>
            <geometry>
                <box size="0.9109175566436437 0.7917443793145716 0.17556775115961476" />
            </geometry>
            <material name="Green">
                <color rgba="0.0 1.0 0.0 1.0"/>
            </material>
        </visual>
        <collision>
            <origin xyz="-0.12371638595247987 -0.3958721896572858 0.028761033664091853" rpy="0 0 0"/>
            <geometry>
                <box size="0.9109175566436437 0.7917443793145716 0.17556775115961476" />
            </geometry>
        </collision>
    </link>
</robot>