<robot name = "robot">
    <link name="link0">
        <inertial>
            <origin xyz="0 0 1" rpy="0 0 0"/>
            <mass value="1" />
            <inertia ixx="100" ixy="0" ixz="0" iyy="100" iyz="0" izz="100" />
        </inertial>
        <visual>
            <origin xyz="0 0 1" rpy="0 0 0"/>
            <geometry>
                <box size="0.7093574645682789 0.26601965311195397 0.9934524034830561" />
            </geometry>
            <material name="Cyan">
                <color rgba="0 1.0 1.0 1.0"/>
            </material>
        </visual>
        <collision>
            <origin xyz="0 0 1" rpy="0 0 0"/>
            <geometry>
                <box size="0.7093574645682789 0.26601965311195397 0.9934524034830561" />
            </geometry>
        </collision>
    </link>
    <joint name="link0_link1" type="revolute">
       <parent link="link0"/>
       <child  link="link1"/>
       <origin rpy="0 0 0" xyz="-0.35467873228413943 -0.020022641767925554 0.6580525248410696" />
     <axis xyz="0 1 0"/>
       <limit effort="0.0" lower="-3.14159" upper="3.14159" velocity="0.0"/>
    </joint>
    <link name="link1">
        <inertial>
            <origin xyz="-0.45368664862027985 0.19670822823454218 0.005574591487900859" rpy="0 0 0"/>
            <mass value="1" />
            <inertia ixx="100" ixy="0" ixz="0" iyy="100" iyz="0" izz="100" />
        </inertial>
        <visual>
            <origin xyz="-0.45368664862027985 0.19670822823454218 0.005574591487900859" rpy="0 0 0"/>
            <geometry>
                <box size="0.9073732972405597 0.9467683834285302 0.25961138656785265" />
            </geometry>
            <material name="Cyan">
                <color rgba="0 1.0 1.0 1.0"/>
            </material>
        </visual>
        <collision>
            <origin xyz="-0.45368664862027985 0.19670822823454218 0.005574591487900859" rpy="0 0 0"/>
            <geometry>
                <box size="0.9073732972405597 0.9467683834285302 0.25961138656785265" />
            </geometry>
        </collision>
    </link>
    <joint name="link0_link2" type="revolute">
       <parent link="link0"/>
       <child  link="link2"/>
       <origin rpy="0 0 0" xyz="-0.05481491565815909 0.033389364817265836 1.4967262017415282" />
     <axis xyz="0 0 1"/>
       <limit effort="0.0" lower="-3.14159" upper="3.14159" velocity="0.0"/>
    </joint>
    <link name="link2">
        <inertial>
            <origin xyz="-0.06451627970854293 -0.047666112232383685 0.11684208501213472" rpy="0 0 0"/>
            <mass value="1" />
            <inertia ixx="100" ixy="0" ixz="0" iyy="100" iyz="0" izz="100" />
        </inertial>
        <visual>
            <origin xyz="-0.06451627970854293 -0.047666112232383685 0.11684208501213472" rpy="0 0 0"/>
            <geometry>
                <box size="0.5379856405334336 0.4434897518057851 0.23368417002426944" />
            </geometry>
            <material name="Cyan">
                <color rgba="0 1.0 1.0 1.0"/>
            </material>
        </visual>
        <collision>
            <origin xyz="-0.06451627970854293 -0.047666112232383685 0.11684208501213472" rpy="0 0 0"/>
            <geometry>
                <box size="0.5379856405334336 0.4434897518057851 0.23368417002426944" />
            </geometry>
        </collision>
    </link>
    <joint name="link1_link3" type="revolute">
       <parent link="link1"/>
       <child  link="link3"/>
       <origin rpy="0 0 0" xyz="-0.5831902779939652 -0.2766759634797229 -0.02199892727121914" />
     <axis xyz="0 0 1"/>
       <limit effort="0.0" lower="-3.14159" upper="3.14159" velocity="0.0"/>
    </joint>
    <link name="link3">
        <inertial>
            <origin xyz="-0.3251235844468065 -0.04538812388207797 -0.05064796698302921" rpy="0 0 0"/>
            <mass value="1" />
            <inertia ixx="100" ixy="0" ixz="0" iyy="100" iyz="0" izz="100" />
        </inertial>
        <visual>
            <origin xyz="-0.3251235844468065 -0.04538812388207797 -0.05064796698302921" rpy="0 0 0"/>
            <geometry>
                <box size="0.915181609493902 0.09077624776415594 0.9745262732764403" />
            </geometry>
            <material name="Cyan">
                <color rgba="0 1.0 1.0 1.0"/>
            </material>
        </visual>
        <collision>
            <origin xyz="-0.3251235844468065 -0.04538812388207797 -0.05064796698302921" rpy="0 0 0"/>
            <geometry>
                <box size="0.915181609493902 0.09077624776415594 0.9745262732764403" />
            </geometry>
        </collision>
    </link>
    <joint name="link0_link4" type="revolute">
       <parent link="link0"/>
       <child  link="link4"/>
       <origin rpy="0 0 0" xyz="0.3527556692899745 0.02656517978929623 0.503273798258472" />
     <axis xyz="0 1 0"/>
       <limit effort="0.0" lower="-3.14159" upper="3.14159" velocity="0.0"/>
    </joint>
    <link name="link4">
        <inertial>
            <origin xyz="0.03460205620335499 -0.013370053359251451 -0.22794223239266248" rpy="0 0 0"/>
            <mass value="1" />
            <inertia ixx="100" ixy="0" ixz="0" iyy="100" iyz="0" izz="100" />
        </inertial>
        <visual>
            <origin xyz="0.03460205620335499 -0.013370053359251451 -0.22794223239266248" rpy="0 0 0"/>
            <geometry>
                <box size="0.33492273540720796 0.15470452248250532 0.45588446478532496" />
            </geometry>
            <material name="Cyan">
                <color rgba="0 1.0 1.0 1.0"/>
            </material>
        </visual>
        <collision>
            <origin xyz="0.03460205620335499 -0.013370053359251451 -0.22794223239266248" rpy="0 0 0"/>
            <geometry>
                <box size="0.33492273540720796 0.15470452248250532 0.45588446478532496" />
            </geometry>
        </collision>
    </link>
</robot>