<robot name = "robot">
    <link name="link0">
        <inertial>
            <origin xyz="0 0 1" rpy="0 0 0"/>
            <mass value="1" />
            <inertia ixx="100" ixy="0" ixz="0" iyy="100" iyz="0" izz="100" />
        </inertial>
        <visual>
            <origin xyz="0 0 1" rpy="0 0 0"/>
            <geometry>
                <box size="0.09119705668500022 0.9024992711796131 0.8767548132356359" />
            </geometry>
            <material name="Cyan">
                <color rgba="0 1.0 1.0 1.0"/>
            </material>
        </visual>
        <collision>
            <origin xyz="0 0 1" rpy="0 0 0"/>
            <geometry>
                <box size="0.09119705668500022 0.9024992711796131 0.8767548132356359" />
            </geometry>
        </collision>
    </link>
    <joint name="link0_link1" type="revolute">
       <parent link="link0"/>
       <child  link="link1"/>
       <origin rpy="0 0 0" xyz="-0.04559852834250011 -0.34529068773609767 1.1919400888331657" />
     <axis xyz="0 0 1"/>
       <limit effort="0.0" lower="-3.14159" upper="3.14159" velocity="0.0"/>
    </joint>
    <link name="link1">
        <inertial>
            <origin xyz="-0.4768245744224677 -0.12511945460117258 0.02945261290585559" rpy="0 0 0"/>
            <mass value="1" />
            <inertia ixx="100" ixy="0" ixz="0" iyy="100" iyz="0" izz="100" />
        </inertial>
        <visual>
            <origin xyz="-0.4768245744224677 -0.12511945460117258 0.02945261290585559" rpy="0 0 0"/>
            <geometry>
                <box size="0.9536491488449353 0.463776370022822 0.9426752955720248" />
            </geometry>
            <material name="Cyan">
                <color rgba="0 1.0 1.0 1.0"/>
            </material>
        </visual>
        <collision>
            <origin xyz="-0.4768245744224677 -0.12511945460117258 0.02945261290585559" rpy="0 0 0"/>
            <geometry>
                <box size="0.9536491488449353 0.463776370022822 0.9426752955720248" />
            </geometry>
        </collision>
    </link>
    <joint name="link0_link2" type="revolute">
       <parent link="link0"/>
       <child  link="link2"/>
       <origin rpy="0 0 0" xyz="0.006092410093126052 0.43192912721798893 1.4383774066178179" />
     <axis xyz="0 0 1"/>
       <limit effort="0.0" lower="-3.14159" upper="3.14159" velocity="0.0"/>
    </joint>
    <link name="link2">
        <inertial>
            <origin xyz="0.08135784264743542 -0.1455090793137398 0.016707366930856837" rpy="0 0 0"/>
            <mass value="1" />
            <inertia ixx="100" ixy="0" ixz="0" iyy="100" iyz="0" izz="100" />
        </inertial>
        <visual>
            <origin xyz="0.08135784264743542 -0.1455090793137398 0.016707366930856837" rpy="0 0 0"/>
            <geometry>
                <box size="0.9919615657454242 0.5434376933300522 0.033414733861713675" />
            </geometry>
            <material name="Cyan">
                <color rgba="0 1.0 1.0 1.0"/>
            </material>
        </visual>
        <collision>
            <origin xyz="0.08135784264743542 -0.1455090793137398 0.016707366930856837" rpy="0 0 0"/>
            <geometry>
                <box size="0.9919615657454242 0.5434376933300522 0.033414733861713675" />
            </geometry>
        </collision>
    </link>
    <joint name="link2_link3" type="revolute">
       <parent link="link2"/>
       <child  link="link3"/>
       <origin rpy="0 0 0" xyz="0.5773386255201475 -0.02443517821025054 0.007070606708979051" />
     <axis xyz="0 0 1"/>
       <limit effort="0.0" lower="-3.14159" upper="3.14159" velocity="0.0"/>
    </joint>
    <link name="link3">
        <inertial>
            <origin xyz="0.14965165838243216 -0.39321597342544495 0.03119378040707482" rpy="0 0 0"/>
            <mass value="1" />
            <inertia ixx="100" ixy="0" ixz="0" iyy="100" iyz="0" izz="100" />
        </inertial>
        <visual>
            <origin xyz="0.14965165838243216 -0.39321597342544495 0.03119378040707482" rpy="0 0 0"/>
            <geometry>
                <box size="0.2993033167648643 0.8617267428927927 0.1189127568242232" />
            </geometry>
            <material name="Cyan">
                <color rgba="0 1.0 1.0 1.0"/>
            </material>
        </visual>
        <collision>
            <origin xyz="0.14965165838243216 -0.39321597342544495 0.03119378040707482" rpy="0 0 0"/>
            <geometry>
                <box size="0.2993033167648643 0.8617267428927927 0.1189127568242232" />
            </geometry>
        </collision>
    </link>
    <joint name="link1_link4" type="revolute">
       <parent link="link1"/>
       <child  link="link4"/>
       <origin rpy="0 0 0" xyz="-0.5946481689191334 -0.1090649688195103 -0.4418850348801568" />
     <axis xyz="1 0 0"/>
       <limit effort="0.0" lower="-3.14159" upper="3.14159" velocity="0.0"/>
    </joint>
    <link name="link4">
        <inertial>
            <origin xyz="0.3353072689136362 -0.00024879321817611924 -0.26216534570447186" rpy="0 0 0"/>
            <mass value="1" />
            <inertia ixx="100" ixy="0" ixz="0" iyy="100" iyz="0" izz="100" />
        </inertial>
        <visual>
            <origin xyz="0.3353072689136362 -0.00024879321817611924 -0.26216534570447186" rpy="0 0 0"/>
            <geometry>
                <box size="0.9301813887943108 0.0009497998693901444 0.5243306914089437" />
            </geometry>
            <material name="Cyan">
                <color rgba="0 1.0 1.0 1.0"/>
            </material>
        </visual>
        <collision>
            <origin xyz="0.3353072689136362 -0.00024879321817611924 -0.26216534570447186" rpy="0 0 0"/>
            <geometry>
                <box size="0.9301813887943108 0.0009497998693901444 0.5243306914089437" />
            </geometry>
        </collision>
    </link>
    <joint name="link4_link5" type="revolute">
       <parent link="link4"/>
       <child  link="link5"/>
       <origin rpy="0 0 0" xyz="-0.12978342548351918 0.00015299615345926257 -0.17958005361323587" />
     <axis xyz="0 1 0"/>
       <limit effort="0.0" lower="-3.14159" upper="3.14159" velocity="0.0"/>
    </joint>
    <link name="link5">
        <inertial>
            <origin xyz="-0.14390192609024138 0.039794602435560184 -0.04428124980888481" rpy="0 0 0"/>
            <mass value="1" />
            <inertia ixx="100" ixy="0" ixz="0" iyy="100" iyz="0" izz="100" />
        </inertial>
        <visual>
            <origin xyz="-0.14390192609024138 0.039794602435560184 -0.04428124980888481" rpy="0 0 0"/>
            <geometry>
                <box size="0.28780385218048277 0.48681211094477284 0.15510981935226253" />
            </geometry>
            <material name="Cyan">
                <color rgba="0 1.0 1.0 1.0"/>
            </material>
        </visual>
        <collision>
            <origin xyz="-0.14390192609024138 0.039794602435560184 -0.04428124980888481" rpy="0 0 0"/>
            <geometry>
                <box size="0.28780385218048277 0.48681211094477284 0.15510981935226253" />
            </geometry>
        </collision>
    </link>
    <joint name="link1_link6" type="revolute">
       <parent link="link1"/>
       <child  link="link6"/>
       <origin rpy="0 0 0" xyz="-0.9499437702957362 -0.3570076396125836 0.46154757960387455" />
     <axis xyz="1 0 0"/>
       <limit effort="0.0" lower="-3.14159" upper="3.14159" velocity="0.0"/>
    </joint>
    <link name="link6">
        <inertial>
            <origin xyz="-0.006635500430647788 -0.3421014078848986 0.08759511931181778" rpy="0 0 0"/>
            <mass value="1" />
            <inertia ixx="100" ixy="0" ixz="0" iyy="100" iyz="0" izz="100" />
        </inertial>
        <visual>
            <origin xyz="-0.006635500430647788 -0.3421014078848986 0.08759511931181778" rpy="0 0 0"/>
            <geometry>
                <box size="0.1467144284837406 0.6842028157697972 0.18211381196878462" />
            </geometry>
            <material name="Cyan">
                <color rgba="0 1.0 1.0 1.0"/>
            </material>
        </visual>
        <collision>
            <origin xyz="-0.006635500430647788 -0.3421014078848986 0.08759511931181778" rpy="0 0 0"/>
            <geometry>
                <box size="0.1467144284837406 0.6842028157697972 0.18211381196878462" />
            </geometry>
        </collision>
    </link>
    <joint name="link0_link7" type="revolute">
       <parent link="link0"/>
       <child  link="link7"/>
       <origin rpy="0 0 0" xyz="-0.021971620491570733 0.4512496355898066 1.010538161833765" />
     <axis xyz="1 0 0"/>
       <limit effort="0.0" lower="-3.14159" upper="3.14159" velocity="0.0"/>
    </joint>
    <link name="link7">
        <inertial>
            <origin xyz="-0.10928257801415472 0.3189404007733066 -0.2540340491720284" rpy="0 0 0"/>
            <mass value="1" />
            <inertia ixx="100" ixy="0" ixz="0" iyy="100" iyz="0" izz="100" />
        </inertial>
        <visual>
            <origin xyz="-0.10928257801415472 0.3189404007733066 -0.2540340491720284" rpy="0 0 0"/>
            <geometry>
                <box size="0.24487452341735771 0.6378808015466132 0.5572725371842948" />
            </geometry>
            <material name="Cyan">
                <color rgba="0 1.0 1.0 1.0"/>
            </material>
        </visual>
        <collision>
            <origin xyz="-0.10928257801415472 0.3189404007733066 -0.2540340491720284" rpy="0 0 0"/>
            <geometry>
                <box size="0.24487452341735771 0.6378808015466132 0.5572725371842948" />
            </geometry>
        </collision>
    </link>
</robot>