<robot name = "robot">
    <link name="link0">
        <inertial>
            <origin xyz="0 0 1" rpy="0 0 0"/>
            <mass value="1" />
            <inertia ixx="100" ixy="0" ixz="0" iyy="100" iyz="0" izz="100" />
        </inertial>
        <visual>
            <origin xyz="0 0 1" rpy="0 0 0"/>
            <geometry>
                <box size="0.9748198583047035 0.034921859575674064 0.2098666223138005" />
            </geometry>
            <material name="Cyan">
                <color rgba="0.0 1.0 1.0 1.0"/>
            </material>
        </visual>
        <collision>
            <origin xyz="0 0 1" rpy="0 0 0"/>
            <geometry>
                <box size="0.9748198583047035 0.034921859575674064 0.2098666223138005" />
            </geometry>
        </collision>
    </link>
    <joint name="link0_link1" type="revolute">
       <parent link="link0"/>
       <child  link="link1"/>
       <origin rpy="0 0 0" xyz="-0.0032411086475903927 -0.017460929787837032 0.9031873686819263" />
     <axis xyz="0 1 0"/>
       <limit effort="0.0" lower="-3.14159" upper="3.14159" velocity="0.0"/>
    </joint>
    <link name="link1">
        <inertial>
            <origin xyz="-0.09251651659879155 -0.15489038619633294 0.044305368143623174" rpy="0 0 0"/>
            <mass value="1" />
            <inertia ixx="100" ixy="0" ixz="0" iyy="100" iyz="0" izz="100" />
        </inertial>
        <visual>
            <origin xyz="-0.09251651659879155 -0.15489038619633294 0.044305368143623174" rpy="0 0 0"/>
            <geometry>
                <box size="0.27946609380292353 0.3097807723926659 0.7056657337969258" />
            </geometry>
            <material name="Green">
                <color rgba="0.0 1.0 0.0 1.0"/>
            </material>
        </visual>
        <collision>
            <origin xyz="-0.09251651659879155 -0.15489038619633294 0.044305368143623174" rpy="0 0 0"/>
            <geometry>
                <box size="0.27946609380292353 0.3097807723926659 0.7056657337969258" />
            </geometry>
        </collision>
    </link>
</robot>