<robot name = "robot">
    <link name="link0">
        <inertial>
            <origin xyz="0 0 1" rpy="0 0 0"/>
            <mass value="1" />
            <inertia ixx="100" ixy="0" ixz="0" iyy="100" iyz="0" izz="100" />
        </inertial>
        <visual>
            <origin xyz="0 0 1" rpy="0 0 0"/>
            <geometry>
                <box size="0.49321871057678834 0.1036267965987715 0.5109387938140327" />
            </geometry>
            <material name="Cyan">
                <color rgba="0.0 1.0 1.0 1.0"/>
            </material>
        </visual>
        <collision>
            <origin xyz="0 0 1" rpy="0 0 0"/>
            <geometry>
                <box size="0.49321871057678834 0.1036267965987715 0.5109387938140327" />
            </geometry>
        </collision>
    </link>
    <joint name="link0_link1" type="revolute">
       <parent link="link0"/>
       <child  link="link1"/>
       <origin rpy="0 0 0" xyz="-0.24660935528839417 -0.007967879208687577 0.7519651933499341" />
     <axis xyz="0 1 0"/>
       <limit effort="0.0" lower="-3.14159" upper="3.14159" velocity="0.0"/>
    </joint>
    <link name="link1">
        <inertial>
            <origin xyz="-0.01706342860124138 0.03815498753850721 0.34811037123412225" rpy="0 0 0"/>
            <mass value="1" />
            <inertia ixx="100" ixy="0" ixz="0" iyy="100" iyz="0" izz="100" />
        </inertial>
        <visual>
            <origin xyz="-0.01706342860124138 0.03815498753850721 0.34811037123412225" rpy="0 0 0"/>
            <geometry>
                <box size="0.03412685720248276 0.12504455042212403 0.9394233057601915" />
            </geometry>
            <material name="Green">
                <color rgba="0.0 1.0 0.0 1.0"/>
            </material>
        </visual>
        <collision>
            <origin xyz="-0.01706342860124138 0.03815498753850721 0.34811037123412225" rpy="0 0 0"/>
            <geometry>
                <box size="0.03412685720248276 0.12504455042212403 0.9394233057601915" />
            </geometry>
        </collision>
    </link>
    <joint name="link1_link2" type="revolute">
       <parent link="link1"/>
       <child  link="link2"/>
       <origin rpy="0 0 0" xyz="-0.02940746732219799 0.025439362308270194 0.817822024114218" />
     <axis xyz="0 0 1"/>
       <limit effort="0.0" lower="-3.14159" upper="3.14159" velocity="0.0"/>
    </joint>
    <link name="link2">
        <inertial>
            <origin xyz="0.00559788753493662 -0.30846278122313286 0.06284829372010026" rpy="0 0 0"/>
            <mass value="1" />
            <inertia ixx="100" ixy="0" ixz="0" iyy="100" iyz="0" izz="100" />
        </inertial>
        <visual>
            <origin xyz="0.00559788753493662 -0.30846278122313286 0.06284829372010026" rpy="0 0 0"/>
            <geometry>
                <box size="0.02075243558844675 0.9650897318317088 0.1256965874402005" />
            </geometry>
            <material name="Green">
                <color rgba="0.0 1.0 0.0 1.0"/>
            </material>
        </visual>
        <collision>
            <origin xyz="0.00559788753493662 -0.30846278122313286 0.06284829372010026" rpy="0 0 0"/>
            <geometry>
                <box size="0.02075243558844675 0.9650897318317088 0.1256965874402005" />
            </geometry>
        </collision>
    </link>
    <joint name="link0_link3" type="revolute">
       <parent link="link0"/>
       <child  link="link3"/>
       <origin rpy="0 0 0" xyz="0.24660935528839417 -0.022386672461055582 1.1013012747247566" />
     <axis xyz="0 0 1"/>
       <limit effort="0.0" lower="-3.14159" upper="3.14159" velocity="0.0"/>
    </joint>
    <link name="link3">
        <inertial>
            <origin xyz="0.1383139715672082 -0.05007665380123643 -0.07041267224443995" rpy="0 0 0"/>
            <mass value="1" />
            <inertia ixx="100" ixy="0" ixz="0" iyy="100" iyz="0" izz="100" />
        </inertial>
        <visual>
            <origin xyz="0.1383139715672082 -0.05007665380123643 -0.07041267224443995" rpy="0 0 0"/>
            <geometry>
                <box size="0.2766279431344164 0.10276896831110105 0.5244941401053667" />
            </geometry>
            <material name="Green">
                <color rgba="0.0 1.0 0.0 1.0"/>
            </material>
        </visual>
        <collision>
            <origin xyz="0.1383139715672082 -0.05007665380123643 -0.07041267224443995" rpy="0 0 0"/>
            <geometry>
                <box size="0.2766279431344164 0.10276896831110105 0.5244941401053667" />
            </geometry>
        </collision>
    </link>
    <joint name="link3_link4" type="revolute">
       <parent link="link3"/>
       <child  link="link4"/>
       <origin rpy="0 0 0" xyz="0.22674346154976932 -0.10146113795678696 -0.17210655531742763" />
     <axis xyz="0 1 0"/>
       <limit effort="0.0" lower="-3.14159" upper="3.14159" velocity="0.0"/>
    </joint>
    <link name="link4">
        <inertial>
            <origin xyz="0.06838714457704628 -0.37123860019204596 0.17316696073160925" rpy="0 0 0"/>
            <mass value="1" />
            <inertia ixx="100" ixy="0" ixz="0" iyy="100" iyz="0" izz="100" />
        </inertial>
        <visual>
            <origin xyz="0.06838714457704628 -0.37123860019204596 0.17316696073160925" rpy="0 0 0"/>
            <geometry>
                <box size="0.6370844687734599 0.7424772003840919 0.8962926026177216" />
            </geometry>
            <material name="Green">
                <color rgba="0.0 1.0 0.0 1.0"/>
            </material>
        </visual>
        <collision>
            <origin xyz="0.06838714457704628 -0.37123860019204596 0.17316696073160925" rpy="0 0 0"/>
            <geometry>
                <box size="0.6370844687734599 0.7424772003840919 0.8962926026177216" />
            </geometry>
        </collision>
    </link>
    <joint name="link4_link5" type="revolute">
       <parent link="link4"/>
       <child  link="link5"/>
       <origin rpy="0 0 0" xyz="0.3370506936363986 -0.6314832730359504 0.62131326204047" />
     <axis xyz="0 1 0"/>
       <limit effort="0.0" lower="-3.14159" upper="3.14159" velocity="0.0"/>
    </joint>
    <link name="link5">
        <inertial>
            <origin xyz="-0.17847340818587074 -0.07153249270965162 0.058873487022151505" rpy="0 0 0"/>
            <mass value="1" />
            <inertia ixx="100" ixy="0" ixz="0" iyy="100" iyz="0" izz="100" />
        </inertial>
        <visual>
            <origin xyz="-0.17847340818587074 -0.07153249270965162 0.058873487022151505" rpy="0 0 0"/>
            <geometry>
                <box size="0.9808672231306346 0.20482050124773332 0.11774697404430301" />
            </geometry>
            <material name="Green">
                <color rgba="0.0 1.0 0.0 1.0"/>
            </material>
        </visual>
        <collision>
            <origin xyz="-0.17847340818587074 -0.07153249270965162 0.058873487022151505" rpy="0 0 0"/>
            <geometry>
                <box size="0.9808672231306346 0.20482050124773332 0.11774697404430301" />
            </geometry>
        </collision>
    </link>
    <joint name="link5_link6" type="revolute">
       <parent link="link5"/>
       <child  link="link6"/>
       <origin rpy="0 0 0" xyz="0.3119602033794465 0.024116384659251103 0.018554959356311948" />
     <axis xyz="0 1 0"/>
       <limit effort="0.0" lower="-3.14159" upper="3.14159" velocity="0.0"/>
    </joint>
    <link name="link6">
        <inertial>
            <origin xyz="0.2728638607024553 0.003082805653713594 -0.417391088491836" rpy="0 0 0"/>
            <mass value="1" />
            <inertia ixx="100" ixy="0" ixz="0" iyy="100" iyz="0" izz="100" />
        </inertial>
        <visual>
            <origin xyz="0.2728638607024553 0.003082805653713594 -0.417391088491836" rpy="0 0 0"/>
            <geometry>
                <box size="0.5457277214049105 0.011799368726044812 0.8421469049592205" />
            </geometry>
            <material name="Green">
                <color rgba="0.0 1.0 0.0 1.0"/>
            </material>
        </visual>
        <collision>
            <origin xyz="0.2728638607024553 0.003082805653713594 -0.417391088491836" rpy="0 0 0"/>
            <geometry>
                <box size="0.5457277214049105 0.011799368726044812 0.8421469049592205" />
            </geometry>
        </collision>
    </link>
</robot>