<robot name = "robot">
    <link name="link0">
        <inertial>
            <origin xyz="0 0 1" rpy="0 0 0"/>
            <mass value="1" />
            <inertia ixx="100" ixy="0" ixz="0" iyy="100" iyz="0" izz="100" />
        </inertial>
        <visual>
            <origin xyz="0 0 1" rpy="0 0 0"/>
            <geometry>
                <box size="0.7342836119687147 0.5868323532865485 0.7141384470727118" />
            </geometry>
            <material name="Cyan">
                <color rgba="0.0 1.0 1.0 1.0"/>
            </material>
        </visual>
        <collision>
            <origin xyz="0 0 1" rpy="0 0 0"/>
            <geometry>
                <box size="0.7342836119687147 0.5868323532865485 0.7141384470727118" />
            </geometry>
        </collision>
    </link>
    <joint name="link0_link1" type="revolute">
       <parent link="link0"/>
       <child  link="link1"/>
       <origin rpy="0 0 0" xyz="-0.32176776432999743 0.29341617664327424 0.6709962742889168" />
     <axis xyz="0 0 1"/>
       <limit effort="0.0" lower="-3.14159" upper="3.14159" velocity="0.0"/>
    </joint>
    <link name="link1">
        <inertial>
            <origin xyz="0.18889192440795455 0.262973100547935 0.16459656149211122" rpy="0 0 0"/>
            <mass value="1" />
            <inertia ixx="100" ixy="0" ixz="0" iyy="100" iyz="0" izz="100" />
        </inertial>
        <visual>
            <origin xyz="0.18889192440795455 0.262973100547935 0.16459656149211122" rpy="0 0 0"/>
            <geometry>
                <box size="0.7207833264763385 0.52594620109587 0.3833025184477623" />
            </geometry>
            <material name="Green">
                <color rgba="0.0 1.0 0.0 1.0"/>
            </material>
        </visual>
        <collision>
            <origin xyz="0.18889192440795455 0.262973100547935 0.16459656149211122" rpy="0 0 0"/>
            <geometry>
                <box size="0.7207833264763385 0.52594620109587 0.3833025184477623" />
            </geometry>
        </collision>
    </link>
    <joint name="link1_link2" type="revolute">
       <parent link="link1"/>
       <child  link="link2"/>
       <origin rpy="0 0 0" xyz="-0.038998359677225924 0.52594620109587 0.09936323080391583" />
     <axis xyz="0 1 0"/>
       <limit effort="0.0" lower="-3.14159" upper="3.14159" velocity="0.0"/>
    </joint>
    <link name="link2">
        <inertial>
            <origin xyz="0.28404681331600584 0.22107707309479485 -0.01915991758385826" rpy="0 0 0"/>
            <mass value="1" />
            <inertia ixx="100" ixy="0" ixz="0" iyy="100" iyz="0" izz="100" />
        </inertial>
        <visual>
            <origin xyz="0.28404681331600584 0.22107707309479485 -0.01915991758385826" rpy="0 0 0"/>
            <geometry>
                <box size="0.8524543543146075 0.4421541461895897 0.062268761038573706" />
            </geometry>
            <material name="Cyan">
                <color rgba="0.0 1.0 1.0 1.0"/>
            </material>
        </visual>
        <collision>
            <origin xyz="0.28404681331600584 0.22107707309479485 -0.01915991758385826" rpy="0 0 0"/>
            <geometry>
                <box size="0.8524543543146075 0.4421541461895897 0.062268761038573706" />
            </geometry>
        </collision>
    </link>
    <joint name="link1_link3" type="revolute">
       <parent link="link1"/>
       <child  link="link3"/>
       <origin rpy="0 0 0" xyz="-0.1714997388302147 0.5121738525715921 0.01958717594531037" />
     <axis xyz="0 0 1"/>
       <limit effort="0.0" lower="-3.14159" upper="3.14159" velocity="0.0"/>
    </joint>
    <link name="link3">
        <inertial>
            <origin xyz="-0.09998674978283822 0.02939797423377128 -0.07982965076193393" rpy="0 0 0"/>
            <mass value="1" />
            <inertia ixx="100" ixy="0" ixz="0" iyy="100" iyz="0" izz="100" />
        </inertial>
        <visual>
            <origin xyz="-0.09998674978283822 0.02939797423377128 -0.07982965076193393" rpy="0 0 0"/>
            <geometry>
                <box size="0.19997349956567645 0.14269130216792092 0.2965846804399487" />
            </geometry>
            <material name="Green">
                <color rgba="0.0 1.0 0.0 1.0"/>
            </material>
        </visual>
        <collision>
            <origin xyz="-0.09998674978283822 0.02939797423377128 -0.07982965076193393" rpy="0 0 0"/>
            <geometry>
                <box size="0.19997349956567645 0.14269130216792092 0.2965846804399487" />
            </geometry>
        </collision>
    </link>
    <joint name="link3_link4" type="revolute">
       <parent link="link3"/>
       <child  link="link4"/>
       <origin rpy="0 0 0" xyz="-0.11731561663279196 0.10074362531773173 0.05574947573682146" />
     <axis xyz="0 0 1"/>
       <limit effort="0.0" lower="-3.14159" upper="3.14159" velocity="0.0"/>
    </joint>
    <link name="link4">
        <inertial>
            <origin xyz="-0.16066425752168317 0.2632115044876528 -0.05685847400596828" rpy="0 0 0"/>
            <mass value="1" />
            <inertia ixx="100" ixy="0" ixz="0" iyy="100" iyz="0" izz="100" />
        </inertial>
        <visual>
            <origin xyz="-0.16066425752168317 0.2632115044876528 -0.05685847400596828" rpy="0 0 0"/>
            <geometry>
                <box size="0.3360902085934687 0.5264230089753056 0.5069691179180593" />
            </geometry>
            <material name="Green">
                <color rgba="0.0 1.0 0.0 1.0"/>
            </material>
        </visual>
        <collision>
            <origin xyz="-0.16066425752168317 0.2632115044876528 -0.05685847400596828" rpy="0 0 0"/>
            <geometry>
                <box size="0.3360902085934687 0.5264230089753056 0.5069691179180593" />
            </geometry>
        </collision>
    </link>
    <joint name="link1_link5" type="revolute">
       <parent link="link1"/>
       <child  link="link5"/>
       <origin rpy="0 0 0" xyz="0.5492835876461237 0.19623921780315823 0.3174725785428139" />
     <axis xyz="0 0 1"/>
       <limit effort="0.0" lower="-3.14159" upper="3.14159" velocity="0.0"/>
    </joint>
    <link name="link5">
        <inertial>
            <origin xyz="0.41404372278247753 -0.08014095560693288 0.23676592363039065" rpy="0 0 0"/>
            <mass value="1" />
            <inertia ixx="100" ixy="0" ixz="0" iyy="100" iyz="0" izz="100" />
        </inertial>
        <visual>
            <origin xyz="0.41404372278247753 -0.08014095560693288 0.23676592363039065" rpy="0 0 0"/>
            <geometry>
                <box size="0.8280874455649551 0.16926187467502285 0.9579429563468511" />
            </geometry>
            <material name="Cyan">
                <color rgba="0.0 1.0 1.0 1.0"/>
            </material>
        </visual>
        <collision>
            <origin xyz="0.41404372278247753 -0.08014095560693288 0.23676592363039065" rpy="0 0 0"/>
            <geometry>
                <box size="0.8280874455649551 0.16926187467502285 0.9579429563468511" />
            </geometry>
        </collision>
    </link>
</robot>