<robot name = "robot">
    <link name="link0">
        <inertial>
            <origin xyz="0 0 1" rpy="0 0 0"/>
            <mass value="1" />
            <inertia ixx="100" ixy="0" ixz="0" iyy="100" iyz="0" izz="100" />
        </inertial>
        <visual>
            <origin xyz="0 0 1" rpy="0 0 0"/>
            <geometry>
                <box size="0.8298431234710304 0.8507650199925063 0.3059558615985256" />
            </geometry>
            <material name="Cyan">
                <color rgba="0.0 1.0 1.0 1.0"/>
            </material>
        </visual>
        <collision>
            <origin xyz="0 0 1" rpy="0 0 0"/>
            <geometry>
                <box size="0.8298431234710304 0.8507650199925063 0.3059558615985256" />
            </geometry>
        </collision>
    </link>
    <joint name="link0_link1" type="revolute">
       <parent link="link0"/>
       <child  link="link1"/>
       <origin rpy="0 0 0" xyz="-0.33004963993385505 0.19304253335568902 1.152977930799263" />
     <axis xyz="0 0 1"/>
       <limit effort="0.0" lower="-3.14159" upper="3.14159" velocity="0.0"/>
    </joint>
    <link name="link1">
        <inertial>
            <origin xyz="0.05891966580146774 -0.06654183259859373 0.20571368411886654" rpy="0 0 0"/>
            <mass value="1" />
            <inertia ixx="100" ixy="0" ixz="0" iyy="100" iyz="0" izz="100" />
        </inertial>
        <visual>
            <origin xyz="0.05891966580146774 -0.06654183259859373 0.20571368411886654" rpy="0 0 0"/>
            <geometry>
                <box size="0.9078733739710649 0.2847474377349053 0.41142736823773307" />
            </geometry>
            <material name="Green">
                <color rgba="0.0 1.0 0.0 1.0"/>
            </material>
        </visual>
        <collision>
            <origin xyz="0.05891966580146774 -0.06654183259859373 0.20571368411886654" rpy="0 0 0"/>
            <geometry>
                <box size="0.9078733739710649 0.2847474377349053 0.41142736823773307" />
            </geometry>
        </collision>
    </link>
    <joint name="link0_link2" type="revolute">
       <parent link="link0"/>
       <child  link="link2"/>
       <origin rpy="0 0 0" xyz="0.21016071639297224 0.3675226077473608 1.152977930799263" />
     <axis xyz="0 1 0"/>
       <limit effort="0.0" lower="-3.14159" upper="3.14159" velocity="0.0"/>
    </joint>
    <link name="link2">
        <inertial>
            <origin xyz="0.17483244391529018 0.02403876218479716 0.08409749001303451" rpy="0 0 0"/>
            <mass value="1" />
            <inertia ixx="100" ixy="0" ixz="0" iyy="100" iyz="0" izz="100" />
        </inertial>
        <visual>
            <origin xyz="0.17483244391529018 0.02403876218479716 0.08409749001303451" rpy="0 0 0"/>
            <geometry>
                <box size="0.3839010623485821 0.20352613032606603 0.16819498002606903" />
            </geometry>
            <material name="Green">
                <color rgba="0.0 1.0 0.0 1.0"/>
            </material>
        </visual>
        <collision>
            <origin xyz="0.17483244391529018 0.02403876218479716 0.08409749001303451" rpy="0 0 0"/>
            <geometry>
                <box size="0.3839010623485821 0.20352613032606603 0.16819498002606903" />
            </geometry>
        </collision>
    </link>
    <joint name="link1_link3" type="revolute">
       <parent link="link1"/>
       <child  link="link3"/>
       <origin rpy="0 0 0" xyz="0.28524423329566634 -0.20891555146604637 0.2013400815651082" />
     <axis xyz="1 0 0"/>
       <limit effort="0.0" lower="-3.14159" upper="3.14159" velocity="0.0"/>
    </joint>
    <link name="link3">
        <inertial>
            <origin xyz="-0.1302391201048524 -0.05113644271290457 -0.11529454354121962" rpy="0 0 0"/>
            <mass value="1" />
            <inertia ixx="100" ixy="0" ixz="0" iyy="100" iyz="0" izz="100" />
        </inertial>
        <visual>
            <origin xyz="-0.1302391201048524 -0.05113644271290457 -0.11529454354121962" rpy="0 0 0"/>
            <geometry>
                <box size="0.3686007570925991 0.10227288542580915 0.5611637803814107" />
            </geometry>
            <material name="Green">
                <color rgba="0.0 1.0 0.0 1.0"/>
            </material>
        </visual>
        <collision>
            <origin xyz="-0.1302391201048524 -0.05113644271290457 -0.11529454354121962" rpy="0 0 0"/>
            <geometry>
                <box size="0.3686007570925991 0.10227288542580915 0.5611637803814107" />
            </geometry>
        </collision>
    </link>
    <joint name="link0_link4" type="revolute">
       <parent link="link0"/>
       <child  link="link4"/>
       <origin rpy="0 0 0" xyz="0.3404694617298427 0.42538250999625316 0.9829140260986202" />
     <axis xyz="0 1 0"/>
       <limit effort="0.0" lower="-3.14159" upper="3.14159" velocity="0.0"/>
    </joint>
    <link name="link4">
        <inertial>
            <origin xyz="0.12149076763193811 0.08707403876467917 -0.04305104742478077" rpy="0 0 0"/>
            <mass value="1" />
            <inertia ixx="100" ixy="0" ixz="0" iyy="100" iyz="0" izz="100" />
        </inertial>
        <visual>
            <origin xyz="0.12149076763193811 0.08707403876467917 -0.04305104742478077" rpy="0 0 0"/>
            <geometry>
                <box size="0.5639691936920541 0.17414807752935835 0.5081959422068968" />
            </geometry>
            <material name="Cyan">
                <color rgba="0.0 1.0 1.0 1.0"/>
            </material>
        </visual>
        <collision>
            <origin xyz="0.12149076763193811 0.08707403876467917 -0.04305104742478077" rpy="0 0 0"/>
            <geometry>
                <box size="0.5639691936920541 0.17414807752935835 0.5081959422068968" />
            </geometry>
        </collision>
    </link>
    <joint name="link3_link5" type="revolute">
       <parent link="link3"/>
       <child  link="link5"/>
       <origin rpy="0 0 0" xyz="0.05406125844144716 -0.04139096394830073 0.06461520152905445" />
     <axis xyz="0 1 0"/>
       <limit effort="0.0" lower="-3.14159" upper="3.14159" velocity="0.0"/>
    </joint>
    <link name="link5">
        <inertial>
            <origin xyz="0.06570187567373253 0.04712960484916093 0.17802365052635852" rpy="0 0 0"/>
            <mass value="1" />
            <inertia ixx="100" ixy="0" ixz="0" iyy="100" iyz="0" izz="100" />
        </inertial>
        <visual>
            <origin xyz="0.06570187567373253 0.04712960484916093 0.17802365052635852" rpy="0 0 0"/>
            <geometry>
                <box size="0.13140375134746507 0.4262063457402512 0.4351734485615232" />
            </geometry>
            <material name="Green">
                <color rgba="0.0 1.0 0.0 1.0"/>
            </material>
        </visual>
        <collision>
            <origin xyz="0.06570187567373253 0.04712960484916093 0.17802365052635852" rpy="0 0 0"/>
            <geometry>
                <box size="0.13140375134746507 0.4262063457402512 0.4351734485615232" />
            </geometry>
        </collision>
    </link>
    <joint name="link4_link6" type="revolute">
       <parent link="link4"/>
       <child  link="link6"/>
       <origin rpy="0 0 0" xyz="-0.09379795441269281 0.0 0.14094036175304525" />
     <axis xyz="0 1 0"/>
       <limit effort="0.0" lower="-3.14159" upper="3.14159" velocity="0.0"/>
    </joint>
    <link name="link6">
        <inertial>
            <origin xyz="0.07555111910778849 -0.40050290801827565 -0.155648657850348" rpy="0 0 0"/>
            <mass value="1" />
            <inertia ixx="100" ixy="0" ixz="0" iyy="100" iyz="0" izz="100" />
        </inertial>
        <visual>
            <origin xyz="0.07555111910778849 -0.40050290801827565 -0.155648657850348" rpy="0 0 0"/>
            <geometry>
                <box size="0.22044125031460615 0.8010058160365513 0.6594051314419103" />
            </geometry>
            <material name="Green">
                <color rgba="0.0 1.0 0.0 1.0"/>
            </material>
        </visual>
        <collision>
            <origin xyz="0.07555111910778849 -0.40050290801827565 -0.155648657850348" rpy="0 0 0"/>
            <geometry>
                <box size="0.22044125031460615 0.8010058160365513 0.6594051314419103" />
            </geometry>
        </collision>
    </link>
    <joint name="link0_link7" type="revolute">
       <parent link="link0"/>
       <child  link="link7"/>
       <origin rpy="0 0 0" xyz="0.4149215617355152 0.28765469712955033 0.9620606178905845" />
     <axis xyz="1 0 0"/>
       <limit effort="0.0" lower="-3.14159" upper="3.14159" velocity="0.0"/>
    </joint>
    <link name="link7">
        <inertial>
            <origin xyz="0.39731493496070447 0.4059236644591897 0.3687079714656836" rpy="0 0 0"/>
            <mass value="1" />
            <inertia ixx="100" ixy="0" ixz="0" iyy="100" iyz="0" izz="100" />
        </inertial>
        <visual>
            <origin xyz="0.39731493496070447 0.4059236644591897 0.3687079714656836" rpy="0 0 0"/>
            <geometry>
                <box size="0.7946298699214089 0.9946834015147736 0.7732163833601791" />
            </geometry>
            <material name="Green">
                <color rgba="0.0 1.0 0.0 1.0"/>
            </material>
        </visual>
        <collision>
            <origin xyz="0.39731493496070447 0.4059236644591897 0.3687079714656836" rpy="0 0 0"/>
            <geometry>
                <box size="0.7946298699214089 0.9946834015147736 0.7732163833601791" />
            </geometry>
        </collision>
    </link>
</robot>