<robot name = "robot">
    <link name="link0">
        <inertial>
            <origin xyz="0 0 1" rpy="0 0 0"/>
            <mass value="1" />
            <inertia ixx="100" ixy="0" ixz="0" iyy="100" iyz="0" izz="100" />
        </inertial>
        <visual>
            <origin xyz="0 0 1" rpy="0 0 0"/>
            <geometry>
                <box size="0.22052214141491078 0.9125400322974014 0.8550179975174113" />
            </geometry>
            <material name="Cyan">
                <color rgba="0 1.0 1.0 1.0"/>
            </material>
        </visual>
        <collision>
            <origin xyz="0 0 1" rpy="0 0 0"/>
            <geometry>
                <box size="0.22052214141491078 0.9125400322974014 0.8550179975174113" />
            </geometry>
        </collision>
    </link>
    <joint name="link0_link1" type="revolute">
       <parent link="link0"/>
       <child  link="link1"/>
       <origin rpy="0 0 0" xyz="-0.08533581599914866 0.0947142648677885 1.4275089987587055" />
     <axis xyz="0 0 1"/>
       <limit effort="0.0" lower="-3.14159" upper="3.14159" velocity="0.0"/>
    </joint>
    <link name="link1">
        <inertial>
            <origin xyz="0.18635584718203604 -0.15390124293642024 0.48889835976922846" rpy="0 0 0"/>
            <mass value="1" />
            <inertia ixx="100" ixy="0" ixz="0" iyy="100" iyz="0" izz="100" />
        </inertial>
        <visual>
            <origin xyz="0.18635584718203604 -0.15390124293642024 0.48889835976922846" rpy="0 0 0"/>
            <geometry>
                <box size="0.5889900714480814 0.358858234522208 0.9777967195384569" />
            </geometry>
            <material name="Cyan">
                <color rgba="0 1.0 1.0 1.0"/>
            </material>
        </visual>
        <collision>
            <origin xyz="0.18635584718203604 -0.15390124293642024 0.48889835976922846" rpy="0 0 0"/>
            <geometry>
                <box size="0.5889900714480814 0.358858234522208 0.9777967195384569" />
            </geometry>
        </collision>
    </link>
    <joint name="link0_link2" type="revolute">
       <parent link="link0"/>
       <child  link="link2"/>
       <origin rpy="0 0 0" xyz="0.11026107070745539 -0.43188713906698134 0.967605171767173" />
     <axis xyz="1 0 0"/>
       <limit effort="0.0" lower="-3.14159" upper="3.14159" velocity="0.0"/>
    </joint>
    <link name="link2">
        <inertial>
            <origin xyz="0.4900152001335867 -0.061112744302062254 0.043992096277825195" rpy="0 0 0"/>
            <mass value="1" />
            <inertia ixx="100" ixy="0" ixz="0" iyy="100" iyz="0" izz="100" />
        </inertial>
        <visual>
            <origin xyz="0.4900152001335867 -0.061112744302062254 0.043992096277825195" rpy="0 0 0"/>
            <geometry>
                <box size="0.9800304002671734 0.2126321769631373 0.19897646078311138" />
            </geometry>
            <material name="Cyan">
                <color rgba="0 1.0 1.0 1.0"/>
            </material>
        </visual>
        <collision>
            <origin xyz="0.4900152001335867 -0.061112744302062254 0.043992096277825195" rpy="0 0 0"/>
            <geometry>
                <box size="0.9800304002671734 0.2126321769631373 0.19897646078311138" />
            </geometry>
        </collision>
    </link>
    <joint name="link2_link3" type="revolute">
       <parent link="link2"/>
       <child  link="link3"/>
       <origin rpy="0 0 0" xyz="0.06920162848843026 -0.1674288327836309 -0.047521040551569284" />
     <axis xyz="0 1 0"/>
       <limit effort="0.0" lower="-3.14159" upper="3.14159" velocity="0.0"/>
    </joint>
    <link name="link3">
        <inertial>
            <origin xyz="-0.0697058184048435 -0.299879430987945 -0.39001304081327043" rpy="0 0 0"/>
            <mass value="1" />
            <inertia ixx="100" ixy="0" ixz="0" iyy="100" iyz="0" izz="100" />
        </inertial>
        <visual>
            <origin xyz="-0.0697058184048435 -0.299879430987945 -0.39001304081327043" rpy="0 0 0"/>
            <geometry>
                <box size="0.41966026716841187 0.59975886197589 0.9894074829536833" />
            </geometry>
            <material name="Cyan">
                <color rgba="0 1.0 1.0 1.0"/>
            </material>
        </visual>
        <collision>
            <origin xyz="-0.0697058184048435 -0.299879430987945 -0.39001304081327043" rpy="0 0 0"/>
            <geometry>
                <box size="0.41966026716841187 0.59975886197589 0.9894074829536833" />
            </geometry>
        </collision>
    </link>
    <joint name="link0_link4" type="revolute">
       <parent link="link0"/>
       <child  link="link4"/>
       <origin rpy="0 0 0" xyz="0.11026107070745539 -0.3875888934901261 0.835447950264816" />
     <axis xyz="0 1 0"/>
       <limit effort="0.0" lower="-3.14159" upper="3.14159" velocity="0.0"/>
    </joint>
    <link name="link4">
        <inertial>
            <origin xyz="0.1416039931528285 0.09154251322167051 -0.2508035422579683" rpy="0 0 0"/>
            <mass value="1" />
            <inertia ixx="100" ixy="0" ixz="0" iyy="100" iyz="0" izz="100" />
        </inertial>
        <visual>
            <origin xyz="0.1416039931528285 0.09154251322167051 -0.2508035422579683" rpy="0 0 0"/>
            <geometry>
                <box size="0.283207986305657 0.7551308052957002 0.6881540156579088" />
            </geometry>
            <material name="Cyan">
                <color rgba="0 1.0 1.0 1.0"/>
            </material>
        </visual>
        <collision>
            <origin xyz="0.1416039931528285 0.09154251322167051 -0.2508035422579683" rpy="0 0 0"/>
            <geometry>
                <box size="0.283207986305657 0.7551308052957002 0.6881540156579088" />
            </geometry>
        </collision>
    </link>
    <joint name="link2_link5" type="revolute">
       <parent link="link2"/>
       <child  link="link5"/>
       <origin rpy="0 0 0" xyz="0.0 0.005636356191901969 -0.04925825270317207" />
     <axis xyz="0 0 1"/>
       <limit effort="0.0" lower="-3.14159" upper="3.14159" velocity="0.0"/>
    </joint>
    <link name="link5">
        <inertial>
            <origin xyz="-0.3020730269333201 0.026188744785460367 -0.22163190747877176" rpy="0 0 0"/>
            <mass value="1" />
            <inertia ixx="100" ixy="0" ixz="0" iyy="100" iyz="0" izz="100" />
        </inertial>
        <visual>
            <origin xyz="-0.3020730269333201 0.026188744785460367 -0.22163190747877176" rpy="0 0 0"/>
            <geometry>
                <box size="0.6041460538666402 0.6105711640293227 0.6583793820590368" />
            </geometry>
            <material name="Cyan">
                <color rgba="0 1.0 1.0 1.0"/>
            </material>
        </visual>
        <collision>
            <origin xyz="-0.3020730269333201 0.026188744785460367 -0.22163190747877176" rpy="0 0 0"/>
            <geometry>
                <box size="0.6041460538666402 0.6105711640293227 0.6583793820590368" />
            </geometry>
        </collision>
    </link>
    <joint name="link4_link6" type="revolute">
       <parent link="link4"/>
       <child  link="link6"/>
       <origin rpy="0 0 0" xyz="0.12903696896071287 0.4691079158695206 -0.44979894138119225" />
     <axis xyz="1 0 0"/>
       <limit effort="0.0" lower="-3.14159" upper="3.14159" velocity="0.0"/>
    </joint>
    <link name="link6">
        <inertial>
            <origin xyz="0.27836290897714383 0.3168876577055853 0.006798286679614995" rpy="0 0 0"/>
            <mass value="1" />
            <inertia ixx="100" ixy="0" ixz="0" iyy="100" iyz="0" izz="100" />
        </inertial>
        <visual>
            <origin xyz="0.27836290897714383 0.3168876577055853 0.006798286679614995" rpy="0 0 0"/>
            <geometry>
                <box size="0.7187043646763751 0.6337753154111706 0.013740177971349965" />
            </geometry>
            <material name="Cyan">
                <color rgba="0 1.0 1.0 1.0"/>
            </material>
        </visual>
        <collision>
            <origin xyz="0.27836290897714383 0.3168876577055853 0.006798286679614995" rpy="0 0 0"/>
            <geometry>
                <box size="0.7187043646763751 0.6337753154111706 0.013740177971349965" />
            </geometry>
        </collision>
    </link>
    <joint name="link2_link7" type="revolute">
       <parent link="link2"/>
       <child  link="link7"/>
       <origin rpy="0 0 0" xyz="0.0 -0.11225889793955253 -0.027223980139300143" />
     <axis xyz="0 0 1"/>
       <limit effort="0.0" lower="-3.14159" upper="3.14159" velocity="0.0"/>
    </joint>
    <link name="link7">
        <inertial>
            <origin xyz="-0.028123629179329868 0.3992242664965929 -0.0056400574908978636" rpy="0 0 0"/>
            <mass value="1" />
            <inertia ixx="100" ixy="0" ixz="0" iyy="100" iyz="0" izz="100" />
        </inertial>
        <visual>
            <origin xyz="-0.028123629179329868 0.3992242664965929 -0.0056400574908978636" rpy="0 0 0"/>
            <geometry>
                <box size="0.056247258358659735 0.8298910899026387 0.22958544661019642" />
            </geometry>
            <material name="Cyan">
                <color rgba="0 1.0 1.0 1.0"/>
            </material>
        </visual>
        <collision>
            <origin xyz="-0.028123629179329868 0.3992242664965929 -0.0056400574908978636" rpy="0 0 0"/>
            <geometry>
                <box size="0.056247258358659735 0.8298910899026387 0.22958544661019642" />
            </geometry>
        </collision>
    </link>
    <joint name="link1_link8" type="revolute">
       <parent link="link1"/>
       <child  link="link8"/>
       <origin rpy="0 0 0" xyz="-0.10813918854200463 -0.0995464668753123 0.4429388017393261" />
     <axis xyz="0 1 0"/>
       <limit effort="0.0" lower="-3.14159" upper="3.14159" velocity="0.0"/>
    </joint>
    <link name="link8">
        <inertial>
            <origin xyz="-0.4627828400981511 0.1618102922268608 0.31008616590406135" rpy="0 0 0"/>
            <mass value="1" />
            <inertia ixx="100" ixy="0" ixz="0" iyy="100" iyz="0" izz="100" />
        </inertial>
        <visual>
            <origin xyz="-0.4627828400981511 0.1618102922268608 0.31008616590406135" rpy="0 0 0"/>
            <geometry>
                <box size="0.9255656801963023 0.8729116424271787 0.9784506328908317" />
            </geometry>
            <material name="Cyan">
                <color rgba="0 1.0 1.0 1.0"/>
            </material>
        </visual>
        <collision>
            <origin xyz="-0.4627828400981511 0.1618102922268608 0.31008616590406135" rpy="0 0 0"/>
            <geometry>
                <box size="0.9255656801963023 0.8729116424271787 0.9784506328908317" />
            </geometry>
        </collision>
    </link>
    <joint name="link3_link9" type="revolute">
       <parent link="link3"/>
       <child  link="link9"/>
       <origin rpy="0 0 0" xyz="0.14012431517936244 -0.5343419222728932 -0.5710325057724754" />
     <axis xyz="1 0 0"/>
       <limit effort="0.0" lower="-3.14159" upper="3.14159" velocity="0.0"/>
    </joint>
    <link name="link9">
        <inertial>
            <origin xyz="0.07528162177961956 -0.0938660470475299 -0.15920499469075614" rpy="0 0 0"/>
            <mass value="1" />
            <inertia ixx="100" ixy="0" ixz="0" iyy="100" iyz="0" izz="100" />
        </inertial>
        <visual>
            <origin xyz="0.07528162177961956 -0.0938660470475299 -0.15920499469075614" rpy="0 0 0"/>
            <geometry>
                <box size="0.1505632435592391 0.28251146520964043 0.9509241387657288" />
            </geometry>
            <material name="Cyan">
                <color rgba="0 1.0 1.0 1.0"/>
            </material>
        </visual>
        <collision>
            <origin xyz="0.07528162177961956 -0.0938660470475299 -0.15920499469075614" rpy="0 0 0"/>
            <geometry>
                <box size="0.1505632435592391 0.28251146520964043 0.9509241387657288" />
            </geometry>
        </collision>
    </link>
</robot>