<robot name = "robot">
    <link name="link0">
        <inertial>
            <origin xyz="0 0 1" rpy="0 0 0"/>
            <mass value="1" />
            <inertia ixx="100" ixy="0" ixz="0" iyy="100" iyz="0" izz="100" />
        </inertial>
        <visual>
            <origin xyz="0 0 1" rpy="0 0 0"/>
            <geometry>
                <box size="0.5226398182657578 0.006046387014123855 0.8469539461824387" />
            </geometry>
            <material name="Cyan">
                <color rgba="0 1.0 1.0 1.0"/>
            </material>
        </visual>
        <collision>
            <origin xyz="0 0 1" rpy="0 0 0"/>
            <geometry>
                <box size="0.5226398182657578 0.006046387014123855 0.8469539461824387" />
            </geometry>
        </collision>
    </link>
    <joint name="link0_link1" type="revolute">
       <parent link="link0"/>
       <child  link="link1"/>
       <origin rpy="0 0 0" xyz="0.16734137459519752 0.0024436979802650747 1.4234769730912193" />
     <axis xyz="1 0 0"/>
       <limit effort="0.0" lower="-3.14159" upper="3.14159" velocity="0.0"/>
    </joint>
    <link name="link1">
        <inertial>
            <origin xyz="0.1778018781431638 0.15563548601822033 0.3483691582093631" rpy="0 0 0"/>
            <mass value="1" />
            <inertia ixx="100" ixy="0" ixz="0" iyy="100" iyz="0" izz="100" />
        </inertial>
        <visual>
            <origin xyz="0.1778018781431638 0.15563548601822033 0.3483691582093631" rpy="0 0 0"/>
            <geometry>
                <box size="0.4267849156500757 0.44264645887863807 0.6967383164187262" />
            </geometry>
            <material name="Cyan">
                <color rgba="0 1.0 1.0 1.0"/>
            </material>
        </visual>
        <collision>
            <origin xyz="0.1778018781431638 0.15563548601822033 0.3483691582093631" rpy="0 0 0"/>
            <geometry>
                <box size="0.4267849156500757 0.44264645887863807 0.6967383164187262" />
            </geometry>
        </collision>
    </link>
    <joint name="link1_link2" type="revolute">
       <parent link="link1"/>
       <child  link="link2"/>
       <origin rpy="0 0 0" xyz="-0.03559057968187404 0.04555779780887585 0.5682105362025465" />
     <axis xyz="0 1 0"/>
       <limit effort="0.0" lower="-3.14159" upper="3.14159" velocity="0.0"/>
    </joint>
    <link name="link2">
        <inertial>
            <origin xyz="-0.2617567498794647 0.014952037467681737 0.02193404093870424" rpy="0 0 0"/>
            <mass value="1" />
            <inertia ixx="100" ixy="0" ixz="0" iyy="100" iyz="0" izz="100" />
        </inertial>
        <visual>
            <origin xyz="-0.2617567498794647 0.014952037467681737 0.02193404093870424" rpy="0 0 0"/>
            <geometry>
                <box size="0.5235134997589294 0.03619636960403516 0.04663540345658357" />
            </geometry>
            <material name="Cyan">
                <color rgba="0 1.0 1.0 1.0"/>
            </material>
        </visual>
        <collision>
            <origin xyz="-0.2617567498794647 0.014952037467681737 0.02193404093870424" rpy="0 0 0"/>
            <geometry>
                <box size="0.5235134997589294 0.03619636960403516 0.04663540345658357" />
            </geometry>
        </collision>
    </link>
    <joint name="link1_link3" type="revolute">
       <parent link="link1"/>
       <child  link="link3"/>
       <origin rpy="0 0 0" xyz="0.26398714213217267 0.37695871545753934 0.5955260156312557" />
     <axis xyz="1 0 0"/>
       <limit effort="0.0" lower="-3.14159" upper="3.14159" velocity="0.0"/>
    </joint>
    <link name="link3">
        <inertial>
            <origin xyz="0.11702553766949227 0.40479939262056064 0.08645040163061424" rpy="0 0 0"/>
            <mass value="1" />
            <inertia ixx="100" ixy="0" ixz="0" iyy="100" iyz="0" izz="100" />
        </inertial>
        <visual>
            <origin xyz="0.11702553766949227 0.40479939262056064 0.08645040163061424" rpy="0 0 0"/>
            <geometry>
                <box size="0.521439971975091 0.8095987852411213 0.6818736954234749" />
            </geometry>
            <material name="Cyan">
                <color rgba="0 1.0 1.0 1.0"/>
            </material>
        </visual>
        <collision>
            <origin xyz="0.11702553766949227 0.40479939262056064 0.08645040163061424" rpy="0 0 0"/>
            <geometry>
                <box size="0.521439971975091 0.8095987852411213 0.6818736954234749" />
            </geometry>
        </collision>
    </link>
    <joint name="link1_link4" type="revolute">
       <parent link="link1"/>
       <child  link="link4"/>
       <origin rpy="0 0 0" xyz="0.11101984798010328 -0.0656877434210987 0.16431121214902025" />
     <axis xyz="1 0 0"/>
       <limit effort="0.0" lower="-3.14159" upper="3.14159" velocity="0.0"/>
    </joint>
    <link name="link4">
        <inertial>
            <origin xyz="-0.18019018717029506 -0.19476897870074883 0.020116649217149302" rpy="0 0 0"/>
            <mass value="1" />
            <inertia ixx="100" ixy="0" ixz="0" iyy="100" iyz="0" izz="100" />
        </inertial>
        <visual>
            <origin xyz="-0.18019018717029506 -0.19476897870074883 0.020116649217149302" rpy="0 0 0"/>
            <geometry>
                <box size="0.8397785090990586 0.38953795740149766 0.06822064495027469" />
            </geometry>
            <material name="Cyan">
                <color rgba="0 1.0 1.0 1.0"/>
            </material>
        </visual>
        <collision>
            <origin xyz="-0.18019018717029506 -0.19476897870074883 0.020116649217149302" rpy="0 0 0"/>
            <geometry>
                <box size="0.8397785090990586 0.38953795740149766 0.06822064495027469" />
            </geometry>
        </collision>
    </link>
    <joint name="link2_link5" type="revolute">
       <parent link="link2"/>
       <child  link="link5"/>
       <origin rpy="0 0 0" xyz="-0.5235134997589294 0.02270632662518556 0.0015024299818134842" />
     <axis xyz="0 0 1"/>
       <limit effort="0.0" lower="-3.14159" upper="3.14159" velocity="0.0"/>
    </joint>
    <link name="link5">
        <inertial>
            <origin xyz="-0.3077027556365712 0.019189925367586454 -0.03683386493773774" rpy="0 0 0"/>
            <mass value="1" />
            <inertia ixx="100" ixy="0" ixz="0" iyy="100" iyz="0" izz="100" />
        </inertial>
        <visual>
            <origin xyz="-0.3077027556365712 0.019189925367586454 -0.03683386493773774" rpy="0 0 0"/>
            <geometry>
                <box size="0.6154055112731424 0.25750148620550084 0.21179185984621207" />
            </geometry>
            <material name="Cyan">
                <color rgba="0 1.0 1.0 1.0"/>
            </material>
        </visual>
        <collision>
            <origin xyz="-0.3077027556365712 0.019189925367586454 -0.03683386493773774" rpy="0 0 0"/>
            <geometry>
                <box size="0.6154055112731424 0.25750148620550084 0.21179185984621207" />
            </geometry>
        </collision>
    </link>
    <joint name="link4_link6" type="revolute">
       <parent link="link4"/>
       <child  link="link6"/>
       <origin rpy="0 0 0" xyz="-0.08555857919852439 -0.20974823275060597 -0.013993673257988042" />
     <axis xyz="1 0 0"/>
       <limit effort="0.0" lower="-3.14159" upper="3.14159" velocity="0.0"/>
    </joint>
    <link name="link6">
        <inertial>
            <origin xyz="0.028854180380023922 0.016639466240935194 -0.05545914788835965" rpy="0 0 0"/>
            <mass value="1" />
            <inertia ixx="100" ixy="0" ixz="0" iyy="100" iyz="0" izz="100" />
        </inertial>
        <visual>
            <origin xyz="0.028854180380023922 0.016639466240935194 -0.05545914788835965" rpy="0 0 0"/>
            <geometry>
                <box size="0.2978503504421405 0.07579884807144488 0.1109182957767193" />
            </geometry>
            <material name="Cyan">
                <color rgba="0 1.0 1.0 1.0"/>
            </material>
        </visual>
        <collision>
            <origin xyz="0.028854180380023922 0.016639466240935194 -0.05545914788835965" rpy="0 0 0"/>
            <geometry>
                <box size="0.2978503504421405 0.07579884807144488 0.1109182957767193" />
            </geometry>
        </collision>
    </link>
</robot>