<robot name = "robot">
    <link name="link0">
        <inertial>
            <origin xyz="0 0 1" rpy="0 0 0"/>
            <mass value="1" />
            <inertia ixx="100" ixy="0" ixz="0" iyy="100" iyz="0" izz="100" />
        </inertial>
        <visual>
            <origin xyz="0 0 1" rpy="0 0 0"/>
            <geometry>
                <box size="0.48420728253781153 0.27156055862083406 0.23792978327711078" />
            </geometry>
            <material name="Cyan">
                <color rgba="0 1.0 1.0 1.0"/>
            </material>
        </visual>
        <collision>
            <origin xyz="0 0 1" rpy="0 0 0"/>
            <geometry>
                <box size="0.48420728253781153 0.27156055862083406 0.23792978327711078" />
            </geometry>
        </collision>
    </link>
    <joint name="link0_link1" type="revolute">
       <parent link="link0"/>
       <child  link="link1"/>
       <origin rpy="0 0 0" xyz="0.03205193468578632 0.07983485303760966 0.8810351083614446" />
     <axis xyz="1 0 0"/>
       <limit effort="0.0" lower="-3.14159" upper="3.14159" velocity="0.0"/>
    </joint>
    <link name="link1">
        <inertial>
            <origin xyz="-0.009922089440847671 0.021513045810662608 -0.04008176215149606" rpy="0 0 0"/>
            <mass value="1" />
            <inertia ixx="100" ixy="0" ixz="0" iyy="100" iyz="0" izz="100" />
        </inertial>
        <visual>
            <origin xyz="-0.009922089440847671 0.021513045810662608 -0.04008176215149606" rpy="0 0 0"/>
            <geometry>
                <box size="0.15039311948047185 0.045453302041577714 0.08016352430299212" />
            </geometry>
            <material name="Cyan">
                <color rgba="0 1.0 1.0 1.0"/>
            </material>
        </visual>
        <collision>
            <origin xyz="-0.009922089440847671 0.021513045810662608 -0.04008176215149606" rpy="0 0 0"/>
            <geometry>
                <box size="0.15039311948047185 0.045453302041577714 0.08016352430299212" />
            </geometry>
        </collision>
    </link>
    <joint name="link1_link2" type="revolute">
       <parent link="link1"/>
       <child  link="link2"/>
       <origin rpy="0 0 0" xyz="0.02738830554827456 -0.0012136052101262493 -0.07899312390362391" />
     <axis xyz="0 0 1"/>
       <limit effort="0.0" lower="-3.14159" upper="3.14159" velocity="0.0"/>
    </joint>
    <link name="link2">
        <inertial>
            <origin xyz="0.11562124494198849 -0.30263375628683986 0.03361308674493707" rpy="0 0 0"/>
            <mass value="1" />
            <inertia ixx="100" ixy="0" ixz="0" iyy="100" iyz="0" izz="100" />
        </inertial>
        <visual>
            <origin xyz="0.11562124494198849 -0.30263375628683986 0.03361308674493707" rpy="0 0 0"/>
            <geometry>
                <box size="0.4008693667572375 0.6052675125736797 0.09965237327544973" />
            </geometry>
            <material name="Cyan">
                <color rgba="0 1.0 1.0 1.0"/>
            </material>
        </visual>
        <collision>
            <origin xyz="0.11562124494198849 -0.30263375628683986 0.03361308674493707" rpy="0 0 0"/>
            <geometry>
                <box size="0.4008693667572375 0.6052675125736797 0.09965237327544973" />
            </geometry>
        </collision>
    </link>
    <joint name="link1_link3" type="revolute">
       <parent link="link1"/>
       <child  link="link3"/>
       <origin rpy="0 0 0" xyz="0.06527447029938825 0.03944961435138729 -0.019091948751619438" />
     <axis xyz="0 1 0"/>
       <limit effort="0.0" lower="-3.14159" upper="3.14159" velocity="0.0"/>
    </joint>
    <link name="link3">
        <inertial>
            <origin xyz="0.1589503536187688 0.0056242069201451195 -0.010057439889307252" rpy="0 0 0"/>
            <mass value="1" />
            <inertia ixx="100" ixy="0" ixz="0" iyy="100" iyz="0" izz="100" />
        </inertial>
        <visual>
            <origin xyz="0.1589503536187688 0.0056242069201451195 -0.010057439889307252" rpy="0 0 0"/>
            <geometry>
                <box size="0.3179007072375376 0.3369724012914147 0.3929179662660457" />
            </geometry>
            <material name="Cyan">
                <color rgba="0 1.0 1.0 1.0"/>
            </material>
        </visual>
        <collision>
            <origin xyz="0.1589503536187688 0.0056242069201451195 -0.010057439889307252" rpy="0 0 0"/>
            <geometry>
                <box size="0.3179007072375376 0.3369724012914147 0.3929179662660457" />
            </geometry>
        </collision>
    </link>
    <joint name="link3_link4" type="revolute">
       <parent link="link3"/>
       <child  link="link4"/>
       <origin rpy="0 0 0" xyz="0.3179007072375376 0.1712739936265996 0.18103355271832267" />
     <axis xyz="0 1 0"/>
       <limit effort="0.0" lower="-3.14159" upper="3.14159" velocity="0.0"/>
    </joint>
    <link name="link4">
        <inertial>
            <origin xyz="0.031188828973211624 -0.061072431034703376 0.4075183769603105" rpy="0 0 0"/>
            <mass value="1" />
            <inertia ixx="100" ixy="0" ixz="0" iyy="100" iyz="0" izz="100" />
        </inertial>
        <visual>
            <origin xyz="0.031188828973211624 -0.061072431034703376 0.4075183769603105" rpy="0 0 0"/>
            <geometry>
                <box size="0.06237765794642325 0.31742437322112305 0.9493200412902195" />
            </geometry>
            <material name="Cyan">
                <color rgba="0 1.0 1.0 1.0"/>
            </material>
        </visual>
        <collision>
            <origin xyz="0.031188828973211624 -0.061072431034703376 0.4075183769603105" rpy="0 0 0"/>
            <geometry>
                <box size="0.06237765794642325 0.31742437322112305 0.9493200412902195" />
            </geometry>
        </collision>
    </link>
    <joint name="link4_link5" type="revolute">
       <parent link="link4"/>
       <child  link="link5"/>
       <origin rpy="0 0 0" xyz="0.018784591300731047 0.09763975557585815 0.06612049655384461" />
     <axis xyz="1 0 0"/>
       <limit effort="0.0" lower="-3.14159" upper="3.14159" velocity="0.0"/>
    </joint>
    <link name="link5">
        <inertial>
            <origin xyz="0.24900058696864075 0.11786088915633774 -0.035865538100286656" rpy="0 0 0"/>
            <mass value="1" />
            <inertia ixx="100" ixy="0" ixz="0" iyy="100" iyz="0" izz="100" />
        </inertial>
        <visual>
            <origin xyz="0.24900058696864075 0.11786088915633774 -0.035865538100286656" rpy="0 0 0"/>
            <geometry>
                <box size="0.8037415835258204 0.2357217783126755 0.25117040455271267" />
            </geometry>
            <material name="Cyan">
                <color rgba="0 1.0 1.0 1.0"/>
            </material>
        </visual>
        <collision>
            <origin xyz="0.24900058696864075 0.11786088915633774 -0.035865538100286656" rpy="0 0 0"/>
            <geometry>
                <box size="0.8037415835258204 0.2357217783126755 0.25117040455271267" />
            </geometry>
        </collision>
    </link>
    <joint name="link1_link6" type="revolute">
       <parent link="link1"/>
       <child  link="link6"/>
       <origin rpy="0 0 0" xyz="-0.04884872046252707 0.03649259004367149 -0.08016352430299212" />
     <axis xyz="0 1 0"/>
       <limit effort="0.0" lower="-3.14159" upper="3.14159" velocity="0.0"/>
    </joint>
    <link name="link6">
        <inertial>
            <origin xyz="-0.056767230855795776 -0.1370297269991843 -0.11355462732830351" rpy="0 0 0"/>
            <mass value="1" />
            <inertia ixx="100" ixy="0" ixz="0" iyy="100" iyz="0" izz="100" />
        </inertial>
        <visual>
            <origin xyz="-0.056767230855795776 -0.1370297269991843 -0.11355462732830351" rpy="0 0 0"/>
            <geometry>
                <box size="0.14009971718207026 0.6270170253426605 0.22710925465660703" />
            </geometry>
            <material name="Cyan">
                <color rgba="0 1.0 1.0 1.0"/>
            </material>
        </visual>
        <collision>
            <origin xyz="-0.056767230855795776 -0.1370297269991843 -0.11355462732830351" rpy="0 0 0"/>
            <geometry>
                <box size="0.14009971718207026 0.6270170253426605 0.22710925465660703" />
            </geometry>
        </collision>
    </link>
    <joint name="link6_link7" type="revolute">
       <parent link="link6"/>
       <child  link="link7"/>
       <origin rpy="0 0 0" xyz="-0.004636450092839028 -0.45053823967051454 -0.04744727340828411" />
     <axis xyz="0 0 1"/>
       <limit effort="0.0" lower="-3.14159" upper="3.14159" velocity="0.0"/>
    </joint>
    <link name="link7">
        <inertial>
            <origin xyz="-0.31201712197976783 -0.01792396281765196 -0.4674190900849182" rpy="0 0 0"/>
            <mass value="1" />
            <inertia ixx="100" ixy="0" ixz="0" iyy="100" iyz="0" izz="100" />
        </inertial>
        <visual>
            <origin xyz="-0.31201712197976783 -0.01792396281765196 -0.4674190900849182" rpy="0 0 0"/>
            <geometry>
                <box size="0.9008874164264743 0.03584792563530392 0.9911728368735959" />
            </geometry>
            <material name="Cyan">
                <color rgba="0 1.0 1.0 1.0"/>
            </material>
        </visual>
        <collision>
            <origin xyz="-0.31201712197976783 -0.01792396281765196 -0.4674190900849182" rpy="0 0 0"/>
            <geometry>
                <box size="0.9008874164264743 0.03584792563530392 0.9911728368735959" />
            </geometry>
        </collision>
    </link>
    <joint name="link2_link8" type="revolute">
       <parent link="link2"/>
       <child  link="link8"/>
       <origin rpy="0 0 0" xyz="0.31605592832060725 -0.2388463995215666 0.0817852279480104" />
     <axis xyz="0 0 1"/>
       <limit effort="0.0" lower="-3.14159" upper="3.14159" velocity="0.0"/>
    </joint>
    <link name="link8">
        <inertial>
            <origin xyz="0.16645855302796397 -0.09431312225186124 0.04603947266827031" rpy="0 0 0"/>
            <mass value="1" />
            <inertia ixx="100" ixy="0" ixz="0" iyy="100" iyz="0" izz="100" />
        </inertial>
        <visual>
            <origin xyz="0.16645855302796397 -0.09431312225186124 0.04603947266827031" rpy="0 0 0"/>
            <geometry>
                <box size="0.33291710605592795 0.4934830811914507 0.1643099548210083" />
            </geometry>
            <material name="Cyan">
                <color rgba="0 1.0 1.0 1.0"/>
            </material>
        </visual>
        <collision>
            <origin xyz="0.16645855302796397 -0.09431312225186124 0.04603947266827031" rpy="0 0 0"/>
            <geometry>
                <box size="0.33291710605592795 0.4934830811914507 0.1643099548210083" />
            </geometry>
        </collision>
    </link>
    <joint name="link4_link9" type="revolute">
       <parent link="link4"/>
       <child  link="link9"/>
       <origin rpy="0 0 0" xyz="0.06237765794642325 0.051992238748853545 0.4609540817339628" />
     <axis xyz="1 0 0"/>
       <limit effort="0.0" lower="-3.14159" upper="3.14159" velocity="0.0"/>
    </joint>
    <link name="link9">
        <inertial>
            <origin xyz="0.25370386048620835 -0.15534945682723367 0.0018731630227901378" rpy="0 0 0"/>
            <mass value="1" />
            <inertia ixx="100" ixy="0" ixz="0" iyy="100" iyz="0" izz="100" />
        </inertial>
        <visual>
            <origin xyz="0.25370386048620835 -0.15534945682723367 0.0018731630227901378" rpy="0 0 0"/>
            <geometry>
                <box size="0.5074077209724167 0.44419170562918087 0.8603827454829853" />
            </geometry>
            <material name="Cyan">
                <color rgba="0 1.0 1.0 1.0"/>
            </material>
        </visual>
        <collision>
            <origin xyz="0.25370386048620835 -0.15534945682723367 0.0018731630227901378" rpy="0 0 0"/>
            <geometry>
                <box size="0.5074077209724167 0.44419170562918087 0.8603827454829853" />
            </geometry>
        </collision>
    </link>
    <joint name="link1_link10" type="revolute">
       <parent link="link1"/>
       <child  link="link10"/>
       <origin rpy="0 0 0" xyz="-0.0851186491810836 0.006810453235751192 -0.07594594180053504" />
     <axis xyz="0 1 0"/>
       <limit effort="0.0" lower="-3.14159" upper="3.14159" velocity="0.0"/>
    </joint>
    <link name="link10">
        <inertial>
            <origin xyz="-0.22712124036307207 -0.0792440438220178 0.001976948853940242" rpy="0 0 0"/>
            <mass value="1" />
            <inertia ixx="100" ixy="0" ixz="0" iyy="100" iyz="0" izz="100" />
        </inertial>
        <visual>
            <origin xyz="-0.22712124036307207 -0.0792440438220178 0.001976948853940242" rpy="0 0 0"/>
            <geometry>
                <box size="0.45424248072614415 0.270053114170128 0.009509446966756818" />
            </geometry>
            <material name="Cyan">
                <color rgba="0 1.0 1.0 1.0"/>
            </material>
        </visual>
        <collision>
            <origin xyz="-0.22712124036307207 -0.0792440438220178 0.001976948853940242" rpy="0 0 0"/>
            <geometry>
                <box size="0.45424248072614415 0.270053114170128 0.009509446966756818" />
            </geometry>
        </collision>
    </link>
</robot>