<robot name = "robot">
    <link name="link0">
        <inertial>
            <origin xyz="0 0 1" rpy="0 0 0"/>
            <mass value="1" />
            <inertia ixx="100" ixy="0" ixz="0" iyy="100" iyz="0" izz="100" />
        </inertial>
        <visual>
            <origin xyz="0 0 1" rpy="0 0 0"/>
            <geometry>
                <box size="0.1355206626126898 0.2637574806413543 0.985577336569473" />
            </geometry>
            <material name="Cyan">
                <color rgba="0 1.0 1.0 1.0"/>
            </material>
        </visual>
        <collision>
            <origin xyz="0 0 1" rpy="0 0 0"/>
            <geometry>
                <box size="0.1355206626126898 0.2637574806413543 0.985577336569473" />
            </geometry>
        </collision>
    </link>
    <joint name="link0_link1" type="revolute">
       <parent link="link0"/>
       <child  link="link1"/>
       <origin rpy="0 0 0" xyz="-0.0677603313063449 -0.07519227541217366 0.636103483122682" />
     <axis xyz="0 1 0"/>
       <limit effort="0.0" lower="-3.14159" upper="3.14159" velocity="0.0"/>
    </joint>
    <link name="link1">
        <inertial>
            <origin xyz="-0.058922626080653795 0.18135648114729466 -0.02619033298106134" rpy="0 0 0"/>
            <mass value="1" />
            <inertia ixx="100" ixy="0" ixz="0" iyy="100" iyz="0" izz="100" />
        </inertial>
        <visual>
            <origin xyz="-0.058922626080653795 0.18135648114729466 -0.02619033298106134" rpy="0 0 0"/>
            <geometry>
                <box size="0.11784525216130759 0.5689639373238327 0.36784546286866693" />
            </geometry>
            <material name="Cyan">
                <color rgba="0 1.0 1.0 1.0"/>
            </material>
        </visual>
        <collision>
            <origin xyz="-0.058922626080653795 0.18135648114729466 -0.02619033298106134" rpy="0 0 0"/>
            <geometry>
                <box size="0.11784525216130759 0.5689639373238327 0.36784546286866693" />
            </geometry>
        </collision>
    </link>
    <joint name="link0_link2" type="revolute">
       <parent link="link0"/>
       <child  link="link2"/>
       <origin rpy="0 0 0" xyz="-0.031766550099625555 -0.04022740505059206 0.5072113317152636" />
     <axis xyz="0 0 1"/>
       <limit effort="0.0" lower="-3.14159" upper="3.14159" velocity="0.0"/>
    </joint>
    <link name="link2">
        <inertial>
            <origin xyz="0.14251439569867697 0.12353973370009469 -0.47114125423331765" rpy="0 0 0"/>
            <mass value="1" />
            <inertia ixx="100" ixy="0" ixz="0" iyy="100" iyz="0" izz="100" />
        </inertial>
        <visual>
            <origin xyz="0.14251439569867697 0.12353973370009469 -0.47114125423331765" rpy="0 0 0"/>
            <geometry>
                <box size="0.9045023616071585 0.5766430068888767 0.9422825084666353" />
            </geometry>
            <material name="Cyan">
                <color rgba="0 1.0 1.0 1.0"/>
            </material>
        </visual>
        <collision>
            <origin xyz="0.14251439569867697 0.12353973370009469 -0.47114125423331765" rpy="0 0 0"/>
            <geometry>
                <box size="0.9045023616071585 0.5766430068888767 0.9422825084666353" />
            </geometry>
        </collision>
    </link>
    <joint name="link0_link3" type="revolute">
       <parent link="link0"/>
       <child  link="link3"/>
       <origin rpy="0 0 0" xyz="-0.0677603313063449 -0.051836430821931886 1.191832351949659" />
     <axis xyz="0 1 0"/>
       <limit effort="0.0" lower="-3.14159" upper="3.14159" velocity="0.0"/>
    </joint>
    <link name="link3">
        <inertial>
            <origin xyz="-0.4530040589476887 0.1763733929457186 0.22646106629485033" rpy="0 0 0"/>
            <mass value="1" />
            <inertia ixx="100" ixy="0" ixz="0" iyy="100" iyz="0" izz="100" />
        </inertial>
        <visual>
            <origin xyz="-0.4530040589476887 0.1763733929457186 0.22646106629485033" rpy="0 0 0"/>
            <geometry>
                <box size="0.9060081178953774 0.8519044604662146 0.9530779201217486" />
            </geometry>
            <material name="Cyan">
                <color rgba="0 1.0 1.0 1.0"/>
            </material>
        </visual>
        <collision>
            <origin xyz="-0.4530040589476887 0.1763733929457186 0.22646106629485033" rpy="0 0 0"/>
            <geometry>
                <box size="0.9060081178953774 0.8519044604662146 0.9530779201217486" />
            </geometry>
        </collision>
    </link>
    <joint name="link3_link4" type="revolute">
       <parent link="link3"/>
       <child  link="link4"/>
       <origin rpy="0 0 0" xyz="-0.8991557364171789 -0.08084576070111002 0.7030000263557247" />
     <axis xyz="1 0 0"/>
       <limit effort="0.0" lower="-3.14159" upper="3.14159" velocity="0.0"/>
    </joint>
    <link name="link4">
        <inertial>
            <origin xyz="-0.021833662865865036 -0.02075623034109559 0.021894480059155175" rpy="0 0 0"/>
            <mass value="1" />
            <inertia ixx="100" ixy="0" ixz="0" iyy="100" iyz="0" izz="100" />
        </inertial>
        <visual>
            <origin xyz="-0.021833662865865036 -0.02075623034109559 0.021894480059155175" rpy="0 0 0"/>
            <geometry>
                <box size="0.3413665815342153 0.42425993350081936 0.04378896011831035" />
            </geometry>
            <material name="Cyan">
                <color rgba="0 1.0 1.0 1.0"/>
            </material>
        </visual>
        <collision>
            <origin xyz="-0.021833662865865036 -0.02075623034109559 0.021894480059155175" rpy="0 0 0"/>
            <geometry>
                <box size="0.3413665815342153 0.42425993350081936 0.04378896011831035" />
            </geometry>
        </collision>
    </link>
    <joint name="link0_link5" type="revolute">
       <parent link="link0"/>
       <child  link="link5"/>
       <origin rpy="0 0 0" xyz="-0.038041508553049184 0.032098156379379475 0.5072113317152636" />
     <axis xyz="1 0 0"/>
       <limit effort="0.0" lower="-3.14159" upper="3.14159" velocity="0.0"/>
    </joint>
    <link name="link5">
        <inertial>
            <origin xyz="-0.03001881194810635 -0.057571056983411355 -0.08961692056238535" rpy="0 0 0"/>
            <mass value="1" />
            <inertia ixx="100" ixy="0" ixz="0" iyy="100" iyz="0" izz="100" />
        </inertial>
        <visual>
            <origin xyz="-0.03001881194810635 -0.057571056983411355 -0.08961692056238535" rpy="0 0 0"/>
            <geometry>
                <box size="0.36102657068558264 0.9697738410918253 0.1792338411247707" />
            </geometry>
            <material name="Cyan">
                <color rgba="0 1.0 1.0 1.0"/>
            </material>
        </visual>
        <collision>
            <origin xyz="-0.03001881194810635 -0.057571056983411355 -0.08961692056238535" rpy="0 0 0"/>
            <geometry>
                <box size="0.36102657068558264 0.9697738410918253 0.1792338411247707" />
            </geometry>
        </collision>
    </link>
    <joint name="link5_link6" type="revolute">
       <parent link="link5"/>
       <child  link="link6"/>
       <origin rpy="0 0 0" xyz="-0.150553106503274 0.4273158635625013 -0.10393858914874751" />
     <axis xyz="0 0 1"/>
       <limit effort="0.0" lower="-3.14159" upper="3.14159" velocity="0.0"/>
    </joint>
    <link name="link6">
        <inertial>
            <origin xyz="0.1584963132655992 0.22263669820740967 -0.005908261533864593" rpy="0 0 0"/>
            <mass value="1" />
            <inertia ixx="100" ixy="0" ixz="0" iyy="100" iyz="0" izz="100" />
        </inertial>
        <visual>
            <origin xyz="0.1584963132655992 0.22263669820740967 -0.005908261533864593" rpy="0 0 0"/>
            <geometry>
                <box size="0.5693117298113628 0.44527339641481933 0.871732027848029" />
            </geometry>
            <material name="Cyan">
                <color rgba="0 1.0 1.0 1.0"/>
            </material>
        </visual>
        <collision>
            <origin xyz="0.1584963132655992 0.22263669820740967 -0.005908261533864593" rpy="0 0 0"/>
            <geometry>
                <box size="0.5693117298113628 0.44527339641481933 0.871732027848029" />
            </geometry>
        </collision>
    </link>
    <joint name="link3_link7" type="revolute">
       <parent link="link3"/>
       <child  link="link7"/>
       <origin rpy="0 0 0" xyz="-0.9060081178953774 0.17372349711556367 0.5715152241102283" />
     <axis xyz="0 1 0"/>
       <limit effort="0.0" lower="-3.14159" upper="3.14159" velocity="0.0"/>
    </joint>
    <link name="link7">
        <inertial>
            <origin xyz="-0.18218040234682753 0.22284510928702173 0.0009623315499173956" rpy="0 0 0"/>
            <mass value="1" />
            <inertia ixx="100" ixy="0" ixz="0" iyy="100" iyz="0" izz="100" />
        </inertial>
        <visual>
            <origin xyz="-0.18218040234682753 0.22284510928702173 0.0009623315499173956" rpy="0 0 0"/>
            <geometry>
                <box size="0.36436080469365506 0.509836008812759 0.10959071250203078" />
            </geometry>
            <material name="Cyan">
                <color rgba="0 1.0 1.0 1.0"/>
            </material>
        </visual>
        <collision>
            <origin xyz="-0.18218040234682753 0.22284510928702173 0.0009623315499173956" rpy="0 0 0"/>
            <geometry>
                <box size="0.36436080469365506 0.509836008812759 0.10959071250203078" />
            </geometry>
        </collision>
    </link>
    <joint name="link0_link8" type="revolute">
       <parent link="link0"/>
       <child  link="link8"/>
       <origin rpy="0 0 0" xyz="0.0677603313063449 -0.08846298257124838 0.8958860171203104" />
     <axis xyz="1 0 0"/>
       <limit effort="0.0" lower="-3.14159" upper="3.14159" velocity="0.0"/>
    </joint>
    <link name="link8">
        <inertial>
            <origin xyz="0.06643280616524788 0.38092405939241025 0.10055021250093438" rpy="0 0 0"/>
            <mass value="1" />
            <inertia ixx="100" ixy="0" ixz="0" iyy="100" iyz="0" izz="100" />
        </inertial>
        <visual>
            <origin xyz="0.06643280616524788 0.38092405939241025 0.10055021250093438" rpy="0 0 0"/>
            <geometry>
                <box size="0.13286561233049576 0.9886192827408988 0.3244468193857746" />
            </geometry>
            <material name="Cyan">
                <color rgba="0 1.0 1.0 1.0"/>
            </material>
        </visual>
        <collision>
            <origin xyz="0.06643280616524788 0.38092405939241025 0.10055021250093438" rpy="0 0 0"/>
            <geometry>
                <box size="0.13286561233049576 0.9886192827408988 0.3244468193857746" />
            </geometry>
        </collision>
    </link>
</robot>