<robot name = "robot">
    <link name="link0">
        <inertial>
            <origin xyz="0 0 1" rpy="0 0 0"/>
            <mass value="1" />
            <inertia ixx="100" ixy="0" ixz="0" iyy="100" iyz="0" izz="100" />
        </inertial>
        <visual>
            <origin xyz="0 0 1" rpy="0 0 0"/>
            <geometry>
                <box size="0.7096527711433285 0.21780432475926081 0.15355715917178203" />
            </geometry>
            <material name="Cyan">
                <color rgba="0.0 1.0 1.0 1.0"/>
            </material>
        </visual>
        <collision>
            <origin xyz="0 0 1" rpy="0 0 0"/>
            <geometry>
                <box size="0.7096527711433285 0.21780432475926081 0.15355715917178203" />
            </geometry>
        </collision>
    </link>
    <joint name="link0_link1" type="revolute">
       <parent link="link0"/>
       <child  link="link1"/>
       <origin rpy="0 0 0" xyz="-0.03124632844121803 0.10890216237963041 0.9270310288250103" />
     <axis xyz="0 1 0"/>
       <limit effort="0.0" lower="-3.14159" upper="3.14159" velocity="0.0"/>
    </joint>
    <link name="link1">
        <inertial>
            <origin xyz="-0.00948127385757437 0.3717830215514056 0.06408456486295731" rpy="0 0 0"/>
            <mass value="1" />
            <inertia ixx="100" ixy="0" ixz="0" iyy="100" iyz="0" izz="100" />
        </inertial>
        <visual>
            <origin xyz="-0.00948127385757437 0.3717830215514056 0.06408456486295731" rpy="0 0 0"/>
            <geometry>
                <box size="0.05333975833440652 0.7435660431028112 0.13483480201601028" />
            </geometry>
            <material name="Cyan">
                <color rgba="0.0 1.0 1.0 1.0"/>
            </material>
        </visual>
        <collision>
            <origin xyz="-0.00948127385757437 0.3717830215514056 0.06408456486295731" rpy="0 0 0"/>
            <geometry>
                <box size="0.05333975833440652 0.7435660431028112 0.13483480201601028" />
            </geometry>
        </collision>
    </link>
    <joint name="link1_link2" type="revolute">
       <parent link="link1"/>
       <child  link="link2"/>
       <origin rpy="0 0 0" xyz="0.00384631916999076 0.11233608689276225 0.13150196587096247" />
     <axis xyz="0 1 0"/>
       <limit effort="0.0" lower="-3.14159" upper="3.14159" velocity="0.0"/>
    </joint>
    <link name="link2">
        <inertial>
            <origin xyz="-0.359137310953152 -0.11312699999658402 0.06849618449414757" rpy="0 0 0"/>
            <mass value="1" />
            <inertia ixx="100" ixy="0" ixz="0" iyy="100" iyz="0" izz="100" />
        </inertial>
        <visual>
            <origin xyz="-0.359137310953152 -0.11312699999658402 0.06849618449414757" rpy="0 0 0"/>
            <geometry>
                <box size="0.9952514381512929 0.4634956669352158 0.13699236898829514" />
            </geometry>
            <material name="Green">
                <color rgba="0.0 1.0 0.0 1.0"/>
            </material>
        </visual>
        <collision>
            <origin xyz="-0.359137310953152 -0.11312699999658402 0.06849618449414757" rpy="0 0 0"/>
            <geometry>
                <box size="0.9952514381512929 0.4634956669352158 0.13699236898829514" />
            </geometry>
        </collision>
    </link>
    <joint name="link1_link3" type="revolute">
       <parent link="link1"/>
       <child  link="link3"/>
       <origin rpy="0 0 0" xyz="0.0038202897254031795 0.0 0.11303076433892939" />
     <axis xyz="0 0 1"/>
       <limit effort="0.0" lower="-3.14159" upper="3.14159" velocity="0.0"/>
    </joint>
    <link name="link3">
        <inertial>
            <origin xyz="0.12729104380557527 -0.0660964055564141 -0.04990709112265665" rpy="0 0 0"/>
            <mass value="1" />
            <inertia ixx="100" ixy="0" ixz="0" iyy="100" iyz="0" izz="100" />
        </inertial>
        <visual>
            <origin xyz="0.12729104380557527 -0.0660964055564141 -0.04990709112265665" rpy="0 0 0"/>
            <geometry>
                <box size="0.8348972968509812 0.1321928111128282 0.3026207290789238" />
            </geometry>
            <material name="Green">
                <color rgba="0.0 1.0 0.0 1.0"/>
            </material>
        </visual>
        <collision>
            <origin xyz="0.12729104380557527 -0.0660964055564141 -0.04990709112265665" rpy="0 0 0"/>
            <geometry>
                <box size="0.8348972968509812 0.1321928111128282 0.3026207290789238" />
            </geometry>
        </collision>
    </link>
    <joint name="link2_link4" type="revolute">
       <parent link="link2"/>
       <child  link="link4"/>
       <origin rpy="0 0 0" xyz="-0.6909420498849125 -0.3448748334641919 0.10152841155747178" />
     <axis xyz="0 1 0"/>
       <limit effort="0.0" lower="-3.14159" upper="3.14159" velocity="0.0"/>
    </joint>
    <link name="link4">
        <inertial>
            <origin xyz="0.0044334894091607535 -0.2863948042850729 0.13709381106919366" rpy="0 0 0"/>
            <mass value="1" />
            <inertia ixx="100" ixy="0" ixz="0" iyy="100" iyz="0" izz="100" />
        </inertial>
        <visual>
            <origin xyz="0.0044334894091607535 -0.2863948042850729 0.13709381106919366" rpy="0 0 0"/>
            <geometry>
                <box size="0.01824400553291461 0.5727896085701458 0.9183891075078799" />
            </geometry>
            <material name="Green">
                <color rgba="0.0 1.0 0.0 1.0"/>
            </material>
        </visual>
        <collision>
            <origin xyz="0.0044334894091607535 -0.2863948042850729 0.13709381106919366" rpy="0 0 0"/>
            <geometry>
                <box size="0.01824400553291461 0.5727896085701458 0.9183891075078799" />
            </geometry>
        </collision>
    </link>
    <joint name="link3_link5" type="revolute">
       <parent link="link3"/>
       <child  link="link5"/>
       <origin rpy="0 0 0" xyz="0.5447396922310659 -0.11423630264186722 -0.03063879001931504" />
     <axis xyz="1 0 0"/>
       <limit effort="0.0" lower="-3.14159" upper="3.14159" velocity="0.0"/>
    </joint>
    <link name="link5">
        <inertial>
            <origin xyz="0.39555163338432947 0.16608245652562176 -0.12953997902887215" rpy="0 0 0"/>
            <mass value="1" />
            <inertia ixx="100" ixy="0" ixz="0" iyy="100" iyz="0" izz="100" />
        </inertial>
        <visual>
            <origin xyz="0.39555163338432947 0.16608245652562176 -0.12953997902887215" rpy="0 0 0"/>
            <geometry>
                <box size="0.7911032667686589 0.4198345553449693 0.7692958741580727" />
            </geometry>
            <material name="Green">
                <color rgba="0.0 1.0 0.0 1.0"/>
            </material>
        </visual>
        <collision>
            <origin xyz="0.39555163338432947 0.16608245652562176 -0.12953997902887215" rpy="0 0 0"/>
            <geometry>
                <box size="0.7911032667686589 0.4198345553449693 0.7692958741580727" />
            </geometry>
        </collision>
    </link>
    <joint name="link1_link6" type="revolute">
       <parent link="link1"/>
       <child  link="link6"/>
       <origin rpy="0 0 0" xyz="-0.019197252834249782 0.5278155001098701 0.13150196587096247" />
     <axis xyz="1 0 0"/>
       <limit effort="0.0" lower="-3.14159" upper="3.14159" velocity="0.0"/>
    </joint>
    <link name="link6">
        <inertial>
            <origin xyz="-0.014085445601816784 0.36838912557019005 0.014493560627249602" rpy="0 0 0"/>
            <mass value="1" />
            <inertia ixx="100" ixy="0" ixz="0" iyy="100" iyz="0" izz="100" />
        </inertial>
        <visual>
            <origin xyz="-0.014085445601816784 0.36838912557019005 0.014493560627249602" rpy="0 0 0"/>
            <geometry>
                <box size="0.07545675740919 0.747382795554046 0.028987121254499204" />
            </geometry>
            <material name="Green">
                <color rgba="0.0 1.0 0.0 1.0"/>
            </material>
        </visual>
        <collision>
            <origin xyz="-0.014085445601816784 0.36838912557019005 0.014493560627249602" rpy="0 0 0"/>
            <geometry>
                <box size="0.07545675740919 0.747382795554046 0.028987121254499204" />
            </geometry>
        </collision>
    </link>
</robot>