<robot name = "robot">
    <link name="link0">
        <inertial>
            <origin xyz="0 0 1" rpy="0 0 0"/>
            <mass value="1" />
            <inertia ixx="100" ixy="0" ixz="0" iyy="100" iyz="0" izz="100" />
        </inertial>
        <visual>
            <origin xyz="0 0 1" rpy="0 0 0"/>
            <geometry>
                <box size="0.23714552663973687 0.46712353881395796 0.09336674130206668" />
            </geometry>
            <material name="Cyan">
                <color rgba="0 1.0 1.0 1.0"/>
            </material>
        </visual>
        <collision>
            <origin xyz="0 0 1" rpy="0 0 0"/>
            <geometry>
                <box size="0.23714552663973687 0.46712353881395796 0.09336674130206668" />
            </geometry>
        </collision>
    </link>
    <joint name="link0_link1" type="revolute">
       <parent link="link0"/>
       <child  link="link1"/>
       <origin rpy="0 0 0" xyz="0.11857276331986843 -0.16982540877692898 0.9784534047290212" />
     <axis xyz="0 1 0"/>
       <limit effort="0.0" lower="-3.14159" upper="3.14159" velocity="0.0"/>
    </joint>
    <link name="link1">
        <inertial>
            <origin xyz="0.23054548349087267 0.24510602591938932 -0.02483526931487491" rpy="0 0 0"/>
            <mass value="1" />
            <inertia ixx="100" ixy="0" ixz="0" iyy="100" iyz="0" izz="100" />
        </inertial>
        <visual>
            <origin xyz="0.23054548349087267 0.24510602591938932 -0.02483526931487491" rpy="0 0 0"/>
            <geometry>
                <box size="0.46109096698174534 0.7981199443647181 0.06417990034102672" />
            </geometry>
            <material name="Cyan">
                <color rgba="0 1.0 1.0 1.0"/>
            </material>
        </visual>
        <collision>
            <origin xyz="0.23054548349087267 0.24510602591938932 -0.02483526931487491" rpy="0 0 0"/>
            <geometry>
                <box size="0.46109096698174534 0.7981199443647181 0.06417990034102672" />
            </geometry>
        </collision>
    </link>
    <joint name="link0_link2" type="revolute">
       <parent link="link0"/>
       <child  link="link2"/>
       <origin rpy="0 0 0" xyz="-0.04364598268601303 -0.18484585116547653 1.0466833706510332" />
     <axis xyz="1 0 0"/>
       <limit effort="0.0" lower="-3.14159" upper="3.14159" velocity="0.0"/>
    </joint>
    <link name="link2">
        <inertial>
            <origin xyz="0.06671220055351489 -0.05765582946031773 0.37074451278207543" rpy="0 0 0"/>
            <mass value="1" />
            <inertia ixx="100" ixy="0" ixz="0" iyy="100" iyz="0" izz="100" />
        </inertial>
        <visual>
            <origin xyz="0.06671220055351489 -0.05765582946031773 0.37074451278207543" rpy="0 0 0"/>
            <geometry>
                <box size="0.47425410401675305 0.16899847014272407 0.7414890255641509" />
            </geometry>
            <material name="Cyan">
                <color rgba="0 1.0 1.0 1.0"/>
            </material>
        </visual>
        <collision>
            <origin xyz="0.06671220055351489 -0.05765582946031773 0.37074451278207543" rpy="0 0 0"/>
            <geometry>
                <box size="0.47425410401675305 0.16899847014272407 0.7414890255641509" />
            </geometry>
        </collision>
    </link>
    <joint name="link0_link3" type="revolute">
       <parent link="link0"/>
       <child  link="link3"/>
       <origin rpy="0 0 0" xyz="0.10193619504639159 -0.2020154962194394 1.0466833706510332" />
     <axis xyz="0 1 0"/>
       <limit effort="0.0" lower="-3.14159" upper="3.14159" velocity="0.0"/>
    </joint>
    <link name="link3">
        <inertial>
            <origin xyz="0.08319411085691615 -0.08008564698964506 0.2816686548466142" rpy="0 0 0"/>
            <mass value="1" />
            <inertia ixx="100" ixy="0" ixz="0" iyy="100" iyz="0" izz="100" />
        </inertial>
        <visual>
            <origin xyz="0.08319411085691615 -0.08008564698964506 0.2816686548466142" rpy="0 0 0"/>
            <geometry>
                <box size="0.19455407120328516 0.9106474578835119 0.5633373096932284" />
            </geometry>
            <material name="Cyan">
                <color rgba="0 1.0 1.0 1.0"/>
            </material>
        </visual>
        <collision>
            <origin xyz="0.08319411085691615 -0.08008564698964506 0.2816686548466142" rpy="0 0 0"/>
            <geometry>
                <box size="0.19455407120328516 0.9106474578835119 0.5633373096932284" />
            </geometry>
        </collision>
    </link>
    <joint name="link3_link4" type="revolute">
       <parent link="link3"/>
       <child  link="link4"/>
       <origin rpy="0 0 0" xyz="-0.014082589204932078 -0.3482836399288351 0.0" />
     <axis xyz="0 0 1"/>
       <limit effort="0.0" lower="-3.14159" upper="3.14159" velocity="0.0"/>
    </joint>
    <link name="link4">
        <inertial>
            <origin xyz="0.1864411566955713 0.23227099187266118 -0.1779727435131807" rpy="0 0 0"/>
            <mass value="1" />
            <inertia ixx="100" ixy="0" ixz="0" iyy="100" iyz="0" izz="100" />
        </inertial>
        <visual>
            <origin xyz="0.1864411566955713 0.23227099187266118 -0.1779727435131807" rpy="0 0 0"/>
            <geometry>
                <box size="0.9161679363059075 0.5399843711109781 0.3559454870263614" />
            </geometry>
            <material name="Cyan">
                <color rgba="0 1.0 1.0 1.0"/>
            </material>
        </visual>
        <collision>
            <origin xyz="0.1864411566955713 0.23227099187266118 -0.1779727435131807" rpy="0 0 0"/>
            <geometry>
                <box size="0.9161679363059075 0.5399843711109781 0.3559454870263614" />
            </geometry>
        </collision>
    </link>
    <joint name="link0_link5" type="revolute">
       <parent link="link0"/>
       <child  link="link5"/>
       <origin rpy="0 0 0" xyz="-0.10000675351635276 0.05051850761789106 1.0466833706510332" />
     <axis xyz="0 1 0"/>
       <limit effort="0.0" lower="-3.14159" upper="3.14159" velocity="0.0"/>
    </joint>
    <link name="link5">
        <inertial>
            <origin xyz="0.003216591650748684 -0.10423245840753892 0.3367471763027334" rpy="0 0 0"/>
            <mass value="1" />
            <inertia ixx="100" ixy="0" ixz="0" iyy="100" iyz="0" izz="100" />
        </inertial>
        <visual>
            <origin xyz="0.003216591650748684 -0.10423245840753892 0.3367471763027334" rpy="0 0 0"/>
            <geometry>
                <box size="0.40031369507310366 0.5723175085030585 0.6734943526054668" />
            </geometry>
            <material name="Cyan">
                <color rgba="0 1.0 1.0 1.0"/>
            </material>
        </visual>
        <collision>
            <origin xyz="0.003216591650748684 -0.10423245840753892 0.3367471763027334" rpy="0 0 0"/>
            <geometry>
                <box size="0.40031369507310366 0.5723175085030585 0.6734943526054668" />
            </geometry>
        </collision>
    </link>
    <joint name="link2_link6" type="revolute">
       <parent link="link2"/>
       <child  link="link6"/>
       <origin rpy="0 0 0" xyz="0.0006975873637016378 -0.14215506453167975 0.013473050888064275" />
     <axis xyz="0 0 1"/>
       <limit effort="0.0" lower="-3.14159" upper="3.14159" velocity="0.0"/>
    </joint>
    <link name="link6">
        <inertial>
            <origin xyz="-0.1814916245029863 -0.002306829704832647 -0.14380166756727342" rpy="0 0 0"/>
            <mass value="1" />
            <inertia ixx="100" ixy="0" ixz="0" iyy="100" iyz="0" izz="100" />
        </inertial>
        <visual>
            <origin xyz="-0.1814916245029863 -0.002306829704832647 -0.14380166756727342" rpy="0 0 0"/>
            <geometry>
                <box size="0.38612480224104373 0.004613659409665294 0.4182159474181951" />
            </geometry>
            <material name="Cyan">
                <color rgba="0 1.0 1.0 1.0"/>
            </material>
        </visual>
        <collision>
            <origin xyz="-0.1814916245029863 -0.002306829704832647 -0.14380166756727342" rpy="0 0 0"/>
            <geometry>
                <box size="0.38612480224104373 0.004613659409665294 0.4182159474181951" />
            </geometry>
        </collision>
    </link>
    <joint name="link6_link7" type="revolute">
       <parent link="link6"/>
       <child  link="link7"/>
       <origin rpy="0 0 0" xyz="-0.15936476683400067 -0.0024570548250084402 -0.352909641276371" />
     <axis xyz="0 0 1"/>
       <limit effort="0.0" lower="-3.14159" upper="3.14159" velocity="0.0"/>
    </joint>
    <link name="link7">
        <inertial>
            <origin xyz="-0.19210882984936042 0.1267218538406214 -0.040162945649839576" rpy="0 0 0"/>
            <mass value="1" />
            <inertia ixx="100" ixy="0" ixz="0" iyy="100" iyz="0" izz="100" />
        </inertial>
        <visual>
            <origin xyz="-0.19210882984936042 0.1267218538406214 -0.040162945649839576" rpy="0 0 0"/>
            <geometry>
                <box size="0.42343345477363437 0.42993985582115923 0.08032589129967915" />
            </geometry>
            <material name="Cyan">
                <color rgba="0 1.0 1.0 1.0"/>
            </material>
        </visual>
        <collision>
            <origin xyz="-0.19210882984936042 0.1267218538406214 -0.040162945649839576" rpy="0 0 0"/>
            <geometry>
                <box size="0.42343345477363437 0.42993985582115923 0.08032589129967915" />
            </geometry>
        </collision>
    </link>
    <joint name="link7_link8" type="revolute">
       <parent link="link7"/>
       <child  link="link8"/>
       <origin rpy="0 0 0" xyz="-0.1731343735439533 0.341691781751201 -0.044876490088663304" />
     <axis xyz="1 0 0"/>
       <limit effort="0.0" lower="-3.14159" upper="3.14159" velocity="0.0"/>
    </joint>
    <link name="link8">
        <inertial>
            <origin xyz="0.2773916555018747 0.3411698489258123 0.23164430904328848" rpy="0 0 0"/>
            <mass value="1" />
            <inertia ixx="100" ixy="0" ixz="0" iyy="100" iyz="0" izz="100" />
        </inertial>
        <visual>
            <origin xyz="0.2773916555018747 0.3411698489258123 0.23164430904328848" rpy="0 0 0"/>
            <geometry>
                <box size="0.7563189405357631 0.6823396978516246 0.5714921390949776" />
            </geometry>
            <material name="Cyan">
                <color rgba="0 1.0 1.0 1.0"/>
            </material>
        </visual>
        <collision>
            <origin xyz="0.2773916555018747 0.3411698489258123 0.23164430904328848" rpy="0 0 0"/>
            <geometry>
                <box size="0.7563189405357631 0.6823396978516246 0.5714921390949776" />
            </geometry>
        </collision>
    </link>
    <joint name="link5_link9" type="revolute">
       <parent link="link5"/>
       <child  link="link9"/>
       <origin rpy="0 0 0" xyz="-0.030084076344895416 -0.3903912126590682 0.30421799357457385" />
     <axis xyz="0 0 1"/>
       <limit effort="0.0" lower="-3.14159" upper="3.14159" velocity="0.0"/>
    </joint>
    <link name="link9">
        <inertial>
            <origin xyz="-0.0634959876122619 -0.09761456809500813 0.09548934714456826" rpy="0 0 0"/>
            <mass value="1" />
            <inertia ixx="100" ixy="0" ixz="0" iyy="100" iyz="0" izz="100" />
        </inertial>
        <visual>
            <origin xyz="-0.0634959876122619 -0.09761456809500813 0.09548934714456826" rpy="0 0 0"/>
            <geometry>
                <box size="0.21932850528818648 0.19522913619001625 0.5906055577271011" />
            </geometry>
            <material name="Cyan">
                <color rgba="0 1.0 1.0 1.0"/>
            </material>
        </visual>
        <collision>
            <origin xyz="-0.0634959876122619 -0.09761456809500813 0.09548934714456826" rpy="0 0 0"/>
            <geometry>
                <box size="0.21932850528818648 0.19522913619001625 0.5906055577271011" />
            </geometry>
        </collision>
    </link>
</robot>