<robot name = "robot">
    <link name="link0">
        <inertial>
            <origin xyz="0 0 1" rpy="0 0 0"/>
            <mass value="1" />
            <inertia ixx="100" ixy="0" ixz="0" iyy="100" iyz="0" izz="100" />
        </inertial>
        <visual>
            <origin xyz="0 0 1" rpy="0 0 0"/>
            <geometry>
                <box size="0.5357859191889394 0.627948544695617 0.5183935208351126" />
            </geometry>
            <material name="Cyan">
                <color rgba="0.0 1.0 1.0 1.0"/>
            </material>
        </visual>
        <collision>
            <origin xyz="0 0 1" rpy="0 0 0"/>
            <geometry>
                <box size="0.5357859191889394 0.627948544695617 0.5183935208351126" />
            </geometry>
        </collision>
    </link>
    <joint name="link0_link1" type="revolute">
       <parent link="link0"/>
       <child  link="link1"/>
       <origin rpy="0 0 0" xyz="-0.2678929595944697 0.10555134607277245 1.2160261759176543" />
     <axis xyz="0 1 0"/>
       <limit effort="0.0" lower="-3.14159" upper="3.14159" velocity="0.0"/>
    </joint>
    <link name="link1">
        <inertial>
            <origin xyz="-0.28956937929607834 -0.039715082983008576 0.21743674518922187" rpy="0 0 0"/>
            <mass value="1" />
            <inertia ixx="100" ixy="0" ixz="0" iyy="100" iyz="0" izz="100" />
        </inertial>
        <visual>
            <origin xyz="-0.28956937929607834 -0.039715082983008576 0.21743674518922187" rpy="0 0 0"/>
            <geometry>
                <box size="0.5791387585921567 0.14204404380696434 0.8170570016080748" />
            </geometry>
            <material name="Green">
                <color rgba="0.0 1.0 0.0 1.0"/>
            </material>
        </visual>
        <collision>
            <origin xyz="-0.28956937929607834 -0.039715082983008576 0.21743674518922187" rpy="0 0 0"/>
            <geometry>
                <box size="0.5791387585921567 0.14204404380696434 0.8170570016080748" />
            </geometry>
        </collision>
    </link>
    <joint name="link1_link2" type="revolute">
       <parent link="link1"/>
       <child  link="link2"/>
       <origin rpy="0 0 0" xyz="-0.5791387585921567 -0.017581901603485873 0.5608978125488456" />
     <axis xyz="1 0 0"/>
       <limit effort="0.0" lower="-3.14159" upper="3.14159" velocity="0.0"/>
    </joint>
    <link name="link2">
        <inertial>
            <origin xyz="-0.1611129029998426 -0.07540393066339537 -0.18454791817937477" rpy="0 0 0"/>
            <mass value="1" />
            <inertia ixx="100" ixy="0" ixz="0" iyy="100" iyz="0" izz="100" />
        </inertial>
        <visual>
            <origin xyz="-0.1611129029998426 -0.07540393066339537 -0.18454791817937477" rpy="0 0 0"/>
            <geometry>
                <box size="0.3222258059996852 0.1604949721257628 0.43243350932913893" />
            </geometry>
            <material name="Green">
                <color rgba="0.0 1.0 0.0 1.0"/>
            </material>
        </visual>
        <collision>
            <origin xyz="-0.1611129029998426 -0.07540393066339537 -0.18454791817937477" rpy="0 0 0"/>
            <geometry>
                <box size="0.3222258059996852 0.1604949721257628 0.43243350932913893" />
            </geometry>
        </collision>
    </link>
    <joint name="link1_link3" type="revolute">
       <parent link="link1"/>
       <child  link="link3"/>
       <origin rpy="0 0 0" xyz="-0.29467808195631207 0.022001985394498942 0.6259652459932593" />
     <axis xyz="0 1 0"/>
       <limit effort="0.0" lower="-3.14159" upper="3.14159" velocity="0.0"/>
    </joint>
    <link name="link3">
        <inertial>
            <origin xyz="-0.05796869384532052 -0.24848137727254185 0.4683633246977381" rpy="0 0 0"/>
            <mass value="1" />
            <inertia ixx="100" ixy="0" ixz="0" iyy="100" iyz="0" izz="100" />
        </inertial>
        <visual>
            <origin xyz="-0.05796869384532052 -0.24848137727254185 0.4683633246977381" rpy="0 0 0"/>
            <geometry>
                <box size="0.3384529659235316 0.6372230805400559 0.9367266493954762" />
            </geometry>
            <material name="Green">
                <color rgba="0.0 1.0 0.0 1.0"/>
            </material>
        </visual>
        <collision>
            <origin xyz="-0.05796869384532052 -0.24848137727254185 0.4683633246977381" rpy="0 0 0"/>
            <geometry>
                <box size="0.3384529659235316 0.6372230805400559 0.9367266493954762" />
            </geometry>
        </collision>
    </link>
    <joint name="link3_link4" type="revolute">
       <parent link="link3"/>
       <child  link="link4"/>
       <origin rpy="0 0 0" xyz="-0.10101158155662072 -0.1397443428455155 0.9367266493954762" />
     <axis xyz="1 0 0"/>
       <limit effort="0.0" lower="-3.14159" upper="3.14159" velocity="0.0"/>
    </joint>
    <link name="link4">
        <inertial>
            <origin xyz="0.06157324036917703 0.02345009577509234 0.03225474557579322" rpy="0 0 0"/>
            <mass value="1" />
            <inertia ixx="100" ixy="0" ixz="0" iyy="100" iyz="0" izz="100" />
        </inertial>
        <visual>
            <origin xyz="0.06157324036917703 0.02345009577509234 0.03225474557579322" rpy="0 0 0"/>
            <geometry>
                <box size="0.21155071282740845 0.8212883849261581 0.06450949115158644" />
            </geometry>
            <material name="Green">
                <color rgba="0.0 1.0 0.0 1.0"/>
            </material>
        </visual>
        <collision>
            <origin xyz="0.06157324036917703 0.02345009577509234 0.03225474557579322" rpy="0 0 0"/>
            <geometry>
                <box size="0.21155071282740845 0.8212883849261581 0.06450949115158644" />
            </geometry>
        </collision>
    </link>
</robot>