<robot name = "robot">
    <link name="link0">
        <inertial>
            <origin xyz="0 0 1" rpy="0 0 0"/>
            <mass value="1" />
            <inertia ixx="100" ixy="0" ixz="0" iyy="100" iyz="0" izz="100" />
        </inertial>
        <visual>
            <origin xyz="0 0 1" rpy="0 0 0"/>
            <geometry>
                <box size="0.9480806292652489 0.052317688733497514 0.2215750500449617" />
            </geometry>
            <material name="Cyan">
                <color rgba="0 1.0 1.0 1.0"/>
            </material>
        </visual>
        <collision>
            <origin xyz="0 0 1" rpy="0 0 0"/>
            <geometry>
                <box size="0.9480806292652489 0.052317688733497514 0.2215750500449617" />
            </geometry>
        </collision>
    </link>
    <joint name="link0_link1" type="revolute">
       <parent link="link0"/>
       <child  link="link1"/>
       <origin rpy="0 0 0" xyz="-0.47404031463262447 -0.01699085396496725 1.030833145813512" />
     <axis xyz="1 0 0"/>
       <limit effort="0.0" lower="-3.14159" upper="3.14159" velocity="0.0"/>
    </joint>
    <link name="link1">
        <inertial>
            <origin xyz="-0.19941581318651896 -0.33482014228668666 -0.30768910667338917" rpy="0 0 0"/>
            <mass value="1" />
            <inertia ixx="100" ixy="0" ixz="0" iyy="100" iyz="0" izz="100" />
        </inertial>
        <visual>
            <origin xyz="-0.19941581318651896 -0.33482014228668666 -0.30768910667338917" rpy="0 0 0"/>
            <geometry>
                <box size="0.39883162637303793 0.7085999629161677 0.6377482840449222" />
            </geometry>
            <material name="Cyan">
                <color rgba="0 1.0 1.0 1.0"/>
            </material>
        </visual>
        <collision>
            <origin xyz="-0.19941581318651896 -0.33482014228668666 -0.30768910667338917" rpy="0 0 0"/>
            <geometry>
                <box size="0.39883162637303793 0.7085999629161677 0.6377482840449222" />
            </geometry>
        </collision>
    </link>
    <joint name="link1_link2" type="revolute">
       <parent link="link1"/>
       <child  link="link2"/>
       <origin rpy="0 0 0" xyz="-0.029256876386923453 -0.42811075565997386 0.011185035349071948" />
     <axis xyz="0 1 0"/>
       <limit effort="0.0" lower="-3.14159" upper="3.14159" velocity="0.0"/>
    </joint>
    <link name="link2">
        <inertial>
            <origin xyz="-0.4328239252652249 -0.0038788665088108003 0.31569914819944983" rpy="0 0 0"/>
            <mass value="1" />
            <inertia ixx="100" ixy="0" ixz="0" iyy="100" iyz="0" izz="100" />
        </inertial>
        <visual>
            <origin xyz="-0.4328239252652249 -0.0038788665088108003 0.31569914819944983" rpy="0 0 0"/>
            <geometry>
                <box size="0.932035010989458 0.3046051952610801 0.6313982963988997" />
            </geometry>
            <material name="Cyan">
                <color rgba="0 1.0 1.0 1.0"/>
            </material>
        </visual>
        <collision>
            <origin xyz="-0.4328239252652249 -0.0038788665088108003 0.31569914819944983" rpy="0 0 0"/>
            <geometry>
                <box size="0.932035010989458 0.3046051952610801 0.6313982963988997" />
            </geometry>
        </collision>
    </link>
    <joint name="link1_link3" type="revolute">
       <parent link="link1"/>
       <child  link="link3"/>
       <origin rpy="0 0 0" xyz="-0.02022683422077487 0.019479839171397173 -0.5231620192532098" />
     <axis xyz="1 0 0"/>
       <limit effort="0.0" lower="-3.14159" upper="3.14159" velocity="0.0"/>
    </joint>
    <link name="link3">
        <inertial>
            <origin xyz="0.08291145913711982 0.3558581127931889 0.005364991330121179" rpy="0 0 0"/>
            <mass value="1" />
            <inertia ixx="100" ixy="0" ixz="0" iyy="100" iyz="0" izz="100" />
        </inertial>
        <visual>
            <origin xyz="0.08291145913711982 0.3558581127931889 0.005364991330121179" rpy="0 0 0"/>
            <geometry>
                <box size="0.3594083886964121 0.7117162255863778 0.0843462891504948" />
            </geometry>
            <material name="Cyan">
                <color rgba="0 1.0 1.0 1.0"/>
            </material>
        </visual>
        <collision>
            <origin xyz="0.08291145913711982 0.3558581127931889 0.005364991330121179" rpy="0 0 0"/>
            <geometry>
                <box size="0.3594083886964121 0.7117162255863778 0.0843462891504948" />
            </geometry>
        </collision>
    </link>
    <joint name="link0_link4" type="revolute">
       <parent link="link0"/>
       <child  link="link4"/>
       <origin rpy="0 0 0" xyz="0.4001239493979564 0.016316073273898873 1.1107875250224808" />
     <axis xyz="0 0 1"/>
       <limit effort="0.0" lower="-3.14159" upper="3.14159" velocity="0.0"/>
    </joint>
    <link name="link4">
        <inertial>
            <origin xyz="0.2720222788713487 0.04606897635163393 0.39931287615396643" rpy="0 0 0"/>
            <mass value="1" />
            <inertia ixx="100" ixy="0" ixz="0" iyy="100" iyz="0" izz="100" />
        </inertial>
        <visual>
            <origin xyz="0.2720222788713487 0.04606897635163393 0.39931287615396643" rpy="0 0 0"/>
            <geometry>
                <box size="0.5468018820995499 0.10719534280416032 0.7986257523079329" />
            </geometry>
            <material name="Cyan">
                <color rgba="0 1.0 1.0 1.0"/>
            </material>
        </visual>
        <collision>
            <origin xyz="0.2720222788713487 0.04606897635163393 0.39931287615396643" rpy="0 0 0"/>
            <geometry>
                <box size="0.5468018820995499 0.10719534280416032 0.7986257523079329" />
            </geometry>
        </collision>
    </link>
</robot>