<robot name = "robot">
    <link name="link0">
        <inertial>
            <origin xyz="0 0 1" rpy="0 0 0"/>
            <mass value="1" />
            <inertia ixx="100" ixy="0" ixz="0" iyy="100" iyz="0" izz="100" />
        </inertial>
        <visual>
            <origin xyz="0 0 1" rpy="0 0 0"/>
            <geometry>
                <box size="0.935425401541218 0.9574606081705008 0.4489956109744594" />
            </geometry>
            <material name="Cyan">
                <color rgba="0 1.0 1.0 1.0"/>
            </material>
        </visual>
        <collision>
            <origin xyz="0 0 1" rpy="0 0 0"/>
            <geometry>
                <box size="0.935425401541218 0.9574606081705008 0.4489956109744594" />
            </geometry>
        </collision>
    </link>
    <joint name="link0_link1" type="revolute">
       <parent link="link0"/>
       <child  link="link1"/>
       <origin rpy="0 0 0" xyz="0.06388035905863994 -0.4787303040852504 1.0784118787679455" />
     <axis xyz="1 0 0"/>
       <limit effort="0.0" lower="-3.14159" upper="3.14159" velocity="0.0"/>
    </joint>
    <link name="link1">
        <inertial>
            <origin xyz="0.07874270600604769 -0.10244004716688165 0.11422476588229172" rpy="0 0 0"/>
            <mass value="1" />
            <inertia ixx="100" ixy="0" ixz="0" iyy="100" iyz="0" izz="100" />
        </inertial>
        <visual>
            <origin xyz="0.07874270600604769 -0.10244004716688165 0.11422476588229172" rpy="0 0 0"/>
            <geometry>
                <box size="0.2589101332681113 0.2048800943337633 0.43824758344980985" />
            </geometry>
            <material name="Cyan">
                <color rgba="0 1.0 1.0 1.0"/>
            </material>
        </visual>
        <collision>
            <origin xyz="0.07874270600604769 -0.10244004716688165 0.11422476588229172" rpy="0 0 0"/>
            <geometry>
                <box size="0.2589101332681113 0.2048800943337633 0.43824758344980985" />
            </geometry>
        </collision>
    </link>
</robot>