<robot name = "robot">
    <link name="link0">
        <inertial>
            <origin xyz="0 0 1" rpy="0 0 0"/>
            <mass value="1" />
            <inertia ixx="100" ixy="0" ixz="0" iyy="100" iyz="0" izz="100" />
        </inertial>
        <visual>
            <origin xyz="0 0 1" rpy="0 0 0"/>
            <geometry>
                <box size="0.06835833331033236 0.7855541736464643 0.649221120535865" />
            </geometry>
            <material name="Cyan">
                <color rgba="0 1.0 1.0 1.0"/>
            </material>
        </visual>
        <collision>
            <origin xyz="0 0 1" rpy="0 0 0"/>
            <geometry>
                <box size="0.06835833331033236 0.7855541736464643 0.649221120535865" />
            </geometry>
        </collision>
    </link>
    <joint name="link0_link1" type="revolute">
       <parent link="link0"/>
       <child  link="link1"/>
       <origin rpy="0 0 0" xyz="-0.029213460218940605 -0.24206585469360198 0.6753894397320674" />
     <axis xyz="0 0 1"/>
       <limit effort="0.0" lower="-3.14159" upper="3.14159" velocity="0.0"/>
    </joint>
    <link name="link1">
        <inertial>
            <origin xyz="0.14180064860695055 0.20368246822422 -0.204036310886547" rpy="0 0 0"/>
            <mass value="1" />
            <inertia ixx="100" ixy="0" ixz="0" iyy="100" iyz="0" izz="100" />
        </inertial>
        <visual>
            <origin xyz="0.14180064860695055 0.20368246822422 -0.204036310886547" rpy="0 0 0"/>
            <geometry>
                <box size="0.4567130191466574 0.42805844267505533 0.408072621773094" />
            </geometry>
            <material name="Cyan">
                <color rgba="0 1.0 1.0 1.0"/>
            </material>
        </visual>
        <collision>
            <origin xyz="0.14180064860695055 0.20368246822422 -0.204036310886547" rpy="0 0 0"/>
            <geometry>
                <box size="0.4567130191466574 0.42805844267505533 0.408072621773094" />
            </geometry>
        </collision>
    </link>
</robot>