<robot name = "robot">
    <link name="link0">
        <inertial>
            <origin xyz="0 0 1" rpy="0 0 0"/>
            <mass value="1" />
            <inertia ixx="100" ixy="0" ixz="0" iyy="100" iyz="0" izz="100" />
        </inertial>
        <visual>
            <origin xyz="0 0 1" rpy="0 0 0"/>
            <geometry>
                <box size="0.282681073828262 0.8981272016275726 0.37401697669201617" />
            </geometry>
            <material name="Cyan">
                <color rgba="0.0 1.0 1.0 1.0"/>
            </material>
        </visual>
        <collision>
            <origin xyz="0 0 1" rpy="0 0 0"/>
            <geometry>
                <box size="0.282681073828262 0.8981272016275726 0.37401697669201617" />
            </geometry>
        </collision>
    </link>
    <joint name="link0_link1" type="revolute">
       <parent link="link0"/>
       <child  link="link1"/>
       <origin rpy="0 0 0" xyz="-0.00965107505796355 -0.4490636008137863 1.110925032718891" />
     <axis xyz="0 1 0"/>
       <limit effort="0.0" lower="-3.14159" upper="3.14159" velocity="0.0"/>
    </joint>
    <link name="link1">
        <inertial>
            <origin xyz="0.06617517674130056 -0.4347242465688781 -0.021095574337664017" rpy="0 0 0"/>
            <mass value="1" />
            <inertia ixx="100" ixy="0" ixz="0" iyy="100" iyz="0" izz="100" />
        </inertial>
        <visual>
            <origin xyz="0.06617517674130056 -0.4347242465688781 -0.021095574337664017" rpy="0 0 0"/>
            <geometry>
                <box size="0.8858299838443666 0.8694484931377562 0.5069956572852489" />
            </geometry>
            <material name="Green">
                <color rgba="0.0 1.0 0.0 1.0"/>
            </material>
        </visual>
        <collision>
            <origin xyz="0.06617517674130056 -0.4347242465688781 -0.021095574337664017" rpy="0 0 0"/>
            <geometry>
                <box size="0.8858299838443666 0.8694484931377562 0.5069956572852489" />
            </geometry>
        </collision>
    </link>
    <joint name="link0_link2" type="revolute">
       <parent link="link0"/>
       <child  link="link2"/>
       <origin rpy="0 0 0" xyz="0.141340536914131 0.368603732142041 1.0425709261124052" />
     <axis xyz="0 1 0"/>
       <limit effort="0.0" lower="-3.14159" upper="3.14159" velocity="0.0"/>
    </joint>
    <link name="link2">
        <inertial>
            <origin xyz="0.3624849177883672 -0.026274293834438453 -0.07513029920710433" rpy="0 0 0"/>
            <mass value="1" />
            <inertia ixx="100" ixy="0" ixz="0" iyy="100" iyz="0" izz="100" />
        </inertial>
        <visual>
            <origin xyz="0.3624849177883672 -0.026274293834438453 -0.07513029920710433" rpy="0 0 0"/>
            <geometry>
                <box size="0.7249698355767344 0.06696151450324717 0.6999536411232209" />
            </geometry>
            <material name="Green">
                <color rgba="0.0 1.0 0.0 1.0"/>
            </material>
        </visual>
        <collision>
            <origin xyz="0.3624849177883672 -0.026274293834438453 -0.07513029920710433" rpy="0 0 0"/>
            <geometry>
                <box size="0.7249698355767344 0.06696151450324717 0.6999536411232209" />
            </geometry>
        </collision>
    </link>
</robot>