<robot name = "robot">
    <link name="link0">
        <inertial>
            <origin xyz="0 0 1" rpy="0 0 0"/>
            <mass value="1" />
            <inertia ixx="100" ixy="0" ixz="0" iyy="100" iyz="0" izz="100" />
        </inertial>
        <visual>
            <origin xyz="0 0 1" rpy="0 0 0"/>
            <geometry>
                <box size="0.46830955479939473 0.6766512589832551 0.3372507266212309" />
            </geometry>
            <material name="Cyan">
                <color rgba="0 1.0 1.0 1.0"/>
            </material>
        </visual>
        <collision>
            <origin xyz="0 0 1" rpy="0 0 0"/>
            <geometry>
                <box size="0.46830955479939473 0.6766512589832551 0.3372507266212309" />
            </geometry>
        </collision>
    </link>
    <joint name="link0_link1" type="revolute">
       <parent link="link0"/>
       <child  link="link1"/>
       <origin rpy="0 0 0" xyz="0.23415477739969737 -0.05188355207474841 1.105085388213042" />
     <axis xyz="0 0 1"/>
       <limit effort="0.0" lower="-3.14159" upper="3.14159" velocity="0.0"/>
    </joint>
    <link name="link1">
        <inertial>
            <origin xyz="0.48117471536040163 -0.13166757626812514 0.016900362066992518" rpy="0 0 0"/>
            <mass value="1" />
            <inertia ixx="100" ixy="0" ixz="0" iyy="100" iyz="0" izz="100" />
        </inertial>
        <visual>
            <origin xyz="0.48117471536040163 -0.13166757626812514 0.016900362066992518" rpy="0 0 0"/>
            <geometry>
                <box size="0.9623494307208033 0.45736323258971145 0.5990830147792334" />
            </geometry>
            <material name="Cyan">
                <color rgba="0 1.0 1.0 1.0"/>
            </material>
        </visual>
        <collision>
            <origin xyz="0.48117471536040163 -0.13166757626812514 0.016900362066992518" rpy="0 0 0"/>
            <geometry>
                <box size="0.9623494307208033 0.45736323258971145 0.5990830147792334" />
            </geometry>
        </collision>
    </link>
    <joint name="link0_link2" type="revolute">
       <parent link="link0"/>
       <child  link="link2"/>
       <origin rpy="0 0 0" xyz="0.08074243085706195 -0.04629887571903189 1.1686253633106154" />
     <axis xyz="1 0 0"/>
       <limit effort="0.0" lower="-3.14159" upper="3.14159" velocity="0.0"/>
    </joint>
    <link name="link2">
        <inertial>
            <origin xyz="-0.4062518080619074 -0.03266868678588431 0.1749275572648229" rpy="0 0 0"/>
            <mass value="1" />
            <inertia ixx="100" ixy="0" ixz="0" iyy="100" iyz="0" izz="100" />
        </inertial>
        <visual>
            <origin xyz="-0.4062518080619074 -0.03266868678588431 0.1749275572648229" rpy="0 0 0"/>
            <geometry>
                <box size="0.8458759299658019 0.13363147186246127 0.3498551145296458" />
            </geometry>
            <material name="Cyan">
                <color rgba="0 1.0 1.0 1.0"/>
            </material>
        </visual>
        <collision>
            <origin xyz="-0.4062518080619074 -0.03266868678588431 0.1749275572648229" rpy="0 0 0"/>
            <geometry>
                <box size="0.8458759299658019 0.13363147186246127 0.3498551145296458" />
            </geometry>
        </collision>
    </link>
    <joint name="link0_link3" type="revolute">
       <parent link="link0"/>
       <child  link="link3"/>
       <origin rpy="0 0 0" xyz="-0.23415477739969737 0.028141614119308624 0.8616598031776332" />
     <axis xyz="0 0 1"/>
       <limit effort="0.0" lower="-3.14159" upper="3.14159" velocity="0.0"/>
    </joint>
    <link name="link3">
        <inertial>
            <origin xyz="-0.41645499502343725 -0.24153303577098595 0.05121841103252987" rpy="0 0 0"/>
            <mass value="1" />
            <inertia ixx="100" ixy="0" ixz="0" iyy="100" iyz="0" izz="100" />
        </inertial>
        <visual>
            <origin xyz="-0.41645499502343725 -0.24153303577098595 0.05121841103252987" rpy="0 0 0"/>
            <geometry>
                <box size="0.8329099900468745 0.48925962767996445 0.10765254131784852" />
            </geometry>
            <material name="Cyan">
                <color rgba="0 1.0 1.0 1.0"/>
            </material>
        </visual>
        <collision>
            <origin xyz="-0.41645499502343725 -0.24153303577098595 0.05121841103252987" rpy="0 0 0"/>
            <geometry>
                <box size="0.8329099900468745 0.48925962767996445 0.10765254131784852" />
            </geometry>
        </collision>
    </link>
    <joint name="link0_link4" type="revolute">
       <parent link="link0"/>
       <child  link="link4"/>
       <origin rpy="0 0 0" xyz="0.23415477739969737 0.24218882007092676 0.8617728234649206" />
     <axis xyz="1 0 0"/>
       <limit effort="0.0" lower="-3.14159" upper="3.14159" velocity="0.0"/>
    </joint>
    <link name="link4">
        <inertial>
            <origin xyz="0.13252240319269498 0.21709774820349784 0.05590360123617566" rpy="0 0 0"/>
            <mass value="1" />
            <inertia ixx="100" ixy="0" ixz="0" iyy="100" iyz="0" izz="100" />
        </inertial>
        <visual>
            <origin xyz="0.13252240319269498 0.21709774820349784 0.05590360123617566" rpy="0 0 0"/>
            <geometry>
                <box size="0.26504480638538996 0.7453878718166568 0.37791263623756055" />
            </geometry>
            <material name="Cyan">
                <color rgba="0 1.0 1.0 1.0"/>
            </material>
        </visual>
        <collision>
            <origin xyz="0.13252240319269498 0.21709774820349784 0.05590360123617566" rpy="0 0 0"/>
            <geometry>
                <box size="0.26504480638538996 0.7453878718166568 0.37791263623756055" />
            </geometry>
        </collision>
    </link>
    <joint name="link4_link5" type="revolute">
       <parent link="link4"/>
       <child  link="link5"/>
       <origin rpy="0 0 0" xyz="0.0 0.0826271427619619 0.23336665213139132" />
     <axis xyz="0 0 1"/>
       <limit effort="0.0" lower="-3.14159" upper="3.14159" velocity="0.0"/>
    </joint>
    <link name="link5">
        <inertial>
            <origin xyz="-0.062243383901885385 0.09134214022435513 -0.03488407550363978" rpy="0 0 0"/>
            <mass value="1" />
            <inertia ixx="100" ixy="0" ixz="0" iyy="100" iyz="0" izz="100" />
        </inertial>
        <visual>
            <origin xyz="-0.062243383901885385 0.09134214022435513 -0.03488407550363978" rpy="0 0 0"/>
            <geometry>
                <box size="0.12448676780377077 0.7862413457581722 0.7006898478568454" />
            </geometry>
            <material name="Cyan">
                <color rgba="0 1.0 1.0 1.0"/>
            </material>
        </visual>
        <collision>
            <origin xyz="-0.062243383901885385 0.09134214022435513 -0.03488407550363978" rpy="0 0 0"/>
            <geometry>
                <box size="0.12448676780377077 0.7862413457581722 0.7006898478568454" />
            </geometry>
        </collision>
    </link>
    <joint name="link5_link6" type="revolute">
       <parent link="link5"/>
       <child  link="link6"/>
       <origin rpy="0 0 0" xyz="-0.008334035630976046 0.4377082110926036 0.31546084842478295" />
     <axis xyz="0 0 1"/>
       <limit effort="0.0" lower="-3.14159" upper="3.14159" velocity="0.0"/>
    </joint>
    <link name="link6">
        <inertial>
            <origin xyz="0.17574955066552878 -0.0914284331247391 0.09326363524362008" rpy="0 0 0"/>
            <mass value="1" />
            <inertia ixx="100" ixy="0" ixz="0" iyy="100" iyz="0" izz="100" />
        </inertial>
        <visual>
            <origin xyz="0.17574955066552878 -0.0914284331247391 0.09326363524362008" rpy="0 0 0"/>
            <geometry>
                <box size="0.6622773449945683 0.5258874437760483 0.18652727048724016" />
            </geometry>
            <material name="Cyan">
                <color rgba="0 1.0 1.0 1.0"/>
            </material>
        </visual>
        <collision>
            <origin xyz="0.17574955066552878 -0.0914284331247391 0.09326363524362008" rpy="0 0 0"/>
            <geometry>
                <box size="0.6622773449945683 0.5258874437760483 0.18652727048724016" />
            </geometry>
        </collision>
    </link>
    <joint name="link4_link7" type="revolute">
       <parent link="link4"/>
       <child  link="link7"/>
       <origin rpy="0 0 0" xyz="0.2612336913702542 0.2585811891963292 0.24485991935495593" />
     <axis xyz="1 0 0"/>
       <limit effort="0.0" lower="-3.14159" upper="3.14159" velocity="0.0"/>
    </joint>
    <link name="link7">
        <inertial>
            <origin xyz="0.006919584899505514 0.06403549123515133 0.027187357075894314" rpy="0 0 0"/>
            <mass value="1" />
            <inertia ixx="100" ixy="0" ixz="0" iyy="100" iyz="0" izz="100" />
        </inertial>
        <visual>
            <origin xyz="0.006919584899505514 0.06403549123515133 0.027187357075894314" rpy="0 0 0"/>
            <geometry>
                <box size="0.02370187580009897 0.2902224907752793 0.05437471415178863" />
            </geometry>
            <material name="Cyan">
                <color rgba="0 1.0 1.0 1.0"/>
            </material>
        </visual>
        <collision>
            <origin xyz="0.006919584899505514 0.06403549123515133 0.027187357075894314" rpy="0 0 0"/>
            <geometry>
                <box size="0.02370187580009897 0.2902224907752793 0.05437471415178863" />
            </geometry>
        </collision>
    </link>
    <joint name="link3_link8" type="revolute">
       <parent link="link3"/>
       <child  link="link8"/>
       <origin rpy="0 0 0" xyz="-0.30049195024004194 -0.1518593664114238 -0.002607859626394385" />
     <axis xyz="1 0 0"/>
       <limit effort="0.0" lower="-3.14159" upper="3.14159" velocity="0.0"/>
    </joint>
    <link name="link8">
        <inertial>
            <origin xyz="-0.013289820205807885 -0.13281827715536776 -0.3916970427199036" rpy="0 0 0"/>
            <mass value="1" />
            <inertia ixx="100" ixy="0" ixz="0" iyy="100" iyz="0" izz="100" />
        </inertial>
        <visual>
            <origin xyz="-0.013289820205807885 -0.13281827715536776 -0.3916970427199036" rpy="0 0 0"/>
            <geometry>
                <box size="0.13159342792961515 0.5756344807887513 0.7833940854398072" />
            </geometry>
            <material name="Cyan">
                <color rgba="0 1.0 1.0 1.0"/>
            </material>
        </visual>
        <collision>
            <origin xyz="-0.013289820205807885 -0.13281827715536776 -0.3916970427199036" rpy="0 0 0"/>
            <geometry>
                <box size="0.13159342792961515 0.5756344807887513 0.7833940854398072" />
            </geometry>
        </collision>
    </link>
    <joint name="link4_link9" type="revolute">
       <parent link="link4"/>
       <child  link="link9"/>
       <origin rpy="0 0 0" xyz="0.0 0.3445374259058392 0.020915246377427803" />
     <axis xyz="0 1 0"/>
       <limit effort="0.0" lower="-3.14159" upper="3.14159" velocity="0.0"/>
    </joint>
    <link name="link9">
        <inertial>
            <origin xyz="-0.4237337076093844 0.07470747269061746 0.1329869613791715" rpy="0 0 0"/>
            <mass value="1" />
            <inertia ixx="100" ixy="0" ixz="0" iyy="100" iyz="0" izz="100" />
        </inertial>
        <visual>
            <origin xyz="-0.4237337076093844 0.07470747269061746 0.1329869613791715" rpy="0 0 0"/>
            <geometry>
                <box size="0.8474674152187688 0.2321045501767055 0.393873720698265" />
            </geometry>
            <material name="Cyan">
                <color rgba="0 1.0 1.0 1.0"/>
            </material>
        </visual>
        <collision>
            <origin xyz="-0.4237337076093844 0.07470747269061746 0.1329869613791715" rpy="0 0 0"/>
            <geometry>
                <box size="0.8474674152187688 0.2321045501767055 0.393873720698265" />
            </geometry>
        </collision>
    </link>
</robot>