<robot name = "robot">
    <link name="link0">
        <inertial>
            <origin xyz="0 0 1" rpy="0 0 0"/>
            <mass value="1" />
            <inertia ixx="100" ixy="0" ixz="0" iyy="100" iyz="0" izz="100" />
        </inertial>
        <visual>
            <origin xyz="0 0 1" rpy="0 0 0"/>
            <geometry>
                <box size="0.37714837947622926 0.9612559009124103 0.598332311773087" />
            </geometry>
            <material name="Cyan">
                <color rgba="0.0 1.0 1.0 1.0"/>
            </material>
        </visual>
        <collision>
            <origin xyz="0 0 1" rpy="0 0 0"/>
            <geometry>
                <box size="0.37714837947622926 0.9612559009124103 0.598332311773087" />
            </geometry>
        </collision>
    </link>
    <joint name="link0_link1" type="revolute">
       <parent link="link0"/>
       <child  link="link1"/>
       <origin rpy="0 0 0" xyz="0.013960115167326046 -0.15678486331816127 1.2991661558865435" />
     <axis xyz="0 0 1"/>
       <limit effort="0.0" lower="-3.14159" upper="3.14159" velocity="0.0"/>
    </joint>
    <link name="link1">
        <inertial>
            <origin xyz="-0.010144359268438374 0.013058721617441094 0.3829769676152303" rpy="0 0 0"/>
            <mass value="1" />
            <inertia ixx="100" ixy="0" ixz="0" iyy="100" iyz="0" izz="100" />
        </inertial>
        <visual>
            <origin xyz="-0.010144359268438374 0.013058721617441094 0.3829769676152303" rpy="0 0 0"/>
            <geometry>
                <box size="0.1742518408940832 0.03720347883569408 0.7659539352304606" />
            </geometry>
            <material name="Green">
                <color rgba="0.0 1.0 0.0 1.0"/>
            </material>
        </visual>
        <collision>
            <origin xyz="-0.010144359268438374 0.013058721617441094 0.3829769676152303" rpy="0 0 0"/>
            <geometry>
                <box size="0.1742518408940832 0.03720347883569408 0.7659539352304606" />
            </geometry>
        </collision>
    </link>
    <joint name="link0_link2" type="revolute">
       <parent link="link0"/>
       <child  link="link2"/>
       <origin rpy="0 0 0" xyz="0.18857418973811463 0.03784807912089524 1.2457006124094825" />
     <axis xyz="0 1 0"/>
       <limit effort="0.0" lower="-3.14159" upper="3.14159" velocity="0.0"/>
    </joint>
    <link name="link2">
        <inertial>
            <origin xyz="0.18959154251145544 0.005155626211895073 0.01548199429633355" rpy="0 0 0"/>
            <mass value="1" />
            <inertia ixx="100" ixy="0" ixz="0" iyy="100" iyz="0" izz="100" />
        </inertial>
        <visual>
            <origin xyz="0.18959154251145544 0.005155626211895073 0.01548199429633355" rpy="0 0 0"/>
            <geometry>
                <box size="0.37918308502291087 0.011827602383713054 0.042619377332950514" />
            </geometry>
            <material name="Green">
                <color rgba="0.0 1.0 0.0 1.0"/>
            </material>
        </visual>
        <collision>
            <origin xyz="0.18959154251145544 0.005155626211895073 0.01548199429633355" rpy="0 0 0"/>
            <geometry>
                <box size="0.37918308502291087 0.011827602383713054 0.042619377332950514" />
            </geometry>
        </collision>
    </link>
    <joint name="link0_link3" type="revolute">
       <parent link="link0"/>
       <child  link="link3"/>
       <origin rpy="0 0 0" xyz="0.009520099558909714 0.48062795045620516 1.2221241879050027" />
     <axis xyz="0 0 1"/>
       <limit effort="0.0" lower="-3.14159" upper="3.14159" velocity="0.0"/>
    </joint>
    <link name="link3">
        <inertial>
            <origin xyz="-0.3735784227089039 0.18946753301667885 0.17358352343891784" rpy="0 0 0"/>
            <mass value="1" />
            <inertia ixx="100" ixy="0" ixz="0" iyy="100" iyz="0" izz="100" />
        </inertial>
        <visual>
            <origin xyz="-0.3735784227089039 0.18946753301667885 0.17358352343891784" rpy="0 0 0"/>
            <geometry>
                <box size="0.9305730819719789 0.3789350660333577 0.5273342156549804" />
            </geometry>
            <material name="Green">
                <color rgba="0.0 1.0 0.0 1.0"/>
            </material>
        </visual>
        <collision>
            <origin xyz="-0.3735784227089039 0.18946753301667885 0.17358352343891784" rpy="0 0 0"/>
            <geometry>
                <box size="0.9305730819719789 0.3789350660333577 0.5273342156549804" />
            </geometry>
        </collision>
    </link>
    <joint name="link0_link4" type="revolute">
       <parent link="link0"/>
       <child  link="link4"/>
       <origin rpy="0 0 0" xyz="0.13033338631351715 -0.11781016980259883 1.2991661558865435" />
     <axis xyz="1 0 0"/>
       <limit effort="0.0" lower="-3.14159" upper="3.14159" velocity="0.0"/>
    </joint>
    <link name="link4">
        <inertial>
            <origin xyz="-0.011338450087057927 0.1396381472415707 0.49066661038513165" rpy="0 0 0"/>
            <mass value="1" />
            <inertia ixx="100" ixy="0" ixz="0" iyy="100" iyz="0" izz="100" />
        </inertial>
        <visual>
            <origin xyz="-0.011338450087057927 0.1396381472415707 0.49066661038513165" rpy="0 0 0"/>
            <geometry>
                <box size="0.18334490247956936 0.4225070238711297 0.9813332207702633" />
            </geometry>
            <material name="Green">
                <color rgba="0.0 1.0 0.0 1.0"/>
            </material>
        </visual>
        <collision>
            <origin xyz="-0.011338450087057927 0.1396381472415707 0.49066661038513165" rpy="0 0 0"/>
            <geometry>
                <box size="0.18334490247956936 0.4225070238711297 0.9813332207702633" />
            </geometry>
        </collision>
    </link>
    <joint name="link4_link5" type="revolute">
       <parent link="link4"/>
       <child  link="link5"/>
       <origin rpy="0 0 0" xyz="-0.10301090132684261 0.1518512329280331 0.6055762808614755" />
     <axis xyz="0 0 1"/>
       <limit effort="0.0" lower="-3.14159" upper="3.14159" velocity="0.0"/>
    </joint>
    <link name="link5">
        <inertial>
            <origin xyz="-0.09638253990465617 -0.030036080246437242 -0.18519026483405676" rpy="0 0 0"/>
            <mass value="1" />
            <inertia ixx="100" ixy="0" ixz="0" iyy="100" iyz="0" izz="100" />
        </inertial>
        <visual>
            <origin xyz="-0.09638253990465617 -0.030036080246437242 -0.18519026483405676" rpy="0 0 0"/>
            <geometry>
                <box size="0.19276507980931235 0.4723797908065207 0.7278313871310645" />
            </geometry>
            <material name="Green">
                <color rgba="0.0 1.0 0.0 1.0"/>
            </material>
        </visual>
        <collision>
            <origin xyz="-0.09638253990465617 -0.030036080246437242 -0.18519026483405676" rpy="0 0 0"/>
            <geometry>
                <box size="0.19276507980931235 0.4723797908065207 0.7278313871310645" />
            </geometry>
        </collision>
    </link>
    <joint name="link2_link6" type="revolute">
       <parent link="link2"/>
       <child  link="link6"/>
       <origin rpy="0 0 0" xyz="0.37918308502291087 0.0009162845448081767 0.029173574985013863" />
     <axis xyz="0 1 0"/>
       <limit effort="0.0" lower="-3.14159" upper="3.14159" velocity="0.0"/>
    </joint>
    <link name="link6">
        <inertial>
            <origin xyz="0.17833442386423948 0.2118168989272962 0.03417269835189683" rpy="0 0 0"/>
            <mass value="1" />
            <inertia ixx="100" ixy="0" ixz="0" iyy="100" iyz="0" izz="100" />
        </inertial>
        <visual>
            <origin xyz="0.17833442386423948 0.2118168989272962 0.03417269835189683" rpy="0 0 0"/>
            <geometry>
                <box size="0.35666884772847895 0.7524456488530195 0.23066255615757858" />
            </geometry>
            <material name="Green">
                <color rgba="0.0 1.0 0.0 1.0"/>
            </material>
        </visual>
        <collision>
            <origin xyz="0.17833442386423948 0.2118168989272962 0.03417269835189683" rpy="0 0 0"/>
            <geometry>
                <box size="0.35666884772847895 0.7524456488530195 0.23066255615757858" />
            </geometry>
        </collision>
    </link>
    <joint name="link0_link7" type="revolute">
       <parent link="link0"/>
       <child  link="link7"/>
       <origin rpy="0 0 0" xyz="0.18857418973811463 0.4288422052508517 0.7295213414404356" />
     <axis xyz="0 1 0"/>
       <limit effort="0.0" lower="-3.14159" upper="3.14159" velocity="0.0"/>
    </joint>
    <link name="link7">
        <inertial>
            <origin xyz="0.29248494977256523 0.3194693978101395 -0.007155831606342579" rpy="0 0 0"/>
            <mass value="1" />
            <inertia ixx="100" ixy="0" ixz="0" iyy="100" iyz="0" izz="100" />
        </inertial>
        <visual>
            <origin xyz="0.29248494977256523 0.3194693978101395 -0.007155831606342579" rpy="0 0 0"/>
            <geometry>
                <box size="0.5849698995451305 0.914319038959374 0.4965304658580202" />
            </geometry>
            <material name="Green">
                <color rgba="0.0 1.0 0.0 1.0"/>
            </material>
        </visual>
        <collision>
            <origin xyz="0.29248494977256523 0.3194693978101395 -0.007155831606342579" rpy="0 0 0"/>
            <geometry>
                <box size="0.5849698995451305 0.914319038959374 0.4965304658580202" />
            </geometry>
        </collision>
    </link>
    <joint name="link5_link8" type="revolute">
       <parent link="link5"/>
       <child  link="link8"/>
       <origin rpy="0 0 0" xyz="-0.08390354067205814 -0.2662259756496976 0.15530536303113285" />
     <axis xyz="1 0 0"/>
       <limit effort="0.0" lower="-3.14159" upper="3.14159" velocity="0.0"/>
    </joint>
    <link name="link8">
        <inertial>
            <origin xyz="-0.09370934107347483 -0.1676869973624875 -0.23484178840180026" rpy="0 0 0"/>
            <mass value="1" />
            <inertia ixx="100" ixy="0" ixz="0" iyy="100" iyz="0" izz="100" />
        </inertial>
        <visual>
            <origin xyz="-0.09370934107347483 -0.1676869973624875 -0.23484178840180026" rpy="0 0 0"/>
            <geometry>
                <box size="0.32356133366561246 0.335373994724975 0.6187010023898569" />
            </geometry>
            <material name="Green">
                <color rgba="0.0 1.0 0.0 1.0"/>
            </material>
        </visual>
        <collision>
            <origin xyz="-0.09370934107347483 -0.1676869973624875 -0.23484178840180026" rpy="0 0 0"/>
            <geometry>
                <box size="0.32356133366561246 0.335373994724975 0.6187010023898569" />
            </geometry>
        </collision>
    </link>
    <joint name="link7_link9" type="revolute">
       <parent link="link7"/>
       <child  link="link9"/>
       <origin rpy="0 0 0" xyz="0.0 0.06613144317097353 -0.08597834454781363" />
     <axis xyz="0 0 1"/>
       <limit effort="0.0" lower="-3.14159" upper="3.14159" velocity="0.0"/>
    </joint>
    <link name="link9">
        <inertial>
            <origin xyz="-0.3551992824689624 0.09172817788387971 0.029777087137799637" rpy="0 0 0"/>
            <mass value="1" />
            <inertia ixx="100" ixy="0" ixz="0" iyy="100" iyz="0" izz="100" />
        </inertial>
        <visual>
            <origin xyz="-0.3551992824689624 0.09172817788387971 0.029777087137799637" rpy="0 0 0"/>
            <geometry>
                <box size="0.7103985649379247 0.44815527967073554 0.10424315090560066" />
            </geometry>
            <material name="Green">
                <color rgba="0.0 1.0 0.0 1.0"/>
            </material>
        </visual>
        <collision>
            <origin xyz="-0.3551992824689624 0.09172817788387971 0.029777087137799637" rpy="0 0 0"/>
            <geometry>
                <box size="0.7103985649379247 0.44815527967073554 0.10424315090560066" />
            </geometry>
        </collision>
    </link>
</robot>