<robot name = "robot">
    <link name="link0">
        <inertial>
            <origin xyz="0 0 1" rpy="0 0 0"/>
            <mass value="1" />
            <inertia ixx="100" ixy="0" ixz="0" iyy="100" iyz="0" izz="100" />
        </inertial>
        <visual>
            <origin xyz="0 0 1" rpy="0 0 0"/>
            <geometry>
                <box size="0.4469724567448382 0.17353569676232905 0.6349527671622015" />
            </geometry>
            <material name="Cyan">
                <color rgba="0.0 1.0 1.0 1.0"/>
            </material>
        </visual>
        <collision>
            <origin xyz="0 0 1" rpy="0 0 0"/>
            <geometry>
                <box size="0.4469724567448382 0.17353569676232905 0.6349527671622015" />
            </geometry>
        </collision>
    </link>
    <joint name="link0_link1" type="revolute">
       <parent link="link0"/>
       <child  link="link1"/>
       <origin rpy="0 0 0" xyz="0.2234862283724191 0.0051746686016196615 0.9727188086684011" />
     <axis xyz="1 0 0"/>
       <limit effort="0.0" lower="-3.14159" upper="3.14159" velocity="0.0"/>
    </joint>
    <link name="link1">
        <inertial>
            <origin xyz="0.0785949841647311 0.1949959435418572 0.20874330956691073" rpy="0 0 0"/>
            <mass value="1" />
            <inertia ixx="100" ixy="0" ixz="0" iyy="100" iyz="0" izz="100" />
        </inertial>
        <visual>
            <origin xyz="0.0785949841647311 0.1949959435418572 0.20874330956691073" rpy="0 0 0"/>
            <geometry>
                <box size="0.1571899683294622 0.4593399875076981 0.4731114546604447" />
            </geometry>
            <material name="Green">
                <color rgba="0.0 1.0 0.0 1.0"/>
            </material>
        </visual>
        <collision>
            <origin xyz="0.0785949841647311 0.1949959435418572 0.20874330956691073" rpy="0 0 0"/>
            <geometry>
                <box size="0.1571899683294622 0.4593399875076981 0.4731114546604447" />
            </geometry>
        </collision>
    </link>
</robot>