<robot name = "robot">
    <link name="link0">
        <inertial>
            <origin xyz="0 0 1" rpy="0 0 0"/>
            <mass value="1" />
            <inertia ixx="100" ixy="0" ixz="0" iyy="100" iyz="0" izz="100" />
        </inertial>
        <visual>
            <origin xyz="0 0 1" rpy="0 0 0"/>
            <geometry>
                <box size="0.2907827791424422 0.14177051447533695 0.6479397661950544" />
            </geometry>
            <material name="Cyan">
                <color rgba="0.0 1.0 1.0 1.0"/>
            </material>
        </visual>
        <collision>
            <origin xyz="0 0 1" rpy="0 0 0"/>
            <geometry>
                <box size="0.2907827791424422 0.14177051447533695 0.6479397661950544" />
            </geometry>
        </collision>
    </link>
    <joint name="link0_link1" type="revolute">
       <parent link="link0"/>
       <child  link="link1"/>
       <origin rpy="0 0 0" xyz="0.1453913895712211 0.04572368906435368 0.7353999073636887" />
     <axis xyz="0 1 0"/>
       <limit effort="0.0" lower="-3.14159" upper="3.14159" velocity="0.0"/>
    </joint>
    <link name="link1">
        <inertial>
            <origin xyz="0.35670035687597323 0.1071260571853964 -0.11347791912657684" rpy="0 0 0"/>
            <mass value="1" />
            <inertia ixx="100" ixy="0" ixz="0" iyy="100" iyz="0" izz="100" />
        </inertial>
        <visual>
            <origin xyz="0.35670035687597323 0.1071260571853964 -0.11347791912657684" rpy="0 0 0"/>
            <geometry>
                <box size="0.7134007137519465 0.34208264391551957 0.4863636159697955" />
            </geometry>
            <material name="Cyan">
                <color rgba="0.0 1.0 1.0 1.0"/>
            </material>
        </visual>
        <collision>
            <origin xyz="0.35670035687597323 0.1071260571853964 -0.11347791912657684" rpy="0 0 0"/>
            <geometry>
                <box size="0.7134007137519465 0.34208264391551957 0.4863636159697955" />
            </geometry>
        </collision>
    </link>
    <joint name="link1_link2" type="revolute">
       <parent link="link1"/>
       <child  link="link2"/>
       <origin rpy="0 0 0" xyz="0.015115449195086228 -0.06391526477236338 -0.24502925336960873" />
     <axis xyz="0 1 0"/>
       <limit effort="0.0" lower="-3.14159" upper="3.14159" velocity="0.0"/>
    </joint>
    <link name="link2">
        <inertial>
            <origin xyz="0.16503460700590378 -0.33598335751239305 -0.3641649188603246" rpy="0 0 0"/>
            <mass value="1" />
            <inertia ixx="100" ixy="0" ixz="0" iyy="100" iyz="0" izz="100" />
        </inertial>
        <visual>
            <origin xyz="0.16503460700590378 -0.33598335751239305 -0.3641649188603246" rpy="0 0 0"/>
            <geometry>
                <box size="0.8987327879707224 0.6719667150247861 0.7648810051137237" />
            </geometry>
            <material name="Green">
                <color rgba="0.0 1.0 0.0 1.0"/>
            </material>
        </visual>
        <collision>
            <origin xyz="0.16503460700590378 -0.33598335751239305 -0.3641649188603246" rpy="0 0 0"/>
            <geometry>
                <box size="0.8987327879707224 0.6719667150247861 0.7648810051137237" />
            </geometry>
        </collision>
    </link>
</robot>