<robot name = "robot">
    <link name="link0">
        <inertial>
            <origin xyz="0 0 1" rpy="0 0 0"/>
            <mass value="1" />
            <inertia ixx="100" ixy="0" ixz="0" iyy="100" iyz="0" izz="100" />
        </inertial>
        <visual>
            <origin xyz="0 0 1" rpy="0 0 0"/>
            <geometry>
                <box size="0.41816481354275836 0.38409131224994364 0.9254210778943961" />
            </geometry>
            <material name="Cyan">
                <color rgba="0.0 1.0 1.0 1.0"/>
            </material>
        </visual>
        <collision>
            <origin xyz="0 0 1" rpy="0 0 0"/>
            <geometry>
                <box size="0.41816481354275836 0.38409131224994364 0.9254210778943961" />
            </geometry>
        </collision>
    </link>
    <joint name="link0_link1" type="revolute">
       <parent link="link0"/>
       <child  link="link1"/>
       <origin rpy="0 0 0" xyz="-0.20908240677137918 0.0466106942186368 0.6872837903511171" />
     <axis xyz="0 1 0"/>
       <limit effort="0.0" lower="-3.14159" upper="3.14159" velocity="0.0"/>
    </joint>
    <link name="link1">
        <inertial>
            <origin xyz="-0.04983379124895354 0.2089034464212357 -0.045031061995663715" rpy="0 0 0"/>
            <mass value="1" />
            <inertia ixx="100" ixy="0" ixz="0" iyy="100" iyz="0" izz="100" />
        </inertial>
        <visual>
            <origin xyz="-0.04983379124895354 0.2089034464212357 -0.045031061995663715" rpy="0 0 0"/>
            <geometry>
                <box size="0.09966758249790708 0.4389333446990814 0.4441156577910179" />
            </geometry>
            <material name="Green">
                <color rgba="0.0 1.0 0.0 1.0"/>
            </material>
        </visual>
        <collision>
            <origin xyz="-0.04983379124895354 0.2089034464212357 -0.045031061995663715" rpy="0 0 0"/>
            <geometry>
                <box size="0.09966758249790708 0.4389333446990814 0.4441156577910179" />
            </geometry>
        </collision>
    </link>
    <joint name="link0_link2" type="revolute">
       <parent link="link0"/>
       <child  link="link2"/>
       <origin rpy="0 0 0" xyz="0.07984193364730344 -0.19204565612497182 0.6303393291736319" />
     <axis xyz="1 0 0"/>
       <limit effort="0.0" lower="-3.14159" upper="3.14159" velocity="0.0"/>
    </joint>
    <link name="link2">
        <inertial>
            <origin xyz="-0.004774097656556354 -0.4745175961286881 -0.2277377944618296" rpy="0 0 0"/>
            <mass value="1" />
            <inertia ixx="100" ixy="0" ixz="0" iyy="100" iyz="0" izz="100" />
        </inertial>
        <visual>
            <origin xyz="-0.004774097656556354 -0.4745175961286881 -0.2277377944618296" rpy="0 0 0"/>
            <geometry>
                <box size="0.042674572641504205 0.9490351922573762 0.8407550430143037" />
            </geometry>
            <material name="Cyan">
                <color rgba="0.0 1.0 1.0 1.0"/>
            </material>
        </visual>
        <collision>
            <origin xyz="-0.004774097656556354 -0.4745175961286881 -0.2277377944618296" rpy="0 0 0"/>
            <geometry>
                <box size="0.042674572641504205 0.9490351922573762 0.8407550430143037" />
            </geometry>
        </collision>
    </link>
    <joint name="link2_link3" type="revolute">
       <parent link="link2"/>
       <child  link="link3"/>
       <origin rpy="0 0 0" xyz="0.012830345344881066 -0.9490351922573762 0.03385819056546488" />
     <axis xyz="0 1 0"/>
       <limit effort="0.0" lower="-3.14159" upper="3.14159" velocity="0.0"/>
    </joint>
    <link name="link3">
        <inertial>
            <origin xyz="0.4410589415756372 -0.07537655272866128 0.3385592506713494" rpy="0 0 0"/>
            <mass value="1" />
            <inertia ixx="100" ixy="0" ixz="0" iyy="100" iyz="0" izz="100" />
        </inertial>
        <visual>
            <origin xyz="0.4410589415756372 -0.07537655272866128 0.3385592506713494" rpy="0 0 0"/>
            <geometry>
                <box size="0.8834871746831994 0.15075310545732257 0.9338093467568289" />
            </geometry>
            <material name="Cyan">
                <color rgba="0.0 1.0 1.0 1.0"/>
            </material>
        </visual>
        <collision>
            <origin xyz="0.4410589415756372 -0.07537655272866128 0.3385592506713494" rpy="0 0 0"/>
            <geometry>
                <box size="0.8834871746831994 0.15075310545732257 0.9338093467568289" />
            </geometry>
        </collision>
    </link>
    <joint name="link1_link4" type="revolute">
       <parent link="link1"/>
       <child  link="link4"/>
       <origin rpy="0 0 0" xyz="-0.07413038425608832 0.3512936846356267 0.17702676689984526" />
     <axis xyz="1 0 0"/>
       <limit effort="0.0" lower="-3.14159" upper="3.14159" velocity="0.0"/>
    </joint>
    <link name="link4">
        <inertial>
            <origin xyz="-0.2518717487940979 -0.1308336241285285 0.2201038946448028" rpy="0 0 0"/>
            <mass value="1" />
            <inertia ixx="100" ixy="0" ixz="0" iyy="100" iyz="0" izz="100" />
        </inertial>
        <visual>
            <origin xyz="-0.2518717487940979 -0.1308336241285285 0.2201038946448028" rpy="0 0 0"/>
            <geometry>
                <box size="0.6716699908105855 0.45655947582999123 0.4402077892896056" />
            </geometry>
            <material name="Cyan">
                <color rgba="0.0 1.0 1.0 1.0"/>
            </material>
        </visual>
        <collision>
            <origin xyz="-0.2518717487940979 -0.1308336241285285 0.2201038946448028" rpy="0 0 0"/>
            <geometry>
                <box size="0.6716699908105855 0.45655947582999123 0.4402077892896056" />
            </geometry>
        </collision>
    </link>
    <joint name="link1_link5" type="revolute">
       <parent link="link1"/>
       <child  link="link5"/>
       <origin rpy="0 0 0" xyz="-0.019436842445370552 0.4283701187707764 -0.061071075556893235" />
     <axis xyz="0 0 1"/>
       <limit effort="0.0" lower="-3.14159" upper="3.14159" velocity="0.0"/>
    </joint>
    <link name="link5">
        <inertial>
            <origin xyz="-0.15546812687576297 0.270637587831045 -0.07527554148541903" rpy="0 0 0"/>
            <mass value="1" />
            <inertia ixx="100" ixy="0" ixz="0" iyy="100" iyz="0" izz="100" />
        </inertial>
        <visual>
            <origin xyz="-0.15546812687576297 0.270637587831045 -0.07527554148541903" rpy="0 0 0"/>
            <geometry>
                <box size="0.9718363617373654 0.54127517566209 0.3790149645533688" />
            </geometry>
            <material name="Cyan">
                <color rgba="0.0 1.0 1.0 1.0"/>
            </material>
        </visual>
        <collision>
            <origin xyz="-0.15546812687576297 0.270637587831045 -0.07527554148541903" rpy="0 0 0"/>
            <geometry>
                <box size="0.9718363617373654 0.54127517566209 0.3790149645533688" />
            </geometry>
        </collision>
    </link>
    <joint name="link2_link6" type="revolute">
       <parent link="link2"/>
       <child  link="link6"/>
       <origin rpy="0 0 0" xyz="0.014795086194677025 -0.9490351922573762 -0.5383651185868643" />
     <axis xyz="1 0 0"/>
       <limit effort="0.0" lower="-3.14159" upper="3.14159" velocity="0.0"/>
    </joint>
    <link name="link6">
        <inertial>
            <origin xyz="-0.04241263402690389 -0.42723369689632584 0.10298691085943144" rpy="0 0 0"/>
            <mass value="1" />
            <inertia ixx="100" ixy="0" ixz="0" iyy="100" iyz="0" izz="100" />
        </inertial>
        <visual>
            <origin xyz="-0.04241263402690389 -0.42723369689632584 0.10298691085943144" rpy="0 0 0"/>
            <geometry>
                <box size="0.7845001507470772 0.8544673937926517 0.32115071967019704" />
            </geometry>
            <material name="Green">
                <color rgba="0.0 1.0 0.0 1.0"/>
            </material>
        </visual>
        <collision>
            <origin xyz="-0.04241263402690389 -0.42723369689632584 0.10298691085943144" rpy="0 0 0"/>
            <geometry>
                <box size="0.7845001507470772 0.8544673937926517 0.32115071967019704" />
            </geometry>
        </collision>
    </link>
</robot>