<robot name = "robot">
    <link name="link0">
        <inertial>
            <origin xyz="0 0 1" rpy="0 0 0"/>
            <mass value="1" />
            <inertia ixx="100" ixy="0" ixz="0" iyy="100" iyz="0" izz="100" />
        </inertial>
        <visual>
            <origin xyz="0 0 1" rpy="0 0 0"/>
            <geometry>
                <box size="0.6135649121009364 0.7231589346069878 0.7098332357052254" />
            </geometry>
            <material name="Cyan">
                <color rgba="0.0 1.0 1.0 1.0"/>
            </material>
        </visual>
        <collision>
            <origin xyz="0 0 1" rpy="0 0 0"/>
            <geometry>
                <box size="0.6135649121009364 0.7231589346069878 0.7098332357052254" />
            </geometry>
        </collision>
    </link>
    <joint name="link0_link1" type="revolute">
       <parent link="link0"/>
       <child  link="link1"/>
       <origin rpy="0 0 0" xyz="0.2852760232278834 0.3615794673034939 1.1354838127878115" />
     <axis xyz="0 1 0"/>
       <limit effort="0.0" lower="-3.14159" upper="3.14159" velocity="0.0"/>
    </joint>
    <link name="link1">
        <inertial>
            <origin xyz="0.012810275063340289 0.444755609511107 -0.05373291050981526" rpy="0 0 0"/>
            <mass value="1" />
            <inertia ixx="100" ixy="0" ixz="0" iyy="100" iyz="0" izz="100" />
        </inertial>
        <visual>
            <origin xyz="0.012810275063340289 0.444755609511107 -0.05373291050981526" rpy="0 0 0"/>
            <geometry>
                <box size="0.6160253932527745 0.889511219022214 0.40681091706553985" />
            </geometry>
            <material name="Green">
                <color rgba="0.0 1.0 0.0 1.0"/>
            </material>
        </visual>
        <collision>
            <origin xyz="0.012810275063340289 0.444755609511107 -0.05373291050981526" rpy="0 0 0"/>
            <geometry>
                <box size="0.6160253932527745 0.889511219022214 0.40681091706553985" />
            </geometry>
        </collision>
    </link>
    <joint name="link0_link2" type="revolute">
       <parent link="link0"/>
       <child  link="link2"/>
       <origin rpy="0 0 0" xyz="-0.03614732219091096 0.137251011039843 1.3549166178526126" />
     <axis xyz="1 0 0"/>
       <limit effort="0.0" lower="-3.14159" upper="3.14159" velocity="0.0"/>
    </joint>
    <link name="link2">
        <inertial>
            <origin xyz="0.06995160107205052 -0.006984116835554203 0.1642583737644056" rpy="0 0 0"/>
            <mass value="1" />
            <inertia ixx="100" ixy="0" ixz="0" iyy="100" iyz="0" izz="100" />
        </inertial>
        <visual>
            <origin xyz="0.06995160107205052 -0.006984116835554203 0.1642583737644056" rpy="0 0 0"/>
            <geometry>
                <box size="0.1637057323147605 0.05609270241884323 0.3285167475288112" />
            </geometry>
            <material name="Green">
                <color rgba="0.0 1.0 0.0 1.0"/>
            </material>
        </visual>
        <collision>
            <origin xyz="0.06995160107205052 -0.006984116835554203 0.1642583737644056" rpy="0 0 0"/>
            <geometry>
                <box size="0.1637057323147605 0.05609270241884323 0.3285167475288112" />
            </geometry>
        </collision>
    </link>
    <joint name="link1_link3" type="revolute">
       <parent link="link1"/>
       <child  link="link3"/>
       <origin rpy="0 0 0" xyz="-0.20178547214730586 0.889511219022214 -0.05117982211524955" />
     <axis xyz="1 0 0"/>
       <limit effort="0.0" lower="-3.14159" upper="3.14159" velocity="0.0"/>
    </joint>
    <link name="link3">
        <inertial>
            <origin xyz="-0.03707249370412244 0.15520762238064062 0.16212366176027537" rpy="0 0 0"/>
            <mass value="1" />
            <inertia ixx="100" ixy="0" ixz="0" iyy="100" iyz="0" izz="100" />
        </inertial>
        <visual>
            <origin xyz="-0.03707249370412244 0.15520762238064062 0.16212366176027537" rpy="0 0 0"/>
            <geometry>
                <box size="0.7856971465450513 0.31041524476128124 0.9384545513205176" />
            </geometry>
            <material name="Green">
                <color rgba="0.0 1.0 0.0 1.0"/>
            </material>
        </visual>
        <collision>
            <origin xyz="-0.03707249370412244 0.15520762238064062 0.16212366176027537" rpy="0 0 0"/>
            <geometry>
                <box size="0.7856971465450513 0.31041524476128124 0.9384545513205176" />
            </geometry>
        </collision>
    </link>
    <joint name="link1_link4" type="revolute">
       <parent link="link1"/>
       <child  link="link4"/>
       <origin rpy="0 0 0" xyz="0.16570041969168453 0.36823531879324717 0.14967254802295465" />
     <axis xyz="0 0 1"/>
       <limit effort="0.0" lower="-3.14159" upper="3.14159" velocity="0.0"/>
    </joint>
    <link name="link4">
        <inertial>
            <origin xyz="0.17307164600555178 0.0364311082910944 0.3431809401920335" rpy="0 0 0"/>
            <mass value="1" />
            <inertia ixx="100" ixy="0" ixz="0" iyy="100" iyz="0" izz="100" />
        </inertial>
        <visual>
            <origin xyz="0.17307164600555178 0.0364311082910944 0.3431809401920335" rpy="0 0 0"/>
            <geometry>
                <box size="0.51434132985192 0.10396818266692476 0.686361880384067" />
            </geometry>
            <material name="Green">
                <color rgba="0.0 1.0 0.0 1.0"/>
            </material>
        </visual>
        <collision>
            <origin xyz="0.17307164600555178 0.0364311082910944 0.3431809401920335" rpy="0 0 0"/>
            <geometry>
                <box size="0.51434132985192 0.10396818266692476 0.686361880384067" />
            </geometry>
        </collision>
    </link>
    <joint name="link0_link5" type="revolute">
       <parent link="link0"/>
       <child  link="link5"/>
       <origin rpy="0 0 0" xyz="-0.0027942178514014505 0.009195295081661817 1.3549166178526126" />
     <axis xyz="1 0 0"/>
       <limit effort="0.0" lower="-3.14159" upper="3.14159" velocity="0.0"/>
    </joint>
    <link name="link5">
        <inertial>
            <origin xyz="0.2190116554408588 0.28913338698476626 0.3763290853384081" rpy="0 0 0"/>
            <mass value="1" />
            <inertia ixx="100" ixy="0" ixz="0" iyy="100" iyz="0" izz="100" />
        </inertial>
        <visual>
            <origin xyz="0.2190116554408588 0.28913338698476626 0.3763290853384081" rpy="0 0 0"/>
            <geometry>
                <box size="0.5883667051182315 0.6501386867486972 0.7526581706768162" />
            </geometry>
            <material name="Cyan">
                <color rgba="0.0 1.0 1.0 1.0"/>
            </material>
        </visual>
        <collision>
            <origin xyz="0.2190116554408588 0.28913338698476626 0.3763290853384081" rpy="0 0 0"/>
            <geometry>
                <box size="0.5883667051182315 0.6501386867486972 0.7526581706768162" />
            </geometry>
        </collision>
    </link>
    <joint name="link5_link6" type="revolute">
       <parent link="link5"/>
       <child  link="link6"/>
       <origin rpy="0 0 0" xyz="-0.07517169711825697 0.04094605392959638 0.345755209893808" />
     <axis xyz="0 1 0"/>
       <limit effort="0.0" lower="-3.14159" upper="3.14159" velocity="0.0"/>
    </joint>
    <link name="link6">
        <inertial>
            <origin xyz="-0.09252359433657692 0.42262117048881004 -0.10503376121460113" rpy="0 0 0"/>
            <mass value="1" />
            <inertia ixx="100" ixy="0" ixz="0" iyy="100" iyz="0" izz="100" />
        </inertial>
        <visual>
            <origin xyz="-0.09252359433657692 0.42262117048881004 -0.10503376121460113" rpy="0 0 0"/>
            <geometry>
                <box size="0.18504718867315384 0.9214889187958701 0.3023904065059029" />
            </geometry>
            <material name="Cyan">
                <color rgba="0.0 1.0 1.0 1.0"/>
            </material>
        </visual>
        <collision>
            <origin xyz="-0.09252359433657692 0.42262117048881004 -0.10503376121460113" rpy="0 0 0"/>
            <geometry>
                <box size="0.18504718867315384 0.9214889187958701 0.3023904065059029" />
            </geometry>
        </collision>
    </link>
    <joint name="link3_link7" type="revolute">
       <parent link="link3"/>
       <child  link="link7"/>
       <origin rpy="0 0 0" xyz="-0.0722688643738529 0.14758902609891777 0.6313509374205342" />
     <axis xyz="0 1 0"/>
       <limit effort="0.0" lower="-3.14159" upper="3.14159" velocity="0.0"/>
    </joint>
    <link name="link7">
        <inertial>
            <origin xyz="-0.09809351455616358 -0.011158584400951861 0.3619572448964572" rpy="0 0 0"/>
            <mass value="1" />
            <inertia ixx="100" ixy="0" ixz="0" iyy="100" iyz="0" izz="100" />
        </inertial>
        <visual>
            <origin xyz="-0.09809351455616358 -0.011158584400951861 0.3619572448964572" rpy="0 0 0"/>
            <geometry>
                <box size="0.4728169654484936 0.07844113893561122 0.7239144897929144" />
            </geometry>
            <material name="Green">
                <color rgba="0.0 1.0 0.0 1.0"/>
            </material>
        </visual>
        <collision>
            <origin xyz="-0.09809351455616358 -0.011158584400951861 0.3619572448964572" rpy="0 0 0"/>
            <geometry>
                <box size="0.4728169654484936 0.07844113893561122 0.7239144897929144" />
            </geometry>
        </collision>
    </link>
    <joint name="link2_link8" type="revolute">
       <parent link="link2"/>
       <child  link="link8"/>
       <origin rpy="0 0 0" xyz="-0.009789182000380911 -0.03503046804497582 0.2641851053780891" />
     <axis xyz="0 1 0"/>
       <limit effort="0.0" lower="-3.14159" upper="3.14159" velocity="0.0"/>
    </joint>
    <link name="link8">
        <inertial>
            <origin xyz="-0.05435622077902825 -0.27679851537524097 -0.11311887288237994" rpy="0 0 0"/>
            <mass value="1" />
            <inertia ixx="100" ixy="0" ixz="0" iyy="100" iyz="0" izz="100" />
        </inertial>
        <visual>
            <origin xyz="-0.05435622077902825 -0.27679851537524097 -0.11311887288237994" rpy="0 0 0"/>
            <geometry>
                <box size="0.11060494359549056 0.5535970307504819 0.4371665575336926" />
            </geometry>
            <material name="Green">
                <color rgba="0.0 1.0 0.0 1.0"/>
            </material>
        </visual>
        <collision>
            <origin xyz="-0.05435622077902825 -0.27679851537524097 -0.11311887288237994" rpy="0 0 0"/>
            <geometry>
                <box size="0.11060494359549056 0.5535970307504819 0.4371665575336926" />
            </geometry>
        </collision>
    </link>
    <joint name="link3_link9" type="revolute">
       <parent link="link3"/>
       <child  link="link9"/>
       <origin rpy="0 0 0" xyz="-0.13529690721888632 0.16203338354503627 0.6313509374205342" />
     <axis xyz="0 1 0"/>
       <limit effort="0.0" lower="-3.14159" upper="3.14159" velocity="0.0"/>
    </joint>
    <link name="link9">
        <inertial>
            <origin xyz="-0.17475435816752533 0.1303178213820573 0.30975588881257804" rpy="0 0 0"/>
            <mass value="1" />
            <inertia ixx="100" ixy="0" ixz="0" iyy="100" iyz="0" izz="100" />
        </inertial>
        <visual>
            <origin xyz="-0.17475435816752533 0.1303178213820573 0.30975588881257804" rpy="0 0 0"/>
            <geometry>
                <box size="0.8059989994133208 0.5459779869366371 0.6195117776251561" />
            </geometry>
            <material name="Green">
                <color rgba="0.0 1.0 0.0 1.0"/>
            </material>
        </visual>
        <collision>
            <origin xyz="-0.17475435816752533 0.1303178213820573 0.30975588881257804" rpy="0 0 0"/>
            <geometry>
                <box size="0.8059989994133208 0.5459779869366371 0.6195117776251561" />
            </geometry>
        </collision>
    </link>
</robot>