<robot name = "robot">
    <link name="link0">
        <inertial>
            <origin xyz="0 0 1" rpy="0 0 0"/>
            <mass value="1" />
            <inertia ixx="100" ixy="0" ixz="0" iyy="100" iyz="0" izz="100" />
        </inertial>
        <visual>
            <origin xyz="0 0 1" rpy="0 0 0"/>
            <geometry>
                <box size="0.49974035451598087 0.1483217811062938 0.7745896490116919" />
            </geometry>
            <material name="Cyan">
                <color rgba="0.0 1.0 1.0 1.0"/>
            </material>
        </visual>
        <collision>
            <origin xyz="0 0 1" rpy="0 0 0"/>
            <geometry>
                <box size="0.49974035451598087 0.1483217811062938 0.7745896490116919" />
            </geometry>
        </collision>
    </link>
    <joint name="link0_link1" type="revolute">
       <parent link="link0"/>
       <child  link="link1"/>
       <origin rpy="0 0 0" xyz="-0.0013488521899694633 -0.019955893568157055 1.387294824505846" />
     <axis xyz="0 0 1"/>
       <limit effort="0.0" lower="-3.14159" upper="3.14159" velocity="0.0"/>
    </joint>
    <link name="link1">
        <inertial>
            <origin xyz="0.04361381679903641 -0.04402298706123216 0.37051828423079863" rpy="0 0 0"/>
            <mass value="1" />
            <inertia ixx="100" ixy="0" ixz="0" iyy="100" iyz="0" izz="100" />
        </inertial>
        <visual>
            <origin xyz="0.04361381679903641 -0.04402298706123216 0.37051828423079863" rpy="0 0 0"/>
            <geometry>
                <box size="0.3578965541388195 0.3973441390955993 0.7410365684615973" />
            </geometry>
            <material name="Green">
                <color rgba="0.0 1.0 0.0 1.0"/>
            </material>
        </visual>
        <collision>
            <origin xyz="0.04361381679903641 -0.04402298706123216 0.37051828423079863" rpy="0 0 0"/>
            <geometry>
                <box size="0.3578965541388195 0.3973441390955993 0.7410365684615973" />
            </geometry>
        </collision>
    </link>
    <joint name="link1_link2" type="revolute">
       <parent link="link1"/>
       <child  link="link2"/>
       <origin rpy="0 0 0" xyz="0.180353566078207 0.1546490824865675 0.4714896626472348" />
     <axis xyz="1 0 0"/>
       <limit effort="0.0" lower="-3.14159" upper="3.14159" velocity="0.0"/>
    </joint>
    <link name="link2">
        <inertial>
            <origin xyz="-0.16993292010314276 0.12353482732992405 -0.1430383524675121" rpy="0 0 0"/>
            <mass value="1" />
            <inertia ixx="100" ixy="0" ixz="0" iyy="100" iyz="0" izz="100" />
        </inertial>
        <visual>
            <origin xyz="-0.16993292010314276 0.12353482732992405 -0.1430383524675121" rpy="0 0 0"/>
            <geometry>
                <box size="0.6237815956790566 0.2470696546598481 0.9624538095056714" />
            </geometry>
            <material name="Green">
                <color rgba="0.0 1.0 0.0 1.0"/>
            </material>
        </visual>
        <collision>
            <origin xyz="-0.16993292010314276 0.12353482732992405 -0.1430383524675121" rpy="0 0 0"/>
            <geometry>
                <box size="0.6237815956790566 0.2470696546598481 0.9624538095056714" />
            </geometry>
        </collision>
    </link>
    <joint name="link1_link3" type="revolute">
       <parent link="link1"/>
       <child  link="link3"/>
       <origin rpy="0 0 0" xyz="0.04155766181953505 -0.16018127597528603 0.7410365684615973" />
     <axis xyz="0 0 1"/>
       <limit effort="0.0" lower="-3.14159" upper="3.14159" velocity="0.0"/>
    </joint>
    <link name="link3">
        <inertial>
            <origin xyz="0.03353649746001078 -0.004945670942264048 0.009674303687149388" rpy="0 0 0"/>
            <mass value="1" />
            <inertia ixx="100" ixy="0" ixz="0" iyy="100" iyz="0" izz="100" />
        </inertial>
        <visual>
            <origin xyz="0.03353649746001078 -0.004945670942264048 0.009674303687149388" rpy="0 0 0"/>
            <geometry>
                <box size="0.27518318188692004 0.02487270511340356 0.019348607374298776" />
            </geometry>
            <material name="Green">
                <color rgba="0.0 1.0 0.0 1.0"/>
            </material>
        </visual>
        <collision>
            <origin xyz="0.03353649746001078 -0.004945670942264048 0.009674303687149388" rpy="0 0 0"/>
            <geometry>
                <box size="0.27518318188692004 0.02487270511340356 0.019348607374298776" />
            </geometry>
        </collision>
    </link>
    <joint name="link2_link4" type="revolute">
       <parent link="link2"/>
       <child  link="link4"/>
       <origin rpy="0 0 0" xyz="0.017489950292894546 0.2470696546598481 -0.31898881208828406" />
     <axis xyz="0 1 0"/>
       <limit effort="0.0" lower="-3.14159" upper="3.14159" velocity="0.0"/>
    </joint>
    <link name="link4">
        <inertial>
            <origin xyz="-0.08458153116973013 0.3650539145949278 0.13623978933557027" rpy="0 0 0"/>
            <mass value="1" />
            <inertia ixx="100" ixy="0" ixz="0" iyy="100" iyz="0" izz="100" />
        </inertial>
        <visual>
            <origin xyz="-0.08458153116973013 0.3650539145949278 0.13623978933557027" rpy="0 0 0"/>
            <geometry>
                <box size="0.7903341191160107 0.7301078291898556 0.4457762606059329" />
            </geometry>
            <material name="Green">
                <color rgba="0.0 1.0 0.0 1.0"/>
            </material>
        </visual>
        <collision>
            <origin xyz="-0.08458153116973013 0.3650539145949278 0.13623978933557027" rpy="0 0 0"/>
            <geometry>
                <box size="0.7903341191160107 0.7301078291898556 0.4457762606059329" />
            </geometry>
        </collision>
    </link>
    <joint name="link1_link5" type="revolute">
       <parent link="link1"/>
       <child  link="link5"/>
       <origin rpy="0 0 0" xyz="0.07198046634774413 -0.003566281332393159 0.7410365684615973" />
     <axis xyz="0 1 0"/>
       <limit effort="0.0" lower="-3.14159" upper="3.14159" velocity="0.0"/>
    </joint>
    <link name="link5">
        <inertial>
            <origin xyz="-0.033135262259165285 0.06204548714479694 0.45290151859034433" rpy="0 0 0"/>
            <mass value="1" />
            <inertia ixx="100" ixy="0" ixz="0" iyy="100" iyz="0" izz="100" />
        </inertial>
        <visual>
            <origin xyz="-0.033135262259165285 0.06204548714479694 0.45290151859034433" rpy="0 0 0"/>
            <geometry>
                <box size="0.22645298335021458 0.8390409486917813 0.9058030371806887" />
            </geometry>
            <material name="Green">
                <color rgba="0.0 1.0 0.0 1.0"/>
            </material>
        </visual>
        <collision>
            <origin xyz="-0.033135262259165285 0.06204548714479694 0.45290151859034433" rpy="0 0 0"/>
            <geometry>
                <box size="0.22645298335021458 0.8390409486917813 0.9058030371806887" />
            </geometry>
        </collision>
    </link>
    <joint name="link2_link6" type="revolute">
       <parent link="link2"/>
       <child  link="link6"/>
       <origin rpy="0 0 0" xyz="-0.48182371794267104 0.13104208366971193 -0.516006836383426" />
     <axis xyz="0 1 0"/>
       <limit effort="0.0" lower="-3.14159" upper="3.14159" velocity="0.0"/>
    </joint>
    <link name="link6">
        <inertial>
            <origin xyz="-0.34206073644914664 0.12281882729084664 0.2035270298574215" rpy="0 0 0"/>
            <mass value="1" />
            <inertia ixx="100" ixy="0" ixz="0" iyy="100" iyz="0" izz="100" />
        </inertial>
        <visual>
            <origin xyz="-0.34206073644914664 0.12281882729084664 0.2035270298574215" rpy="0 0 0"/>
            <geometry>
                <box size="0.6841214728982933 0.7171537686497611 0.6044624965394765" />
            </geometry>
            <material name="Green">
                <color rgba="0.0 1.0 0.0 1.0"/>
            </material>
        </visual>
        <collision>
            <origin xyz="-0.34206073644914664 0.12281882729084664 0.2035270298574215" rpy="0 0 0"/>
            <geometry>
                <box size="0.6841214728982933 0.7171537686497611 0.6044624965394765" />
            </geometry>
        </collision>
    </link>
    <joint name="link1_link7" type="revolute">
       <parent link="link1"/>
       <child  link="link7"/>
       <origin rpy="0 0 0" xyz="0.11350436051636911 -0.0601930730434071 0.7410365684615973" />
     <axis xyz="0 1 0"/>
       <limit effort="0.0" lower="-3.14159" upper="3.14159" velocity="0.0"/>
    </joint>
    <link name="link7">
        <inertial>
            <origin xyz="-0.3318349480272707 0.014159140732608768 0.28089539718481527" rpy="0 0 0"/>
            <mass value="1" />
            <inertia ixx="100" ixy="0" ixz="0" iyy="100" iyz="0" izz="100" />
        </inertial>
        <visual>
            <origin xyz="-0.3318349480272707 0.014159140732608768 0.28089539718481527" rpy="0 0 0"/>
            <geometry>
                <box size="0.6913374090144586 0.3896923842633052 0.5617907943696305" />
            </geometry>
            <material name="Green">
                <color rgba="0.0 1.0 0.0 1.0"/>
            </material>
        </visual>
        <collision>
            <origin xyz="-0.3318349480272707 0.014159140732608768 0.28089539718481527" rpy="0 0 0"/>
            <geometry>
                <box size="0.6913374090144586 0.3896923842633052 0.5617907943696305" />
            </geometry>
        </collision>
    </link>
    <joint name="link1_link8" type="revolute">
       <parent link="link1"/>
       <child  link="link8"/>
       <origin rpy="0 0 0" xyz="-0.13533446027037332 -0.24262237228334876 0.1361700379790772" />
     <axis xyz="0 0 1"/>
       <limit effort="0.0" lower="-3.14159" upper="3.14159" velocity="0.0"/>
    </joint>
    <link name="link8">
        <inertial>
            <origin xyz="-0.16956814772912532 -0.06469521021073944 -0.1468318548548642" rpy="0 0 0"/>
            <mass value="1" />
            <inertia ixx="100" ixy="0" ixz="0" iyy="100" iyz="0" izz="100" />
        </inertial>
        <visual>
            <origin xyz="-0.16956814772912532 -0.06469521021073944 -0.1468318548548642" rpy="0 0 0"/>
            <geometry>
                <box size="0.33913629545825064 0.7558811859055373 0.3409617828726852" />
            </geometry>
            <material name="Green">
                <color rgba="0.0 1.0 0.0 1.0"/>
            </material>
        </visual>
        <collision>
            <origin xyz="-0.16956814772912532 -0.06469521021073944 -0.1468318548548642" rpy="0 0 0"/>
            <geometry>
                <box size="0.33913629545825064 0.7558811859055373 0.3409617828726852" />
            </geometry>
        </collision>
    </link>
    <joint name="link5_link9" type="revolute">
       <parent link="link5"/>
       <child  link="link9"/>
       <origin rpy="0 0 0" xyz="0.04216753886049514 0.061898899953686054 0.9058030371806887" />
     <axis xyz="0 0 1"/>
       <limit effort="0.0" lower="-3.14159" upper="3.14159" velocity="0.0"/>
    </joint>
    <link name="link9">
        <inertial>
            <origin xyz="0.0006477876832217078 -0.22789647795520937 0.20855274067349994" rpy="0 0 0"/>
            <mass value="1" />
            <inertia ixx="100" ixy="0" ixz="0" iyy="100" iyz="0" izz="100" />
        </inertial>
        <visual>
            <origin xyz="0.0006477876832217078 -0.22789647795520937 0.20855274067349994" rpy="0 0 0"/>
            <geometry>
                <box size="0.007107646340373641 0.5346823070707404 0.4171054813469999" />
            </geometry>
            <material name="Cyan">
                <color rgba="0.0 1.0 1.0 1.0"/>
            </material>
        </visual>
        <collision>
            <origin xyz="0.0006477876832217078 -0.22789647795520937 0.20855274067349994" rpy="0 0 0"/>
            <geometry>
                <box size="0.007107646340373641 0.5346823070707404 0.4171054813469999" />
            </geometry>
        </collision>
    </link>
</robot>