<robot name = "robot">
    <link name="link0">
        <inertial>
            <origin xyz="0 0 1" rpy="0 0 0"/>
            <mass value="1" />
            <inertia ixx="100" ixy="0" ixz="0" iyy="100" iyz="0" izz="100" />
        </inertial>
        <visual>
            <origin xyz="0 0 1" rpy="0 0 0"/>
            <geometry>
                <box size="0.07564662368136488 0.8335747036155599 0.34826022361483877" />
            </geometry>
            <material name="Cyan">
                <color rgba="0.0 1.0 1.0 1.0"/>
            </material>
        </visual>
        <collision>
            <origin xyz="0 0 1" rpy="0 0 0"/>
            <geometry>
                <box size="0.07564662368136488 0.8335747036155599 0.34826022361483877" />
            </geometry>
        </collision>
    </link>
    <joint name="link0_link1" type="revolute">
       <parent link="link0"/>
       <child  link="link1"/>
       <origin rpy="0 0 0" xyz="0.03251448522693092 -0.4167873518077799 1.1078198067513094" />
     <axis xyz="0 0 1"/>
       <limit effort="0.0" lower="-3.14159" upper="3.14159" velocity="0.0"/>
    </joint>
    <link name="link1">
        <inertial>
            <origin xyz="-0.001255196093168028 -0.03825670142053256 0.060273697352558345" rpy="0 0 0"/>
            <mass value="1" />
            <inertia ixx="100" ixy="0" ixz="0" iyy="100" iyz="0" izz="100" />
        </inertial>
        <visual>
            <origin xyz="-0.001255196093168028 -0.03825670142053256 0.060273697352558345" rpy="0 0 0"/>
            <geometry>
                <box size="0.09564793376377212 0.07651340284106511 0.3741437121011624" />
            </geometry>
            <material name="Green">
                <color rgba="0.0 1.0 0.0 1.0"/>
            </material>
        </visual>
        <collision>
            <origin xyz="-0.001255196093168028 -0.03825670142053256 0.060273697352558345" rpy="0 0 0"/>
            <geometry>
                <box size="0.09564793376377212 0.07651340284106511 0.3741437121011624" />
            </geometry>
        </collision>
    </link>
    <joint name="link0_link2" type="revolute">
       <parent link="link0"/>
       <child  link="link2"/>
       <origin rpy="0 0 0" xyz="0.0026029405734746902 -0.4167873518077799 0.839477234139247" />
     <axis xyz="0 0 1"/>
       <limit effort="0.0" lower="-3.14159" upper="3.14159" velocity="0.0"/>
    </joint>
    <link name="link2">
        <inertial>
            <origin xyz="-0.30983855397981497 -0.48741882032375655 -0.1998911568606977" rpy="0 0 0"/>
            <mass value="1" />
            <inertia ixx="100" ixy="0" ixz="0" iyy="100" iyz="0" izz="100" />
        </inertial>
        <visual>
            <origin xyz="-0.30983855397981497 -0.48741882032375655 -0.1998911568606977" rpy="0 0 0"/>
            <geometry>
                <box size="0.8957071329412819 0.9748376406475131 0.910320312094223" />
            </geometry>
            <material name="Green">
                <color rgba="0.0 1.0 0.0 1.0"/>
            </material>
        </visual>
        <collision>
            <origin xyz="-0.30983855397981497 -0.48741882032375655 -0.1998911568606977" rpy="0 0 0"/>
            <geometry>
                <box size="0.8957071329412819 0.9748376406475131 0.910320312094223" />
            </geometry>
        </collision>
    </link>
</robot>