<robot name = "robot">
    <link name="link0">
        <inertial>
            <origin xyz="0 0 1" rpy="0 0 0"/>
            <mass value="1" />
            <inertia ixx="100" ixy="0" ixz="0" iyy="100" iyz="0" izz="100" />
        </inertial>
        <visual>
            <origin xyz="0 0 1" rpy="0 0 0"/>
            <geometry>
                <box size="0.4868844214492781 0.3043596208409962 0.486793717726117" />
            </geometry>
            <material name="Cyan">
                <color rgba="0 1.0 1.0 1.0"/>
            </material>
        </visual>
        <collision>
            <origin xyz="0 0 1" rpy="0 0 0"/>
            <geometry>
                <box size="0.4868844214492781 0.3043596208409962 0.486793717726117" />
            </geometry>
        </collision>
    </link>
    <joint name="link0_link1" type="revolute">
       <parent link="link0"/>
       <child  link="link1"/>
       <origin rpy="0 0 0" xyz="0.23957650365734934 0.1521798104204981 0.9088894044633135" />
     <axis xyz="1 0 0"/>
       <limit effort="0.0" lower="-3.14159" upper="3.14159" velocity="0.0"/>
    </joint>
    <link name="link1">
        <inertial>
            <origin xyz="-0.12172789443458848 0.461402841365816 0.15822055760396575" rpy="0 0 0"/>
            <mass value="1" />
            <inertia ixx="100" ixy="0" ixz="0" iyy="100" iyz="0" izz="100" />
        </inertial>
        <visual>
            <origin xyz="-0.12172789443458848 0.461402841365816 0.15822055760396575" rpy="0 0 0"/>
            <geometry>
                <box size="0.3756551175072016 0.922805682731632 0.6247800716529767" />
            </geometry>
            <material name="Cyan">
                <color rgba="0 1.0 1.0 1.0"/>
            </material>
        </visual>
        <collision>
            <origin xyz="-0.12172789443458848 0.461402841365816 0.15822055760396575" rpy="0 0 0"/>
            <geometry>
                <box size="0.3756551175072016 0.922805682731632 0.6247800716529767" />
            </geometry>
        </collision>
    </link>
</robot>