<robot name = "robot">
    <link name="link0">
        <inertial>
            <origin xyz="0 0 1" rpy="0 0 0"/>
            <mass value="1" />
            <inertia ixx="100" ixy="0" ixz="0" iyy="100" iyz="0" izz="100" />
        </inertial>
        <visual>
            <origin xyz="0 0 1" rpy="0 0 0"/>
            <geometry>
                <box size="0.21698303693091536 0.32617204897728513 0.5248397499697743" />
            </geometry>
            <material name="Cyan">
                <color rgba="0.0 1.0 1.0 1.0"/>
            </material>
        </visual>
        <collision>
            <origin xyz="0 0 1" rpy="0 0 0"/>
            <geometry>
                <box size="0.21698303693091536 0.32617204897728513 0.5248397499697743" />
            </geometry>
        </collision>
    </link>
    <joint name="link0_link1" type="revolute">
       <parent link="link0"/>
       <child  link="link1"/>
       <origin rpy="0 0 0" xyz="0.10849151846545768 0.04202825524503087 0.7600499093755483" />
     <axis xyz="0 0 1"/>
       <limit effort="0.0" lower="-3.14159" upper="3.14159" velocity="0.0"/>
    </joint>
    <link name="link1">
        <inertial>
            <origin xyz="0.29855115724883363 0.03701086886975614 0.09891023934967151" rpy="0 0 0"/>
            <mass value="1" />
            <inertia ixx="100" ixy="0" ixz="0" iyy="100" iyz="0" izz="100" />
        </inertial>
        <visual>
            <origin xyz="0.29855115724883363 0.03701086886975614 0.09891023934967151" rpy="0 0 0"/>
            <geometry>
                <box size="0.5971023144976673 0.1083113950202651 0.2971123093864618" />
            </geometry>
            <material name="Green">
                <color rgba="0.0 1.0 0.0 1.0"/>
            </material>
        </visual>
        <collision>
            <origin xyz="0.29855115724883363 0.03701086886975614 0.09891023934967151" rpy="0 0 0"/>
            <geometry>
                <box size="0.5971023144976673 0.1083113950202651 0.2971123093864618" />
            </geometry>
        </collision>
    </link>
    <joint name="link0_link2" type="revolute">
       <parent link="link0"/>
       <child  link="link2"/>
       <origin rpy="0 0 0" xyz="0.10849151846545768 0.1540507988892082 1.0554506206390637" />
     <axis xyz="0 0 1"/>
       <limit effort="0.0" lower="-3.14159" upper="3.14159" velocity="0.0"/>
    </joint>
    <link name="link2">
        <inertial>
            <origin xyz="0.3008812383033554 0.010640750118730124 0.06825610836311488" rpy="0 0 0"/>
            <mass value="1" />
            <inertia ixx="100" ixy="0" ixz="0" iyy="100" iyz="0" izz="100" />
        </inertial>
        <visual>
            <origin xyz="0.3008812383033554 0.010640750118730124 0.06825610836311488" rpy="0 0 0"/>
            <geometry>
                <box size="0.6017624766067108 0.11955904318315158 0.32560725677454183" />
            </geometry>
            <material name="Green">
                <color rgba="0.0 1.0 0.0 1.0"/>
            </material>
        </visual>
        <collision>
            <origin xyz="0.3008812383033554 0.010640750118730124 0.06825610836311488" rpy="0 0 0"/>
            <geometry>
                <box size="0.6017624766067108 0.11955904318315158 0.32560725677454183" />
            </geometry>
        </collision>
    </link>
    <joint name="link2_link3" type="revolute">
       <parent link="link2"/>
       <child  link="link3"/>
       <origin rpy="0 0 0" xyz="0.10306544828437814 0.07042027171030592 0.09375417745457029" />
     <axis xyz="0 1 0"/>
       <limit effort="0.0" lower="-3.14159" upper="3.14159" velocity="0.0"/>
    </joint>
    <link name="link3">
        <inertial>
            <origin xyz="-0.1794949124007362 0.20005945433511962 -0.13326776228877013" rpy="0 0 0"/>
            <mass value="1" />
            <inertia ixx="100" ixy="0" ixz="0" iyy="100" iyz="0" izz="100" />
        </inertial>
        <visual>
            <origin xyz="-0.1794949124007362 0.20005945433511962 -0.13326776228877013" rpy="0 0 0"/>
            <geometry>
                <box size="0.848963427862027 0.40011890867023925 0.409514623698892" />
            </geometry>
            <material name="Green">
                <color rgba="0.0 1.0 0.0 1.0"/>
            </material>
        </visual>
        <collision>
            <origin xyz="-0.1794949124007362 0.20005945433511962 -0.13326776228877013" rpy="0 0 0"/>
            <geometry>
                <box size="0.848963427862027 0.40011890867023925 0.409514623698892" />
            </geometry>
        </collision>
    </link>
    <joint name="link1_link4" type="revolute">
       <parent link="link1"/>
       <child  link="link4"/>
       <origin rpy="0 0 0" xyz="0.45636526171030256 0.09116656637988868 0.04369038972161743" />
     <axis xyz="1 0 0"/>
       <limit effort="0.0" lower="-3.14159" upper="3.14159" velocity="0.0"/>
    </joint>
    <link name="link4">
        <inertial>
            <origin xyz="0.11755879761046932 0.2281906968694256 -0.04046745884457382" rpy="0 0 0"/>
            <mass value="1" />
            <inertia ixx="100" ixy="0" ixz="0" iyy="100" iyz="0" izz="100" />
        </inertial>
        <visual>
            <origin xyz="0.11755879761046932 0.2281906968694256 -0.04046745884457382" rpy="0 0 0"/>
            <geometry>
                <box size="0.47322975909536225 0.4563813937388512 0.9435135327808919" />
            </geometry>
            <material name="Green">
                <color rgba="0.0 1.0 0.0 1.0"/>
            </material>
        </visual>
        <collision>
            <origin xyz="0.11755879761046932 0.2281906968694256 -0.04046745884457382" rpy="0 0 0"/>
            <geometry>
                <box size="0.47322975909536225 0.4563813937388512 0.9435135327808919" />
            </geometry>
        </collision>
    </link>
    <joint name="link2_link5" type="revolute">
       <parent link="link2"/>
       <child  link="link5"/>
       <origin rpy="0 0 0" xyz="0.4529046721604686 -0.04913877147284566 -0.0638704974680249" />
     <axis xyz="0 1 0"/>
       <limit effort="0.0" lower="-3.14159" upper="3.14159" velocity="0.0"/>
    </joint>
    <link name="link5">
        <inertial>
            <origin xyz="-0.2753169790908621 -0.4611940360909828 0.16050284552601057" rpy="0 0 0"/>
            <mass value="1" />
            <inertia ixx="100" ixy="0" ixz="0" iyy="100" iyz="0" izz="100" />
        </inertial>
        <visual>
            <origin xyz="-0.2753169790908621 -0.4611940360909828 0.16050284552601057" rpy="0 0 0"/>
            <geometry>
                <box size="0.8319074374509291 0.9223880721819656 0.45715824669604543" />
            </geometry>
            <material name="Cyan">
                <color rgba="0.0 1.0 1.0 1.0"/>
            </material>
        </visual>
        <collision>
            <origin xyz="-0.2753169790908621 -0.4611940360909828 0.16050284552601057" rpy="0 0 0"/>
            <geometry>
                <box size="0.8319074374509291 0.9223880721819656 0.45715824669604543" />
            </geometry>
        </collision>
    </link>
    <joint name="link0_link6" type="revolute">
       <parent link="link0"/>
       <child  link="link6"/>
       <origin rpy="0 0 0" xyz="-0.045009169276096515 0.12927145649572744 1.2624198749848872" />
     <axis xyz="0 1 0"/>
       <limit effort="0.0" lower="-3.14159" upper="3.14159" velocity="0.0"/>
    </joint>
    <link name="link6">
        <inertial>
            <origin xyz="-0.17376144657625842 -0.13396440719276587 0.06984495323416079" rpy="0 0 0"/>
            <mass value="1" />
            <inertia ixx="100" ixy="0" ixz="0" iyy="100" iyz="0" izz="100" />
        </inertial>
        <visual>
            <origin xyz="-0.17376144657625842 -0.13396440719276587 0.06984495323416079" rpy="0 0 0"/>
            <geometry>
                <box size="0.7308136312931739 0.6557197132407543 0.13968990646832158" />
            </geometry>
            <material name="Green">
                <color rgba="0.0 1.0 0.0 1.0"/>
            </material>
        </visual>
        <collision>
            <origin xyz="-0.17376144657625842 -0.13396440719276587 0.06984495323416079" rpy="0 0 0"/>
            <geometry>
                <box size="0.7308136312931739 0.6557197132407543 0.13968990646832158" />
            </geometry>
        </collision>
    </link>
    <joint name="link3_link7" type="revolute">
       <parent link="link3"/>
       <child  link="link7"/>
       <origin rpy="0 0 0" xyz="-0.2703366151576882 0.40011890867023925 0.0484721469990356" />
     <axis xyz="0 1 0"/>
       <limit effort="0.0" lower="-3.14159" upper="3.14159" velocity="0.0"/>
    </joint>
    <link name="link7">
        <inertial>
            <origin xyz="0.010587740595280278 0.18030480276539546 0.10114513932160837" rpy="0 0 0"/>
            <mass value="1" />
            <inertia ixx="100" ixy="0" ixz="0" iyy="100" iyz="0" izz="100" />
        </inertial>
        <visual>
            <origin xyz="0.010587740595280278 0.18030480276539546 0.10114513932160837" rpy="0 0 0"/>
            <geometry>
                <box size="0.32590152694491636 0.3606096055307909 0.2601195072834519" />
            </geometry>
            <material name="Green">
                <color rgba="0.0 1.0 0.0 1.0"/>
            </material>
        </visual>
        <collision>
            <origin xyz="0.010587740595280278 0.18030480276539546 0.10114513932160837" rpy="0 0 0"/>
            <geometry>
                <box size="0.32590152694491636 0.3606096055307909 0.2601195072834519" />
            </geometry>
        </collision>
    </link>
    <joint name="link0_link8" type="revolute">
       <parent link="link0"/>
       <child  link="link8"/>
       <origin rpy="0 0 0" xyz="-0.09473120846684446 -0.1516581496422674 1.2624198749848872" />
     <axis xyz="0 1 0"/>
       <limit effort="0.0" lower="-3.14159" upper="3.14159" velocity="0.0"/>
    </joint>
    <link name="link8">
        <inertial>
            <origin xyz="-0.15063727691742287 0.10191242071877762 0.30965367799492516" rpy="0 0 0"/>
            <mass value="1" />
            <inertia ixx="100" ixy="0" ixz="0" iyy="100" iyz="0" izz="100" />
        </inertial>
        <visual>
            <origin xyz="-0.15063727691742287 0.10191242071877762 0.30965367799492516" rpy="0 0 0"/>
            <geometry>
                <box size="0.4215024636439054 0.5218649411501715 0.6193073559898503" />
            </geometry>
            <material name="Green">
                <color rgba="0.0 1.0 0.0 1.0"/>
            </material>
        </visual>
        <collision>
            <origin xyz="-0.15063727691742287 0.10191242071877762 0.30965367799492516" rpy="0 0 0"/>
            <geometry>
                <box size="0.4215024636439054 0.5218649411501715 0.6193073559898503" />
            </geometry>
        </collision>
    </link>
</robot>