<robot name = "robot">
    <link name="link0">
        <inertial>
            <origin xyz="0 0 1" rpy="0 0 0"/>
            <mass value="1" />
            <inertia ixx="100" ixy="0" ixz="0" iyy="100" iyz="0" izz="100" />
        </inertial>
        <visual>
            <origin xyz="0 0 1" rpy="0 0 0"/>
            <geometry>
                <box size="0.8793941840806251 0.22540807326318157 0.7146477918990395" />
            </geometry>
            <material name="Cyan">
                <color rgba="0.0 1.0 1.0 1.0"/>
            </material>
        </visual>
        <collision>
            <origin xyz="0 0 1" rpy="0 0 0"/>
            <geometry>
                <box size="0.8793941840806251 0.22540807326318157 0.7146477918990395" />
            </geometry>
        </collision>
    </link>
    <joint name="link0_link1" type="revolute">
       <parent link="link0"/>
       <child  link="link1"/>
       <origin rpy="0 0 0" xyz="-0.13828698944632567 0.11270403663159079 1.3465983858524317" />
     <axis xyz="1 0 0"/>
       <limit effort="0.0" lower="-3.14159" upper="3.14159" velocity="0.0"/>
    </joint>
    <link name="link1">
        <inertial>
            <origin xyz="-0.07081928968969003 0.08028883677068105 0.11775651787474825" rpy="0 0 0"/>
            <mass value="1" />
            <inertia ixx="100" ixy="0" ixz="0" iyy="100" iyz="0" izz="100" />
        </inertial>
        <visual>
            <origin xyz="-0.07081928968969003 0.08028883677068105 0.11775651787474825" rpy="0 0 0"/>
            <geometry>
                <box size="0.16184675628561007 0.1605776735413621 0.33009034222537703" />
            </geometry>
            <material name="Green">
                <color rgba="0.0 1.0 0.0 1.0"/>
            </material>
        </visual>
        <collision>
            <origin xyz="-0.07081928968969003 0.08028883677068105 0.11775651787474825" rpy="0 0 0"/>
            <geometry>
                <box size="0.16184675628561007 0.1605776735413621 0.33009034222537703" />
            </geometry>
        </collision>
    </link>
    <joint name="link1_link2" type="revolute">
       <parent link="link1"/>
       <child  link="link2"/>
       <origin rpy="0 0 0" xyz="-0.013841875013003185 0.091566291014361 0.28280168898743674" />
     <axis xyz="1 0 0"/>
       <limit effort="0.0" lower="-3.14159" upper="3.14159" velocity="0.0"/>
    </joint>
    <link name="link2">
        <inertial>
            <origin xyz="0.2827987823680078 0.3673617273505889 0.3156169229210718" rpy="0 0 0"/>
            <mass value="1" />
            <inertia ixx="100" ixy="0" ixz="0" iyy="100" iyz="0" izz="100" />
        </inertial>
        <visual>
            <origin xyz="0.2827987823680078 0.3673617273505889 0.3156169229210718" rpy="0 0 0"/>
            <geometry>
                <box size="0.5918180161315096 0.779622459387017 0.6312338458421436" />
            </geometry>
            <material name="Green">
                <color rgba="0.0 1.0 0.0 1.0"/>
            </material>
        </visual>
        <collision>
            <origin xyz="0.2827987823680078 0.3673617273505889 0.3156169229210718" rpy="0 0 0"/>
            <geometry>
                <box size="0.5918180161315096 0.779622459387017 0.6312338458421436" />
            </geometry>
        </collision>
    </link>
    <joint name="link1_link3" type="revolute">
       <parent link="link1"/>
       <child  link="link3"/>
       <origin rpy="0 0 0" xyz="-0.12554843097243037 0.0 -0.016939115819388673" />
     <axis xyz="0 1 0"/>
       <limit effort="0.0" lower="-3.14159" upper="3.14159" velocity="0.0"/>
    </joint>
    <link name="link3">
        <inertial>
            <origin xyz="0.051726722686871195 -0.48407877420166157 -0.2750818085748139" rpy="0 0 0"/>
            <mass value="1" />
            <inertia ixx="100" ixy="0" ixz="0" iyy="100" iyz="0" izz="100" />
        </inertial>
        <visual>
            <origin xyz="0.051726722686871195 -0.48407877420166157 -0.2750818085748139" rpy="0 0 0"/>
            <geometry>
                <box size="0.3977943892915591 0.9681575484033231 0.6897238330802259" />
            </geometry>
            <material name="Green">
                <color rgba="0.0 1.0 0.0 1.0"/>
            </material>
        </visual>
        <collision>
            <origin xyz="0.051726722686871195 -0.48407877420166157 -0.2750818085748139" rpy="0 0 0"/>
            <geometry>
                <box size="0.3977943892915591 0.9681575484033231 0.6897238330802259" />
            </geometry>
        </collision>
    </link>
    <joint name="link3_link4" type="revolute">
       <parent link="link3"/>
       <child  link="link4"/>
       <origin rpy="0 0 0" xyz="0.2506239173326507 -0.18518872480805404 -0.18561946911694063" />
     <axis xyz="0 1 0"/>
       <limit effort="0.0" lower="-3.14159" upper="3.14159" velocity="0.0"/>
    </joint>
    <link name="link4">
        <inertial>
            <origin xyz="0.3275989325029464 -0.2207025323286042 -0.03093029764782665" rpy="0 0 0"/>
            <mass value="1" />
            <inertia ixx="100" ixy="0" ixz="0" iyy="100" iyz="0" izz="100" />
        </inertial>
        <visual>
            <origin xyz="0.3275989325029464 -0.2207025323286042 -0.03093029764782665" rpy="0 0 0"/>
            <geometry>
                <box size="0.6551978650058928 0.46148605102069984 0.8766286453078632" />
            </geometry>
            <material name="Green">
                <color rgba="0.0 1.0 0.0 1.0"/>
            </material>
        </visual>
        <collision>
            <origin xyz="0.3275989325029464 -0.2207025323286042 -0.03093029764782665" rpy="0 0 0"/>
            <geometry>
                <box size="0.6551978650058928 0.46148605102069984 0.8766286453078632" />
            </geometry>
        </collision>
    </link>
    <joint name="link2_link5" type="revolute">
       <parent link="link2"/>
       <child  link="link5"/>
       <origin rpy="0 0 0" xyz="0.11423412457708035 -0.02244950234291959 0.5271252376630851" />
     <axis xyz="0 1 0"/>
       <limit effort="0.0" lower="-3.14159" upper="3.14159" velocity="0.0"/>
    </joint>
    <link name="link5">
        <inertial>
            <origin xyz="0.037019199051435706 -0.4835181176407318 -0.022555469750788648" rpy="0 0 0"/>
            <mass value="1" />
            <inertia ixx="100" ixy="0" ixz="0" iyy="100" iyz="0" izz="100" />
        </inertial>
        <visual>
            <origin xyz="0.037019199051435706 -0.4835181176407318 -0.022555469750788648" rpy="0 0 0"/>
            <geometry>
                <box size="0.488855853151121 0.9670362352814637 0.11118032955704693" />
            </geometry>
            <material name="Green">
                <color rgba="0.0 1.0 0.0 1.0"/>
            </material>
        </visual>
        <collision>
            <origin xyz="0.037019199051435706 -0.4835181176407318 -0.022555469750788648" rpy="0 0 0"/>
            <geometry>
                <box size="0.488855853151121 0.9670362352814637 0.11118032955704693" />
            </geometry>
        </collision>
    </link>
</robot>