<robot name = "robot">
    <link name="link0">
        <inertial>
            <origin xyz="0 0 1" rpy="0 0 0"/>
            <mass value="1" />
            <inertia ixx="100" ixy="0" ixz="0" iyy="100" iyz="0" izz="100" />
        </inertial>
        <visual>
            <origin xyz="0 0 1" rpy="0 0 0"/>
            <geometry>
                <box size="0.28037331677387833 0.5587879945257599 0.9188709566624791" />
            </geometry>
            <material name="Cyan">
                <color rgba="0.0 1.0 1.0 1.0"/>
            </material>
        </visual>
        <collision>
            <origin xyz="0 0 1" rpy="0 0 0"/>
            <geometry>
                <box size="0.28037331677387833 0.5587879945257599 0.9188709566624791" />
            </geometry>
        </collision>
    </link>
    <joint name="link0_link1" type="revolute">
       <parent link="link0"/>
       <child  link="link1"/>
       <origin rpy="0 0 0" xyz="-0.053718193717106365 0.27939399726287995 1.2032576645217057" />
     <axis xyz="0 1 0"/>
       <limit effort="0.0" lower="-3.14159" upper="3.14159" velocity="0.0"/>
    </joint>
    <link name="link1">
        <inertial>
            <origin xyz="-0.044816812466955507 0.371834976247183 0.11266465171626132" rpy="0 0 0"/>
            <mass value="1" />
            <inertia ixx="100" ixy="0" ixz="0" iyy="100" iyz="0" izz="100" />
        </inertial>
        <visual>
            <origin xyz="-0.044816812466955507 0.371834976247183 0.11266465171626132" rpy="0 0 0"/>
            <geometry>
                <box size="0.19584991532558516 0.743669952494366 0.9491305224960873" />
            </geometry>
            <material name="Green">
                <color rgba="0.0 1.0 0.0 1.0"/>
            </material>
        </visual>
        <collision>
            <origin xyz="-0.044816812466955507 0.371834976247183 0.11266465171626132" rpy="0 0 0"/>
            <geometry>
                <box size="0.19584991532558516 0.743669952494366 0.9491305224960873" />
            </geometry>
        </collision>
    </link>
    <joint name="link1_link2" type="revolute">
       <parent link="link1"/>
       <child  link="link2"/>
       <origin rpy="0 0 0" xyz="0.0061130789185535675 0.15097028635645202 0.5872299129643049" />
     <axis xyz="0 1 0"/>
       <limit effort="0.0" lower="-3.14159" upper="3.14159" velocity="0.0"/>
    </joint>
    <link name="link2">
        <inertial>
            <origin xyz="0.019214710313791093 0.07512999785591448 0.08862193384691291" rpy="0 0 0"/>
            <mass value="1" />
            <inertia ixx="100" ixy="0" ixz="0" iyy="100" iyz="0" izz="100" />
        </inertial>
        <visual>
            <origin xyz="0.019214710313791093 0.07512999785591448 0.08862193384691291" rpy="0 0 0"/>
            <geometry>
                <box size="0.040081589731078004 0.6614828699263292 0.17724386769382583" />
            </geometry>
            <material name="Green">
                <color rgba="0.0 1.0 0.0 1.0"/>
            </material>
        </visual>
        <collision>
            <origin xyz="0.019214710313791093 0.07512999785591448 0.08862193384691291" rpy="0 0 0"/>
            <geometry>
                <box size="0.040081589731078004 0.6614828699263292 0.17724386769382583" />
            </geometry>
        </collision>
    </link>
</robot>