<robot name = "robot">
    <link name="link0">
        <inertial>
            <origin xyz="0 0 1" rpy="0 0 0"/>
            <mass value="1" />
            <inertia ixx="100" ixy="0" ixz="0" iyy="100" iyz="0" izz="100" />
        </inertial>
        <visual>
            <origin xyz="0 0 1" rpy="0 0 0"/>
            <geometry>
                <box size="0.1355881414522192 0.6067137898203734 0.40514799732384854" />
            </geometry>
            <material name="Cyan">
                <color rgba="0.0 1.0 1.0 1.0"/>
            </material>
        </visual>
        <collision>
            <origin xyz="0 0 1" rpy="0 0 0"/>
            <geometry>
                <box size="0.1355881414522192 0.6067137898203734 0.40514799732384854" />
            </geometry>
        </collision>
    </link>
    <joint name="link0_link1" type="revolute">
       <parent link="link0"/>
       <child  link="link1"/>
       <origin rpy="0 0 0" xyz="-0.030096212180296556 0.3033568949101867 1.188155169490271" />
     <axis xyz="0 0 1"/>
       <limit effort="0.0" lower="-3.14159" upper="3.14159" velocity="0.0"/>
    </joint>
    <link name="link1">
        <inertial>
            <origin xyz="-0.08811876911883697 0.46498468753512506 -0.028286606673412013" rpy="0 0 0"/>
            <mass value="1" />
            <inertia ixx="100" ixy="0" ixz="0" iyy="100" iyz="0" izz="100" />
        </inertial>
        <visual>
            <origin xyz="-0.08811876911883697 0.46498468753512506 -0.028286606673412013" rpy="0 0 0"/>
            <geometry>
                <box size="0.709292873767213 0.9299693750702501 0.08923541703217464" />
            </geometry>
            <material name="Green">
                <color rgba="0.0 1.0 0.0 1.0"/>
            </material>
        </visual>
        <collision>
            <origin xyz="-0.08811876911883697 0.46498468753512506 -0.028286606673412013" rpy="0 0 0"/>
            <geometry>
                <box size="0.709292873767213 0.9299693750702501 0.08923541703217464" />
            </geometry>
        </collision>
    </link>
    <joint name="link1_link2" type="revolute">
       <parent link="link1"/>
       <child  link="link2"/>
       <origin rpy="0 0 0" xyz="0.22568067835570182 0.9299693750702501 -0.04997971268067997" />
     <axis xyz="1 0 0"/>
       <limit effort="0.0" lower="-3.14159" upper="3.14159" velocity="0.0"/>
    </joint>
    <link name="link2">
        <inertial>
            <origin xyz="0.24625436095358635 0.08348945893329657 0.0009631407409928554" rpy="0 0 0"/>
            <mass value="1" />
            <inertia ixx="100" ixy="0" ixz="0" iyy="100" iyz="0" izz="100" />
        </inertial>
        <visual>
            <origin xyz="0.24625436095358635 0.08348945893329657 0.0009631407409928554" rpy="0 0 0"/>
            <geometry>
                <box size="0.9275338100888112 0.16697891786659314 0.20762763866852585" />
            </geometry>
            <material name="Green">
                <color rgba="0.0 1.0 0.0 1.0"/>
            </material>
        </visual>
        <collision>
            <origin xyz="0.24625436095358635 0.08348945893329657 0.0009631407409928554" rpy="0 0 0"/>
            <geometry>
                <box size="0.9275338100888112 0.16697891786659314 0.20762763866852585" />
            </geometry>
        </collision>
    </link>
    <joint name="link1_link3" type="revolute">
       <parent link="link1"/>
       <child  link="link3"/>
       <origin rpy="0 0 0" xyz="0.22753273651739414 0.1836977044054361 0.016331101842675305" />
     <axis xyz="1 0 0"/>
       <limit effort="0.0" lower="-3.14159" upper="3.14159" velocity="0.0"/>
    </joint>
    <link name="link3">
        <inertial>
            <origin xyz="-0.18776110850933614 0.05382830207265648 0.11493514463499949" rpy="0 0 0"/>
            <mass value="1" />
            <inertia ixx="100" ixy="0" ixz="0" iyy="100" iyz="0" izz="100" />
        </inertial>
        <visual>
            <origin xyz="-0.18776110850933614 0.05382830207265648 0.11493514463499949" rpy="0 0 0"/>
            <geometry>
                <box size="0.7170348531701682 0.3458744455175895 0.22987028926999897" />
            </geometry>
            <material name="Green">
                <color rgba="0.0 1.0 0.0 1.0"/>
            </material>
        </visual>
        <collision>
            <origin xyz="-0.18776110850933614 0.05382830207265648 0.11493514463499949" rpy="0 0 0"/>
            <geometry>
                <box size="0.7170348531701682 0.3458744455175895 0.22987028926999897" />
            </geometry>
        </collision>
    </link>
    <joint name="link2_link4" type="revolute">
       <parent link="link2"/>
       <child  link="link4"/>
       <origin rpy="0 0 0" xyz="-0.21751254409081924 0.0889641668444321 0.06937864027980901" />
     <axis xyz="0 0 1"/>
       <limit effort="0.0" lower="-3.14159" upper="3.14159" velocity="0.0"/>
    </joint>
    <link name="link4">
        <inertial>
            <origin xyz="-0.46068231942612886 -0.11474258518177326 0.07387873647448784" rpy="0 0 0"/>
            <mass value="1" />
            <inertia ixx="100" ixy="0" ixz="0" iyy="100" iyz="0" izz="100" />
        </inertial>
        <visual>
            <origin xyz="-0.46068231942612886 -0.11474258518177326 0.07387873647448784" rpy="0 0 0"/>
            <geometry>
                <box size="0.9213646388522577 0.31064148820073356 0.8064034241030273" />
            </geometry>
            <material name="Cyan">
                <color rgba="0.0 1.0 1.0 1.0"/>
            </material>
        </visual>
        <collision>
            <origin xyz="-0.46068231942612886 -0.11474258518177326 0.07387873647448784" rpy="0 0 0"/>
            <geometry>
                <box size="0.9213646388522577 0.31064148820073356 0.8064034241030273" />
            </geometry>
        </collision>
    </link>
    <joint name="link0_link5" type="revolute">
       <parent link="link0"/>
       <child  link="link5"/>
       <origin rpy="0 0 0" xyz="-0.052710304935780924 -0.3033568949101867 1.0297601832349237" />
     <axis xyz="1 0 0"/>
       <limit effort="0.0" lower="-3.14159" upper="3.14159" velocity="0.0"/>
    </joint>
    <link name="link5">
        <inertial>
            <origin xyz="0.09153114244816668 -0.4749181274492301 0.07545932832894217" rpy="0 0 0"/>
            <mass value="1" />
            <inertia ixx="100" ixy="0" ixz="0" iyy="100" iyz="0" izz="100" />
        </inertial>
        <visual>
            <origin xyz="0.09153114244816668 -0.4749181274492301 0.07545932832894217" rpy="0 0 0"/>
            <geometry>
                <box size="0.29357480806944936 0.9498362548984602 0.15562012048112828" />
            </geometry>
            <material name="Cyan">
                <color rgba="0.0 1.0 1.0 1.0"/>
            </material>
        </visual>
        <collision>
            <origin xyz="0.09153114244816668 -0.4749181274492301 0.07545932832894217" rpy="0 0 0"/>
            <geometry>
                <box size="0.29357480806944936 0.9498362548984602 0.15562012048112828" />
            </geometry>
        </collision>
    </link>
    <joint name="link1_link6" type="revolute">
       <parent link="link1"/>
       <child  link="link6"/>
       <origin rpy="0 0 0" xyz="0.2665276677647695 0.6656895656739512 -0.008212863472112104" />
     <axis xyz="0 0 1"/>
       <limit effort="0.0" lower="-3.14159" upper="3.14159" velocity="0.0"/>
    </joint>
    <link name="link6">
        <inertial>
            <origin xyz="0.49337453984485863 0.024456856585988496 0.0993821653741381" rpy="0 0 0"/>
            <mass value="1" />
            <inertia ixx="100" ixy="0" ixz="0" iyy="100" iyz="0" izz="100" />
        </inertial>
        <visual>
            <origin xyz="0.49337453984485863 0.024456856585988496 0.0993821653741381" rpy="0 0 0"/>
            <geometry>
                <box size="0.9867490796897173 0.20911787318708464 0.22302120864513608" />
            </geometry>
            <material name="Green">
                <color rgba="0.0 1.0 0.0 1.0"/>
            </material>
        </visual>
        <collision>
            <origin xyz="0.49337453984485863 0.024456856585988496 0.0993821653741381" rpy="0 0 0"/>
            <geometry>
                <box size="0.9867490796897173 0.20911787318708464 0.22302120864513608" />
            </geometry>
        </collision>
    </link>
</robot>