<robot name = "robot">
    <link name="link0">
        <inertial>
            <origin xyz="0 0 1" rpy="0 0 0"/>
            <mass value="1" />
            <inertia ixx="100" ixy="0" ixz="0" iyy="100" iyz="0" izz="100" />
        </inertial>
        <visual>
            <origin xyz="0 0 1" rpy="0 0 0"/>
            <geometry>
                <box size="0.3076814676824928 0.42208033991092875 0.6371462164460202" />
            </geometry>
            <material name="Cyan">
                <color rgba="0.0 1.0 1.0 1.0"/>
            </material>
        </visual>
        <collision>
            <origin xyz="0 0 1" rpy="0 0 0"/>
            <geometry>
                <box size="0.3076814676824928 0.42208033991092875 0.6371462164460202" />
            </geometry>
        </collision>
    </link>
    <joint name="link0_link1" type="revolute">
       <parent link="link0"/>
       <child  link="link1"/>
       <origin rpy="0 0 0" xyz="0.1538407338412464 -0.10187315256363398 0.7322478261073913" />
     <axis xyz="0 0 1"/>
       <limit effort="0.0" lower="-3.14159" upper="3.14159" velocity="0.0"/>
    </joint>
    <link name="link1">
        <inertial>
            <origin xyz="0.40986434710635933 -0.14762990656808575 -0.04246699672098704" rpy="0 0 0"/>
            <mass value="1" />
            <inertia ixx="100" ixy="0" ixz="0" iyy="100" iyz="0" izz="100" />
        </inertial>
        <visual>
            <origin xyz="0.40986434710635933 -0.14762990656808575 -0.04246699672098704" rpy="0 0 0"/>
            <geometry>
                <box size="0.8197286942127187 0.7715316734567509 0.13332243623871565" />
            </geometry>
            <material name="Cyan">
                <color rgba="0.0 1.0 1.0 1.0"/>
            </material>
        </visual>
        <collision>
            <origin xyz="0.40986434710635933 -0.14762990656808575 -0.04246699672098704" rpy="0 0 0"/>
            <geometry>
                <box size="0.8197286942127187 0.7715316734567509 0.13332243623871565" />
            </geometry>
        </collision>
    </link>
    <joint name="link1_link2" type="revolute">
       <parent link="link1"/>
       <child  link="link2"/>
       <origin rpy="0 0 0" xyz="0.8197286942127187 -0.30903680138444833 -0.037472129302897235" />
     <axis xyz="1 0 0"/>
       <limit effort="0.0" lower="-3.14159" upper="3.14159" velocity="0.0"/>
    </joint>
    <link name="link2">
        <inertial>
            <origin xyz="0.42361583501122596 0.019475222227194135 -0.06715429697249622" rpy="0 0 0"/>
            <mass value="1" />
            <inertia ixx="100" ixy="0" ixz="0" iyy="100" iyz="0" izz="100" />
        </inertial>
        <visual>
            <origin xyz="0.42361583501122596 0.019475222227194135 -0.06715429697249622" rpy="0 0 0"/>
            <geometry>
                <box size="0.8472316700224519 0.25798726682941553 0.1489108167203772" />
            </geometry>
            <material name="Green">
                <color rgba="0.0 1.0 0.0 1.0"/>
            </material>
        </visual>
        <collision>
            <origin xyz="0.42361583501122596 0.019475222227194135 -0.06715429697249622" rpy="0 0 0"/>
            <geometry>
                <box size="0.8472316700224519 0.25798726682941553 0.1489108167203772" />
            </geometry>
        </collision>
    </link>
    <joint name="link1_link3" type="revolute">
       <parent link="link1"/>
       <child  link="link3"/>
       <origin rpy="0 0 0" xyz="0.0 0.013369375997139277 -0.07134912475678601" />
     <axis xyz="1 0 0"/>
       <limit effort="0.0" lower="-3.14159" upper="3.14159" velocity="0.0"/>
    </joint>
    <link name="link3">
        <inertial>
            <origin xyz="-0.27836773743346555 -0.45305021068698303 -0.07341709408269287" rpy="0 0 0"/>
            <mass value="1" />
            <inertia ixx="100" ixy="0" ixz="0" iyy="100" iyz="0" izz="100" />
        </inertial>
        <visual>
            <origin xyz="-0.27836773743346555 -0.45305021068698303 -0.07341709408269287" rpy="0 0 0"/>
            <geometry>
                <box size="0.5567354748669311 0.9071404687534601 0.6909196772631628" />
            </geometry>
            <material name="Green">
                <color rgba="0.0 1.0 0.0 1.0"/>
            </material>
        </visual>
        <collision>
            <origin xyz="-0.27836773743346555 -0.45305021068698303 -0.07341709408269287" rpy="0 0 0"/>
            <geometry>
                <box size="0.5567354748669311 0.9071404687534601 0.6909196772631628" />
            </geometry>
        </collision>
    </link>
    <joint name="link0_link4" type="revolute">
       <parent link="link0"/>
       <child  link="link4"/>
       <origin rpy="0 0 0" xyz="-0.12369401962416238 0.21104016995546437 1.1091315591872923" />
     <axis xyz="0 0 1"/>
       <limit effort="0.0" lower="-3.14159" upper="3.14159" velocity="0.0"/>
    </joint>
    <link name="link4">
        <inertial>
            <origin xyz="0.06956267573545011 0.3459003378724489 0.00025802813721002014" rpy="0 0 0"/>
            <mass value="1" />
            <inertia ixx="100" ixy="0" ixz="0" iyy="100" iyz="0" izz="100" />
        </inertial>
        <visual>
            <origin xyz="0.06956267573545011 0.3459003378724489 0.00025802813721002014" rpy="0 0 0"/>
            <geometry>
                <box size="0.22384381326220015 0.6918006757448978 0.34031520915292257" />
            </geometry>
            <material name="Green">
                <color rgba="0.0 1.0 0.0 1.0"/>
            </material>
        </visual>
        <collision>
            <origin xyz="0.06956267573545011 0.3459003378724489 0.00025802813721002014" rpy="0 0 0"/>
            <geometry>
                <box size="0.22384381326220015 0.6918006757448978 0.34031520915292257" />
            </geometry>
        </collision>
    </link>
    <joint name="link3_link5" type="revolute">
       <parent link="link3"/>
       <child  link="link5"/>
       <origin rpy="0 0 0" xyz="-0.33074195901662323 -0.9066204450637131 -0.17168245929994436" />
     <axis xyz="0 1 0"/>
       <limit effort="0.0" lower="-3.14159" upper="3.14159" velocity="0.0"/>
    </joint>
    <link name="link5">
        <inertial>
            <origin xyz="0.07120993726096697 -0.011697267471936168 -0.06940928576351078" rpy="0 0 0"/>
            <mass value="1" />
            <inertia ixx="100" ixy="0" ixz="0" iyy="100" iyz="0" izz="100" />
        </inertial>
        <visual>
            <origin xyz="0.07120993726096697 -0.011697267471936168 -0.06940928576351078" rpy="0 0 0"/>
            <geometry>
                <box size="0.2407744414506361 0.023394534943872336 0.4603976894271984" />
            </geometry>
            <material name="Green">
                <color rgba="0.0 1.0 0.0 1.0"/>
            </material>
        </visual>
        <collision>
            <origin xyz="0.07120993726096697 -0.011697267471936168 -0.06940928576351078" rpy="0 0 0"/>
            <geometry>
                <box size="0.2407744414506361 0.023394534943872336 0.4603976894271984" />
            </geometry>
        </collision>
    </link>
    <joint name="link3_link6" type="revolute">
       <parent link="link3"/>
       <child  link="link6"/>
       <origin rpy="0 0 0" xyz="-0.4902281160534949 0.0005200236897470178 0.2636604447060425" />
     <axis xyz="0 0 1"/>
       <limit effort="0.0" lower="-3.14159" upper="3.14159" velocity="0.0"/>
    </joint>
    <link name="link6">
        <inertial>
            <origin xyz="-0.17246443024757982 0.08450022100345711 0.08563734063627855" rpy="0 0 0"/>
            <mass value="1" />
            <inertia ixx="100" ixy="0" ixz="0" iyy="100" iyz="0" izz="100" />
        </inertial>
        <visual>
            <origin xyz="-0.17246443024757982 0.08450022100345711 0.08563734063627855" rpy="0 0 0"/>
            <geometry>
                <box size="0.9053122624513984 0.16900044200691422 0.32688217261082964" />
            </geometry>
            <material name="Green">
                <color rgba="0.0 1.0 0.0 1.0"/>
            </material>
        </visual>
        <collision>
            <origin xyz="-0.17246443024757982 0.08450022100345711 0.08563734063627855" rpy="0 0 0"/>
            <geometry>
                <box size="0.9053122624513984 0.16900044200691422 0.32688217261082964" />
            </geometry>
        </collision>
    </link>
    <joint name="link0_link7" type="revolute">
       <parent link="link0"/>
       <child  link="link7"/>
       <origin rpy="0 0 0" xyz="-0.10189048667830947 0.05253659931871044 1.31857310822301" />
     <axis xyz="0 1 0"/>
       <limit effort="0.0" lower="-3.14159" upper="3.14159" velocity="0.0"/>
    </joint>
    <link name="link7">
        <inertial>
            <origin xyz="-0.26607015532475115 0.010834525887169027 0.3271658512717259" rpy="0 0 0"/>
            <mass value="1" />
            <inertia ixx="100" ixy="0" ixz="0" iyy="100" iyz="0" izz="100" />
        </inertial>
        <visual>
            <origin xyz="-0.26607015532475115 0.010834525887169027 0.3271658512717259" rpy="0 0 0"/>
            <geometry>
                <box size="0.8812617453152786 0.1343094565036994 0.6543317025434519" />
            </geometry>
            <material name="Green">
                <color rgba="0.0 1.0 0.0 1.0"/>
            </material>
        </visual>
        <collision>
            <origin xyz="-0.26607015532475115 0.010834525887169027 0.3271658512717259" rpy="0 0 0"/>
            <geometry>
                <box size="0.8812617453152786 0.1343094565036994 0.6543317025434519" />
            </geometry>
        </collision>
    </link>
</robot>