<robot name = "robot">
    <link name="link0">
        <inertial>
            <origin xyz="0 0 1" rpy="0 0 0"/>
            <mass value="1" />
            <inertia ixx="100" ixy="0" ixz="0" iyy="100" iyz="0" izz="100" />
        </inertial>
        <visual>
            <origin xyz="0 0 1" rpy="0 0 0"/>
            <geometry>
                <box size="0.7730672528785435 0.09723516875483962 0.8318674213076213" />
            </geometry>
            <material name="Cyan">
                <color rgba="0.0 1.0 1.0 1.0"/>
            </material>
        </visual>
        <collision>
            <origin xyz="0 0 1" rpy="0 0 0"/>
            <geometry>
                <box size="0.7730672528785435 0.09723516875483962 0.8318674213076213" />
            </geometry>
        </collision>
    </link>
    <joint name="link0_link1" type="revolute">
       <parent link="link0"/>
       <child  link="link1"/>
       <origin rpy="0 0 0" xyz="0.24510700006910133 0.04861758437741981 1.3071336046972166" />
     <axis xyz="0 1 0"/>
       <limit effort="0.0" lower="-3.14159" upper="3.14159" velocity="0.0"/>
    </joint>
    <link name="link1">
        <inertial>
            <origin xyz="0.13380923649656576 0.28151416620329356 -0.09064924766392912" rpy="0 0 0"/>
            <mass value="1" />
            <inertia ixx="100" ixy="0" ixz="0" iyy="100" iyz="0" izz="100" />
        </inertial>
        <visual>
            <origin xyz="0.13380923649656576 0.28151416620329356 -0.09064924766392912" rpy="0 0 0"/>
            <geometry>
                <box size="0.4992243644710229 0.5630283324065871 0.29417838932162643" />
            </geometry>
            <material name="Green">
                <color rgba="0.0 1.0 0.0 1.0"/>
            </material>
        </visual>
        <collision>
            <origin xyz="0.13380923649656576 0.28151416620329356 -0.09064924766392912" rpy="0 0 0"/>
            <geometry>
                <box size="0.4992243644710229 0.5630283324065871 0.29417838932162643" />
            </geometry>
        </collision>
    </link>
    <joint name="link1_link2" type="revolute">
       <parent link="link1"/>
       <child  link="link2"/>
       <origin rpy="0 0 0" xyz="0.12069854521899888 0.0 -0.23735706286290337" />
     <axis xyz="0 0 1"/>
       <limit effort="0.0" lower="-3.14159" upper="3.14159" velocity="0.0"/>
    </joint>
    <link name="link2">
        <inertial>
            <origin xyz="0.23330389761996012 -0.35410669680678825 0.17667774753589632" rpy="0 0 0"/>
            <mass value="1" />
            <inertia ixx="100" ixy="0" ixz="0" iyy="100" iyz="0" izz="100" />
        </inertial>
        <visual>
            <origin xyz="0.23330389761996012 -0.35410669680678825 0.17667774753589632" rpy="0 0 0"/>
            <geometry>
                <box size="0.7464122196610926 0.7082133936135765 0.37682556217522734" />
            </geometry>
            <material name="Green">
                <color rgba="0.0 1.0 0.0 1.0"/>
            </material>
        </visual>
        <collision>
            <origin xyz="0.23330389761996012 -0.35410669680678825 0.17667774753589632" rpy="0 0 0"/>
            <geometry>
                <box size="0.7464122196610926 0.7082133936135765 0.37682556217522734" />
            </geometry>
        </collision>
    </link>
    <joint name="link0_link3" type="revolute">
       <parent link="link0"/>
       <child  link="link3"/>
       <origin rpy="0 0 0" xyz="-0.10534249063337715 -0.04340035687532159 1.4159337106538106" />
     <axis xyz="1 0 0"/>
       <limit effort="0.0" lower="-3.14159" upper="3.14159" velocity="0.0"/>
    </joint>
    <link name="link3">
        <inertial>
            <origin xyz="-0.23203819889559535 0.16122561701411742 0.046742217751187476" rpy="0 0 0"/>
            <mass value="1" />
            <inertia ixx="100" ixy="0" ixz="0" iyy="100" iyz="0" izz="100" />
        </inertial>
        <visual>
            <origin xyz="-0.23203819889559535 0.16122561701411742 0.046742217751187476" rpy="0 0 0"/>
            <geometry>
                <box size="0.7702710974272599 0.5895551586504514 0.09348443550237495" />
            </geometry>
            <material name="Cyan">
                <color rgba="0.0 1.0 1.0 1.0"/>
            </material>
        </visual>
        <collision>
            <origin xyz="-0.23203819889559535 0.16122561701411742 0.046742217751187476" rpy="0 0 0"/>
            <geometry>
                <box size="0.7702710974272599 0.5895551586504514 0.09348443550237495" />
            </geometry>
        </collision>
    </link>
    <joint name="link1_link4" type="revolute">
       <parent link="link1"/>
       <child  link="link4"/>
       <origin rpy="0 0 0" xyz="0.1567300910344307 0.48405977182997073 0.056439946996884094" />
     <axis xyz="1 0 0"/>
       <limit effort="0.0" lower="-3.14159" upper="3.14159" velocity="0.0"/>
    </joint>
    <link name="link4">
        <inertial>
            <origin xyz="0.1440276053876595 -0.11628147389868937 0.25103799499683194" rpy="0 0 0"/>
            <mass value="1" />
            <inertia ixx="100" ixy="0" ixz="0" iyy="100" iyz="0" izz="100" />
        </inertial>
        <visual>
            <origin xyz="0.1440276053876595 -0.11628147389868937 0.25103799499683194" rpy="0 0 0"/>
            <geometry>
                <box size="0.42822207127746004 0.6614785285577259 0.5020759899936639" />
            </geometry>
            <material name="Green">
                <color rgba="0.0 1.0 0.0 1.0"/>
            </material>
        </visual>
        <collision>
            <origin xyz="0.1440276053876595 -0.11628147389868937 0.25103799499683194" rpy="0 0 0"/>
            <geometry>
                <box size="0.42822207127746004 0.6614785285577259 0.5020759899936639" />
            </geometry>
        </collision>
    </link>
    <joint name="link2_link5" type="revolute">
       <parent link="link2"/>
       <child  link="link5"/>
       <origin rpy="0 0 0" xyz="-0.13990221221058619 -0.00876913519755862 0.20246728033157185" />
     <axis xyz="0 1 0"/>
       <limit effort="0.0" lower="-3.14159" upper="3.14159" velocity="0.0"/>
    </joint>
    <link name="link5">
        <inertial>
            <origin xyz="-0.34133360569710813 -0.009503111421895406 -0.15116891903331162" rpy="0 0 0"/>
            <mass value="1" />
            <inertia ixx="100" ixy="0" ixz="0" iyy="100" iyz="0" izz="100" />
        </inertial>
        <visual>
            <origin xyz="-0.34133360569710813 -0.009503111421895406 -0.15116891903331162" rpy="0 0 0"/>
            <geometry>
                <box size="0.6826672113942163 0.040775241604245505 0.5545251637854592" />
            </geometry>
            <material name="Green">
                <color rgba="0.0 1.0 0.0 1.0"/>
            </material>
        </visual>
        <collision>
            <origin xyz="-0.34133360569710813 -0.009503111421895406 -0.15116891903331162" rpy="0 0 0"/>
            <geometry>
                <box size="0.6826672113942163 0.040775241604245505 0.5545251637854592" />
            </geometry>
        </collision>
    </link>
    <joint name="link3_link6" type="revolute">
       <parent link="link3"/>
       <child  link="link6"/>
       <origin rpy="0 0 0" xyz="-0.5363490841515571 -0.13355196231110827 0.0542518069469041" />
     <axis xyz="1 0 0"/>
       <limit effort="0.0" lower="-3.14159" upper="3.14159" velocity="0.0"/>
    </joint>
    <link name="link6">
        <inertial>
            <origin xyz="0.3129351523138313 -0.25571437982399353 -0.05683892357159224" rpy="0 0 0"/>
            <mass value="1" />
            <inertia ixx="100" ixy="0" ixz="0" iyy="100" iyz="0" izz="100" />
        </inertial>
        <visual>
            <origin xyz="0.3129351523138313 -0.25571437982399353 -0.05683892357159224" rpy="0 0 0"/>
            <geometry>
                <box size="0.7439399814861162 0.5114287596479871 0.46814240830547005" />
            </geometry>
            <material name="Green">
                <color rgba="0.0 1.0 0.0 1.0"/>
            </material>
        </visual>
        <collision>
            <origin xyz="0.3129351523138313 -0.25571437982399353 -0.05683892357159224" rpy="0 0 0"/>
            <geometry>
                <box size="0.7439399814861162 0.5114287596479871 0.46814240830547005" />
            </geometry>
        </collision>
    </link>
    <joint name="link0_link7" type="revolute">
       <parent link="link0"/>
       <child  link="link7"/>
       <origin rpy="0 0 0" xyz="-0.38653362643927175 0.015290834219851245 1.0897247666280208" />
     <axis xyz="0 0 1"/>
       <limit effort="0.0" lower="-3.14159" upper="3.14159" velocity="0.0"/>
    </joint>
    <link name="link7">
        <inertial>
            <origin xyz="-0.48030817449472335 0.03204451427102518 -0.12288478951510004" rpy="0 0 0"/>
            <mass value="1" />
            <inertia ixx="100" ixy="0" ixz="0" iyy="100" iyz="0" izz="100" />
        </inertial>
        <visual>
            <origin xyz="-0.48030817449472335 0.03204451427102518 -0.12288478951510004" rpy="0 0 0"/>
            <geometry>
                <box size="0.9606163489894467 0.1294401237550573 0.7808690579072632" />
            </geometry>
            <material name="Cyan">
                <color rgba="0.0 1.0 1.0 1.0"/>
            </material>
        </visual>
        <collision>
            <origin xyz="-0.48030817449472335 0.03204451427102518 -0.12288478951510004" rpy="0 0 0"/>
            <geometry>
                <box size="0.9606163489894467 0.1294401237550573 0.7808690579072632" />
            </geometry>
        </collision>
    </link>
</robot>