<robot name = "robot">
    <link name="link0">
        <inertial>
            <origin xyz="0 0 1" rpy="0 0 0"/>
            <mass value="1" />
            <inertia ixx="100" ixy="0" ixz="0" iyy="100" iyz="0" izz="100" />
        </inertial>
        <visual>
            <origin xyz="0 0 1" rpy="0 0 0"/>
            <geometry>
                <box size="0.7602746838938486 0.28358585649241774 0.4595943318922203" />
            </geometry>
            <material name="Cyan">
                <color rgba="0.0 1.0 1.0 1.0"/>
            </material>
        </visual>
        <collision>
            <origin xyz="0 0 1" rpy="0 0 0"/>
            <geometry>
                <box size="0.7602746838938486 0.28358585649241774 0.4595943318922203" />
            </geometry>
        </collision>
    </link>
    <joint name="link0_link1" type="revolute">
       <parent link="link0"/>
       <child  link="link1"/>
       <origin rpy="0 0 0" xyz="0.31212214615048317 0.021451599521649205 1.2297971659461102" />
     <axis xyz="0 0 1"/>
       <limit effort="0.0" lower="-3.14159" upper="3.14159" velocity="0.0"/>
    </joint>
    <link name="link1">
        <inertial>
            <origin xyz="0.07833847489689094 0.08174288015843573 0.4899491700341905" rpy="0 0 0"/>
            <mass value="1" />
            <inertia ixx="100" ixy="0" ixz="0" iyy="100" iyz="0" izz="100" />
        </inertial>
        <visual>
            <origin xyz="0.07833847489689094 0.08174288015843573 0.4899491700341905" rpy="0 0 0"/>
            <geometry>
                <box size="0.3953693240811188 0.23615136976851192 0.979898340068381" />
            </geometry>
            <material name="Green">
                <color rgba="0.0 1.0 0.0 1.0"/>
            </material>
        </visual>
        <collision>
            <origin xyz="0.07833847489689094 0.08174288015843573 0.4899491700341905" rpy="0 0 0"/>
            <geometry>
                <box size="0.3953693240811188 0.23615136976851192 0.979898340068381" />
            </geometry>
        </collision>
    </link>
    <joint name="link1_link2" type="revolute">
       <parent link="link1"/>
       <child  link="link2"/>
       <origin rpy="0 0 0" xyz="-0.05588992732569331 0.07144234555591936 0.979898340068381" />
     <axis xyz="1 0 0"/>
       <limit effort="0.0" lower="-3.14159" upper="3.14159" velocity="0.0"/>
    </joint>
    <link name="link2">
        <inertial>
            <origin xyz="-0.11098159501250629 0.11405548624598742 0.2502787963109777" rpy="0 0 0"/>
            <mass value="1" />
            <inertia ixx="100" ixy="0" ixz="0" iyy="100" iyz="0" izz="100" />
        </inertial>
        <visual>
            <origin xyz="-0.11098159501250629 0.11405548624598742 0.2502787963109777" rpy="0 0 0"/>
            <geometry>
                <box size="0.33667481182854775 0.4464738227054216 0.5005575926219554" />
            </geometry>
            <material name="Green">
                <color rgba="0.0 1.0 0.0 1.0"/>
            </material>
        </visual>
        <collision>
            <origin xyz="-0.11098159501250629 0.11405548624598742 0.2502787963109777" rpy="0 0 0"/>
            <geometry>
                <box size="0.33667481182854775 0.4464738227054216 0.5005575926219554" />
            </geometry>
        </collision>
    </link>
    <joint name="link1_link3" type="revolute">
       <parent link="link1"/>
       <child  link="link3"/>
       <origin rpy="0 0 0" xyz="-0.0780807480682928 -0.036332804725820234 0.8620782872979006" />
     <axis xyz="1 0 0"/>
       <limit effort="0.0" lower="-3.14159" upper="3.14159" velocity="0.0"/>
    </joint>
    <link name="link3">
        <inertial>
            <origin xyz="0.04956289085097145 -0.3541411119266331 0.022347101017943086" rpy="0 0 0"/>
            <mass value="1" />
            <inertia ixx="100" ixy="0" ixz="0" iyy="100" iyz="0" izz="100" />
        </inertial>
        <visual>
            <origin xyz="0.04956289085097145 -0.3541411119266331 0.022347101017943086" rpy="0 0 0"/>
            <geometry>
                <box size="0.1292663673350698 0.7082822238532662 0.15411102080959516" />
            </geometry>
            <material name="Green">
                <color rgba="0.0 1.0 0.0 1.0"/>
            </material>
        </visual>
        <collision>
            <origin xyz="0.04956289085097145 -0.3541411119266331 0.022347101017943086" rpy="0 0 0"/>
            <geometry>
                <box size="0.1292663673350698 0.7082822238532662 0.15411102080959516" />
            </geometry>
        </collision>
    </link>
</robot>