<robot name = "robot">
    <link name="link0">
        <inertial>
            <origin xyz="0 0 1" rpy="0 0 0"/>
            <mass value="1" />
            <inertia ixx="100" ixy="0" ixz="0" iyy="100" iyz="0" izz="100" />
        </inertial>
        <visual>
            <origin xyz="0 0 1" rpy="0 0 0"/>
            <geometry>
                <box size="0.16711894586264364 0.7418758027083359 0.12759498975742678" />
            </geometry>
            <material name="Cyan">
                <color rgba="0.0 1.0 1.0 1.0"/>
            </material>
        </visual>
        <collision>
            <origin xyz="0 0 1" rpy="0 0 0"/>
            <geometry>
                <box size="0.16711894586264364 0.7418758027083359 0.12759498975742678" />
            </geometry>
        </collision>
    </link>
    <joint name="link0_link1" type="revolute">
       <parent link="link0"/>
       <child  link="link1"/>
       <origin rpy="0 0 0" xyz="0.007158230599801947 -0.37093790135416793 1.0449763108672654" />
     <axis xyz="1 0 0"/>
       <limit effort="0.0" lower="-3.14159" upper="3.14159" velocity="0.0"/>
    </joint>
    <link name="link1">
        <inertial>
            <origin xyz="-0.16237091649062854 -0.13505629318310625 0.07475785886422986" rpy="0 0 0"/>
            <mass value="1" />
            <inertia ixx="100" ixy="0" ixz="0" iyy="100" iyz="0" izz="100" />
        </inertial>
        <visual>
            <origin xyz="-0.16237091649062854 -0.13505629318310625 0.07475785886422986" rpy="0 0 0"/>
            <geometry>
                <box size="0.5080655858154463 0.2701125863662125 0.45814661177728466" />
            </geometry>
            <material name="Green">
                <color rgba="0.0 1.0 0.0 1.0"/>
            </material>
        </visual>
        <collision>
            <origin xyz="-0.16237091649062854 -0.13505629318310625 0.07475785886422986" rpy="0 0 0"/>
            <geometry>
                <box size="0.5080655858154463 0.2701125863662125 0.45814661177728466" />
            </geometry>
        </collision>
    </link>
    <joint name="link1_link2" type="revolute">
       <parent link="link1"/>
       <child  link="link2"/>
       <origin rpy="0 0 0" xyz="-0.2983200645839975 0.0 -0.13090766193642014" />
     <axis xyz="1 0 0"/>
       <limit effort="0.0" lower="-3.14159" upper="3.14159" velocity="0.0"/>
    </joint>
    <link name="link2">
        <inertial>
            <origin xyz="0.10532110692462611 0.002533080510162322 0.019720610516018998" rpy="0 0 0"/>
            <mass value="1" />
            <inertia ixx="100" ixy="0" ixz="0" iyy="100" iyz="0" izz="100" />
        </inertial>
        <visual>
            <origin xyz="0.10532110692462611 0.002533080510162322 0.019720610516018998" rpy="0 0 0"/>
            <geometry>
                <box size="0.42674761635526204 0.005066161020324644 0.45988555354644156" />
            </geometry>
            <material name="Green">
                <color rgba="0.0 1.0 0.0 1.0"/>
            </material>
        </visual>
        <collision>
            <origin xyz="0.10532110692462611 0.002533080510162322 0.019720610516018998" rpy="0 0 0"/>
            <geometry>
                <box size="0.42674761635526204 0.005066161020324644 0.45988555354644156" />
            </geometry>
        </collision>
    </link>
    <joint name="link1_link3" type="revolute">
       <parent link="link1"/>
       <child  link="link3"/>
       <origin rpy="0 0 0" xyz="-0.15224173813662642 -0.2701125863662125 0.05137309216079927" />
     <axis xyz="0 1 0"/>
       <limit effort="0.0" lower="-3.14159" upper="3.14159" velocity="0.0"/>
    </joint>
    <link name="link3">
        <inertial>
            <origin xyz="-0.03595813749996618 -0.2795514298690056 0.2542002401866346" rpy="0 0 0"/>
            <mass value="1" />
            <inertia ixx="100" ixy="0" ixz="0" iyy="100" iyz="0" izz="100" />
        </inertial>
        <visual>
            <origin xyz="-0.03595813749996618 -0.2795514298690056 0.2542002401866346" rpy="0 0 0"/>
            <geometry>
                <box size="0.5836802433229126 0.5591028597380112 0.9001913888750557" />
            </geometry>
            <material name="Green">
                <color rgba="0.0 1.0 0.0 1.0"/>
            </material>
        </visual>
        <collision>
            <origin xyz="-0.03595813749996618 -0.2795514298690056 0.2542002401866346" rpy="0 0 0"/>
            <geometry>
                <box size="0.5836802433229126 0.5591028597380112 0.9001913888750557" />
            </geometry>
        </collision>
    </link>
    <joint name="link1_link4" type="revolute">
       <parent link="link1"/>
       <child  link="link4"/>
       <origin rpy="0 0 0" xyz="0.09166187641709458 -0.22478450403914413 0.14369386377072793" />
     <axis xyz="1 0 0"/>
       <limit effort="0.0" lower="-3.14159" upper="3.14159" velocity="0.0"/>
    </joint>
    <link name="link4">
        <inertial>
            <origin xyz="0.40737362971343166 -0.14346991272105517 -0.013430195968353162" rpy="0 0 0"/>
            <mass value="1" />
            <inertia ixx="100" ixy="0" ixz="0" iyy="100" iyz="0" izz="100" />
        </inertial>
        <visual>
            <origin xyz="0.40737362971343166 -0.14346991272105517 -0.013430195968353162" rpy="0 0 0"/>
            <geometry>
                <box size="0.8147472594268633 0.33990053201974535 0.3117419956154821" />
            </geometry>
            <material name="Green">
                <color rgba="0.0 1.0 0.0 1.0"/>
            </material>
        </visual>
        <collision>
            <origin xyz="0.40737362971343166 -0.14346991272105517 -0.013430195968353162" rpy="0 0 0"/>
            <geometry>
                <box size="0.8147472594268633 0.33990053201974535 0.3117419956154821" />
            </geometry>
        </collision>
    </link>
    <joint name="link4_link5" type="revolute">
       <parent link="link4"/>
       <child  link="link5"/>
       <origin rpy="0 0 0" xyz="0.37672826749075133 0.02648035328881751 -0.07235853596131028" />
     <axis xyz="0 1 0"/>
       <limit effort="0.0" lower="-3.14159" upper="3.14159" velocity="0.0"/>
    </joint>
    <link name="link5">
        <inertial>
            <origin xyz="-0.08579919971748853 0.2916124331338943 -0.24620041368628487" rpy="0 0 0"/>
            <mass value="1" />
            <inertia ixx="100" ixy="0" ixz="0" iyy="100" iyz="0" izz="100" />
        </inertial>
        <visual>
            <origin xyz="-0.08579919971748853 0.2916124331338943 -0.24620041368628487" rpy="0 0 0"/>
            <geometry>
                <box size="0.2908232740147667 0.5832248662677886 0.8306633681047155" />
            </geometry>
            <material name="Green">
                <color rgba="0.0 1.0 0.0 1.0"/>
            </material>
        </visual>
        <collision>
            <origin xyz="-0.08579919971748853 0.2916124331338943 -0.24620041368628487" rpy="0 0 0"/>
            <geometry>
                <box size="0.2908232740147667 0.5832248662677886 0.8306633681047155" />
            </geometry>
        </collision>
    </link>
    <joint name="link3_link6" type="revolute">
       <parent link="link3"/>
       <child  link="link6"/>
       <origin rpy="0 0 0" xyz="-0.0821233252687133 -0.4714162035030721 0.7042959346241624" />
     <axis xyz="1 0 0"/>
       <limit effort="0.0" lower="-3.14159" upper="3.14159" velocity="0.0"/>
    </joint>
    <link name="link6">
        <inertial>
            <origin xyz="-0.3523571744628927 0.30833901455196433 0.3908664050291457" rpy="0 0 0"/>
            <mass value="1" />
            <inertia ixx="100" ixy="0" ixz="0" iyy="100" iyz="0" izz="100" />
        </inertial>
        <visual>
            <origin xyz="-0.3523571744628927 0.30833901455196433 0.3908664050291457" rpy="0 0 0"/>
            <geometry>
                <box size="0.9749655739348997 0.8750858525610836 0.7817328100582914" />
            </geometry>
            <material name="Green">
                <color rgba="0.0 1.0 0.0 1.0"/>
            </material>
        </visual>
        <collision>
            <origin xyz="-0.3523571744628927 0.30833901455196433 0.3908664050291457" rpy="0 0 0"/>
            <geometry>
                <box size="0.9749655739348997 0.8750858525610836 0.7817328100582914" />
            </geometry>
        </collision>
    </link>
    <joint name="link1_link7" type="revolute">
       <parent link="link1"/>
       <child  link="link7"/>
       <origin rpy="0 0 0" xyz="-0.4164037093983517 -0.11692515588445566 0.001292048625839079" />
     <axis xyz="0 0 1"/>
       <limit effort="0.0" lower="-3.14159" upper="3.14159" velocity="0.0"/>
    </joint>
    <link name="link7">
        <inertial>
            <origin xyz="-0.010407047488151189 0.008766193309533545 -0.08876582788476148" rpy="0 0 0"/>
            <mass value="1" />
            <inertia ixx="100" ixy="0" ixz="0" iyy="100" iyz="0" izz="100" />
        </inertial>
        <visual>
            <origin xyz="-0.010407047488151189 0.008766193309533545 -0.08876582788476148" rpy="0 0 0"/>
            <geometry>
                <box size="0.020814094976302377 0.04944398844730613 0.8238735198507214" />
            </geometry>
            <material name="Green">
                <color rgba="0.0 1.0 0.0 1.0"/>
            </material>
        </visual>
        <collision>
            <origin xyz="-0.010407047488151189 0.008766193309533545 -0.08876582788476148" rpy="0 0 0"/>
            <geometry>
                <box size="0.020814094976302377 0.04944398844730613 0.8238735198507214" />
            </geometry>
        </collision>
    </link>
    <joint name="link0_link8" type="revolute">
       <parent link="link0"/>
       <child  link="link8"/>
       <origin rpy="0 0 0" xyz="0.05910452847029273 0.37093790135416793 0.956013625603034" />
     <axis xyz="1 0 0"/>
       <limit effort="0.0" lower="-3.14159" upper="3.14159" velocity="0.0"/>
    </joint>
    <link name="link8">
        <inertial>
            <origin xyz="0.20775893002638252 0.20285825938153806 0.02996070489313521" rpy="0 0 0"/>
            <mass value="1" />
            <inertia ixx="100" ixy="0" ixz="0" iyy="100" iyz="0" izz="100" />
        </inertial>
        <visual>
            <origin xyz="0.20775893002638252 0.20285825938153806 0.02996070489313521" rpy="0 0 0"/>
            <geometry>
                <box size="0.9860106651481834 0.40571651876307613 0.6622873020866523" />
            </geometry>
            <material name="Green">
                <color rgba="0.0 1.0 0.0 1.0"/>
            </material>
        </visual>
        <collision>
            <origin xyz="0.20775893002638252 0.20285825938153806 0.02996070489313521" rpy="0 0 0"/>
            <geometry>
                <box size="0.9860106651481834 0.40571651876307613 0.6622873020866523" />
            </geometry>
        </collision>
    </link>
    <joint name="link0_link9" type="revolute">
       <parent link="link0"/>
       <child  link="link9"/>
       <origin rpy="0 0 0" xyz="0.08241317946007629 0.2452032543131529 1.0637974948787134" />
     <axis xyz="1 0 0"/>
       <limit effort="0.0" lower="-3.14159" upper="3.14159" velocity="0.0"/>
    </joint>
    <link name="link9">
        <inertial>
            <origin xyz="-0.10924202084584915 0.018084361607806604 0.15302429262567335" rpy="0 0 0"/>
            <mass value="1" />
            <inertia ixx="100" ixy="0" ixz="0" iyy="100" iyz="0" izz="100" />
        </inertial>
        <visual>
            <origin xyz="-0.10924202084584915 0.018084361607806604 0.15302429262567335" rpy="0 0 0"/>
            <geometry>
                <box size="0.9943867331413239 0.410662488207287 0.3060485852513467" />
            </geometry>
            <material name="Green">
                <color rgba="0.0 1.0 0.0 1.0"/>
            </material>
        </visual>
        <collision>
            <origin xyz="-0.10924202084584915 0.018084361607806604 0.15302429262567335" rpy="0 0 0"/>
            <geometry>
                <box size="0.9943867331413239 0.410662488207287 0.3060485852513467" />
            </geometry>
        </collision>
    </link>
</robot>