<robot name = "robot">
    <link name="link0">
        <inertial>
            <origin xyz="0 0 1" rpy="0 0 0"/>
            <mass value="1" />
            <inertia ixx="100" ixy="0" ixz="0" iyy="100" iyz="0" izz="100" />
        </inertial>
        <visual>
            <origin xyz="0 0 1" rpy="0 0 0"/>
            <geometry>
                <box size="0.9502224964479187 0.033136185925609074 0.8870606914668894" />
            </geometry>
            <material name="Cyan">
                <color rgba="0 1.0 1.0 1.0"/>
            </material>
        </visual>
        <collision>
            <origin xyz="0 0 1" rpy="0 0 0"/>
            <geometry>
                <box size="0.9502224964479187 0.033136185925609074 0.8870606914668894" />
            </geometry>
        </collision>
    </link>
    <joint name="link0_link1" type="revolute">
       <parent link="link0"/>
       <child  link="link1"/>
       <origin rpy="0 0 0" xyz="0.25908376196077293 0.016568092962804537 0.8196908494175439" />
     <axis xyz="0 0 1"/>
       <limit effort="0.0" lower="-3.14159" upper="3.14159" velocity="0.0"/>
    </joint>
    <link name="link1">
        <inertial>
            <origin xyz="-0.12931073810998645 0.2392320542070719 0.09603107400721278" rpy="0 0 0"/>
            <mass value="1" />
            <inertia ixx="100" ixy="0" ixz="0" iyy="100" iyz="0" izz="100" />
        </inertial>
        <visual>
            <origin xyz="-0.12931073810998645 0.2392320542070719 0.09603107400721278" rpy="0 0 0"/>
            <geometry>
                <box size="0.5598984896440976 0.4784641084141438 0.7091071886970095" />
            </geometry>
            <material name="Cyan">
                <color rgba="0 1.0 1.0 1.0"/>
            </material>
        </visual>
        <collision>
            <origin xyz="-0.12931073810998645 0.2392320542070719 0.09603107400721278" rpy="0 0 0"/>
            <geometry>
                <box size="0.5598984896440976 0.4784641084141438 0.7091071886970095" />
            </geometry>
        </collision>
    </link>
    <joint name="link0_link2" type="revolute">
       <parent link="link0"/>
       <child  link="link2"/>
       <origin rpy="0 0 0" xyz="-0.47511124822395934 0.01169629619754404 0.7129270906399509" />
     <axis xyz="1 0 0"/>
       <limit effort="0.0" lower="-3.14159" upper="3.14159" velocity="0.0"/>
    </joint>
    <link name="link2">
        <inertial>
            <origin xyz="-0.16210728007132302 -0.0618313292965896 0.25833524896646926" rpy="0 0 0"/>
            <mass value="1" />
            <inertia ixx="100" ixy="0" ixz="0" iyy="100" iyz="0" izz="100" />
        </inertial>
        <visual>
            <origin xyz="-0.16210728007132302 -0.0618313292965896 0.25833524896646926" rpy="0 0 0"/>
            <geometry>
                <box size="0.32421456014264605 0.18348912931779648 0.7967135484966125" />
            </geometry>
            <material name="Cyan">
                <color rgba="0 1.0 1.0 1.0"/>
            </material>
        </visual>
        <collision>
            <origin xyz="-0.16210728007132302 -0.0618313292965896 0.25833524896646926" rpy="0 0 0"/>
            <geometry>
                <box size="0.32421456014264605 0.18348912931779648 0.7967135484966125" />
            </geometry>
        </collision>
    </link>
    <joint name="link2_link3" type="revolute">
       <parent link="link2"/>
       <child  link="link3"/>
       <origin rpy="0 0 0" xyz="0.0 -0.1512637627264845 0.21544909898899522" />
     <axis xyz="0 0 1"/>
       <limit effort="0.0" lower="-3.14159" upper="3.14159" velocity="0.0"/>
    </joint>
    <link name="link3">
        <inertial>
            <origin xyz="0.3641233757155793 0.03992910250181846 -0.07326397681667562" rpy="0 0 0"/>
            <mass value="1" />
            <inertia ixx="100" ixy="0" ixz="0" iyy="100" iyz="0" izz="100" />
        </inertial>
        <visual>
            <origin xyz="0.3641233757155793 0.03992910250181846 -0.07326397681667562" rpy="0 0 0"/>
            <geometry>
                <box size="0.7282467514311586 0.78376753333217 0.27917213520741024" />
            </geometry>
            <material name="Cyan">
                <color rgba="0 1.0 1.0 1.0"/>
            </material>
        </visual>
        <collision>
            <origin xyz="0.3641233757155793 0.03992910250181846 -0.07326397681667562" rpy="0 0 0"/>
            <geometry>
                <box size="0.7282467514311586 0.78376753333217 0.27917213520741024" />
            </geometry>
        </collision>
    </link>
    <joint name="link0_link4" type="revolute">
       <parent link="link0"/>
       <child  link="link4"/>
       <origin rpy="0 0 0" xyz="-0.11858951473855847 -0.016568092962804537 1.2291156448313307" />
     <axis xyz="1 0 0"/>
       <limit effort="0.0" lower="-3.14159" upper="3.14159" velocity="0.0"/>
    </joint>
    <link name="link4">
        <inertial>
            <origin xyz="-0.12884265462102798 -0.4194359116589365 0.15871389612676962" rpy="0 0 0"/>
            <mass value="1" />
            <inertia ixx="100" ixy="0" ixz="0" iyy="100" iyz="0" izz="100" />
        </inertial>
        <visual>
            <origin xyz="-0.12884265462102798 -0.4194359116589365 0.15871389612676962" rpy="0 0 0"/>
            <geometry>
                <box size="0.2908424439294699 0.838871823317873 0.583332995403483" />
            </geometry>
            <material name="Cyan">
                <color rgba="0 1.0 1.0 1.0"/>
            </material>
        </visual>
        <collision>
            <origin xyz="-0.12884265462102798 -0.4194359116589365 0.15871389612676962" rpy="0 0 0"/>
            <geometry>
                <box size="0.2908424439294699 0.838871823317873 0.583332995403483" />
            </geometry>
        </collision>
    </link>
    <joint name="link3_link5" type="revolute">
       <parent link="link3"/>
       <child  link="link5"/>
       <origin rpy="0 0 0" xyz="0.14543979542621577 -0.23941270981052026 -0.21285004442038075" />
     <axis xyz="1 0 0"/>
       <limit effort="0.0" lower="-3.14159" upper="3.14159" velocity="0.0"/>
    </joint>
    <link name="link5">
        <inertial>
            <origin xyz="-0.034228261000589226 0.25652615596838674 -0.14715053232010517" rpy="0 0 0"/>
            <mass value="1" />
            <inertia ixx="100" ixy="0" ixz="0" iyy="100" iyz="0" izz="100" />
        </inertial>
        <visual>
            <origin xyz="-0.034228261000589226 0.25652615596838674 -0.14715053232010517" rpy="0 0 0"/>
            <geometry>
                <box size="0.40004482400359864 0.576272724887725 0.29430106464021033" />
            </geometry>
            <material name="Cyan">
                <color rgba="0 1.0 1.0 1.0"/>
            </material>
        </visual>
        <collision>
            <origin xyz="-0.034228261000589226 0.25652615596838674 -0.14715053232010517" rpy="0 0 0"/>
            <geometry>
                <box size="0.40004482400359864 0.576272724887725 0.29430106464021033" />
            </geometry>
        </collision>
    </link>
    <joint name="link4_link6" type="revolute">
       <parent link="link4"/>
       <child  link="link6"/>
       <origin rpy="0 0 0" xyz="-0.2742638765857629 -0.7372485400865594 0.39329398662749204" />
     <axis xyz="1 0 0"/>
       <limit effort="0.0" lower="-3.14159" upper="3.14159" velocity="0.0"/>
    </joint>
    <link name="link6">
        <inertial>
            <origin xyz="-0.4580814952116398 -0.3805427540269141 -0.035273385426082535" rpy="0 0 0"/>
            <mass value="1" />
            <inertia ixx="100" ixy="0" ixz="0" iyy="100" iyz="0" izz="100" />
        </inertial>
        <visual>
            <origin xyz="-0.4580814952116398 -0.3805427540269141 -0.035273385426082535" rpy="0 0 0"/>
            <geometry>
                <box size="0.9161629904232796 0.8001471640888146 0.15099908610820933" />
            </geometry>
            <material name="Cyan">
                <color rgba="0 1.0 1.0 1.0"/>
            </material>
        </visual>
        <collision>
            <origin xyz="-0.4580814952116398 -0.3805427540269141 -0.035273385426082535" rpy="0 0 0"/>
            <geometry>
                <box size="0.9161629904232796 0.8001471640888146 0.15099908610820933" />
            </geometry>
        </collision>
    </link>
    <joint name="link2_link7" type="revolute">
       <parent link="link2"/>
       <child  link="link7"/>
       <origin rpy="0 0 0" xyz="0.0 -0.018938854531068076 -0.12531061432827834" />
     <axis xyz="0 1 0"/>
       <limit effort="0.0" lower="-3.14159" upper="3.14159" velocity="0.0"/>
    </joint>
    <link name="link7">
        <inertial>
            <origin xyz="0.0707145859442373 0.28026859854840763 -0.015175912659525576" rpy="0 0 0"/>
            <mass value="1" />
            <inertia ixx="100" ixy="0" ixz="0" iyy="100" iyz="0" izz="100" />
        </inertial>
        <visual>
            <origin xyz="0.0707145859442373 0.28026859854840763 -0.015175912659525576" rpy="0 0 0"/>
            <geometry>
                <box size="0.1414291718884746 0.7444641745606009 0.4663008484145761" />
            </geometry>
            <material name="Cyan">
                <color rgba="0 1.0 1.0 1.0"/>
            </material>
        </visual>
        <collision>
            <origin xyz="0.0707145859442373 0.28026859854840763 -0.015175912659525576" rpy="0 0 0"/>
            <geometry>
                <box size="0.1414291718884746 0.7444641745606009 0.4663008484145761" />
            </geometry>
        </collision>
    </link>
</robot>