<robot name = "robot">
    <link name="link0">
        <inertial>
            <origin xyz="0 0 1" rpy="0 0 0"/>
            <mass value="1" />
            <inertia ixx="100" ixy="0" ixz="0" iyy="100" iyz="0" izz="100" />
        </inertial>
        <visual>
            <origin xyz="0 0 1" rpy="0 0 0"/>
            <geometry>
                <box size="0.476255481920854 0.594134513837436 0.9018363985606516" />
            </geometry>
            <material name="Cyan">
                <color rgba="0.0 1.0 1.0 1.0"/>
            </material>
        </visual>
        <collision>
            <origin xyz="0 0 1" rpy="0 0 0"/>
            <geometry>
                <box size="0.476255481920854 0.594134513837436 0.9018363985606516" />
            </geometry>
        </collision>
    </link>
    <joint name="link0_link1" type="revolute">
       <parent link="link0"/>
       <child  link="link1"/>
       <origin rpy="0 0 0" xyz="-0.238127740960427 -0.17692209792377542 1.2574313318925074" />
     <axis xyz="1 0 0"/>
       <limit effort="0.0" lower="-3.14159" upper="3.14159" velocity="0.0"/>
    </joint>
    <link name="link1">
        <inertial>
            <origin xyz="-0.21864898088612433 -0.14063789185532205 0.049323203125406855" rpy="0 0 0"/>
            <mass value="1" />
            <inertia ixx="100" ixy="0" ixz="0" iyy="100" iyz="0" izz="100" />
        </inertial>
        <visual>
            <origin xyz="-0.21864898088612433 -0.14063789185532205 0.049323203125406855" rpy="0 0 0"/>
            <geometry>
                <box size="0.43729796177224867 0.42465526908671547 0.17414955459980108" />
            </geometry>
            <material name="Green">
                <color rgba="0.0 1.0 0.0 1.0"/>
            </material>
        </visual>
        <collision>
            <origin xyz="-0.21864898088612433 -0.14063789185532205 0.049323203125406855" rpy="0 0 0"/>
            <geometry>
                <box size="0.43729796177224867 0.42465526908671547 0.17414955459980108" />
            </geometry>
        </collision>
    </link>
    <joint name="link0_link2" type="revolute">
       <parent link="link0"/>
       <child  link="link2"/>
       <origin rpy="0 0 0" xyz="-0.11147281476063299 0.10796214817987461 1.4509181992803257" />
     <axis xyz="0 1 0"/>
       <limit effort="0.0" lower="-3.14159" upper="3.14159" velocity="0.0"/>
    </joint>
    <link name="link2">
        <inertial>
            <origin xyz="-0.2287724416617456 -0.08051060742352362 0.26990639295759644" rpy="0 0 0"/>
            <mass value="1" />
            <inertia ixx="100" ixy="0" ixz="0" iyy="100" iyz="0" izz="100" />
        </inertial>
        <visual>
            <origin xyz="-0.2287724416617456 -0.08051060742352362 0.26990639295759644" rpy="0 0 0"/>
            <geometry>
                <box size="0.9258309288884653 0.371170682672906 0.5398127859151929" />
            </geometry>
            <material name="Green">
                <color rgba="0.0 1.0 0.0 1.0"/>
            </material>
        </visual>
        <collision>
            <origin xyz="-0.2287724416617456 -0.08051060742352362 0.26990639295759644" rpy="0 0 0"/>
            <geometry>
                <box size="0.9258309288884653 0.371170682672906 0.5398127859151929" />
            </geometry>
        </collision>
    </link>
    <joint name="link0_link3" type="revolute">
       <parent link="link0"/>
       <child  link="link3"/>
       <origin rpy="0 0 0" xyz="0.238127740960427 0.149994219146787 0.7494626516851504" />
     <axis xyz="1 0 0"/>
       <limit effort="0.0" lower="-3.14159" upper="3.14159" velocity="0.0"/>
    </joint>
    <link name="link3">
        <inertial>
            <origin xyz="0.2136955082976889 0.2657952713572761 0.03699483325134698" rpy="0 0 0"/>
            <mass value="1" />
            <inertia ixx="100" ixy="0" ixz="0" iyy="100" iyz="0" izz="100" />
        </inertial>
        <visual>
            <origin xyz="0.2136955082976889 0.2657952713572761 0.03699483325134698" rpy="0 0 0"/>
            <geometry>
                <box size="0.4273910165953778 0.845550795070668 0.8604646992398101" />
            </geometry>
            <material name="Green">
                <color rgba="0.0 1.0 0.0 1.0"/>
            </material>
        </visual>
        <collision>
            <origin xyz="0.2136955082976889 0.2657952713572761 0.03699483325134698" rpy="0 0 0"/>
            <geometry>
                <box size="0.4273910165953778 0.845550795070668 0.8604646992398101" />
            </geometry>
        </collision>
    </link>
</robot>