<robot name = "robot">
    <link name="link0">
        <inertial>
            <origin xyz="0 0 1" rpy="0 0 0"/>
            <mass value="1" />
            <inertia ixx="100" ixy="0" ixz="0" iyy="100" iyz="0" izz="100" />
        </inertial>
        <visual>
            <origin xyz="0 0 1" rpy="0 0 0"/>
            <geometry>
                <box size="0.7653275594910429 0.6418673235485352 0.0849535745265051" />
            </geometry>
            <material name="Cyan">
                <color rgba="0.0 1.0 1.0 1.0"/>
            </material>
        </visual>
        <collision>
            <origin xyz="0 0 1" rpy="0 0 0"/>
            <geometry>
                <box size="0.7653275594910429 0.6418673235485352 0.0849535745265051" />
            </geometry>
        </collision>
    </link>
    <joint name="link0_link1" type="revolute">
       <parent link="link0"/>
       <child  link="link1"/>
       <origin rpy="0 0 0" xyz="-0.38266377974552146 0.22484290514470814 0.9996124348994073" />
     <axis xyz="0 1 0"/>
       <limit effort="0.0" lower="-3.14159" upper="3.14159" velocity="0.0"/>
    </joint>
    <link name="link1">
        <inertial>
            <origin xyz="-0.19329932846807169 -0.005916913558874662 -0.0375330416273468" rpy="0 0 0"/>
            <mass value="1" />
            <inertia ixx="100" ixy="0" ixz="0" iyy="100" iyz="0" izz="100" />
        </inertial>
        <visual>
            <origin xyz="-0.19329932846807169 -0.005916913558874662 -0.0375330416273468" rpy="0 0 0"/>
            <geometry>
                <box size="0.38659865693614337 0.23003876493009012 0.5558778975917356" />
            </geometry>
            <material name="Green">
                <color rgba="0.0 1.0 0.0 1.0"/>
            </material>
        </visual>
        <collision>
            <origin xyz="-0.19329932846807169 -0.005916913558874662 -0.0375330416273468" rpy="0 0 0"/>
            <geometry>
                <box size="0.38659865693614337 0.23003876493009012 0.5558778975917356" />
            </geometry>
        </collision>
    </link>
    <joint name="link1_link2" type="revolute">
       <parent link="link1"/>
       <child  link="link2"/>
       <origin rpy="0 0 0" xyz="-0.29401853709738734 0.039441938546133294 0.24040590716852098" />
     <axis xyz="0 0 1"/>
       <limit effort="0.0" lower="-3.14159" upper="3.14159" velocity="0.0"/>
    </joint>
    <link name="link2">
        <inertial>
            <origin xyz="0.2200607513942593 -0.013693460757750117 0.3750379548276048" rpy="0 0 0"/>
            <mass value="1" />
            <inertia ixx="100" ixy="0" ixz="0" iyy="100" iyz="0" izz="100" />
        </inertial>
        <visual>
            <origin xyz="0.2200607513942593 -0.013693460757750117 0.3750379548276048" rpy="0 0 0"/>
            <geometry>
                <box size="0.802820421793588 0.502444528634576 0.7500759096552096" />
            </geometry>
            <material name="Green">
                <color rgba="0.0 1.0 0.0 1.0"/>
            </material>
        </visual>
        <collision>
            <origin xyz="0.2200607513942593 -0.013693460757750117 0.3750379548276048" rpy="0 0 0"/>
            <geometry>
                <box size="0.802820421793588 0.502444528634576 0.7500759096552096" />
            </geometry>
        </collision>
    </link>
    <joint name="link0_link3" type="revolute">
       <parent link="link0"/>
       <child  link="link3"/>
       <origin rpy="0 0 0" xyz="0.13102346764440853 0.3209336617742676 1.0060354495848884" />
     <axis xyz="0 0 1"/>
       <limit effort="0.0" lower="-3.14159" upper="3.14159" velocity="0.0"/>
    </joint>
    <link name="link3">
        <inertial>
            <origin xyz="0.30573366947804353 0.3810001710120553 -0.022901317015806274" rpy="0 0 0"/>
            <mass value="1" />
            <inertia ixx="100" ixy="0" ixz="0" iyy="100" iyz="0" izz="100" />
        </inertial>
        <visual>
            <origin xyz="0.30573366947804353 0.3810001710120553 -0.022901317015806274" rpy="0 0 0"/>
            <geometry>
                <box size="0.74895169776266 0.7620003420241106 0.6025801738357365" />
            </geometry>
            <material name="Green">
                <color rgba="0.0 1.0 0.0 1.0"/>
            </material>
        </visual>
        <collision>
            <origin xyz="0.30573366947804353 0.3810001710120553 -0.022901317015806274" rpy="0 0 0"/>
            <geometry>
                <box size="0.74895169776266 0.7620003420241106 0.6025801738357365" />
            </geometry>
        </collision>
    </link>
    <joint name="link3_link4" type="revolute">
       <parent link="link3"/>
       <child  link="link4"/>
       <origin rpy="0 0 0" xyz="0.3222772515533741 0.0 0.2424475792478697" />
     <axis xyz="1 0 0"/>
       <limit effort="0.0" lower="-3.14159" upper="3.14159" velocity="0.0"/>
    </joint>
    <link name="link4">
        <inertial>
            <origin xyz="0.35017864370349344 -0.4851114764462809 0.17509986409024733" rpy="0 0 0"/>
            <mass value="1" />
            <inertia ixx="100" ixy="0" ixz="0" iyy="100" iyz="0" izz="100" />
        </inertial>
        <visual>
            <origin xyz="0.35017864370349344 -0.4851114764462809 0.17509986409024733" rpy="0 0 0"/>
            <geometry>
                <box size="0.9390274541148137 0.9702229528925618 0.41629807151681864" />
            </geometry>
            <material name="Green">
                <color rgba="0.0 1.0 0.0 1.0"/>
            </material>
        </visual>
        <collision>
            <origin xyz="0.35017864370349344 -0.4851114764462809 0.17509986409024733" rpy="0 0 0"/>
            <geometry>
                <box size="0.9390274541148137 0.9702229528925618 0.41629807151681864" />
            </geometry>
        </collision>
    </link>
    <joint name="link4_link5" type="revolute">
       <parent link="link4"/>
       <child  link="link5"/>
       <origin rpy="0 0 0" xyz="0.8196923707609003 -0.3912752397781932 0.2629064654979637" />
     <axis xyz="1 0 0"/>
       <limit effort="0.0" lower="-3.14159" upper="3.14159" velocity="0.0"/>
    </joint>
    <link name="link5">
        <inertial>
            <origin xyz="0.05006046056892366 0.004696201493094394 0.4083337430956619" rpy="0 0 0"/>
            <mass value="1" />
            <inertia ixx="100" ixy="0" ixz="0" iyy="100" iyz="0" izz="100" />
        </inertial>
        <visual>
            <origin xyz="0.05006046056892366 0.004696201493094394 0.4083337430956619" rpy="0 0 0"/>
            <geometry>
                <box size="0.10012092113784732 0.010732259470020766 0.8664859495995929" />
            </geometry>
            <material name="Green">
                <color rgba="0.0 1.0 0.0 1.0"/>
            </material>
        </visual>
        <collision>
            <origin xyz="0.05006046056892366 0.004696201493094394 0.4083337430956619" rpy="0 0 0"/>
            <geometry>
                <box size="0.10012092113784732 0.010732259470020766 0.8664859495995929" />
            </geometry>
        </collision>
    </link>
    <joint name="link5_link6" type="revolute">
       <parent link="link5"/>
       <child  link="link6"/>
       <origin rpy="0 0 0" xyz="0.10012092113784732 0.008382684229226334 0.43115264253115115" />
     <axis xyz="0 1 0"/>
       <limit effort="0.0" lower="-3.14159" upper="3.14159" velocity="0.0"/>
    </joint>
    <link name="link6">
        <inertial>
            <origin xyz="0.020689368793173124 -0.23552462245081118 0.38750554185842107" rpy="0 0 0"/>
            <mass value="1" />
            <inertia ixx="100" ixy="0" ixz="0" iyy="100" iyz="0" izz="100" />
        </inertial>
        <visual>
            <origin xyz="0.020689368793173124 -0.23552462245081118 0.38750554185842107" rpy="0 0 0"/>
            <geometry>
                <box size="0.04137873758634625 0.7905151760118494 0.9487838818165331" />
            </geometry>
            <material name="Green">
                <color rgba="0.0 1.0 0.0 1.0"/>
            </material>
        </visual>
        <collision>
            <origin xyz="0.020689368793173124 -0.23552462245081118 0.38750554185842107" rpy="0 0 0"/>
            <geometry>
                <box size="0.04137873758634625 0.7905151760118494 0.9487838818165331" />
            </geometry>
        </collision>
    </link>
    <joint name="link4_link7" type="revolute">
       <parent link="link4"/>
       <child  link="link7"/>
       <origin rpy="0 0 0" xyz="0.7456251799832128 -0.5337387783452361 0.3832488998486566" />
     <axis xyz="1 0 0"/>
       <limit effort="0.0" lower="-3.14159" upper="3.14159" velocity="0.0"/>
    </joint>
    <link name="link7">
        <inertial>
            <origin xyz="0.16703381250467567 -0.12300526841513872 0.4494726841756754" rpy="0 0 0"/>
            <mass value="1" />
            <inertia ixx="100" ixy="0" ixz="0" iyy="100" iyz="0" izz="100" />
        </inertial>
        <visual>
            <origin xyz="0.16703381250467567 -0.12300526841513872 0.4494726841756754" rpy="0 0 0"/>
            <geometry>
                <box size="0.5349071692648266 0.39818812284754035 0.8989453683513507" />
            </geometry>
            <material name="Green">
                <color rgba="0.0 1.0 0.0 1.0"/>
            </material>
        </visual>
        <collision>
            <origin xyz="0.16703381250467567 -0.12300526841513872 0.4494726841756754" rpy="0 0 0"/>
            <geometry>
                <box size="0.5349071692648266 0.39818812284754035 0.8989453683513507" />
            </geometry>
        </collision>
    </link>
</robot>