<robot name = "robot">
    <link name="link0">
        <inertial>
            <origin xyz="0 0 1" rpy="0 0 0"/>
            <mass value="1" />
            <inertia ixx="100" ixy="0" ixz="0" iyy="100" iyz="0" izz="100" />
        </inertial>
        <visual>
            <origin xyz="0 0 1" rpy="0 0 0"/>
            <geometry>
                <box size="0.8632402938052403 0.4196756550373705 0.23698751315134614" />
            </geometry>
            <material name="Cyan">
                <color rgba="0.0 1.0 1.0 1.0"/>
            </material>
        </visual>
        <collision>
            <origin xyz="0 0 1" rpy="0 0 0"/>
            <geometry>
                <box size="0.8632402938052403 0.4196756550373705 0.23698751315134614" />
            </geometry>
        </collision>
    </link>
    <joint name="link0_link1" type="revolute">
       <parent link="link0"/>
       <child  link="link1"/>
       <origin rpy="0 0 0" xyz="0.3753636371541969 0.20983782751868524 0.9926248878818934" />
     <axis xyz="0 1 0"/>
       <limit effort="0.0" lower="-3.14159" upper="3.14159" velocity="0.0"/>
    </joint>
    <link name="link1">
        <inertial>
            <origin xyz="0.2867043955199994 0.08172631335344566 0.04482437735840364" rpy="0 0 0"/>
            <mass value="1" />
            <inertia ixx="100" ixy="0" ixz="0" iyy="100" iyz="0" izz="100" />
        </inertial>
        <visual>
            <origin xyz="0.2867043955199994 0.08172631335344566 0.04482437735840364" rpy="0 0 0"/>
            <geometry>
                <box size="0.6986264402957513 0.1634526267068913 0.27164133296909376" />
            </geometry>
            <material name="Cyan">
                <color rgba="0.0 1.0 1.0 1.0"/>
            </material>
        </visual>
        <collision>
            <origin xyz="0.2867043955199994 0.08172631335344566 0.04482437735840364" rpy="0 0 0"/>
            <geometry>
                <box size="0.6986264402957513 0.1634526267068913 0.27164133296909376" />
            </geometry>
        </collision>
    </link>
    <joint name="link0_link2" type="revolute">
       <parent link="link0"/>
       <child  link="link2"/>
       <origin rpy="0 0 0" xyz="0.3367868430733785 -0.20983782751868524 1.0657606258146068" />
     <axis xyz="1 0 0"/>
       <limit effort="0.0" lower="-3.14159" upper="3.14159" velocity="0.0"/>
    </joint>
    <link name="link2">
        <inertial>
            <origin xyz="-0.13341937012686578 -0.15594772617300506 -0.27981877660071336" rpy="0 0 0"/>
            <mass value="1" />
            <inertia ixx="100" ixy="0" ixz="0" iyy="100" iyz="0" izz="100" />
        </inertial>
        <visual>
            <origin xyz="-0.13341937012686578 -0.15594772617300506 -0.27981877660071336" rpy="0 0 0"/>
            <geometry>
                <box size="0.5146735396827319 0.3118954523460101 0.7384676210387386" />
            </geometry>
            <material name="Green">
                <color rgba="0.0 1.0 0.0 1.0"/>
            </material>
        </visual>
        <collision>
            <origin xyz="-0.13341937012686578 -0.15594772617300506 -0.27981877660071336" rpy="0 0 0"/>
            <geometry>
                <box size="0.5146735396827319 0.3118954523460101 0.7384676210387386" />
            </geometry>
        </collision>
    </link>
    <joint name="link0_link3" type="revolute">
       <parent link="link0"/>
       <child  link="link3"/>
       <origin rpy="0 0 0" xyz="-0.3537729050191115 0.20983782751868524 1.0808477965207992" />
     <axis xyz="1 0 0"/>
       <limit effort="0.0" lower="-3.14159" upper="3.14159" velocity="0.0"/>
    </joint>
    <link name="link3">
        <inertial>
            <origin xyz="0.27246385653996325 0.33788382977399467 0.0009055587287774276" rpy="0 0 0"/>
            <mass value="1" />
            <inertia ixx="100" ixy="0" ixz="0" iyy="100" iyz="0" izz="100" />
        </inertial>
        <visual>
            <origin xyz="0.27246385653996325 0.33788382977399467 0.0009055587287774276" rpy="0 0 0"/>
            <geometry>
                <box size="0.8411397924875026 0.6757676595479893 0.010686420020619147" />
            </geometry>
            <material name="Green">
                <color rgba="0.0 1.0 0.0 1.0"/>
            </material>
        </visual>
        <collision>
            <origin xyz="0.27246385653996325 0.33788382977399467 0.0009055587287774276" rpy="0 0 0"/>
            <geometry>
                <box size="0.8411397924875026 0.6757676595479893 0.010686420020619147" />
            </geometry>
        </collision>
    </link>
    <joint name="link2_link4" type="revolute">
       <parent link="link2"/>
       <child  link="link4"/>
       <origin rpy="0 0 0" xyz="-0.3907561399682317 -0.21857227731814194 -0.06443125836497635" />
     <axis xyz="0 0 1"/>
       <limit effort="0.0" lower="-3.14159" upper="3.14159" velocity="0.0"/>
    </joint>
    <link name="link4">
        <inertial>
            <origin xyz="-0.319580399166192 0.41325779542060903 -0.07775940561608419" rpy="0 0 0"/>
            <mass value="1" />
            <inertia ixx="100" ixy="0" ixz="0" iyy="100" iyz="0" izz="100" />
        </inertial>
        <visual>
            <origin xyz="-0.319580399166192 0.41325779542060903 -0.07775940561608419" rpy="0 0 0"/>
            <geometry>
                <box size="0.639160798332384 0.9036066886952047 0.5632880347128291" />
            </geometry>
            <material name="Green">
                <color rgba="0.0 1.0 0.0 1.0"/>
            </material>
        </visual>
        <collision>
            <origin xyz="-0.319580399166192 0.41325779542060903 -0.07775940561608419" rpy="0 0 0"/>
            <geometry>
                <box size="0.639160798332384 0.9036066886952047 0.5632880347128291" />
            </geometry>
        </collision>
    </link>
</robot>