<robot name = "robot">
    <link name="link0">
        <inertial>
            <origin xyz="0 0 1" rpy="0 0 0"/>
            <mass value="1" />
            <inertia ixx="100" ixy="0" ixz="0" iyy="100" iyz="0" izz="100" />
        </inertial>
        <visual>
            <origin xyz="0 0 1" rpy="0 0 0"/>
            <geometry>
                <box size="0.29282860365907215 0.8219840591891258 0.8776458689490149" />
            </geometry>
            <material name="Cyan">
                <color rgba="0 1.0 1.0 1.0"/>
            </material>
        </visual>
        <collision>
            <origin xyz="0 0 1" rpy="0 0 0"/>
            <geometry>
                <box size="0.29282860365907215 0.8219840591891258 0.8776458689490149" />
            </geometry>
        </collision>
    </link>
    <joint name="link0_link1" type="revolute">
       <parent link="link0"/>
       <child  link="link1"/>
       <origin rpy="0 0 0" xyz="0.13279347321042023 0.4109920295945629 0.9145803215720798" />
     <axis xyz="0 0 1"/>
       <limit effort="0.0" lower="-3.14159" upper="3.14159" velocity="0.0"/>
    </joint>
    <link name="link1">
        <inertial>
            <origin xyz="0.16195496250746894 0.23605970459211284 0.013881545660780053" rpy="0 0 0"/>
            <mass value="1" />
            <inertia ixx="100" ixy="0" ixz="0" iyy="100" iyz="0" izz="100" />
        </inertial>
        <visual>
            <origin xyz="0.16195496250746894 0.23605970459211284 0.013881545660780053" rpy="0 0 0"/>
            <geometry>
                <box size="0.34019182282110405 0.4721194091842257 0.13598572213328908" />
            </geometry>
            <material name="Cyan">
                <color rgba="0 1.0 1.0 1.0"/>
            </material>
        </visual>
        <collision>
            <origin xyz="0.16195496250746894 0.23605970459211284 0.013881545660780053" rpy="0 0 0"/>
            <geometry>
                <box size="0.34019182282110405 0.4721194091842257 0.13598572213328908" />
            </geometry>
        </collision>
    </link>
    <joint name="link1_link2" type="revolute">
       <parent link="link1"/>
       <child  link="link2"/>
       <origin rpy="0 0 0" xyz="0.3152672789551044 0.0 0.01490671696878051" />
     <axis xyz="0 1 0"/>
       <limit effort="0.0" lower="-3.14159" upper="3.14159" velocity="0.0"/>
    </joint>
    <link name="link2">
        <inertial>
            <origin xyz="0.000812656631039796 -0.40924621037288517 0.07706132874280888" rpy="0 0 0"/>
            <mass value="1" />
            <inertia ixx="100" ixy="0" ixz="0" iyy="100" iyz="0" izz="100" />
        </inertial>
        <visual>
            <origin xyz="0.000812656631039796 -0.40924621037288517 0.07706132874280888" rpy="0 0 0"/>
            <geometry>
                <box size="0.04586834084013913 0.8184924207457703 0.8886532488867144" />
            </geometry>
            <material name="Cyan">
                <color rgba="0 1.0 1.0 1.0"/>
            </material>
        </visual>
        <collision>
            <origin xyz="0.000812656631039796 -0.40924621037288517 0.07706132874280888" rpy="0 0 0"/>
            <geometry>
                <box size="0.04586834084013913 0.8184924207457703 0.8886532488867144" />
            </geometry>
        </collision>
    </link>
    <joint name="link1_link3" type="revolute">
       <parent link="link1"/>
       <child  link="link3"/>
       <origin rpy="0 0 0" xyz="-0.00814094890308309 0.1011296373451514 0.021558621638128852" />
     <axis xyz="0 0 1"/>
       <limit effort="0.0" lower="-3.14159" upper="3.14159" velocity="0.0"/>
    </joint>
    <link name="link3">
        <inertial>
            <origin xyz="-0.16857606014404158 0.06989694731527811 0.07840704202946563" rpy="0 0 0"/>
            <mass value="1" />
            <inertia ixx="100" ixy="0" ixz="0" iyy="100" iyz="0" izz="100" />
        </inertial>
        <visual>
            <origin xyz="-0.16857606014404158 0.06989694731527811 0.07840704202946563" rpy="0 0 0"/>
            <geometry>
                <box size="0.33715212028808317 0.2819487793417109 0.46465866559111946" />
            </geometry>
            <material name="Cyan">
                <color rgba="0 1.0 1.0 1.0"/>
            </material>
        </visual>
        <collision>
            <origin xyz="-0.16857606014404158 0.06989694731527811 0.07840704202946563" rpy="0 0 0"/>
            <geometry>
                <box size="0.33715212028808317 0.2819487793417109 0.46465866559111946" />
            </geometry>
        </collision>
    </link>
    <joint name="link3_link4" type="revolute">
       <parent link="link3"/>
       <child  link="link4"/>
       <origin rpy="0 0 0" xyz="-0.2549195313077578 -0.07107744235557735 0.3019728141381254" />
     <axis xyz="1 0 0"/>
       <limit effort="0.0" lower="-3.14159" upper="3.14159" velocity="0.0"/>
    </joint>
    <link name="link4">
        <inertial>
            <origin xyz="-0.35914186130184056 -0.04702964812500182 0.040843558205040216" rpy="0 0 0"/>
            <mass value="1" />
            <inertia ixx="100" ixy="0" ixz="0" iyy="100" iyz="0" izz="100" />
        </inertial>
        <visual>
            <origin xyz="-0.35914186130184056 -0.04702964812500182 0.040843558205040216" rpy="0 0 0"/>
            <geometry>
                <box size="0.7652298479966924 0.09405929625000364 0.6818007558705731" />
            </geometry>
            <material name="Cyan">
                <color rgba="0 1.0 1.0 1.0"/>
            </material>
        </visual>
        <collision>
            <origin xyz="-0.35914186130184056 -0.04702964812500182 0.040843558205040216" rpy="0 0 0"/>
            <geometry>
                <box size="0.7652298479966924 0.09405929625000364 0.6818007558705731" />
            </geometry>
        </collision>
    </link>
    <joint name="link0_link5" type="revolute">
       <parent link="link0"/>
       <child  link="link5"/>
       <origin rpy="0 0 0" xyz="-0.01635806859684539 0.4109920295945629 0.7494539123158186" />
     <axis xyz="0 0 1"/>
       <limit effort="0.0" lower="-3.14159" upper="3.14159" velocity="0.0"/>
    </joint>
    <link name="link5">
        <inertial>
            <origin xyz="0.23748843845307005 0.009954336070944314 0.03590448693057436" rpy="0 0 0"/>
            <mass value="1" />
            <inertia ixx="100" ixy="0" ixz="0" iyy="100" iyz="0" izz="100" />
        </inertial>
        <visual>
            <origin xyz="0.23748843845307005 0.009954336070944314 0.03590448693057436" rpy="0 0 0"/>
            <geometry>
                <box size="0.5793651357968164 0.019908672141888628 0.07358947992589526" />
            </geometry>
            <material name="Cyan">
                <color rgba="0 1.0 1.0 1.0"/>
            </material>
        </visual>
        <collision>
            <origin xyz="0.23748843845307005 0.009954336070944314 0.03590448693057436" rpy="0 0 0"/>
            <geometry>
                <box size="0.5793651357968164 0.019908672141888628 0.07358947992589526" />
            </geometry>
        </collision>
    </link>
</robot>