<robot name = "robot">
    <link name="link0">
        <inertial>
            <origin xyz="0 0 1" rpy="0 0 0"/>
            <mass value="1" />
            <inertia ixx="100" ixy="0" ixz="0" iyy="100" iyz="0" izz="100" />
        </inertial>
        <visual>
            <origin xyz="0 0 1" rpy="0 0 0"/>
            <geometry>
                <box size="0.07412900023787161 0.4144781871185478 0.882213787381804" />
            </geometry>
            <material name="Cyan">
                <color rgba="0 1.0 1.0 1.0"/>
            </material>
        </visual>
        <collision>
            <origin xyz="0 0 1" rpy="0 0 0"/>
            <geometry>
                <box size="0.07412900023787161 0.4144781871185478 0.882213787381804" />
            </geometry>
        </collision>
    </link>
    <joint name="link0_link1" type="revolute">
       <parent link="link0"/>
       <child  link="link1"/>
       <origin rpy="0 0 0" xyz="-0.004869959737663419 -0.2072390935592739 0.6680115836952589" />
     <axis xyz="1 0 0"/>
       <limit effort="0.0" lower="-3.14159" upper="3.14159" velocity="0.0"/>
    </joint>
    <link name="link1">
        <inertial>
            <origin xyz="0.1989464773982552 -0.12480732029933872 -0.27060715574338895" rpy="0 0 0"/>
            <mass value="1" />
            <inertia ixx="100" ixy="0" ixz="0" iyy="100" iyz="0" izz="100" />
        </inertial>
        <visual>
            <origin xyz="0.1989464773982552 -0.12480732029933872 -0.27060715574338895" rpy="0 0 0"/>
            <geometry>
                <box size="0.9918450050995299 0.24961464059867744 0.6546028529072514" />
            </geometry>
            <material name="Cyan">
                <color rgba="0 1.0 1.0 1.0"/>
            </material>
        </visual>
        <collision>
            <origin xyz="0.1989464773982552 -0.12480732029933872 -0.27060715574338895" rpy="0 0 0"/>
            <geometry>
                <box size="0.9918450050995299 0.24961464059867744 0.6546028529072514" />
            </geometry>
        </collision>
    </link>
    <joint name="link1_link2" type="revolute">
       <parent link="link1"/>
       <child  link="link2"/>
       <origin rpy="0 0 0" xyz="-0.2969760251515098 -0.04511761882473689 -0.5020226043442118" />
     <axis xyz="1 0 0"/>
       <limit effort="0.0" lower="-3.14159" upper="3.14159" velocity="0.0"/>
    </joint>
    <link name="link2">
        <inertial>
            <origin xyz="-0.46107496856435853 -0.053024319932927014 0.21898342295597562" rpy="0 0 0"/>
            <mass value="1" />
            <inertia ixx="100" ixy="0" ixz="0" iyy="100" iyz="0" izz="100" />
        </inertial>
        <visual>
            <origin xyz="-0.46107496856435853 -0.053024319932927014 0.21898342295597562" rpy="0 0 0"/>
            <geometry>
                <box size="0.9221499371287171 0.9463624103243556 0.7476311834386713" />
            </geometry>
            <material name="Cyan">
                <color rgba="0 1.0 1.0 1.0"/>
            </material>
        </visual>
        <collision>
            <origin xyz="-0.46107496856435853 -0.053024319932927014 0.21898342295597562" rpy="0 0 0"/>
            <geometry>
                <box size="0.9221499371287171 0.9463624103243556 0.7476311834386713" />
            </geometry>
        </collision>
    </link>
    <joint name="link1_link3" type="revolute">
       <parent link="link1"/>
       <child  link="link3"/>
       <origin rpy="0 0 0" xyz="0.3979962282133216 -0.14990376596855262 0.05669427071023675" />
     <axis xyz="0 1 0"/>
       <limit effort="0.0" lower="-3.14159" upper="3.14159" velocity="0.0"/>
    </joint>
    <link name="link3">
        <inertial>
            <origin xyz="0.3980173719855185 0.02918777583143869 0.42615644380338513" rpy="0 0 0"/>
            <mass value="1" />
            <inertia ixx="100" ixy="0" ixz="0" iyy="100" iyz="0" izz="100" />
        </inertial>
        <visual>
            <origin xyz="0.3980173719855185 0.02918777583143869 0.42615644380338513" rpy="0 0 0"/>
            <geometry>
                <box size="0.864351862866107 0.30658034507943166 0.8523128876067703" />
            </geometry>
            <material name="Cyan">
                <color rgba="0 1.0 1.0 1.0"/>
            </material>
        </visual>
        <collision>
            <origin xyz="0.3980173719855185 0.02918777583143869 0.42615644380338513" rpy="0 0 0"/>
            <geometry>
                <box size="0.864351862866107 0.30658034507943166 0.8523128876067703" />
            </geometry>
        </collision>
    </link>
    <joint name="link0_link4" type="revolute">
       <parent link="link0"/>
       <child  link="link4"/>
       <origin rpy="0 0 0" xyz="-0.020044310900271325 -0.0811315883856988 1.441106893690902" />
     <axis xyz="1 0 0"/>
       <limit effort="0.0" lower="-3.14159" upper="3.14159" velocity="0.0"/>
    </joint>
    <link name="link4">
        <inertial>
            <origin xyz="0.07948782084004977 0.0682382862200756 0.26037303856459965" rpy="0 0 0"/>
            <mass value="1" />
            <inertia ixx="100" ixy="0" ixz="0" iyy="100" iyz="0" izz="100" />
        </inertial>
        <visual>
            <origin xyz="0.07948782084004977 0.0682382862200756 0.26037303856459965" rpy="0 0 0"/>
            <geometry>
                <box size="0.4189790987706006 0.2020872812705321 0.5207460771291993" />
            </geometry>
            <material name="Cyan">
                <color rgba="0 1.0 1.0 1.0"/>
            </material>
        </visual>
        <collision>
            <origin xyz="0.07948782084004977 0.0682382862200756 0.26037303856459965" rpy="0 0 0"/>
            <geometry>
                <box size="0.4189790987706006 0.2020872812705321 0.5207460771291993" />
            </geometry>
        </collision>
    </link>
    <joint name="link0_link5" type="revolute">
       <parent link="link0"/>
       <child  link="link5"/>
       <origin rpy="0 0 0" xyz="-0.037064500118935806 0.03816287710388932 0.762288812054123" />
     <axis xyz="1 0 0"/>
       <limit effort="0.0" lower="-3.14159" upper="3.14159" velocity="0.0"/>
    </joint>
    <link name="link5">
        <inertial>
            <origin xyz="-0.32957973476556457 0.2714602129891534 0.03713443347962445" rpy="0 0 0"/>
            <mass value="1" />
            <inertia ixx="100" ixy="0" ixz="0" iyy="100" iyz="0" izz="100" />
        </inertial>
        <visual>
            <origin xyz="-0.32957973476556457 0.2714602129891534 0.03713443347962445" rpy="0 0 0"/>
            <geometry>
                <box size="0.6591594695311291 0.9377191469345995 0.19175871215009965" />
            </geometry>
            <material name="Cyan">
                <color rgba="0 1.0 1.0 1.0"/>
            </material>
        </visual>
        <collision>
            <origin xyz="-0.32957973476556457 0.2714602129891534 0.03713443347962445" rpy="0 0 0"/>
            <geometry>
                <box size="0.6591594695311291 0.9377191469345995 0.19175871215009965" />
            </geometry>
        </collision>
    </link>
    <joint name="link1_link6" type="revolute">
       <parent link="link1"/>
       <child  link="link6"/>
       <origin rpy="0 0 0" xyz="0.6948689799480201 -0.046731294352702846 0.012704930266455083" />
     <axis xyz="0 1 0"/>
       <limit effort="0.0" lower="-3.14159" upper="3.14159" velocity="0.0"/>
    </joint>
    <link name="link6">
        <inertial>
            <origin xyz="0.3179115618665956 -0.1209994126612335 0.0011901340540271597" rpy="0 0 0"/>
            <mass value="1" />
            <inertia ixx="100" ixy="0" ixz="0" iyy="100" iyz="0" izz="100" />
        </inertial>
        <visual>
            <origin xyz="0.3179115618665956 -0.1209994126612335 0.0011901340540271597" rpy="0 0 0"/>
            <geometry>
                <box size="0.6358231237331912 0.7369316322655031 0.283714848409129" />
            </geometry>
            <material name="Cyan">
                <color rgba="0 1.0 1.0 1.0"/>
            </material>
        </visual>
        <collision>
            <origin xyz="0.3179115618665956 -0.1209994126612335 0.0011901340540271597" rpy="0 0 0"/>
            <geometry>
                <box size="0.6358231237331912 0.7369316322655031 0.283714848409129" />
            </geometry>
        </collision>
    </link>
    <joint name="link0_link7" type="revolute">
       <parent link="link0"/>
       <child  link="link7"/>
       <origin rpy="0 0 0" xyz="0.01100323114348135 0.2072390935592739 1.2203042788082856" />
     <axis xyz="1 0 0"/>
       <limit effort="0.0" lower="-3.14159" upper="3.14159" velocity="0.0"/>
    </joint>
    <link name="link7">
        <inertial>
            <origin xyz="0.25936919742212317 0.039372595591663784 -0.01652319189600985" rpy="0 0 0"/>
            <mass value="1" />
            <inertia ixx="100" ixy="0" ixz="0" iyy="100" iyz="0" izz="100" />
        </inertial>
        <visual>
            <origin xyz="0.25936919742212317 0.039372595591663784 -0.01652319189600985" rpy="0 0 0"/>
            <geometry>
                <box size="0.891616976755624 0.07874519118332757 0.21037839434990513" />
            </geometry>
            <material name="Cyan">
                <color rgba="0 1.0 1.0 1.0"/>
            </material>
        </visual>
        <collision>
            <origin xyz="0.25936919742212317 0.039372595591663784 -0.01652319189600985" rpy="0 0 0"/>
            <geometry>
                <box size="0.891616976755624 0.07874519118332757 0.21037839434990513" />
            </geometry>
        </collision>
    </link>
    <joint name="link6_link8" type="revolute">
       <parent link="link6"/>
       <child  link="link8"/>
       <origin rpy="0 0 0" xyz="0.0 -0.21636002435121898 0.0020263312351778357" />
     <axis xyz="1 0 0"/>
       <limit effort="0.0" lower="-3.14159" upper="3.14159" velocity="0.0"/>
    </joint>
    <link name="link8">
        <inertial>
            <origin xyz="-0.38860252072926693 0.14715223518460135 -0.051372633504891886" rpy="0 0 0"/>
            <mass value="1" />
            <inertia ixx="100" ixy="0" ixz="0" iyy="100" iyz="0" izz="100" />
        </inertial>
        <visual>
            <origin xyz="-0.38860252072926693 0.14715223518460135 -0.051372633504891886" rpy="0 0 0"/>
            <geometry>
                <box size="0.7772050414585339 0.4346042972187576 0.2189374454364078" />
            </geometry>
            <material name="Cyan">
                <color rgba="0 1.0 1.0 1.0"/>
            </material>
        </visual>
        <collision>
            <origin xyz="-0.38860252072926693 0.14715223518460135 -0.051372633504891886" rpy="0 0 0"/>
            <geometry>
                <box size="0.7772050414585339 0.4346042972187576 0.2189374454364078" />
            </geometry>
        </collision>
    </link>
    <joint name="link5_link9" type="revolute">
       <parent link="link5"/>
       <child  link="link9"/>
       <origin rpy="0 0 0" xyz="0.0 -0.03317396328287503 -0.0042759403822111505" />
     <axis xyz="0 1 0"/>
       <limit effort="0.0" lower="-3.14159" upper="3.14159" velocity="0.0"/>
    </joint>
    <link name="link9">
        <inertial>
            <origin xyz="0.07380862998248089 -0.039385615403049204 0.03512029076389801" rpy="0 0 0"/>
            <mass value="1" />
            <inertia ixx="100" ixy="0" ixz="0" iyy="100" iyz="0" izz="100" />
        </inertial>
        <visual>
            <origin xyz="0.07380862998248089 -0.039385615403049204 0.03512029076389801" rpy="0 0 0"/>
            <geometry>
                <box size="0.14761725996496178 0.985224707786869 0.7725764149945527" />
            </geometry>
            <material name="Cyan">
                <color rgba="0 1.0 1.0 1.0"/>
            </material>
        </visual>
        <collision>
            <origin xyz="0.07380862998248089 -0.039385615403049204 0.03512029076389801" rpy="0 0 0"/>
            <geometry>
                <box size="0.14761725996496178 0.985224707786869 0.7725764149945527" />
            </geometry>
        </collision>
    </link>
    <joint name="link4_link10" type="revolute">
       <parent link="link4"/>
       <child  link="link10"/>
       <origin rpy="0 0 0" xyz="0.23027440454183462 -0.032805354415190446 0.2870464413582804" />
     <axis xyz="0 0 1"/>
       <limit effort="0.0" lower="-3.14159" upper="3.14159" velocity="0.0"/>
    </joint>
    <link name="link10">
        <inertial>
            <origin xyz="0.0832107373437687 -0.06395343136614012 -0.0008331783133584251" rpy="0 0 0"/>
            <mass value="1" />
            <inertia ixx="100" ixy="0" ixz="0" iyy="100" iyz="0" izz="100" />
        </inertial>
        <visual>
            <origin xyz="0.0832107373437687 -0.06395343136614012 -0.0008331783133584251" rpy="0 0 0"/>
            <geometry>
                <box size="0.8321872361562814 0.12790686273228025 0.007614136545477379" />
            </geometry>
            <material name="Cyan">
                <color rgba="0 1.0 1.0 1.0"/>
            </material>
        </visual>
        <collision>
            <origin xyz="0.0832107373437687 -0.06395343136614012 -0.0008331783133584251" rpy="0 0 0"/>
            <geometry>
                <box size="0.8321872361562814 0.12790686273228025 0.007614136545477379" />
            </geometry>
        </collision>
    </link>
    <joint name="link4_link11" type="revolute">
       <parent link="link4"/>
       <child  link="link11"/>
       <origin rpy="0 0 0" xyz="-0.13000172854525052 0.15697759500928202 0.5029540367000054" />
     <axis xyz="0 0 1"/>
       <limit effort="0.0" lower="-3.14159" upper="3.14159" velocity="0.0"/>
    </joint>
    <link name="link11">
        <inertial>
            <origin xyz="-0.3653415792499703 -0.07111593359402647 -0.25118582826660407" rpy="0 0 0"/>
            <mass value="1" />
            <inertia ixx="100" ixy="0" ixz="0" iyy="100" iyz="0" izz="100" />
        </inertial>
        <visual>
            <origin xyz="-0.3653415792499703 -0.07111593359402647 -0.25118582826660407" rpy="0 0 0"/>
            <geometry>
                <box size="0.7306831584999406 0.40077487110365106 0.5794823004535212" />
            </geometry>
            <material name="Cyan">
                <color rgba="0 1.0 1.0 1.0"/>
            </material>
        </visual>
        <collision>
            <origin xyz="-0.3653415792499703 -0.07111593359402647 -0.25118582826660407" rpy="0 0 0"/>
            <geometry>
                <box size="0.7306831584999406 0.40077487110365106 0.5794823004535212" />
            </geometry>
        </collision>
    </link>
    <joint name="link11_link12" type="revolute">
       <parent link="link11"/>
       <child  link="link12"/>
       <origin rpy="0 0 0" xyz="0.0 -0.056126946680776404 -0.07079342976793981" />
     <axis xyz="0 0 1"/>
       <limit effort="0.0" lower="-3.14159" upper="3.14159" velocity="0.0"/>
    </joint>
    <link name="link12">
        <inertial>
            <origin xyz="0.19672714756963905 -0.34890909480341076 0.28366754706649044" rpy="0 0 0"/>
            <mass value="1" />
            <inertia ixx="100" ixy="0" ixz="0" iyy="100" iyz="0" izz="100" />
        </inertial>
        <visual>
            <origin xyz="0.19672714756963905 -0.34890909480341076 0.28366754706649044" rpy="0 0 0"/>
            <geometry>
                <box size="0.3934542951392781 0.9385286781508194 0.5767560638797001" />
            </geometry>
            <material name="Cyan">
                <color rgba="0 1.0 1.0 1.0"/>
            </material>
        </visual>
        <collision>
            <origin xyz="0.19672714756963905 -0.34890909480341076 0.28366754706649044" rpy="0 0 0"/>
            <geometry>
                <box size="0.3934542951392781 0.9385286781508194 0.5767560638797001" />
            </geometry>
        </collision>
    </link>
</robot>