<robot name = "robot">
    <link name="link0">
        <inertial>
            <origin xyz="0 0 1" rpy="0 0 0"/>
            <mass value="1" />
            <inertia ixx="100" ixy="0" ixz="0" iyy="100" iyz="0" izz="100" />
        </inertial>
        <visual>
            <origin xyz="0 0 1" rpy="0 0 0"/>
            <geometry>
                <box size="0.6613466306056681 0.6533667278929504 0.11394979562505958" />
            </geometry>
            <material name="Cyan">
                <color rgba="0 1.0 1.0 1.0"/>
            </material>
        </visual>
        <collision>
            <origin xyz="0 0 1" rpy="0 0 0"/>
            <geometry>
                <box size="0.6613466306056681 0.6533667278929504 0.11394979562505958" />
            </geometry>
        </collision>
    </link>
    <joint name="link0_link1" type="revolute">
       <parent link="link0"/>
       <child  link="link1"/>
       <origin rpy="0 0 0" xyz="-0.0778343281307367 0.006915687536399082 0.9430251021874703" />
     <axis xyz="1 0 0"/>
       <limit effort="0.0" lower="-3.14159" upper="3.14159" velocity="0.0"/>
    </joint>
    <link name="link1">
        <inertial>
            <origin xyz="0.011757949583770048 0.033425279928700515 -0.24886565823434692" rpy="0 0 0"/>
            <mass value="1" />
            <inertia ixx="100" ixy="0" ixz="0" iyy="100" iyz="0" izz="100" />
        </inertial>
        <visual>
            <origin xyz="0.011757949583770048 0.033425279928700515 -0.24886565823434692" rpy="0 0 0"/>
            <geometry>
                <box size="0.07637424820413397 0.6927437400612151 0.49773131646869384" />
            </geometry>
            <material name="Cyan">
                <color rgba="0 1.0 1.0 1.0"/>
            </material>
        </visual>
        <collision>
            <origin xyz="0.011757949583770048 0.033425279928700515 -0.24886565823434692" rpy="0 0 0"/>
            <geometry>
                <box size="0.07637424820413397 0.6927437400612151 0.49773131646869384" />
            </geometry>
        </collision>
    </link>
</robot>