<robot name = "robot">
    <link name="link0">
        <inertial>
            <origin xyz="0 0 1" rpy="0 0 0"/>
            <mass value="1" />
            <inertia ixx="100" ixy="0" ixz="0" iyy="100" iyz="0" izz="100" />
        </inertial>
        <visual>
            <origin xyz="0 0 1" rpy="0 0 0"/>
            <geometry>
                <box size="0.9744783408071431 0.9422400171742128 0.11311403158093081" />
            </geometry>
            <material name="Cyan">
                <color rgba="0 1.0 1.0 1.0"/>
            </material>
        </visual>
        <collision>
            <origin xyz="0 0 1" rpy="0 0 0"/>
            <geometry>
                <box size="0.9744783408071431 0.9422400171742128 0.11311403158093081" />
            </geometry>
        </collision>
    </link>
    <joint name="link0_link1" type="revolute">
       <parent link="link0"/>
       <child  link="link1"/>
       <origin rpy="0 0 0" xyz="0.06303566521123552 -0.20686652875059036 0.9434429842095347" />
     <axis xyz="0 0 1"/>
       <limit effort="0.0" lower="-3.14159" upper="3.14159" velocity="0.0"/>
    </joint>
    <link name="link1">
        <inertial>
            <origin xyz="-0.1918440061696871 0.1328047949220564 -0.01150162432930657" rpy="0 0 0"/>
            <mass value="1" />
            <inertia ixx="100" ixy="0" ixz="0" iyy="100" iyz="0" izz="100" />
        </inertial>
        <visual>
            <origin xyz="-0.1918440061696871 0.1328047949220564 -0.01150162432930657" rpy="0 0 0"/>
            <geometry>
                <box size="0.5772731840561101 0.3573464654023235 0.02300324865861314" />
            </geometry>
            <material name="Cyan">
                <color rgba="0 1.0 1.0 1.0"/>
            </material>
        </visual>
        <collision>
            <origin xyz="-0.1918440061696871 0.1328047949220564 -0.01150162432930657" rpy="0 0 0"/>
            <geometry>
                <box size="0.5772731840561101 0.3573464654023235 0.02300324865861314" />
            </geometry>
        </collision>
    </link>
    <joint name="link0_link2" type="revolute">
       <parent link="link0"/>
       <child  link="link2"/>
       <origin rpy="0 0 0" xyz="-0.37320918564333094 -0.4316073352784158 1.0565570157904653" />
     <axis xyz="0 0 1"/>
       <limit effort="0.0" lower="-3.14159" upper="3.14159" velocity="0.0"/>
    </joint>
    <link name="link2">
        <inertial>
            <origin xyz="0.09862405527402786 -0.14372911856191542 0.4865418634260484" rpy="0 0 0"/>
            <mass value="1" />
            <inertia ixx="100" ixy="0" ixz="0" iyy="100" iyz="0" izz="100" />
        </inertial>
        <visual>
            <origin xyz="0.09862405527402786 -0.14372911856191542 0.4865418634260484" rpy="0 0 0"/>
            <geometry>
                <box size="0.5629573931929693 0.9183058352619917 0.9730837268520968" />
            </geometry>
            <material name="Cyan">
                <color rgba="0 1.0 1.0 1.0"/>
            </material>
        </visual>
        <collision>
            <origin xyz="0.09862405527402786 -0.14372911856191542 0.4865418634260484" rpy="0 0 0"/>
            <geometry>
                <box size="0.5629573931929693 0.9183058352619917 0.9730837268520968" />
            </geometry>
        </collision>
    </link>
    <joint name="link1_link3" type="revolute">
       <parent link="link1"/>
       <child  link="link3"/>
       <origin rpy="0 0 0" xyz="-0.0359129068801628 0.061676617645359894 0.0" />
     <axis xyz="0 0 1"/>
       <limit effort="0.0" lower="-3.14159" upper="3.14159" velocity="0.0"/>
    </joint>
    <link name="link3">
        <inertial>
            <origin xyz="-0.18679390629779158 -0.29558650665066033 0.4268480849677442" rpy="0 0 0"/>
            <mass value="1" />
            <inertia ixx="100" ixy="0" ixz="0" iyy="100" iyz="0" izz="100" />
        </inertial>
        <visual>
            <origin xyz="-0.18679390629779158 -0.29558650665066033 0.4268480849677442" rpy="0 0 0"/>
            <geometry>
                <box size="0.6763604253411182 0.6331197135306895 0.8536961699354884" />
            </geometry>
            <material name="Cyan">
                <color rgba="0 1.0 1.0 1.0"/>
            </material>
        </visual>
        <collision>
            <origin xyz="-0.18679390629779158 -0.29558650665066033 0.4268480849677442" rpy="0 0 0"/>
            <geometry>
                <box size="0.6763604253411182 0.6331197135306895 0.8536961699354884" />
            </geometry>
        </collision>
    </link>
    <joint name="link2_link4" type="revolute">
       <parent link="link2"/>
       <child  link="link4"/>
       <origin rpy="0 0 0" xyz="-0.08035295856870452 0.31542379906908047 0.14271396905714978" />
     <axis xyz="1 0 0"/>
       <limit effort="0.0" lower="-3.14159" upper="3.14159" velocity="0.0"/>
    </joint>
    <link name="link4">
        <inertial>
            <origin xyz="-0.24815747128824167 0.3056435534665806 0.07080284800122369" rpy="0 0 0"/>
            <mass value="1" />
            <inertia ixx="100" ixy="0" ixz="0" iyy="100" iyz="0" izz="100" />
        </inertial>
        <visual>
            <origin xyz="-0.24815747128824167 0.3056435534665806 0.07080284800122369" rpy="0 0 0"/>
            <geometry>
                <box size="0.7122961203250727 0.6112871069331612 0.2948416476052932" />
            </geometry>
            <material name="Cyan">
                <color rgba="0 1.0 1.0 1.0"/>
            </material>
        </visual>
        <collision>
            <origin xyz="-0.24815747128824167 0.3056435534665806 0.07080284800122369" rpy="0 0 0"/>
            <geometry>
                <box size="0.7122961203250727 0.6112871069331612 0.2948416476052932" />
            </geometry>
        </collision>
    </link>
</robot>