<robot name = "robot">
    <link name="link0">
        <inertial>
            <origin xyz="0 0 1" rpy="0 0 0"/>
            <mass value="1" />
            <inertia ixx="100" ixy="0" ixz="0" iyy="100" iyz="0" izz="100" />
        </inertial>
        <visual>
            <origin xyz="0 0 1" rpy="0 0 0"/>
            <geometry>
                <box size="0.7576791030884418 0.51541900130604 0.7420328813769957" />
            </geometry>
            <material name="Cyan">
                <color rgba="0.0 1.0 1.0 1.0"/>
            </material>
        </visual>
        <collision>
            <origin xyz="0 0 1" rpy="0 0 0"/>
            <geometry>
                <box size="0.7576791030884418 0.51541900130604 0.7420328813769957" />
            </geometry>
        </collision>
    </link>
    <joint name="link0_link1" type="revolute">
       <parent link="link0"/>
       <child  link="link1"/>
       <origin rpy="0 0 0" xyz="0.15104648602924972 -0.13760705525668962 1.371016440688498" />
     <axis xyz="0 0 1"/>
       <limit effort="0.0" lower="-3.14159" upper="3.14159" velocity="0.0"/>
    </joint>
    <link name="link1">
        <inertial>
            <origin xyz="0.03871723699174391 -0.007142488312152092 0.0595099537279386" rpy="0 0 0"/>
            <mass value="1" />
            <inertia ixx="100" ixy="0" ixz="0" iyy="100" iyz="0" izz="100" />
        </inertial>
        <visual>
            <origin xyz="0.03871723699174391 -0.007142488312152092 0.0595099537279386" rpy="0 0 0"/>
            <geometry>
                <box size="0.2707449968079908 0.07669248541465501 0.1190199074558772" />
            </geometry>
            <material name="Green">
                <color rgba="0.0 1.0 0.0 1.0"/>
            </material>
        </visual>
        <collision>
            <origin xyz="0.03871723699174391 -0.007142488312152092 0.0595099537279386" rpy="0 0 0"/>
            <geometry>
                <box size="0.2707449968079908 0.07669248541465501 0.1190199074558772" />
            </geometry>
        </collision>
    </link>
    <joint name="link1_link2" type="revolute">
       <parent link="link1"/>
       <child  link="link2"/>
       <origin rpy="0 0 0" xyz="0.1104339808174425 -0.03491485236311033 0.1190199074558772" />
     <axis xyz="0 1 0"/>
       <limit effort="0.0" lower="-3.14159" upper="3.14159" velocity="0.0"/>
    </joint>
    <link name="link2">
        <inertial>
            <origin xyz="0.034636194821484806 0.03903583650266724 0.2898445263392808" rpy="0 0 0"/>
            <mass value="1" />
            <inertia ixx="100" ixy="0" ixz="0" iyy="100" iyz="0" izz="100" />
        </inertial>
        <visual>
            <origin xyz="0.034636194821484806 0.03903583650266724 0.2898445263392808" rpy="0 0 0"/>
            <geometry>
                <box size="0.251556224267907 0.7680654143911025 0.5796890526785616" />
            </geometry>
            <material name="Green">
                <color rgba="0.0 1.0 0.0 1.0"/>
            </material>
        </visual>
        <collision>
            <origin xyz="0.034636194821484806 0.03903583650266724 0.2898445263392808" rpy="0 0 0"/>
            <geometry>
                <box size="0.251556224267907 0.7680654143911025 0.5796890526785616" />
            </geometry>
        </collision>
    </link>
    <joint name="link0_link3" type="revolute">
       <parent link="link0"/>
       <child  link="link3"/>
       <origin rpy="0 0 0" xyz="0.3788395515442209 -0.14218608037235111 0.8636659350791854" />
     <axis xyz="0 1 0"/>
       <limit effort="0.0" lower="-3.14159" upper="3.14159" velocity="0.0"/>
    </joint>
    <link name="link3">
        <inertial>
            <origin xyz="0.4274008671589508 -0.17068983650972885 -0.020502214671702847" rpy="0 0 0"/>
            <mass value="1" />
            <inertia ixx="100" ixy="0" ixz="0" iyy="100" iyz="0" izz="100" />
        </inertial>
        <visual>
            <origin xyz="0.4274008671589508 -0.17068983650972885 -0.020502214671702847" rpy="0 0 0"/>
            <geometry>
                <box size="0.8548017343179016 0.6828857784124124 0.6903991818749919" />
            </geometry>
            <material name="Green">
                <color rgba="0.0 1.0 0.0 1.0"/>
            </material>
        </visual>
        <collision>
            <origin xyz="0.4274008671589508 -0.17068983650972885 -0.020502214671702847" rpy="0 0 0"/>
            <geometry>
                <box size="0.8548017343179016 0.6828857784124124 0.6903991818749919" />
            </geometry>
        </collision>
    </link>
    <joint name="link1_link4" type="revolute">
       <parent link="link1"/>
       <child  link="link4"/>
       <origin rpy="0 0 0" xyz="0.1740897353957393 0.021918245238909548 0.047475452386456146" />
     <axis xyz="0 0 1"/>
       <limit effort="0.0" lower="-3.14159" upper="3.14159" velocity="0.0"/>
    </joint>
    <link name="link4">
        <inertial>
            <origin xyz="0.09006961882699499 -0.02926856022473132 0.3992830980387985" rpy="0 0 0"/>
            <mass value="1" />
            <inertia ixx="100" ixy="0" ixz="0" iyy="100" iyz="0" izz="100" />
        </inertial>
        <visual>
            <origin xyz="0.09006961882699499 -0.02926856022473132 0.3992830980387985" rpy="0 0 0"/>
            <geometry>
                <box size="0.18013923765398998 0.9770134146477043 0.8301729149768757" />
            </geometry>
            <material name="Green">
                <color rgba="0.0 1.0 0.0 1.0"/>
            </material>
        </visual>
        <collision>
            <origin xyz="0.09006961882699499 -0.02926856022473132 0.3992830980387985" rpy="0 0 0"/>
            <geometry>
                <box size="0.18013923765398998 0.9770134146477043 0.8301729149768757" />
            </geometry>
        </collision>
    </link>
</robot>