<robot name = "robot">
    <link name="link0">
        <inertial>
            <origin xyz="0 0 1" rpy="0 0 0"/>
            <mass value="1" />
            <inertia ixx="100" ixy="0" ixz="0" iyy="100" iyz="0" izz="100" />
        </inertial>
        <visual>
            <origin xyz="0 0 1" rpy="0 0 0"/>
            <geometry>
                <box size="0.35746930205612115 0.16009284964442771 0.0800072254736105" />
            </geometry>
            <material name="Cyan">
                <color rgba="0.0 1.0 1.0 1.0"/>
            </material>
        </visual>
        <collision>
            <origin xyz="0 0 1" rpy="0 0 0"/>
            <geometry>
                <box size="0.35746930205612115 0.16009284964442771 0.0800072254736105" />
            </geometry>
        </collision>
    </link>
    <joint name="link0_link1" type="revolute">
       <parent link="link0"/>
       <child  link="link1"/>
       <origin rpy="0 0 0" xyz="-0.17873465102806058 -0.054928458328185534 1.0228804892418015" />
     <axis xyz="1 0 0"/>
       <limit effort="0.0" lower="-3.14159" upper="3.14159" velocity="0.0"/>
    </joint>
    <link name="link1">
        <inertial>
            <origin xyz="-0.3205900447924308 0.2800991617190831 0.1784206954255158" rpy="0 0 0"/>
            <mass value="1" />
            <inertia ixx="100" ixy="0" ixz="0" iyy="100" iyz="0" izz="100" />
        </inertial>
        <visual>
            <origin xyz="-0.3205900447924308 0.2800991617190831 0.1784206954255158" rpy="0 0 0"/>
            <geometry>
                <box size="0.6411800895848616 0.917288851396797 0.36879322102644096" />
            </geometry>
            <material name="Green">
                <color rgba="0.0 1.0 0.0 1.0"/>
            </material>
        </visual>
        <collision>
            <origin xyz="-0.3205900447924308 0.2800991617190831 0.1784206954255158" rpy="0 0 0"/>
            <geometry>
                <box size="0.6411800895848616 0.917288851396797 0.36879322102644096" />
            </geometry>
        </collision>
    </link>
    <joint name="link0_link2" type="revolute">
       <parent link="link0"/>
       <child  link="link2"/>
       <origin rpy="0 0 0" xyz="0.10195807109209357 -0.028988733938912766 1.0400036127368053" />
     <axis xyz="1 0 0"/>
       <limit effort="0.0" lower="-3.14159" upper="3.14159" velocity="0.0"/>
    </joint>
    <link name="link2">
        <inertial>
            <origin xyz="0.004999869476042518 -0.3232942388797048 0.3468691356974163" rpy="0 0 0"/>
            <mass value="1" />
            <inertia ixx="100" ixy="0" ixz="0" iyy="100" iyz="0" izz="100" />
        </inertial>
        <visual>
            <origin xyz="0.004999869476042518 -0.3232942388797048 0.3468691356974163" rpy="0 0 0"/>
            <geometry>
                <box size="0.48975105141190267 0.7845074137991893 0.6937382713948326" />
            </geometry>
            <material name="Green">
                <color rgba="0.0 1.0 0.0 1.0"/>
            </material>
        </visual>
        <collision>
            <origin xyz="0.004999869476042518 -0.3232942388797048 0.3468691356974163" rpy="0 0 0"/>
            <geometry>
                <box size="0.48975105141190267 0.7845074137991893 0.6937382713948326" />
            </geometry>
        </collision>
    </link>
    <joint name="link1_link3" type="revolute">
       <parent link="link1"/>
       <child  link="link3"/>
       <origin rpy="0 0 0" xyz="-0.23024347886799165 0.32513418357554796 0.3628173059387363" />
     <axis xyz="1 0 0"/>
       <limit effort="0.0" lower="-3.14159" upper="3.14159" velocity="0.0"/>
    </joint>
    <link name="link3">
        <inertial>
            <origin xyz="0.33656892809444316 -0.3453634021261387 0.2620790306123393" rpy="0 0 0"/>
            <mass value="1" />
            <inertia ixx="100" ixy="0" ixz="0" iyy="100" iyz="0" izz="100" />
        </inertial>
        <visual>
            <origin xyz="0.33656892809444316 -0.3453634021261387 0.2620790306123393" rpy="0 0 0"/>
            <geometry>
                <box size="0.7748160573948026 0.8170105665084372 0.5241580612246786" />
            </geometry>
            <material name="Cyan">
                <color rgba="0.0 1.0 1.0 1.0"/>
            </material>
        </visual>
        <collision>
            <origin xyz="0.33656892809444316 -0.3453634021261387 0.2620790306123393" rpy="0 0 0"/>
            <geometry>
                <box size="0.7748160573948026 0.8170105665084372 0.5241580612246786" />
            </geometry>
        </collision>
    </link>
    <joint name="link2_link4" type="revolute">
       <parent link="link2"/>
       <child  link="link4"/>
       <origin rpy="0 0 0" xyz="-0.2398756562299088 -0.11139628821020572 0.5435310602215523" />
     <axis xyz="1 0 0"/>
       <limit effort="0.0" lower="-3.14159" upper="3.14159" velocity="0.0"/>
    </joint>
    <link name="link4">
        <inertial>
            <origin xyz="-0.06695988928086305 0.16820425031362857 0.12563261166638726" rpy="0 0 0"/>
            <mass value="1" />
            <inertia ixx="100" ixy="0" ixz="0" iyy="100" iyz="0" izz="100" />
        </inertial>
        <visual>
            <origin xyz="-0.06695988928086305 0.16820425031362857 0.12563261166638726" rpy="0 0 0"/>
            <geometry>
                <box size="0.1339197785617261 0.9496621651761361 0.8735320462574104" />
            </geometry>
            <material name="Cyan">
                <color rgba="0.0 1.0 1.0 1.0"/>
            </material>
        </visual>
        <collision>
            <origin xyz="-0.06695988928086305 0.16820425031362857 0.12563261166638726" rpy="0 0 0"/>
            <geometry>
                <box size="0.1339197785617261 0.9496621651761361 0.8735320462574104" />
            </geometry>
        </collision>
    </link>
</robot>