<robot name = "robot">
    <link name="link0">
        <inertial>
            <origin xyz="0 0 1" rpy="0 0 0"/>
            <mass value="1" />
            <inertia ixx="100" ixy="0" ixz="0" iyy="100" iyz="0" izz="100" />
        </inertial>
        <visual>
            <origin xyz="0 0 1" rpy="0 0 0"/>
            <geometry>
                <box size="0.4917055148257551 0.30368558694103953 0.002114798045396493" />
            </geometry>
            <material name="Cyan">
                <color rgba="0 1.0 1.0 1.0"/>
            </material>
        </visual>
        <collision>
            <origin xyz="0 0 1" rpy="0 0 0"/>
            <geometry>
                <box size="0.4917055148257551 0.30368558694103953 0.002114798045396493" />
            </geometry>
        </collision>
    </link>
    <joint name="link0_link1" type="revolute">
       <parent link="link0"/>
       <child  link="link1"/>
       <origin rpy="0 0 0" xyz="0.14956800432783915 0.15184279347051977 0.9995962239305958" />
     <axis xyz="0 0 1"/>
       <limit effort="0.0" lower="-3.14159" upper="3.14159" velocity="0.0"/>
    </joint>
    <link name="link1">
        <inertial>
            <origin xyz="-0.18724189169766375 0.3590630378744255 0.389427972940405" rpy="0 0 0"/>
            <mass value="1" />
            <inertia ixx="100" ixy="0" ixz="0" iyy="100" iyz="0" izz="100" />
        </inertial>
        <visual>
            <origin xyz="-0.18724189169766375 0.3590630378744255 0.389427972940405" rpy="0 0 0"/>
            <geometry>
                <box size="0.9876832135334361 0.718126075748851 0.9474044450012149" />
            </geometry>
            <material name="Cyan">
                <color rgba="0 1.0 1.0 1.0"/>
            </material>
        </visual>
        <collision>
            <origin xyz="-0.18724189169766375 0.3590630378744255 0.389427972940405" rpy="0 0 0"/>
            <geometry>
                <box size="0.9876832135334361 0.718126075748851 0.9474044450012149" />
            </geometry>
        </collision>
    </link>
    <joint name="link0_link2" type="revolute">
       <parent link="link0"/>
       <child  link="link2"/>
       <origin rpy="0 0 0" xyz="0.24585275741287754 0.05370211390506864 0.9994770554575473" />
     <axis xyz="0 0 1"/>
       <limit effort="0.0" lower="-3.14159" upper="3.14159" velocity="0.0"/>
    </joint>
    <link name="link2">
        <inertial>
            <origin xyz="0.1885181771500517 0.009004155811022005 0.1368290071620595" rpy="0 0 0"/>
            <mass value="1" />
            <inertia ixx="100" ixy="0" ixz="0" iyy="100" iyz="0" izz="100" />
        </inertial>
        <visual>
            <origin xyz="0.1885181771500517 0.009004155811022005 0.1368290071620595" rpy="0 0 0"/>
            <geometry>
                <box size="0.3770363543001034 0.21668774048913764 0.5772332915944702" />
            </geometry>
            <material name="Cyan">
                <color rgba="0 1.0 1.0 1.0"/>
            </material>
        </visual>
        <collision>
            <origin xyz="0.1885181771500517 0.009004155811022005 0.1368290071620595" rpy="0 0 0"/>
            <geometry>
                <box size="0.3770363543001034 0.21668774048913764 0.5772332915944702" />
            </geometry>
        </collision>
    </link>
    <joint name="link0_link3" type="revolute">
       <parent link="link0"/>
       <child  link="link3"/>
       <origin rpy="0 0 0" xyz="-0.025101064312428794 0.03584045341334794 1.0010573990226983" />
     <axis xyz="1 0 0"/>
       <limit effort="0.0" lower="-3.14159" upper="3.14159" velocity="0.0"/>
    </joint>
    <link name="link3">
        <inertial>
            <origin xyz="-0.15641621897447783 -0.134195550405549 0.008132616443853657" rpy="0 0 0"/>
            <mass value="1" />
            <inertia ixx="100" ixy="0" ixz="0" iyy="100" iyz="0" izz="100" />
        </inertial>
        <visual>
            <origin xyz="-0.15641621897447783 -0.134195550405549 0.008132616443853657" rpy="0 0 0"/>
            <geometry>
                <box size="0.8892687471293534 0.6499755450587895 0.016265232887707315" />
            </geometry>
            <material name="Cyan">
                <color rgba="0 1.0 1.0 1.0"/>
            </material>
        </visual>
        <collision>
            <origin xyz="-0.15641621897447783 -0.134195550405549 0.008132616443853657" rpy="0 0 0"/>
            <geometry>
                <box size="0.8892687471293534 0.6499755450587895 0.016265232887707315" />
            </geometry>
        </collision>
    </link>
    <joint name="link2_link4" type="revolute">
       <parent link="link2"/>
       <child  link="link4"/>
       <origin rpy="0 0 0" xyz="0.07472747692589479 0.07136706462865443 0.4254456529592946" />
     <axis xyz="0 1 0"/>
       <limit effort="0.0" lower="-3.14159" upper="3.14159" velocity="0.0"/>
    </joint>
    <link name="link4">
        <inertial>
            <origin xyz="-0.2390983942423961 -0.011138867344622874 0.2930942673816398" rpy="0 0 0"/>
            <mass value="1" />
            <inertia ixx="100" ixy="0" ixz="0" iyy="100" iyz="0" izz="100" />
        </inertial>
        <visual>
            <origin xyz="-0.2390983942423961 -0.011138867344622874 0.2930942673816398" rpy="0 0 0"/>
            <geometry>
                <box size="0.6261918836428536 0.05933006059974866 0.5861885347632796" />
            </geometry>
            <material name="Cyan">
                <color rgba="0 1.0 1.0 1.0"/>
            </material>
        </visual>
        <collision>
            <origin xyz="-0.2390983942423961 -0.011138867344622874 0.2930942673816398" rpy="0 0 0"/>
            <geometry>
                <box size="0.6261918836428536 0.05933006059974866 0.5861885347632796" />
            </geometry>
        </collision>
    </link>
    <joint name="link3_link5" type="revolute">
       <parent link="link3"/>
       <child  link="link5"/>
       <origin rpy="0 0 0" xyz="-0.15194258912473999 -0.4591833229349438 0.011091002804644302" />
     <axis xyz="0 1 0"/>
       <limit effort="0.0" lower="-3.14159" upper="3.14159" velocity="0.0"/>
    </joint>
    <link name="link5">
        <inertial>
            <origin xyz="-0.06678478497967759 -0.441754382683244 -0.14613314281459427" rpy="0 0 0"/>
            <mass value="1" />
            <inertia ixx="100" ixy="0" ixz="0" iyy="100" iyz="0" izz="100" />
        </inertial>
        <visual>
            <origin xyz="-0.06678478497967759 -0.441754382683244 -0.14613314281459427" rpy="0 0 0"/>
            <geometry>
                <box size="0.49504100851282495 0.883508765366488 0.6856360979154305" />
            </geometry>
            <material name="Cyan">
                <color rgba="0 1.0 1.0 1.0"/>
            </material>
        </visual>
        <collision>
            <origin xyz="-0.06678478497967759 -0.441754382683244 -0.14613314281459427" rpy="0 0 0"/>
            <geometry>
                <box size="0.49504100851282495 0.883508765366488 0.6856360979154305" />
            </geometry>
        </collision>
    </link>
    <joint name="link0_link6" type="revolute">
       <parent link="link0"/>
       <child  link="link6"/>
       <origin rpy="0 0 0" xyz="0.04884610733444328 0.05540519489469271 1.0010573990226983" />
     <axis xyz="0 0 1"/>
       <limit effort="0.0" lower="-3.14159" upper="3.14159" velocity="0.0"/>
    </joint>
    <link name="link6">
        <inertial>
            <origin xyz="0.18660075960269254 0.06896513484921055 0.27664829135964897" rpy="0 0 0"/>
            <mass value="1" />
            <inertia ixx="100" ixy="0" ixz="0" iyy="100" iyz="0" izz="100" />
        </inertial>
        <visual>
            <origin xyz="0.18660075960269254 0.06896513484921055 0.27664829135964897" rpy="0 0 0"/>
            <geometry>
                <box size="0.6995869051256768 0.7590136528084914 0.5532965827192979" />
            </geometry>
            <material name="Cyan">
                <color rgba="0 1.0 1.0 1.0"/>
            </material>
        </visual>
        <collision>
            <origin xyz="0.18660075960269254 0.06896513484921055 0.27664829135964897" rpy="0 0 0"/>
            <geometry>
                <box size="0.6995869051256768 0.7590136528084914 0.5532965827192979" />
            </geometry>
        </collision>
    </link>
</robot>