<robot name = "robot">
    <link name="link0">
        <inertial>
            <origin xyz="0 0 1" rpy="0 0 0"/>
            <mass value="1" />
            <inertia ixx="100" ixy="0" ixz="0" iyy="100" iyz="0" izz="100" />
        </inertial>
        <visual>
            <origin xyz="0 0 1" rpy="0 0 0"/>
            <geometry>
                <box size="0.4586847974148929 0.9077537583970104 0.38637882211706764" />
            </geometry>
            <material name="Cyan">
                <color rgba="0 1.0 1.0 1.0"/>
            </material>
        </visual>
        <collision>
            <origin xyz="0 0 1" rpy="0 0 0"/>
            <geometry>
                <box size="0.4586847974148929 0.9077537583970104 0.38637882211706764" />
            </geometry>
        </collision>
    </link>
    <joint name="link0_link1" type="revolute">
       <parent link="link0"/>
       <child  link="link1"/>
       <origin rpy="0 0 0" xyz="-0.16676068518628112 0.4538768791985052 1.174173255648607" />
     <axis xyz="0 0 1"/>
       <limit effort="0.0" lower="-3.14159" upper="3.14159" velocity="0.0"/>
    </joint>
    <link name="link1">
        <inertial>
            <origin xyz="0.15112532248392796 0.271461988184641 -0.13300545382090545" rpy="0 0 0"/>
            <mass value="1" />
            <inertia ixx="100" ixy="0" ixz="0" iyy="100" iyz="0" izz="100" />
        </inertial>
        <visual>
            <origin xyz="0.15112532248392796 0.271461988184641 -0.13300545382090545" rpy="0 0 0"/>
            <geometry>
                <box size="0.3491212613822351 0.542923976369282 0.3718072541435681" />
            </geometry>
            <material name="Cyan">
                <color rgba="0 1.0 1.0 1.0"/>
            </material>
        </visual>
        <collision>
            <origin xyz="0.15112532248392796 0.271461988184641 -0.13300545382090545" rpy="0 0 0"/>
            <geometry>
                <box size="0.3491212613822351 0.542923976369282 0.3718072541435681" />
            </geometry>
        </collision>
    </link>
</robot>