<robot name = "robot">
    <link name="link0">
        <inertial>
            <origin xyz="0 0 1" rpy="0 0 0"/>
            <mass value="1" />
            <inertia ixx="100" ixy="0" ixz="0" iyy="100" iyz="0" izz="100" />
        </inertial>
        <visual>
            <origin xyz="0 0 1" rpy="0 0 0"/>
            <geometry>
                <box size="0.8336672253912523 0.6067626408267592 0.9952964847580379" />
            </geometry>
            <material name="Cyan">
                <color rgba="0.0 1.0 1.0 1.0"/>
            </material>
        </visual>
        <collision>
            <origin xyz="0 0 1" rpy="0 0 0"/>
            <geometry>
                <box size="0.8336672253912523 0.6067626408267592 0.9952964847580379" />
            </geometry>
        </collision>
    </link>
    <joint name="link0_link1" type="revolute">
       <parent link="link0"/>
       <child  link="link1"/>
       <origin rpy="0 0 0" xyz="0.00527838451087653 -0.24980285672531063 1.497648242379019" />
     <axis xyz="0 0 1"/>
       <limit effort="0.0" lower="-3.14159" upper="3.14159" velocity="0.0"/>
    </joint>
    <link name="link1">
        <inertial>
            <origin xyz="-0.02491628244125713 0.00021051158603811588 0.15816480111018372" rpy="0 0 0"/>
            <mass value="1" />
            <inertia ixx="100" ixy="0" ixz="0" iyy="100" iyz="0" izz="100" />
        </inertial>
        <visual>
            <origin xyz="-0.02491628244125713 0.00021051158603811588 0.15816480111018372" rpy="0 0 0"/>
            <geometry>
                <box size="0.5436838827803773 0.004907348355757568 0.31632960222036743" />
            </geometry>
            <material name="Green">
                <color rgba="0.0 1.0 0.0 1.0"/>
            </material>
        </visual>
        <collision>
            <origin xyz="-0.02491628244125713 0.00021051158603811588 0.15816480111018372" rpy="0 0 0"/>
            <geometry>
                <box size="0.5436838827803773 0.004907348355757568 0.31632960222036743" />
            </geometry>
        </collision>
    </link>
    <joint name="link0_link2" type="revolute">
       <parent link="link0"/>
       <child  link="link2"/>
       <origin rpy="0 0 0" xyz="-0.41683361269562613 0.2836385828067518 0.6154789595444414" />
     <axis xyz="0 0 1"/>
       <limit effort="0.0" lower="-3.14159" upper="3.14159" velocity="0.0"/>
    </joint>
    <link name="link2">
        <inertial>
            <origin xyz="-0.26341290390830513 -0.35792924612861315 0.16113827977136766" rpy="0 0 0"/>
            <mass value="1" />
            <inertia ixx="100" ixy="0" ixz="0" iyy="100" iyz="0" izz="100" />
        </inertial>
        <visual>
            <origin xyz="-0.26341290390830513 -0.35792924612861315 0.16113827977136766" rpy="0 0 0"/>
            <geometry>
                <box size="0.5268258078166103 0.9006070304205483 0.47521315924200536" />
            </geometry>
            <material name="Green">
                <color rgba="0.0 1.0 0.0 1.0"/>
            </material>
        </visual>
        <collision>
            <origin xyz="-0.26341290390830513 -0.35792924612861315 0.16113827977136766" rpy="0 0 0"/>
            <geometry>
                <box size="0.5268258078166103 0.9006070304205483 0.47521315924200536" />
            </geometry>
        </collision>
    </link>
    <joint name="link2_link3" type="revolute">
       <parent link="link2"/>
       <child  link="link3"/>
       <origin rpy="0 0 0" xyz="-0.39443744759517685 -0.7396432920069167 0.39874485939237037" />
     <axis xyz="1 0 0"/>
       <limit effort="0.0" lower="-3.14159" upper="3.14159" velocity="0.0"/>
    </joint>
    <link name="link3">
        <inertial>
            <origin xyz="-0.2763652976333938 0.2868662952997454 0.10072222881808429" rpy="0 0 0"/>
            <mass value="1" />
            <inertia ixx="100" ixy="0" ixz="0" iyy="100" iyz="0" izz="100" />
        </inertial>
        <visual>
            <origin xyz="-0.2763652976333938 0.2868662952997454 0.10072222881808429" rpy="0 0 0"/>
            <geometry>
                <box size="0.6113770504209294 0.9107611977208874 0.20144445763616858" />
            </geometry>
            <material name="Green">
                <color rgba="0.0 1.0 0.0 1.0"/>
            </material>
        </visual>
        <collision>
            <origin xyz="-0.2763652976333938 0.2868662952997454 0.10072222881808429" rpy="0 0 0"/>
            <geometry>
                <box size="0.6113770504209294 0.9107611977208874 0.20144445763616858" />
            </geometry>
        </collision>
    </link>
    <joint name="link2_link4" type="revolute">
       <parent link="link2"/>
       <child  link="link4"/>
       <origin rpy="0 0 0" xyz="-0.5268258078166103 -0.7790920453967007 0.31308074019202237" />
     <axis xyz="0 1 0"/>
       <limit effort="0.0" lower="-3.14159" upper="3.14159" velocity="0.0"/>
    </joint>
    <link name="link4">
        <inertial>
            <origin xyz="-0.02231971069084826 -0.155280393388327 0.027097826438411583" rpy="0 0 0"/>
            <mass value="1" />
            <inertia ixx="100" ixy="0" ixz="0" iyy="100" iyz="0" izz="100" />
        </inertial>
        <visual>
            <origin xyz="-0.02231971069084826 -0.155280393388327 0.027097826438411583" rpy="0 0 0"/>
            <geometry>
                <box size="0.04463942138169652 0.5410475967293095 0.40976727948398073" />
            </geometry>
            <material name="Green">
                <color rgba="0.0 1.0 0.0 1.0"/>
            </material>
        </visual>
        <collision>
            <origin xyz="-0.02231971069084826 -0.155280393388327 0.027097826438411583" rpy="0 0 0"/>
            <geometry>
                <box size="0.04463942138169652 0.5410475967293095 0.40976727948398073" />
            </geometry>
        </collision>
    </link>
    <joint name="link4_link5" type="revolute">
       <parent link="link4"/>
       <child  link="link5"/>
       <origin rpy="0 0 0" xyz="-0.032847093652162394 -0.23788547125665505 0.23198146618040194" />
     <axis xyz="0 0 1"/>
       <limit effort="0.0" lower="-3.14159" upper="3.14159" velocity="0.0"/>
    </joint>
    <link name="link5">
        <inertial>
            <origin xyz="0.028899491689420083 0.07685832212709028 0.239529386456116" rpy="0 0 0"/>
            <mass value="1" />
            <inertia ixx="100" ixy="0" ixz="0" iyy="100" iyz="0" izz="100" />
        </inertial>
        <visual>
            <origin xyz="0.028899491689420083 0.07685832212709028 0.239529386456116" rpy="0 0 0"/>
            <geometry>
                <box size="0.42870184151152213 0.22133933880544776 0.479058772912232" />
            </geometry>
            <material name="Green">
                <color rgba="0.0 1.0 0.0 1.0"/>
            </material>
        </visual>
        <collision>
            <origin xyz="0.028899491689420083 0.07685832212709028 0.239529386456116" rpy="0 0 0"/>
            <geometry>
                <box size="0.42870184151152213 0.22133933880544776 0.479058772912232" />
            </geometry>
        </collision>
    </link>
    <joint name="link4_link6" type="revolute">
       <parent link="link4"/>
       <child  link="link6"/>
       <origin rpy="0 0 0" xyz="0.0 -0.022407250980949617 -0.024570555441136795" />
     <axis xyz="0 0 1"/>
       <limit effort="0.0" lower="-3.14159" upper="3.14159" velocity="0.0"/>
    </joint>
    <link name="link6">
        <inertial>
            <origin xyz="0.41721093423256755 -0.019847227083472144 -0.033498037805061394" rpy="0 0 0"/>
            <mass value="1" />
            <inertia ixx="100" ixy="0" ixz="0" iyy="100" iyz="0" izz="100" />
        </inertial>
        <visual>
            <origin xyz="0.41721093423256755 -0.019847227083472144 -0.033498037805061394" rpy="0 0 0"/>
            <geometry>
                <box size="0.8344218684651351 0.22062503134071654 0.6958017336388074" />
            </geometry>
            <material name="Green">
                <color rgba="0.0 1.0 0.0 1.0"/>
            </material>
        </visual>
        <collision>
            <origin xyz="0.41721093423256755 -0.019847227083472144 -0.033498037805061394" rpy="0 0 0"/>
            <geometry>
                <box size="0.8344218684651351 0.22062503134071654 0.6958017336388074" />
            </geometry>
        </collision>
    </link>
    <joint name="link0_link7" type="revolute">
       <parent link="link0"/>
       <child  link="link7"/>
       <origin rpy="0 0 0" xyz="-0.41683361269562613 0.01654218738476406 1.1673762336519002" />
     <axis xyz="0 0 1"/>
       <limit effort="0.0" lower="-3.14159" upper="3.14159" velocity="0.0"/>
    </joint>
    <link name="link7">
        <inertial>
            <origin xyz="-0.00681920792468127 -0.04457041549554337 -0.23790714437612084" rpy="0 0 0"/>
            <mass value="1" />
            <inertia ixx="100" ixy="0" ixz="0" iyy="100" iyz="0" izz="100" />
        </inertial>
        <visual>
            <origin xyz="-0.00681920792468127 -0.04457041549554337 -0.23790714437612084" rpy="0 0 0"/>
            <geometry>
                <box size="0.01363841584936254 0.09280547442355125 0.6035147736556117" />
            </geometry>
            <material name="Green">
                <color rgba="0.0 1.0 0.0 1.0"/>
            </material>
        </visual>
        <collision>
            <origin xyz="-0.00681920792468127 -0.04457041549554337 -0.23790714437612084" rpy="0 0 0"/>
            <geometry>
                <box size="0.01363841584936254 0.09280547442355125 0.6035147736556117" />
            </geometry>
        </collision>
    </link>
    <joint name="link6_link8" type="revolute">
       <parent link="link6"/>
       <child  link="link8"/>
       <origin rpy="0 0 0" xyz="0.0 0.0005339458182189241 -0.15435313987338986" />
     <axis xyz="0 1 0"/>
       <limit effort="0.0" lower="-3.14159" upper="3.14159" velocity="0.0"/>
    </joint>
    <link name="link8">
        <inertial>
            <origin xyz="-0.2995412832106196 0.1253254632785665 -0.36678068049526236" rpy="0 0 0"/>
            <mass value="1" />
            <inertia ixx="100" ixy="0" ixz="0" iyy="100" iyz="0" izz="100" />
        </inertial>
        <visual>
            <origin xyz="-0.2995412832106196 0.1253254632785665 -0.36678068049526236" rpy="0 0 0"/>
            <geometry>
                <box size="0.5990825664212392 0.8763508532684149 0.7934075694161365" />
            </geometry>
            <material name="Green">
                <color rgba="0.0 1.0 0.0 1.0"/>
            </material>
        </visual>
        <collision>
            <origin xyz="-0.2995412832106196 0.1253254632785665 -0.36678068049526236" rpy="0 0 0"/>
            <geometry>
                <box size="0.5990825664212392 0.8763508532684149 0.7934075694161365" />
            </geometry>
        </collision>
    </link>
    <joint name="link3_link9" type="revolute">
       <parent link="link3"/>
       <child  link="link9"/>
       <origin rpy="0 0 0" xyz="-0.3177408843324925 -0.1685143035606983 0.06048540409804855" />
     <axis xyz="0 1 0"/>
       <limit effort="0.0" lower="-3.14159" upper="3.14159" velocity="0.0"/>
    </joint>
    <link name="link9">
        <inertial>
            <origin xyz="-0.0037591671994607278 -0.3674771989364855 -0.2581080444730476" rpy="0 0 0"/>
            <mass value="1" />
            <inertia ixx="100" ixy="0" ixz="0" iyy="100" iyz="0" izz="100" />
        </inertial>
        <visual>
            <origin xyz="-0.0037591671994607278 -0.3674771989364855 -0.2581080444730476" rpy="0 0 0"/>
            <geometry>
                <box size="0.3340928525806198 0.734954397872971 0.5256941467605579" />
            </geometry>
            <material name="Cyan">
                <color rgba="0.0 1.0 1.0 1.0"/>
            </material>
        </visual>
        <collision>
            <origin xyz="-0.0037591671994607278 -0.3674771989364855 -0.2581080444730476" rpy="0 0 0"/>
            <geometry>
                <box size="0.3340928525806198 0.734954397872971 0.5256941467605579" />
            </geometry>
        </collision>
    </link>
</robot>