<robot name = "robot">
    <link name="link0">
        <inertial>
            <origin xyz="0 0 1" rpy="0 0 0"/>
            <mass value="1" />
            <inertia ixx="100" ixy="0" ixz="0" iyy="100" iyz="0" izz="100" />
        </inertial>
        <visual>
            <origin xyz="0 0 1" rpy="0 0 0"/>
            <geometry>
                <box size="0.997735621442384 0.9313112150900431 0.6104456976121393" />
            </geometry>
            <material name="Cyan">
                <color rgba="0.0 1.0 1.0 1.0"/>
            </material>
        </visual>
        <collision>
            <origin xyz="0 0 1" rpy="0 0 0"/>
            <geometry>
                <box size="0.997735621442384 0.9313112150900431 0.6104456976121393" />
            </geometry>
        </collision>
    </link>
    <joint name="link0_link1" type="revolute">
       <parent link="link0"/>
       <child  link="link1"/>
       <origin rpy="0 0 0" xyz="-0.19568194607790948 0.46565560754502155 1.0948181134532546" />
     <axis xyz="0 0 1"/>
       <limit effort="0.0" lower="-3.14159" upper="3.14159" velocity="0.0"/>
    </joint>
    <link name="link1">
        <inertial>
            <origin xyz="-0.07624397618938944 0.1167435102639171 0.10691663558019102" rpy="0 0 0"/>
            <mass value="1" />
            <inertia ixx="100" ixy="0" ixz="0" iyy="100" iyz="0" izz="100" />
        </inertial>
        <visual>
            <origin xyz="-0.07624397618938944 0.1167435102639171 0.10691663558019102" rpy="0 0 0"/>
            <geometry>
                <box size="0.8030856291382451 0.2334870205278342 0.28264303360557685" />
            </geometry>
            <material name="Green">
                <color rgba="0.0 1.0 0.0 1.0"/>
            </material>
        </visual>
        <collision>
            <origin xyz="-0.07624397618938944 0.1167435102639171 0.10691663558019102" rpy="0 0 0"/>
            <geometry>
                <box size="0.8030856291382451 0.2334870205278342 0.28264303360557685" />
            </geometry>
        </collision>
    </link>
    <joint name="link0_link2" type="revolute">
       <parent link="link0"/>
       <child  link="link2"/>
       <origin rpy="0 0 0" xyz="0.22905726233068985 0.46565560754502155 1.122508112884946" />
     <axis xyz="1 0 0"/>
       <limit effort="0.0" lower="-3.14159" upper="3.14159" velocity="0.0"/>
    </joint>
    <link name="link2">
        <inertial>
            <origin xyz="0.05549960036489268 0.2018025707900722 0.19176641147143994" rpy="0 0 0"/>
            <mass value="1" />
            <inertia ixx="100" ixy="0" ixz="0" iyy="100" iyz="0" izz="100" />
        </inertial>
        <visual>
            <origin xyz="0.05549960036489268 0.2018025707900722 0.19176641147143994" rpy="0 0 0"/>
            <geometry>
                <box size="0.8912707048890517 0.4036051415801444 0.8653614127280758" />
            </geometry>
            <material name="Green">
                <color rgba="0.0 1.0 0.0 1.0"/>
            </material>
        </visual>
        <collision>
            <origin xyz="0.05549960036489268 0.2018025707900722 0.19176641147143994" rpy="0 0 0"/>
            <geometry>
                <box size="0.8912707048890517 0.4036051415801444 0.8653614127280758" />
            </geometry>
        </collision>
    </link>
    <joint name="link1_link3" type="revolute">
       <parent link="link1"/>
       <child  link="link3"/>
       <origin rpy="0 0 0" xyz="-0.477786790758512 0.03343785404897688 0.0780415397989157" />
     <axis xyz="1 0 0"/>
       <limit effort="0.0" lower="-3.14159" upper="3.14159" velocity="0.0"/>
    </joint>
    <link name="link3">
        <inertial>
            <origin xyz="-0.3311911109162224 0.03160238706926989 -0.04029240988085996" rpy="0 0 0"/>
            <mass value="1" />
            <inertia ixx="100" ixy="0" ixz="0" iyy="100" iyz="0" izz="100" />
        </inertial>
        <visual>
            <origin xyz="-0.3311911109162224 0.03160238706926989 -0.04029240988085996" rpy="0 0 0"/>
            <geometry>
                <box size="0.6623822218324448 0.09261223403582541 0.1316827885020162" />
            </geometry>
            <material name="Cyan">
                <color rgba="0.0 1.0 1.0 1.0"/>
            </material>
        </visual>
        <collision>
            <origin xyz="-0.3311911109162224 0.03160238706926989 -0.04029240988085996" rpy="0 0 0"/>
            <geometry>
                <box size="0.6623822218324448 0.09261223403582541 0.1316827885020162" />
            </geometry>
        </collision>
    </link>
    <joint name="link0_link4" type="revolute">
       <parent link="link0"/>
       <child  link="link4"/>
       <origin rpy="0 0 0" xyz="0.498867810721192 -0.029308254993136315 1.153280862209518" />
     <axis xyz="0 0 1"/>
       <limit effort="0.0" lower="-3.14159" upper="3.14159" velocity="0.0"/>
    </joint>
    <link name="link4">
        <inertial>
            <origin xyz="0.32194671980656225 -0.17684486218713424 0.011715352133360168" rpy="0 0 0"/>
            <mass value="1" />
            <inertia ixx="100" ixy="0" ixz="0" iyy="100" iyz="0" izz="100" />
        </inertial>
        <visual>
            <origin xyz="0.32194671980656225 -0.17684486218713424 0.011715352133360168" rpy="0 0 0"/>
            <geometry>
                <box size="0.6438934396131245 0.44469119446356264 0.9874574468640712" />
            </geometry>
            <material name="Green">
                <color rgba="0.0 1.0 0.0 1.0"/>
            </material>
        </visual>
        <collision>
            <origin xyz="0.32194671980656225 -0.17684486218713424 0.011715352133360168" rpy="0 0 0"/>
            <geometry>
                <box size="0.6438934396131245 0.44469119446356264 0.9874574468640712" />
            </geometry>
        </collision>
    </link>
    <joint name="link2_link5" type="revolute">
       <parent link="link2"/>
       <child  link="link5"/>
       <origin rpy="0 0 0" xyz="-0.3086664520921556 0.0 0.04161133085735694" />
     <axis xyz="0 1 0"/>
       <limit effort="0.0" lower="-3.14159" upper="3.14159" velocity="0.0"/>
    </joint>
    <link name="link5">
        <inertial>
            <origin xyz="0.08352854849378691 -0.038205553975352635 0.025472890444803872" rpy="0 0 0"/>
            <mass value="1" />
            <inertia ixx="100" ixy="0" ixz="0" iyy="100" iyz="0" izz="100" />
        </inertial>
        <visual>
            <origin xyz="0.08352854849378691 -0.038205553975352635 0.025472890444803872" rpy="0 0 0"/>
            <geometry>
                <box size="0.3109255124226262 0.07641110795070527 0.7852580447459662" />
            </geometry>
            <material name="Green">
                <color rgba="0.0 1.0 0.0 1.0"/>
            </material>
        </visual>
        <collision>
            <origin xyz="0.08352854849378691 -0.038205553975352635 0.025472890444803872" rpy="0 0 0"/>
            <geometry>
                <box size="0.3109255124226262 0.07641110795070527 0.7852580447459662" />
            </geometry>
        </collision>
    </link>
    <joint name="link1_link6" type="revolute">
       <parent link="link1"/>
       <child  link="link6"/>
       <origin rpy="0 0 0" xyz="-0.009313580732758842 0.08974257604929435 0.24823815238297944" />
     <axis xyz="0 0 1"/>
       <limit effort="0.0" lower="-3.14159" upper="3.14159" velocity="0.0"/>
    </joint>
    <link name="link6">
        <inertial>
            <origin xyz="0.1875480912143373 0.21294718706193236 0.25829839151558726" rpy="0 0 0"/>
            <mass value="1" />
            <inertia ixx="100" ixy="0" ixz="0" iyy="100" iyz="0" izz="100" />
        </inertial>
        <visual>
            <origin xyz="0.1875480912143373 0.21294718706193236 0.25829839151558726" rpy="0 0 0"/>
            <geometry>
                <box size="0.48045931298490063 0.5291391657105635 0.5165967830311745" />
            </geometry>
            <material name="Cyan">
                <color rgba="0.0 1.0 1.0 1.0"/>
            </material>
        </visual>
        <collision>
            <origin xyz="0.1875480912143373 0.21294718706193236 0.25829839151558726" rpy="0 0 0"/>
            <geometry>
                <box size="0.48045931298490063 0.5291391657105635 0.5165967830311745" />
            </geometry>
        </collision>
    </link>
</robot>