<robot name = "robot">
    <link name="link0">
        <inertial>
            <origin xyz="0 0 1" rpy="0 0 0"/>
            <mass value="1" />
            <inertia ixx="100" ixy="0" ixz="0" iyy="100" iyz="0" izz="100" />
        </inertial>
        <visual>
            <origin xyz="0 0 1" rpy="0 0 0"/>
            <geometry>
                <box size="0.5826828134840569 0.16360645839245924 0.20521097744104477" />
            </geometry>
            <material name="Cyan">
                <color rgba="0.0 1.0 1.0 1.0"/>
            </material>
        </visual>
        <collision>
            <origin xyz="0 0 1" rpy="0 0 0"/>
            <geometry>
                <box size="0.5826828134840569 0.16360645839245924 0.20521097744104477" />
            </geometry>
        </collision>
    </link>
    <joint name="link0_link1" type="revolute">
       <parent link="link0"/>
       <child  link="link1"/>
       <origin rpy="0 0 0" xyz="0.005751244157290551 0.0332018067716085 1.1026054887205223" />
     <axis xyz="0 0 1"/>
       <limit effort="0.0" lower="-3.14159" upper="3.14159" velocity="0.0"/>
    </joint>
    <link name="link1">
        <inertial>
            <origin xyz="-0.05262960100447312 0.0627111368429924 0.3902992755829147" rpy="0 0 0"/>
            <mass value="1" />
            <inertia ixx="100" ixy="0" ixz="0" iyy="100" iyz="0" izz="100" />
        </inertial>
        <visual>
            <origin xyz="-0.05262960100447312 0.0627111368429924 0.3902992755829147" rpy="0 0 0"/>
            <geometry>
                <box size="0.32438609575914357 0.6825867191631934 0.7805985511658294" />
            </geometry>
            <material name="Green">
                <color rgba="0.0 1.0 0.0 1.0"/>
            </material>
        </visual>
        <collision>
            <origin xyz="-0.05262960100447312 0.0627111368429924 0.3902992755829147" rpy="0 0 0"/>
            <geometry>
                <box size="0.32438609575914357 0.6825867191631934 0.7805985511658294" />
            </geometry>
        </collision>
    </link>
    <joint name="link1_link2" type="revolute">
       <parent link="link1"/>
       <child  link="link2"/>
       <origin rpy="0 0 0" xyz="0.06102831934443701 -0.2785822227386043 0.2113495870434411" />
     <axis xyz="0 1 0"/>
       <limit effort="0.0" lower="-3.14159" upper="3.14159" velocity="0.0"/>
    </joint>
    <link name="link2">
        <inertial>
            <origin xyz="0.24865219135681393 -0.10028473206527078 -0.048826254066601585" rpy="0 0 0"/>
            <mass value="1" />
            <inertia ixx="100" ixy="0" ixz="0" iyy="100" iyz="0" izz="100" />
        </inertial>
        <visual>
            <origin xyz="0.24865219135681393 -0.10028473206527078 -0.048826254066601585" rpy="0 0 0"/>
            <geometry>
                <box size="0.676887112838086 0.20056946413054155 0.15316424502443537" />
            </geometry>
            <material name="Green">
                <color rgba="0.0 1.0 0.0 1.0"/>
            </material>
        </visual>
        <collision>
            <origin xyz="0.24865219135681393 -0.10028473206527078 -0.048826254066601585" rpy="0 0 0"/>
            <geometry>
                <box size="0.676887112838086 0.20056946413054155 0.15316424502443537" />
            </geometry>
        </collision>
    </link>
</robot>