<robot name = "robot">
    <link name="link0">
        <inertial>
            <origin xyz="0 0 1" rpy="0 0 0"/>
            <mass value="1" />
            <inertia ixx="100" ixy="0" ixz="0" iyy="100" iyz="0" izz="100" />
        </inertial>
        <visual>
            <origin xyz="0 0 1" rpy="0 0 0"/>
            <geometry>
                <box size="0.49590504390158474 0.011848596450181548 0.6522941841529276" />
            </geometry>
            <material name="Cyan">
                <color rgba="0.0 1.0 1.0 1.0"/>
            </material>
        </visual>
        <collision>
            <origin xyz="0 0 1" rpy="0 0 0"/>
            <geometry>
                <box size="0.49590504390158474 0.011848596450181548 0.6522941841529276" />
            </geometry>
        </collision>
    </link>
    <joint name="link0_link1" type="revolute">
       <parent link="link0"/>
       <child  link="link1"/>
       <origin rpy="0 0 0" xyz="0.19772581075245488 -0.0029188214153984143 1.3261470920764638" />
     <axis xyz="0 0 1"/>
       <limit effort="0.0" lower="-3.14159" upper="3.14159" velocity="0.0"/>
    </joint>
    <link name="link1">
        <inertial>
            <origin xyz="-0.14425061809479722 0.16934940131783177 0.17073361554425842" rpy="0 0 0"/>
            <mass value="1" />
            <inertia ixx="100" ixy="0" ixz="0" iyy="100" iyz="0" izz="100" />
        </inertial>
        <visual>
            <origin xyz="-0.14425061809479722 0.16934940131783177 0.17073361554425842" rpy="0 0 0"/>
            <geometry>
                <box size="0.6898356209423643 0.48156169840561713 0.34146723108851684" />
            </geometry>
            <material name="Cyan">
                <color rgba="0.0 1.0 1.0 1.0"/>
            </material>
        </visual>
        <collision>
            <origin xyz="-0.14425061809479722 0.16934940131783177 0.17073361554425842" rpy="0 0 0"/>
            <geometry>
                <box size="0.6898356209423643 0.48156169840561713 0.34146723108851684" />
            </geometry>
        </collision>
    </link>
    <joint name="link1_link2" type="revolute">
       <parent link="link1"/>
       <child  link="link2"/>
       <origin rpy="0 0 0" xyz="0.20066719237638492 -0.05914575558546953 0.005829831252075174" />
     <axis xyz="1 0 0"/>
       <limit effort="0.0" lower="-3.14159" upper="3.14159" velocity="0.0"/>
    </joint>
    <link name="link2">
        <inertial>
            <origin xyz="0.20180089125421857 0.00819967256738606 -0.09261892672843788" rpy="0 0 0"/>
            <mass value="1" />
            <inertia ixx="100" ixy="0" ixz="0" iyy="100" iyz="0" izz="100" />
        </inertial>
        <visual>
            <origin xyz="0.20180089125421857 0.00819967256738606 -0.09261892672843788" rpy="0 0 0"/>
            <geometry>
                <box size="0.40360178250843715 0.4691984440569601 0.28828887331711317" />
            </geometry>
            <material name="Green">
                <color rgba="0.0 1.0 0.0 1.0"/>
            </material>
        </visual>
        <collision>
            <origin xyz="0.20180089125421857 0.00819967256738606 -0.09261892672843788" rpy="0 0 0"/>
            <geometry>
                <box size="0.40360178250843715 0.4691984440569601 0.28828887331711317" />
            </geometry>
        </collision>
    </link>
    <joint name="link2_link3" type="revolute">
       <parent link="link2"/>
       <child  link="link3"/>
       <origin rpy="0 0 0" xyz="0.0 0.10612242742762674 0.026616199080061742" />
     <axis xyz="1 0 0"/>
       <limit effort="0.0" lower="-3.14159" upper="3.14159" velocity="0.0"/>
    </joint>
    <link name="link3">
        <inertial>
            <origin xyz="-0.012439674388488087 0.15670810855060957 -0.2704806838802595" rpy="0 0 0"/>
            <mass value="1" />
            <inertia ixx="100" ixy="0" ixz="0" iyy="100" iyz="0" izz="100" />
        </inertial>
        <visual>
            <origin xyz="-0.012439674388488087 0.15670810855060957 -0.2704806838802595" rpy="0 0 0"/>
            <geometry>
                <box size="0.024879348776976173 0.32315889180839585 0.757388630658332" />
            </geometry>
            <material name="Green">
                <color rgba="0.0 1.0 0.0 1.0"/>
            </material>
        </visual>
        <collision>
            <origin xyz="-0.012439674388488087 0.15670810855060957 -0.2704806838802595" rpy="0 0 0"/>
            <geometry>
                <box size="0.024879348776976173 0.32315889180839585 0.757388630658332" />
            </geometry>
        </collision>
    </link>
    <joint name="link0_link4" type="revolute">
       <parent link="link0"/>
       <child  link="link4"/>
       <origin rpy="0 0 0" xyz="-0.17913787601439368 0.005908700666748287 1.3261470920764638" />
     <axis xyz="0 0 1"/>
       <limit effort="0.0" lower="-3.14159" upper="3.14159" velocity="0.0"/>
    </joint>
    <link name="link4">
        <inertial>
            <origin xyz="0.053665781193107796 -0.004132827002435349 0.038814627793389234" rpy="0 0 0"/>
            <mass value="1" />
            <inertia ixx="100" ixy="0" ixz="0" iyy="100" iyz="0" izz="100" />
        </inertial>
        <visual>
            <origin xyz="0.053665781193107796 -0.004132827002435349 0.038814627793389234" rpy="0 0 0"/>
            <geometry>
                <box size="0.14027902855815588 0.05179672403411173 0.07762925558677847" />
            </geometry>
            <material name="Green">
                <color rgba="0.0 1.0 0.0 1.0"/>
            </material>
        </visual>
        <collision>
            <origin xyz="0.053665781193107796 -0.004132827002435349 0.038814627793389234" rpy="0 0 0"/>
            <geometry>
                <box size="0.14027902855815588 0.05179672403411173 0.07762925558677847" />
            </geometry>
        </collision>
    </link>
    <joint name="link0_link5" type="revolute">
       <parent link="link0"/>
       <child  link="link5"/>
       <origin rpy="0 0 0" xyz="0.04525425220296083 0.005924298225090774 1.0298545904662255" />
     <axis xyz="0 0 1"/>
       <limit effort="0.0" lower="-3.14159" upper="3.14159" velocity="0.0"/>
    </joint>
    <link name="link5">
        <inertial>
            <origin xyz="-0.2206437620404273 0.08393876663427707 -0.3907623216204864" rpy="0 0 0"/>
            <mass value="1" />
            <inertia ixx="100" ixy="0" ixz="0" iyy="100" iyz="0" izz="100" />
        </inertial>
        <visual>
            <origin xyz="-0.2206437620404273 0.08393876663427707 -0.3907623216204864" rpy="0 0 0"/>
            <geometry>
                <box size="0.894159363501018 0.16787753326855415 0.9153249680071144" />
            </geometry>
            <material name="Green">
                <color rgba="0.0 1.0 0.0 1.0"/>
            </material>
        </visual>
        <collision>
            <origin xyz="-0.2206437620404273 0.08393876663427707 -0.3907623216204864" rpy="0 0 0"/>
            <geometry>
                <box size="0.894159363501018 0.16787753326855415 0.9153249680071144" />
            </geometry>
        </collision>
    </link>
    <joint name="link5_link6" type="revolute">
       <parent link="link5"/>
       <child  link="link6"/>
       <origin rpy="0 0 0" xyz="-0.6677234437909363 0.09755367732452387 -0.15790472635369054" />
     <axis xyz="0 0 1"/>
       <limit effort="0.0" lower="-3.14159" upper="3.14159" velocity="0.0"/>
    </joint>
    <link name="link6">
        <inertial>
            <origin xyz="-0.2736835750976422 -0.39734632282947085 -0.15638983247027893" rpy="0 0 0"/>
            <mass value="1" />
            <inertia ixx="100" ixy="0" ixz="0" iyy="100" iyz="0" izz="100" />
        </inertial>
        <visual>
            <origin xyz="-0.2736835750976422 -0.39734632282947085 -0.15638983247027893" rpy="0 0 0"/>
            <geometry>
                <box size="0.5473671501952844 0.9641815728884039 0.5612712603574369" />
            </geometry>
            <material name="Green">
                <color rgba="0.0 1.0 0.0 1.0"/>
            </material>
        </visual>
        <collision>
            <origin xyz="-0.2736835750976422 -0.39734632282947085 -0.15638983247027893" rpy="0 0 0"/>
            <geometry>
                <box size="0.5473671501952844 0.9641815728884039 0.5612712603574369" />
            </geometry>
        </collision>
    </link>
    <joint name="link0_link7" type="revolute">
       <parent link="link0"/>
       <child  link="link7"/>
       <origin rpy="0 0 0" xyz="-0.15554083274695396 0.0054785128596495335 1.3261470920764638" />
     <axis xyz="1 0 0"/>
       <limit effort="0.0" lower="-3.14159" upper="3.14159" velocity="0.0"/>
    </joint>
    <link name="link7">
        <inertial>
            <origin xyz="0.064879630823923 -0.03068382767664323 0.19926322309540279" rpy="0 0 0"/>
            <mass value="1" />
            <inertia ixx="100" ixy="0" ixz="0" iyy="100" iyz="0" izz="100" />
        </inertial>
        <visual>
            <origin xyz="0.064879630823923 -0.03068382767664323 0.19926322309540279" rpy="0 0 0"/>
            <geometry>
                <box size="0.2174242157236973 0.07774800160646222 0.39852644619080557" />
            </geometry>
            <material name="Green">
                <color rgba="0.0 1.0 0.0 1.0"/>
            </material>
        </visual>
        <collision>
            <origin xyz="0.064879630823923 -0.03068382767664323 0.19926322309540279" rpy="0 0 0"/>
            <geometry>
                <box size="0.2174242157236973 0.07774800160646222 0.39852644619080557" />
            </geometry>
        </collision>
    </link>
    <joint name="link1_link8" type="revolute">
       <parent link="link1"/>
       <child  link="link8"/>
       <origin rpy="0 0 0" xyz="-0.121847872682788 0.41013025052064034 0.27487196683502496" />
     <axis xyz="0 1 0"/>
       <limit effort="0.0" lower="-3.14159" upper="3.14159" velocity="0.0"/>
    </joint>
    <link name="link8">
        <inertial>
            <origin xyz="-0.034656833450055984 0.484460046457226 -0.09878430998388495" rpy="0 0 0"/>
            <mass value="1" />
            <inertia ixx="100" ixy="0" ixz="0" iyy="100" iyz="0" izz="100" />
        </inertial>
        <visual>
            <origin xyz="-0.034656833450055984 0.484460046457226 -0.09878430998388495" rpy="0 0 0"/>
            <geometry>
                <box size="0.43158733228692625 0.968920092914452 0.4886636704032322" />
            </geometry>
            <material name="Green">
                <color rgba="0.0 1.0 0.0 1.0"/>
            </material>
        </visual>
        <collision>
            <origin xyz="-0.034656833450055984 0.484460046457226 -0.09878430998388495" rpy="0 0 0"/>
            <geometry>
                <box size="0.43158733228692625 0.968920092914452 0.4886636704032322" />
            </geometry>
        </collision>
    </link>
</robot>