<robot name = "robot">
    <link name="link0">
        <inertial>
            <origin xyz="0 0 1" rpy="0 0 0"/>
            <mass value="1" />
            <inertia ixx="100" ixy="0" ixz="0" iyy="100" iyz="0" izz="100" />
        </inertial>
        <visual>
            <origin xyz="0 0 1" rpy="0 0 0"/>
            <geometry>
                <box size="0.40010367715249073 0.47547297946962075 0.22528571408376652" />
            </geometry>
            <material name="Cyan">
                <color rgba="0.0 1.0 1.0 1.0"/>
            </material>
        </visual>
        <collision>
            <origin xyz="0 0 1" rpy="0 0 0"/>
            <geometry>
                <box size="0.40010367715249073 0.47547297946962075 0.22528571408376652" />
            </geometry>
        </collision>
    </link>
    <joint name="link0_link1" type="revolute">
       <parent link="link0"/>
       <child  link="link1"/>
       <origin rpy="0 0 0" xyz="-0.02886066869208034 -0.23773648973481037 0.9690734744960527" />
     <axis xyz="0 1 0"/>
       <limit effort="0.0" lower="-3.14159" upper="3.14159" velocity="0.0"/>
    </joint>
    <link name="link1">
        <inertial>
            <origin xyz="-0.01739148282586282 -0.35990763754496824 0.005957804366138806" rpy="0 0 0"/>
            <mass value="1" />
            <inertia ixx="100" ixy="0" ixz="0" iyy="100" iyz="0" izz="100" />
        </inertial>
        <visual>
            <origin xyz="-0.01739148282586282 -0.35990763754496824 0.005957804366138806" rpy="0 0 0"/>
            <geometry>
                <box size="0.0707286767288603 0.7198152750899365 0.675079145305633" />
            </geometry>
            <material name="Green">
                <color rgba="0.0 1.0 0.0 1.0"/>
            </material>
        </visual>
        <collision>
            <origin xyz="-0.01739148282586282 -0.35990763754496824 0.005957804366138806" rpy="0 0 0"/>
            <geometry>
                <box size="0.0707286767288603 0.7198152750899365 0.675079145305633" />
            </geometry>
        </collision>
    </link>
    <joint name="link0_link2" type="revolute">
       <parent link="link0"/>
       <child  link="link2"/>
       <origin rpy="0 0 0" xyz="-0.11020368764054563 0.23773648973481037 0.9123312822285659" />
     <axis xyz="0 0 1"/>
       <limit effort="0.0" lower="-3.14159" upper="3.14159" velocity="0.0"/>
    </joint>
    <link name="link2">
        <inertial>
            <origin xyz="0.35139012631831057 0.031033916638159187 -0.06869280909098444" rpy="0 0 0"/>
            <mass value="1" />
            <inertia ixx="100" ixy="0" ixz="0" iyy="100" iyz="0" izz="100" />
        </inertial>
        <visual>
            <origin xyz="0.35139012631831057 0.031033916638159187 -0.06869280909098444" rpy="0 0 0"/>
            <geometry>
                <box size="0.8184332045155615 0.062067833276318374 0.6069298033518311" />
            </geometry>
            <material name="Green">
                <color rgba="0.0 1.0 0.0 1.0"/>
            </material>
        </visual>
        <collision>
            <origin xyz="0.35139012631831057 0.031033916638159187 -0.06869280909098444" rpy="0 0 0"/>
            <geometry>
                <box size="0.8184332045155615 0.062067833276318374 0.6069298033518311" />
            </geometry>
        </collision>
    </link>
    <joint name="link1_link3" type="revolute">
       <parent link="link1"/>
       <child  link="link3"/>
       <origin rpy="0 0 0" xyz="0.01797285553856733 -0.7166248654332157 0.014843319665585367" />
     <axis xyz="1 0 0"/>
       <limit effort="0.0" lower="-3.14159" upper="3.14159" velocity="0.0"/>
    </joint>
    <link name="link3">
        <inertial>
            <origin xyz="0.37297228028902313 -0.015801488805755253 0.054444039348323016" rpy="0 0 0"/>
            <mass value="1" />
            <inertia ixx="100" ixy="0" ixz="0" iyy="100" iyz="0" izz="100" />
        </inertial>
        <visual>
            <origin xyz="0.37297228028902313 -0.015801488805755253 0.054444039348323016" rpy="0 0 0"/>
            <geometry>
                <box size="0.7459445605780463 0.17976360312837114 0.6501672094455063" />
            </geometry>
            <material name="Green">
                <color rgba="0.0 1.0 0.0 1.0"/>
            </material>
        </visual>
        <collision>
            <origin xyz="0.37297228028902313 -0.015801488805755253 0.054444039348323016" rpy="0 0 0"/>
            <geometry>
                <box size="0.7459445605780463 0.17976360312837114 0.6501672094455063" />
            </geometry>
        </collision>
    </link>
</robot>