<robot name = "robot">
    <link name="link0">
        <inertial>
            <origin xyz="0 0 1" rpy="0 0 0"/>
            <mass value="1" />
            <inertia ixx="100" ixy="0" ixz="0" iyy="100" iyz="0" izz="100" />
        </inertial>
        <visual>
            <origin xyz="0 0 1" rpy="0 0 0"/>
            <geometry>
                <box size="0.5703146452034397 0.8870716950292671 0.4710569676593348" />
            </geometry>
            <material name="Cyan">
                <color rgba="0.0 1.0 1.0 1.0"/>
            </material>
        </visual>
        <collision>
            <origin xyz="0 0 1" rpy="0 0 0"/>
            <geometry>
                <box size="0.5703146452034397 0.8870716950292671 0.4710569676593348" />
            </geometry>
        </collision>
    </link>
    <joint name="link0_link1" type="revolute">
       <parent link="link0"/>
       <child  link="link1"/>
       <origin rpy="0 0 0" xyz="0.27424851450975163 -0.44353584751463354 0.9511998662303958" />
     <axis xyz="0 1 0"/>
       <limit effort="0.0" lower="-3.14159" upper="3.14159" velocity="0.0"/>
    </joint>
    <link name="link1">
        <inertial>
            <origin xyz="0.36255506777164803 -0.4319187341794909 -0.40603303824731246" rpy="0 0 0"/>
            <mass value="1" />
            <inertia ixx="100" ixy="0" ixz="0" iyy="100" iyz="0" izz="100" />
        </inertial>
        <visual>
            <origin xyz="0.36255506777164803 -0.4319187341794909 -0.40603303824731246" rpy="0 0 0"/>
            <geometry>
                <box size="0.8691825084619849 0.8638374683589818 0.8994844281288952" />
            </geometry>
            <material name="Green">
                <color rgba="0.0 1.0 0.0 1.0"/>
            </material>
        </visual>
        <collision>
            <origin xyz="0.36255506777164803 -0.4319187341794909 -0.40603303824731246" rpy="0 0 0"/>
            <geometry>
                <box size="0.8691825084619849 0.8638374683589818 0.8994844281288952" />
            </geometry>
        </collision>
    </link>
    <joint name="link0_link2" type="revolute">
       <parent link="link0"/>
       <child  link="link2"/>
       <origin rpy="0 0 0" xyz="-0.04890472705409983 -0.31153374131976763 1.2355284838296674" />
     <axis xyz="0 0 1"/>
       <limit effort="0.0" lower="-3.14159" upper="3.14159" velocity="0.0"/>
    </joint>
    <link name="link2">
        <inertial>
            <origin xyz="-0.00893418686565859 -0.28028099973286047 0.25934655680588037" rpy="0 0 0"/>
            <mass value="1" />
            <inertia ixx="100" ixy="0" ixz="0" iyy="100" iyz="0" izz="100" />
        </inertial>
        <visual>
            <origin xyz="-0.00893418686565859 -0.28028099973286047 0.25934655680588037" rpy="0 0 0"/>
            <geometry>
                <box size="0.020844612103450344 0.94610610131776 0.5186931136117607" />
            </geometry>
            <material name="Green">
                <color rgba="0.0 1.0 0.0 1.0"/>
            </material>
        </visual>
        <collision>
            <origin xyz="-0.00893418686565859 -0.28028099973286047 0.25934655680588037" rpy="0 0 0"/>
            <geometry>
                <box size="0.020844612103450344 0.94610610131776 0.5186931136117607" />
            </geometry>
        </collision>
    </link>
    <joint name="link2_link3" type="revolute">
       <parent link="link2"/>
       <child  link="link3"/>
       <origin rpy="0 0 0" xyz="-0.019356492917383762 -0.47947981469545653 0.4685857689750132" />
     <axis xyz="0 0 1"/>
       <limit effort="0.0" lower="-3.14159" upper="3.14159" velocity="0.0"/>
    </joint>
    <link name="link3">
        <inertial>
            <origin xyz="-0.451870118668571 -0.16139450731753882 0.1577293120316435" rpy="0 0 0"/>
            <mass value="1" />
            <inertia ixx="100" ixy="0" ixz="0" iyy="100" iyz="0" izz="100" />
        </inertial>
        <visual>
            <origin xyz="-0.451870118668571 -0.16139450731753882 0.1577293120316435" rpy="0 0 0"/>
            <geometry>
                <box size="0.903740237337142 0.6779613354715663 0.4889973970840087" />
            </geometry>
            <material name="Green">
                <color rgba="0.0 1.0 0.0 1.0"/>
            </material>
        </visual>
        <collision>
            <origin xyz="-0.451870118668571 -0.16139450731753882 0.1577293120316435" rpy="0 0 0"/>
            <geometry>
                <box size="0.903740237337142 0.6779613354715663 0.4889973970840087" />
            </geometry>
        </collision>
    </link>
    <joint name="link2_link4" type="revolute">
       <parent link="link2"/>
       <child  link="link4"/>
       <origin rpy="0 0 0" xyz="-0.007652085368195286 0.14094175080955168 0.5186931136117607" />
     <axis xyz="0 0 1"/>
       <limit effort="0.0" lower="-3.14159" upper="3.14159" velocity="0.0"/>
    </joint>
    <link name="link4">
        <inertial>
            <origin xyz="-0.069296185118935 0.012385944400364219 0.3223710702592769" rpy="0 0 0"/>
            <mass value="1" />
            <inertia ixx="100" ixy="0" ixz="0" iyy="100" iyz="0" izz="100" />
        </inertial>
        <visual>
            <origin xyz="-0.069296185118935 0.012385944400364219 0.3223710702592769" rpy="0 0 0"/>
            <geometry>
                <box size="0.1424748015348669 0.03300779657250785 0.6447421405185538" />
            </geometry>
            <material name="Green">
                <color rgba="0.0 1.0 0.0 1.0"/>
            </material>
        </visual>
        <collision>
            <origin xyz="-0.069296185118935 0.012385944400364219 0.3223710702592769" rpy="0 0 0"/>
            <geometry>
                <box size="0.1424748015348669 0.03300779657250785 0.6447421405185538" />
            </geometry>
        </collision>
    </link>
    <joint name="link0_link5" type="revolute">
       <parent link="link0"/>
       <child  link="link5"/>
       <origin rpy="0 0 0" xyz="-0.28515732260171983 0.22999211977309864 0.8885949529293651" />
     <axis xyz="0 1 0"/>
       <limit effort="0.0" lower="-3.14159" upper="3.14159" velocity="0.0"/>
    </joint>
    <link name="link5">
        <inertial>
            <origin xyz="-0.49043645608877257 -0.3173299741817718 0.01648164818066125" rpy="0 0 0"/>
            <mass value="1" />
            <inertia ixx="100" ixy="0" ixz="0" iyy="100" iyz="0" izz="100" />
        </inertial>
        <visual>
            <origin xyz="-0.49043645608877257 -0.3173299741817718 0.01648164818066125" rpy="0 0 0"/>
            <geometry>
                <box size="0.9808729121775451 0.9430310409655539 0.4283531709217969" />
            </geometry>
            <material name="Green">
                <color rgba="0.0 1.0 0.0 1.0"/>
            </material>
        </visual>
        <collision>
            <origin xyz="-0.49043645608877257 -0.3173299741817718 0.01648164818066125" rpy="0 0 0"/>
            <geometry>
                <box size="0.9808729121775451 0.9430310409655539 0.4283531709217969" />
            </geometry>
        </collision>
    </link>
</robot>