<robot name = "robot">
    <link name="link0">
        <inertial>
            <origin xyz="0 0 1" rpy="0 0 0"/>
            <mass value="1" />
            <inertia ixx="100" ixy="0" ixz="0" iyy="100" iyz="0" izz="100" />
        </inertial>
        <visual>
            <origin xyz="0 0 1" rpy="0 0 0"/>
            <geometry>
                <box size="0.5181031938236467 0.5904766745554297 0.9471779272645257" />
            </geometry>
            <material name="Cyan">
                <color rgba="0 1.0 1.0 1.0"/>
            </material>
        </visual>
        <collision>
            <origin xyz="0 0 1" rpy="0 0 0"/>
            <geometry>
                <box size="0.5181031938236467 0.5904766745554297 0.9471779272645257" />
            </geometry>
        </collision>
    </link>
    <joint name="link0_link1" type="revolute">
       <parent link="link0"/>
       <child  link="link1"/>
       <origin rpy="0 0 0" xyz="0.25905159691182333 -0.12008562924563068 1.18315428629628" />
     <axis xyz="0 1 0"/>
       <limit effort="0.0" lower="-3.14159" upper="3.14159" velocity="0.0"/>
    </joint>
    <link name="link1">
        <inertial>
            <origin xyz="0.3160811333321593 -0.2651351048746317 0.14456467062350453" rpy="0 0 0"/>
            <mass value="1" />
            <inertia ixx="100" ixy="0" ixz="0" iyy="100" iyz="0" izz="100" />
        </inertial>
        <visual>
            <origin xyz="0.3160811333321593 -0.2651351048746317 0.14456467062350453" rpy="0 0 0"/>
            <geometry>
                <box size="0.6321622666643186 0.5788046120525123 0.7988884182933659" />
            </geometry>
            <material name="Cyan">
                <color rgba="0 1.0 1.0 1.0"/>
            </material>
        </visual>
        <collision>
            <origin xyz="0.3160811333321593 -0.2651351048746317 0.14456467062350453" rpy="0 0 0"/>
            <geometry>
                <box size="0.6321622666643186 0.5788046120525123 0.7988884182933659" />
            </geometry>
        </collision>
    </link>
    <joint name="link0_link2" type="revolute">
       <parent link="link0"/>
       <child  link="link2"/>
       <origin rpy="0 0 0" xyz="-0.09311468630422157 -0.29523833727771487 0.8825053013307909" />
     <axis xyz="1 0 0"/>
       <limit effort="0.0" lower="-3.14159" upper="3.14159" velocity="0.0"/>
    </joint>
    <link name="link2">
        <inertial>
            <origin xyz="0.00013220840192895518 -0.4314358186581632 0.003001630300513063" rpy="0 0 0"/>
            <mass value="1" />
            <inertia ixx="100" ixy="0" ixz="0" iyy="100" iyz="0" izz="100" />
        </inertial>
        <visual>
            <origin xyz="0.00013220840192895518 -0.4314358186581632 0.003001630300513063" rpy="0 0 0"/>
            <geometry>
                <box size="0.6536055929350912 0.8628716373163264 0.02206034901069409" />
            </geometry>
            <material name="Cyan">
                <color rgba="0 1.0 1.0 1.0"/>
            </material>
        </visual>
        <collision>
            <origin xyz="0.00013220840192895518 -0.4314358186581632 0.003001630300513063" rpy="0 0 0"/>
            <geometry>
                <box size="0.6536055929350912 0.8628716373163264 0.02206034901069409" />
            </geometry>
        </collision>
    </link>
    <joint name="link0_link3" type="revolute">
       <parent link="link0"/>
       <child  link="link3"/>
       <origin rpy="0 0 0" xyz="0.25905159691182333 -0.0005110223639127347 1.3433434160328523" />
     <axis xyz="0 1 0"/>
       <limit effort="0.0" lower="-3.14159" upper="3.14159" velocity="0.0"/>
    </joint>
    <link name="link3">
        <inertial>
            <origin xyz="0.43962441343177483 0.22717239926371147 -0.4054233264144588" rpy="0 0 0"/>
            <mass value="1" />
            <inertia ixx="100" ixy="0" ixz="0" iyy="100" iyz="0" izz="100" />
        </inertial>
        <visual>
            <origin xyz="0.43962441343177483 0.22717239926371147 -0.4054233264144588" rpy="0 0 0"/>
            <geometry>
                <box size="0.8792488268635497 0.5032505884955235 0.8919291603142586" />
            </geometry>
            <material name="Cyan">
                <color rgba="0 1.0 1.0 1.0"/>
            </material>
        </visual>
        <collision>
            <origin xyz="0.43962441343177483 0.22717239926371147 -0.4054233264144588" rpy="0 0 0"/>
            <geometry>
                <box size="0.8792488268635497 0.5032505884955235 0.8919291603142586" />
            </geometry>
        </collision>
    </link>
    <joint name="link2_link4" type="revolute">
       <parent link="link2"/>
       <child  link="link4"/>
       <origin rpy="0 0 0" xyz="-0.32667058806561666 -0.6913824156245665 0.012264156337374352" />
     <axis xyz="1 0 0"/>
       <limit effort="0.0" lower="-3.14159" upper="3.14159" velocity="0.0"/>
    </joint>
    <link name="link4">
        <inertial>
            <origin xyz="-0.039075444661668846 0.2418544984975803 -0.07593389164408809" rpy="0 0 0"/>
            <mass value="1" />
            <inertia ixx="100" ixy="0" ixz="0" iyy="100" iyz="0" izz="100" />
        </inertial>
        <visual>
            <origin xyz="-0.039075444661668846 0.2418544984975803 -0.07593389164408809" rpy="0 0 0"/>
            <geometry>
                <box size="0.07815088932333769 0.9221939658192081 0.21025442186310794" />
            </geometry>
            <material name="Cyan">
                <color rgba="0 1.0 1.0 1.0"/>
            </material>
        </visual>
        <collision>
            <origin xyz="-0.039075444661668846 0.2418544984975803 -0.07593389164408809" rpy="0 0 0"/>
            <geometry>
                <box size="0.07815088932333769 0.9221939658192081 0.21025442186310794" />
            </geometry>
        </collision>
    </link>
    <joint name="link1_link5" type="revolute">
       <parent link="link1"/>
       <child  link="link5"/>
       <origin rpy="0 0 0" xyz="0.28012856803158104 0.02426720115162445 0.5213097931897668" />
     <axis xyz="0 0 1"/>
       <limit effort="0.0" lower="-3.14159" upper="3.14159" velocity="0.0"/>
    </joint>
    <link name="link5">
        <inertial>
            <origin xyz="0.006928576798762497 0.13797285092019296 -0.2339054300949133" rpy="0 0 0"/>
            <mass value="1" />
            <inertia ixx="100" ixy="0" ixz="0" iyy="100" iyz="0" izz="100" />
        </inertial>
        <visual>
            <origin xyz="0.006928576798762497 0.13797285092019296 -0.2339054300949133" rpy="0 0 0"/>
            <geometry>
                <box size="0.06824927917112267 0.2759457018403859 0.8638436518597673" />
            </geometry>
            <material name="Cyan">
                <color rgba="0 1.0 1.0 1.0"/>
            </material>
        </visual>
        <collision>
            <origin xyz="0.006928576798762497 0.13797285092019296 -0.2339054300949133" rpy="0 0 0"/>
            <geometry>
                <box size="0.06824927917112267 0.2759457018403859 0.8638436518597673" />
            </geometry>
        </collision>
    </link>
    <joint name="link5_link6" type="revolute">
       <parent link="link5"/>
       <child  link="link6"/>
       <origin rpy="0 0 0" xyz="-0.027196062786798838 0.1588983662433843 -0.5142125960033463" />
     <axis xyz="0 0 1"/>
       <limit effort="0.0" lower="-3.14159" upper="3.14159" velocity="0.0"/>
    </joint>
    <link name="link6">
        <inertial>
            <origin xyz="-0.029876611144224463 0.1176238779976556 0.09436401235559938" rpy="0 0 0"/>
            <mass value="1" />
            <inertia ixx="100" ixy="0" ixz="0" iyy="100" iyz="0" izz="100" />
        </inertial>
        <visual>
            <origin xyz="-0.029876611144224463 0.1176238779976556 0.09436401235559938" rpy="0 0 0"/>
            <geometry>
                <box size="0.059753222288448926 0.3409660344827874 0.6050594603985225" />
            </geometry>
            <material name="Cyan">
                <color rgba="0 1.0 1.0 1.0"/>
            </material>
        </visual>
        <collision>
            <origin xyz="-0.029876611144224463 0.1176238779976556 0.09436401235559938" rpy="0 0 0"/>
            <geometry>
                <box size="0.059753222288448926 0.3409660344827874 0.6050594603985225" />
            </geometry>
        </collision>
    </link>
    <joint name="link1_link7" type="revolute">
       <parent link="link1"/>
       <child  link="link7"/>
       <origin rpy="0 0 0" xyz="0.6321622666643186 -0.4212499250520816 0.23331576361847897" />
     <axis xyz="0 0 1"/>
       <limit effort="0.0" lower="-3.14159" upper="3.14159" velocity="0.0"/>
    </joint>
    <link name="link7">
        <inertial>
            <origin xyz="0.2568920227801774 -0.19740553166435762 -0.1719318384542085" rpy="0 0 0"/>
            <mass value="1" />
            <inertia ixx="100" ixy="0" ixz="0" iyy="100" iyz="0" izz="100" />
        </inertial>
        <visual>
            <origin xyz="0.2568920227801774 -0.19740553166435762 -0.1719318384542085" rpy="0 0 0"/>
            <geometry>
                <box size="0.5137840455603548 0.9972630131294795 0.4750805457200553" />
            </geometry>
            <material name="Cyan">
                <color rgba="0 1.0 1.0 1.0"/>
            </material>
        </visual>
        <collision>
            <origin xyz="0.2568920227801774 -0.19740553166435762 -0.1719318384542085" rpy="0 0 0"/>
            <geometry>
                <box size="0.5137840455603548 0.9972630131294795 0.4750805457200553" />
            </geometry>
        </collision>
    </link>
</robot>