<robot name = "robot">
    <link name="link0">
        <inertial>
            <origin xyz="0 0 1" rpy="0 0 0"/>
            <mass value="1" />
            <inertia ixx="100" ixy="0" ixz="0" iyy="100" iyz="0" izz="100" />
        </inertial>
        <visual>
            <origin xyz="0 0 1" rpy="0 0 0"/>
            <geometry>
                <box size="0.36307889306604335 0.14790827004969365 0.19116954311681778" />
            </geometry>
            <material name="Cyan">
                <color rgba="0 1.0 1.0 1.0"/>
            </material>
        </visual>
        <collision>
            <origin xyz="0 0 1" rpy="0 0 0"/>
            <geometry>
                <box size="0.36307889306604335 0.14790827004969365 0.19116954311681778" />
            </geometry>
        </collision>
    </link>
    <joint name="link0_link1" type="revolute">
       <parent link="link0"/>
       <child  link="link1"/>
       <origin rpy="0 0 0" xyz="0.1090468248355754 0.003741184021459201 0.9044152284415912" />
     <axis xyz="1 0 0"/>
       <limit effort="0.0" lower="-3.14159" upper="3.14159" velocity="0.0"/>
    </joint>
    <link name="link1">
        <inertial>
            <origin xyz="0.0024289412021915504 -0.05314987108690941 -0.3840947550336161" rpy="0 0 0"/>
            <mass value="1" />
            <inertia ixx="100" ixy="0" ixz="0" iyy="100" iyz="0" izz="100" />
        </inertial>
        <visual>
            <origin xyz="0.0024289412021915504 -0.05314987108690941 -0.3840947550336161" rpy="0 0 0"/>
            <geometry>
                <box size="0.013122432855184107 0.5024625759837951 0.7681895100672322" />
            </geometry>
            <material name="Cyan">
                <color rgba="0 1.0 1.0 1.0"/>
            </material>
        </visual>
        <collision>
            <origin xyz="0.0024289412021915504 -0.05314987108690941 -0.3840947550336161" rpy="0 0 0"/>
            <geometry>
                <box size="0.013122432855184107 0.5024625759837951 0.7681895100672322" />
            </geometry>
        </collision>
    </link>
    <joint name="link1_link2" type="revolute">
       <parent link="link1"/>
       <child  link="link2"/>
       <origin rpy="0 0 0" xyz="0.008990157629783604 -0.2740231784509794 -0.6778648908967595" />
     <axis xyz="1 0 0"/>
       <limit effort="0.0" lower="-3.14159" upper="3.14159" velocity="0.0"/>
    </joint>
    <link name="link2">
        <inertial>
            <origin xyz="0.16206577304951925 -0.2226284325088954 -0.0020147230064819686" rpy="0 0 0"/>
            <mass value="1" />
            <inertia ixx="100" ixy="0" ixz="0" iyy="100" iyz="0" izz="100" />
        </inertial>
        <visual>
            <origin xyz="0.16206577304951925 -0.2226284325088954 -0.0020147230064819686" rpy="0 0 0"/>
            <geometry>
                <box size="0.3241315460990385 0.8128096222358792 0.1791122109440747" />
            </geometry>
            <material name="Cyan">
                <color rgba="0 1.0 1.0 1.0"/>
            </material>
        </visual>
        <collision>
            <origin xyz="0.16206577304951925 -0.2226284325088954 -0.0020147230064819686" rpy="0 0 0"/>
            <geometry>
                <box size="0.3241315460990385 0.8128096222358792 0.1791122109440747" />
            </geometry>
        </collision>
    </link>
    <joint name="link0_link3" type="revolute">
       <parent link="link0"/>
       <child  link="link3"/>
       <origin rpy="0 0 0" xyz="-0.00700126223535433 -0.07395413502484682 1.0475781689983923" />
     <axis xyz="0 1 0"/>
       <limit effort="0.0" lower="-3.14159" upper="3.14159" velocity="0.0"/>
    </joint>
    <link name="link3">
        <inertial>
            <origin xyz="0.049305792627760095 -0.3215985323392041 -0.169181479621034" rpy="0 0 0"/>
            <mass value="1" />
            <inertia ixx="100" ixy="0" ixz="0" iyy="100" iyz="0" izz="100" />
        </inertial>
        <visual>
            <origin xyz="0.049305792627760095 -0.3215985323392041 -0.169181479621034" rpy="0 0 0"/>
            <geometry>
                <box size="0.21780002428726375 0.6431970646784082 0.40953888019587115" />
            </geometry>
            <material name="Cyan">
                <color rgba="0 1.0 1.0 1.0"/>
            </material>
        </visual>
        <collision>
            <origin xyz="0.049305792627760095 -0.3215985323392041 -0.169181479621034" rpy="0 0 0"/>
            <geometry>
                <box size="0.21780002428726375 0.6431970646784082 0.40953888019587115" />
            </geometry>
        </collision>
    </link>
    <joint name="link0_link4" type="revolute">
       <parent link="link0"/>
       <child  link="link4"/>
       <origin rpy="0 0 0" xyz="-0.18153944653302168 0.06137140116549192 0.9184756817575788" />
     <axis xyz="0 1 0"/>
       <limit effort="0.0" lower="-3.14159" upper="3.14159" velocity="0.0"/>
    </joint>
    <link name="link4">
        <inertial>
            <origin xyz="-0.1458211049436492 0.33617133257928605 -0.020279566108311227" rpy="0 0 0"/>
            <mass value="1" />
            <inertia ixx="100" ixy="0" ixz="0" iyy="100" iyz="0" izz="100" />
        </inertial>
        <visual>
            <origin xyz="-0.1458211049436492 0.33617133257928605 -0.020279566108311227" rpy="0 0 0"/>
            <geometry>
                <box size="0.2916422098872984 0.7516907190636666 0.5418674624797458" />
            </geometry>
            <material name="Cyan">
                <color rgba="0 1.0 1.0 1.0"/>
            </material>
        </visual>
        <collision>
            <origin xyz="-0.1458211049436492 0.33617133257928605 -0.020279566108311227" rpy="0 0 0"/>
            <geometry>
                <box size="0.2916422098872984 0.7516907190636666 0.5418674624797458" />
            </geometry>
        </collision>
    </link>
</robot>