<robot name = "robot">
    <link name="link0">
        <inertial>
            <origin xyz="0 0 1" rpy="0 0 0"/>
            <mass value="1" />
            <inertia ixx="100" ixy="0" ixz="0" iyy="100" iyz="0" izz="100" />
        </inertial>
        <visual>
            <origin xyz="0 0 1" rpy="0 0 0"/>
            <geometry>
                <box size="0.1018431837718371 0.7929486501794517 0.9413507284363797" />
            </geometry>
            <material name="Cyan">
                <color rgba="0 1.0 1.0 1.0"/>
            </material>
        </visual>
        <collision>
            <origin xyz="0 0 1" rpy="0 0 0"/>
            <geometry>
                <box size="0.1018431837718371 0.7929486501794517 0.9413507284363797" />
            </geometry>
        </collision>
    </link>
    <joint name="link0_link1" type="revolute">
       <parent link="link0"/>
       <child  link="link1"/>
       <origin rpy="0 0 0" xyz="0.04181593216021169 0.02333167445819831 1.4706753642181898" />
     <axis xyz="0 0 1"/>
       <limit effort="0.0" lower="-3.14159" upper="3.14159" velocity="0.0"/>
    </joint>
    <link name="link1">
        <inertial>
            <origin xyz="-0.18894182026893944 0.07259714179280703 0.0735844978186041" rpy="0 0 0"/>
            <mass value="1" />
            <inertia ixx="100" ixy="0" ixz="0" iyy="100" iyz="0" izz="100" />
        </inertial>
        <visual>
            <origin xyz="-0.18894182026893944 0.07259714179280703 0.0735844978186041" rpy="0 0 0"/>
            <geometry>
                <box size="0.9637439999932601 0.5221921517242575 0.1471689956372082" />
            </geometry>
            <material name="Cyan">
                <color rgba="0 1.0 1.0 1.0"/>
            </material>
        </visual>
        <collision>
            <origin xyz="-0.18894182026893944 0.07259714179280703 0.0735844978186041" rpy="0 0 0"/>
            <geometry>
                <box size="0.9637439999932601 0.5221921517242575 0.1471689956372082" />
            </geometry>
        </collision>
    </link>
    <joint name="link0_link2" type="revolute">
       <parent link="link0"/>
       <child  link="link2"/>
       <origin rpy="0 0 0" xyz="-0.039204880650280674 0.39647432508972585 1.1373831178784382" />
     <axis xyz="1 0 0"/>
       <limit effort="0.0" lower="-3.14159" upper="3.14159" velocity="0.0"/>
    </joint>
    <link name="link2">
        <inertial>
            <origin xyz="0.34332229022986416 0.06599514744448365 0.06877619831389502" rpy="0 0 0"/>
            <mass value="1" />
            <inertia ixx="100" ixy="0" ixz="0" iyy="100" iyz="0" izz="100" />
        </inertial>
        <visual>
            <origin xyz="0.34332229022986416 0.06599514744448365 0.06877619831389502" rpy="0 0 0"/>
            <geometry>
                <box size="0.8753068607366387 0.1319902948889673 0.17515170272783054" />
            </geometry>
            <material name="Cyan">
                <color rgba="0 1.0 1.0 1.0"/>
            </material>
        </visual>
        <collision>
            <origin xyz="0.34332229022986416 0.06599514744448365 0.06877619831389502" rpy="0 0 0"/>
            <geometry>
                <box size="0.8753068607366387 0.1319902948889673 0.17515170272783054" />
            </geometry>
        </collision>
    </link>
    <joint name="link0_link3" type="revolute">
       <parent link="link0"/>
       <child  link="link3"/>
       <origin rpy="0 0 0" xyz="0.024301031130733296 0.13992550463424894 1.4706753642181898" />
     <axis xyz="0 1 0"/>
       <limit effort="0.0" lower="-3.14159" upper="3.14159" velocity="0.0"/>
    </joint>
    <link name="link3">
        <inertial>
            <origin xyz="0.047942245828121705 -0.08590995155791908 0.30795298126337833" rpy="0 0 0"/>
            <mass value="1" />
            <inertia ixx="100" ixy="0" ixz="0" iyy="100" iyz="0" izz="100" />
        </inertial>
        <visual>
            <origin xyz="0.047942245828121705 -0.08590995155791908 0.30795298126337833" rpy="0 0 0"/>
            <geometry>
                <box size="0.5060403371320904 0.5609266907262984 0.6159059625267567" />
            </geometry>
            <material name="Cyan">
                <color rgba="0 1.0 1.0 1.0"/>
            </material>
        </visual>
        <collision>
            <origin xyz="0.047942245828121705 -0.08590995155791908 0.30795298126337833" rpy="0 0 0"/>
            <geometry>
                <box size="0.5060403371320904 0.5609266907262984 0.6159059625267567" />
            </geometry>
        </collision>
    </link>
    <joint name="link3_link4" type="revolute">
       <parent link="link3"/>
       <child  link="link4"/>
       <origin rpy="0 0 0" xyz="-0.04458960103528074 0.19455339380523012 0.010784618452279238" />
     <axis xyz="1 0 0"/>
       <limit effort="0.0" lower="-3.14159" upper="3.14159" velocity="0.0"/>
    </joint>
    <link name="link4">
        <inertial>
            <origin xyz="-0.058209786607526216 0.3305326731901407 -0.00038888576790530976" rpy="0 0 0"/>
            <mass value="1" />
            <inertia ixx="100" ixy="0" ixz="0" iyy="100" iyz="0" izz="100" />
        </inertial>
        <visual>
            <origin xyz="-0.058209786607526216 0.3305326731901407 -0.00038888576790530976" rpy="0 0 0"/>
            <geometry>
                <box size="0.6073717578911335 0.6610653463802814 0.0033755912792681197" />
            </geometry>
            <material name="Cyan">
                <color rgba="0 1.0 1.0 1.0"/>
            </material>
        </visual>
        <collision>
            <origin xyz="-0.058209786607526216 0.3305326731901407 -0.00038888576790530976" rpy="0 0 0"/>
            <geometry>
                <box size="0.6073717578911335 0.6610653463802814 0.0033755912792681197" />
            </geometry>
        </collision>
    </link>
    <joint name="link2_link5" type="revolute">
       <parent link="link2"/>
       <child  link="link5"/>
       <origin rpy="0 0 0" xyz="0.7527242962213928 0.11817213836651279 0.1563520496778103" />
     <axis xyz="0 1 0"/>
       <limit effort="0.0" lower="-3.14159" upper="3.14159" velocity="0.0"/>
    </joint>
    <link name="link5">
        <inertial>
            <origin xyz="-0.0014441126010239548 -0.028555184060618532 0.42274799911926375" rpy="0 0 0"/>
            <mass value="1" />
            <inertia ixx="100" ixy="0" ixz="0" iyy="100" iyz="0" izz="100" />
        </inertial>
        <visual>
            <origin xyz="-0.0014441126010239548 -0.028555184060618532 0.42274799911926375" rpy="0 0 0"/>
            <geometry>
                <box size="0.03920214795135557 0.12852434323413298 0.8454959982385275" />
            </geometry>
            <material name="Cyan">
                <color rgba="0 1.0 1.0 1.0"/>
            </material>
        </visual>
        <collision>
            <origin xyz="-0.0014441126010239548 -0.028555184060618532 0.42274799911926375" rpy="0 0 0"/>
            <geometry>
                <box size="0.03920214795135557 0.12852434323413298 0.8454959982385275" />
            </geometry>
        </collision>
    </link>
</robot>