<robot name = "robot">
    <link name="link0">
        <inertial>
            <origin xyz="0 0 1" rpy="0 0 0"/>
            <mass value="1" />
            <inertia ixx="100" ixy="0" ixz="0" iyy="100" iyz="0" izz="100" />
        </inertial>
        <visual>
            <origin xyz="0 0 1" rpy="0 0 0"/>
            <geometry>
                <box size="0.32193664341034045 0.5181413390271934 0.33179073623737687" />
            </geometry>
            <material name="Cyan">
                <color rgba="0.0 1.0 1.0 1.0"/>
            </material>
        </visual>
        <collision>
            <origin xyz="0 0 1" rpy="0 0 0"/>
            <geometry>
                <box size="0.32193664341034045 0.5181413390271934 0.33179073623737687" />
            </geometry>
        </collision>
    </link>
    <joint name="link0_link1" type="revolute">
       <parent link="link0"/>
       <child  link="link1"/>
       <origin rpy="0 0 0" xyz="0.06581217505943325 -0.2590706695135967 0.9688832414889392" />
     <axis xyz="0 0 1"/>
       <limit effort="0.0" lower="-3.14159" upper="3.14159" velocity="0.0"/>
    </joint>
    <link name="link1">
        <inertial>
            <origin xyz="0.16351639280897876 -0.32230346385931985 -0.0691982326879562" rpy="0 0 0"/>
            <mass value="1" />
            <inertia ixx="100" ixy="0" ixz="0" iyy="100" iyz="0" izz="100" />
        </inertial>
        <visual>
            <origin xyz="0.16351639280897876 -0.32230346385931985 -0.0691982326879562" rpy="0 0 0"/>
            <geometry>
                <box size="0.3773288415036772 0.6446069277186397 0.6308892300069937" />
            </geometry>
            <material name="Cyan">
                <color rgba="0.0 1.0 1.0 1.0"/>
            </material>
        </visual>
        <collision>
            <origin xyz="0.16351639280897876 -0.32230346385931985 -0.0691982326879562" rpy="0 0 0"/>
            <geometry>
                <box size="0.3773288415036772 0.6446069277186397 0.6308892300069937" />
            </geometry>
        </collision>
    </link>
    <joint name="link1_link2" type="revolute">
       <parent link="link1"/>
       <child  link="link2"/>
       <origin rpy="0 0 0" xyz="0.3521808135608173 -0.4167478891914925 -0.05985803383150209" />
     <axis xyz="0 0 1"/>
       <limit effort="0.0" lower="-3.14159" upper="3.14159" velocity="0.0"/>
    </joint>
    <link name="link2">
        <inertial>
            <origin xyz="0.084211792344906 0.3040705408835346 -0.030038060051871315" rpy="0 0 0"/>
            <mass value="1" />
            <inertia ixx="100" ixy="0" ixz="0" iyy="100" iyz="0" izz="100" />
        </inertial>
        <visual>
            <origin xyz="0.084211792344906 0.3040705408835346 -0.030038060051871315" rpy="0 0 0"/>
            <geometry>
                <box size="0.168423584689812 0.8671912725964005 0.3013810897234275" />
            </geometry>
            <material name="Cyan">
                <color rgba="0.0 1.0 1.0 1.0"/>
            </material>
        </visual>
        <collision>
            <origin xyz="0.084211792344906 0.3040705408835346 -0.030038060051871315" rpy="0 0 0"/>
            <geometry>
                <box size="0.168423584689812 0.8671912725964005 0.3013810897234275" />
            </geometry>
        </collision>
    </link>
    <joint name="link2_link3" type="revolute">
       <parent link="link2"/>
       <child  link="link3"/>
       <origin rpy="0 0 0" xyz="0.1481992956719641 -0.12952509541466567 -0.05177884345852375" />
     <axis xyz="0 1 0"/>
       <limit effort="0.0" lower="-3.14159" upper="3.14159" velocity="0.0"/>
    </joint>
    <link name="link3">
        <inertial>
            <origin xyz="-0.011464964212640592 -0.4069893537605515 -0.14833042487965314" rpy="0 0 0"/>
            <mass value="1" />
            <inertia ixx="100" ixy="0" ixz="0" iyy="100" iyz="0" izz="100" />
        </inertial>
        <visual>
            <origin xyz="-0.011464964212640592 -0.4069893537605515 -0.14833042487965314" rpy="0 0 0"/>
            <geometry>
                <box size="0.028024744461953355 0.813978707521103 0.5174772063479892" />
            </geometry>
            <material name="Cyan">
                <color rgba="0.0 1.0 1.0 1.0"/>
            </material>
        </visual>
        <collision>
            <origin xyz="-0.011464964212640592 -0.4069893537605515 -0.14833042487965314" rpy="0 0 0"/>
            <geometry>
                <box size="0.028024744461953355 0.813978707521103 0.5174772063479892" />
            </geometry>
        </collision>
    </link>
    <joint name="link2_link4" type="revolute">
       <parent link="link2"/>
       <child  link="link4"/>
       <origin rpy="0 0 0" xyz="0.043889884734282854 0.7376661771817348 -0.11947120406239256" />
     <axis xyz="0 0 1"/>
       <limit effort="0.0" lower="-3.14159" upper="3.14159" velocity="0.0"/>
    </joint>
    <link name="link4">
        <inertial>
            <origin xyz="-0.03563003881072989 0.2633342972914774 -0.02341353102959649" rpy="0 0 0"/>
            <mass value="1" />
            <inertia ixx="100" ixy="0" ixz="0" iyy="100" iyz="0" izz="100" />
        </inertial>
        <visual>
            <origin xyz="-0.03563003881072989 0.2633342972914774 -0.02341353102959649" rpy="0 0 0"/>
            <geometry>
                <box size="0.35065698983799476 0.5266685945829548 0.05189933514299616" />
            </geometry>
            <material name="Green">
                <color rgba="0.0 1.0 0.0 1.0"/>
            </material>
        </visual>
        <collision>
            <origin xyz="-0.03563003881072989 0.2633342972914774 -0.02341353102959649" rpy="0 0 0"/>
            <geometry>
                <box size="0.35065698983799476 0.5266685945829548 0.05189933514299616" />
            </geometry>
        </collision>
    </link>
    <joint name="link1_link5" type="revolute">
       <parent link="link1"/>
       <child  link="link5"/>
       <origin rpy="0 0 0" xyz="-0.025148027942859835 -0.3449726532624251 -0.2529430185968467" />
     <axis xyz="0 1 0"/>
       <limit effort="0.0" lower="-3.14159" upper="3.14159" velocity="0.0"/>
    </joint>
    <link name="link5">
        <inertial>
            <origin xyz="-0.024954496001219628 -0.10251462603486106 -0.4603602421368562" rpy="0 0 0"/>
            <mass value="1" />
            <inertia ixx="100" ixy="0" ixz="0" iyy="100" iyz="0" izz="100" />
        </inertial>
        <visual>
            <origin xyz="-0.024954496001219628 -0.10251462603486106 -0.4603602421368562" rpy="0 0 0"/>
            <geometry>
                <box size="0.049908992002439256 0.3578378870035894 0.9929077099121563" />
            </geometry>
            <material name="Green">
                <color rgba="0.0 1.0 0.0 1.0"/>
            </material>
        </visual>
        <collision>
            <origin xyz="-0.024954496001219628 -0.10251462603486106 -0.4603602421368562" rpy="0 0 0"/>
            <geometry>
                <box size="0.049908992002439256 0.3578378870035894 0.9929077099121563" />
            </geometry>
        </collision>
    </link>
    <joint name="link0_link6" type="revolute">
       <parent link="link0"/>
       <child  link="link6"/>
       <origin rpy="0 0 0" xyz="-0.13328538059827286 0.2590706695135967 0.9490354535155869" />
     <axis xyz="0 1 0"/>
       <limit effort="0.0" lower="-3.14159" upper="3.14159" velocity="0.0"/>
    </joint>
    <link name="link6">
        <inertial>
            <origin xyz="-0.32102856134504976 0.12712013309568543 0.04978941955575231" rpy="0 0 0"/>
            <mass value="1" />
            <inertia ixx="100" ixy="0" ixz="0" iyy="100" iyz="0" izz="100" />
        </inertial>
        <visual>
            <origin xyz="-0.32102856134504976 0.12712013309568543 0.04978941955575231" rpy="0 0 0"/>
            <geometry>
                <box size="0.7868098019167263 0.25424026619137086 0.7032350317145825" />
            </geometry>
            <material name="Green">
                <color rgba="0.0 1.0 0.0 1.0"/>
            </material>
        </visual>
        <collision>
            <origin xyz="-0.32102856134504976 0.12712013309568543 0.04978941955575231" rpy="0 0 0"/>
            <geometry>
                <box size="0.7868098019167263 0.25424026619137086 0.7032350317145825" />
            </geometry>
        </collision>
    </link>
    <joint name="link1_link7" type="revolute">
       <parent link="link1"/>
       <child  link="link7"/>
       <origin rpy="0 0 0" xyz="0.07006123973991285 -0.11585834336483108 0.24624638231554064" />
     <axis xyz="0 1 0"/>
       <limit effort="0.0" lower="-3.14159" upper="3.14159" velocity="0.0"/>
    </joint>
    <link name="link7">
        <inertial>
            <origin xyz="-0.0004505187230024325 0.022449433183070997 0.19714128435456496" rpy="0 0 0"/>
            <mass value="1" />
            <inertia ixx="100" ixy="0" ixz="0" iyy="100" iyz="0" izz="100" />
        </inertial>
        <visual>
            <origin xyz="-0.0004505187230024325 0.022449433183070997 0.19714128435456496" rpy="0 0 0"/>
            <geometry>
                <box size="0.0011688283667969923 0.05135837924453179 0.3942825687091299" />
            </geometry>
            <material name="Green">
                <color rgba="0.0 1.0 0.0 1.0"/>
            </material>
        </visual>
        <collision>
            <origin xyz="-0.0004505187230024325 0.022449433183070997 0.19714128435456496" rpy="0 0 0"/>
            <geometry>
                <box size="0.0011688283667969923 0.05135837924453179 0.3942825687091299" />
            </geometry>
        </collision>
    </link>
    <joint name="link5_link8" type="revolute">
       <parent link="link5"/>
       <child  link="link8"/>
       <origin rpy="0 0 0" xyz="-0.049908992002439256 0.0701176973079293 -0.4998154397766752" />
     <axis xyz="1 0 0"/>
       <limit effort="0.0" lower="-3.14159" upper="3.14159" velocity="0.0"/>
    </joint>
    <link name="link8">
        <inertial>
            <origin xyz="-0.3900958335722133 0.03491780125656483 0.32419501692681246" rpy="0 0 0"/>
            <mass value="1" />
            <inertia ixx="100" ixy="0" ixz="0" iyy="100" iyz="0" izz="100" />
        </inertial>
        <visual>
            <origin xyz="-0.3900958335722133 0.03491780125656483 0.32419501692681246" rpy="0 0 0"/>
            <geometry>
                <box size="0.7801916671444266 0.14779757105615987 0.8541199936134485" />
            </geometry>
            <material name="Green">
                <color rgba="0.0 1.0 0.0 1.0"/>
            </material>
        </visual>
        <collision>
            <origin xyz="-0.3900958335722133 0.03491780125656483 0.32419501692681246" rpy="0 0 0"/>
            <geometry>
                <box size="0.7801916671444266 0.14779757105615987 0.8541199936134485" />
            </geometry>
        </collision>
    </link>
    <joint name="link5_link9" type="revolute">
       <parent link="link5"/>
       <child  link="link9"/>
       <origin rpy="0 0 0" xyz="-0.014348236256466779 0.07640431746693366 -0.14187333112783695" />
     <axis xyz="0 0 1"/>
       <limit effort="0.0" lower="-3.14159" upper="3.14159" velocity="0.0"/>
    </joint>
    <link name="link9">
        <inertial>
            <origin xyz="-0.06143043830346173 0.2390632436856152 0.07080482767346899" rpy="0 0 0"/>
            <mass value="1" />
            <inertia ixx="100" ixy="0" ixz="0" iyy="100" iyz="0" izz="100" />
        </inertial>
        <visual>
            <origin xyz="-0.06143043830346173 0.2390632436856152 0.07080482767346899" rpy="0 0 0"/>
            <geometry>
                <box size="0.16722279255495498 0.4781264873712304 0.6298339204314598" />
            </geometry>
            <material name="Cyan">
                <color rgba="0.0 1.0 1.0 1.0"/>
            </material>
        </visual>
        <collision>
            <origin xyz="-0.06143043830346173 0.2390632436856152 0.07080482767346899" rpy="0 0 0"/>
            <geometry>
                <box size="0.16722279255495498 0.4781264873712304 0.6298339204314598" />
            </geometry>
        </collision>
    </link>
</robot>