<robot name = "robot">
    <link name="link0">
        <inertial>
            <origin xyz="0 0 1" rpy="0 0 0"/>
            <mass value="1" />
            <inertia ixx="100" ixy="0" ixz="0" iyy="100" iyz="0" izz="100" />
        </inertial>
        <visual>
            <origin xyz="0 0 1" rpy="0 0 0"/>
            <geometry>
                <box size="0.05808346011048138 0.7337023033140548 0.8283934439409488" />
            </geometry>
            <material name="Cyan">
                <color rgba="0.0 1.0 1.0 1.0"/>
            </material>
        </visual>
        <collision>
            <origin xyz="0 0 1" rpy="0 0 0"/>
            <geometry>
                <box size="0.05808346011048138 0.7337023033140548 0.8283934439409488" />
            </geometry>
        </collision>
    </link>
    <joint name="link0_link1" type="revolute">
       <parent link="link0"/>
       <child  link="link1"/>
       <origin rpy="0 0 0" xyz="-0.022156225394185974 0.21763249646403132 1.4141967219704745" />
     <axis xyz="0 0 1"/>
       <limit effort="0.0" lower="-3.14159" upper="3.14159" velocity="0.0"/>
    </joint>
    <link name="link1">
        <inertial>
            <origin xyz="0.12424829273786697 -0.10466170665669242 0.4477090153910428" rpy="0 0 0"/>
            <mass value="1" />
            <inertia ixx="100" ixy="0" ixz="0" iyy="100" iyz="0" izz="100" />
        </inertial>
        <visual>
            <origin xyz="0.12424829273786697 -0.10466170665669242 0.4477090153910428" rpy="0 0 0"/>
            <geometry>
                <box size="0.35501850947720326 0.4436210148909874 0.8954180307820856" />
            </geometry>
            <material name="Green">
                <color rgba="0.0 1.0 0.0 1.0"/>
            </material>
        </visual>
        <collision>
            <origin xyz="0.12424829273786697 -0.10466170665669242 0.4477090153910428" rpy="0 0 0"/>
            <geometry>
                <box size="0.35501850947720326 0.4436210148909874 0.8954180307820856" />
            </geometry>
        </collision>
    </link>
    <joint name="link0_link2" type="revolute">
       <parent link="link0"/>
       <child  link="link2"/>
       <origin rpy="0 0 0" xyz="-0.02904173005524069 0.006017965635947251 1.3509036187592898" />
     <axis xyz="1 0 0"/>
       <limit effort="0.0" lower="-3.14159" upper="3.14159" velocity="0.0"/>
    </joint>
    <link name="link2">
        <inertial>
            <origin xyz="-0.2700296287382915 0.05893942831308825 -0.022313585456480406" rpy="0 0 0"/>
            <mass value="1" />
            <inertia ixx="100" ixy="0" ixz="0" iyy="100" iyz="0" izz="100" />
        </inertial>
        <visual>
            <origin xyz="-0.2700296287382915 0.05893942831308825 -0.022313585456480406" rpy="0 0 0"/>
            <geometry>
                <box size="0.540059257476583 0.6471381593990799 0.3109015991153359" />
            </geometry>
            <material name="Green">
                <color rgba="0.0 1.0 0.0 1.0"/>
            </material>
        </visual>
        <collision>
            <origin xyz="-0.2700296287382915 0.05893942831308825 -0.022313585456480406" rpy="0 0 0"/>
            <geometry>
                <box size="0.540059257476583 0.6471381593990799 0.3109015991153359" />
            </geometry>
        </collision>
    </link>
    <joint name="link0_link3" type="revolute">
       <parent link="link0"/>
       <child  link="link3"/>
       <origin rpy="0 0 0" xyz="0.02904173005524069 -0.10953519674715055 0.8622259989832062" />
     <axis xyz="0 1 0"/>
       <limit effort="0.0" lower="-3.14159" upper="3.14159" velocity="0.0"/>
    </joint>
    <link name="link3">
        <inertial>
            <origin xyz="0.3715560314235719 0.0018336268084340802 0.1743983627941696" rpy="0 0 0"/>
            <mass value="1" />
            <inertia ixx="100" ixy="0" ixz="0" iyy="100" iyz="0" izz="100" />
        </inertial>
        <visual>
            <origin xyz="0.3715560314235719 0.0018336268084340802 0.1743983627941696" rpy="0 0 0"/>
            <geometry>
                <box size="0.7431120628471438 0.06416523050450051 0.3811293950354655" />
            </geometry>
            <material name="Green">
                <color rgba="0.0 1.0 0.0 1.0"/>
            </material>
        </visual>
        <collision>
            <origin xyz="0.3715560314235719 0.0018336268084340802 0.1743983627941696" rpy="0 0 0"/>
            <geometry>
                <box size="0.7431120628471438 0.06416523050450051 0.3811293950354655" />
            </geometry>
        </collision>
    </link>
    <joint name="link0_link4" type="revolute">
       <parent link="link0"/>
       <child  link="link4"/>
       <origin rpy="0 0 0" xyz="0.02904173005524069 -0.21447323373273555 0.6150008685685271" />
     <axis xyz="0 0 1"/>
       <limit effort="0.0" lower="-3.14159" upper="3.14159" velocity="0.0"/>
    </joint>
    <link name="link4">
        <inertial>
            <origin xyz="0.2372424232379417 -0.087085704165739 -0.03756872720319312" rpy="0 0 0"/>
            <mass value="1" />
            <inertia ixx="100" ixy="0" ixz="0" iyy="100" iyz="0" izz="100" />
        </inertial>
        <visual>
            <origin xyz="0.2372424232379417 -0.087085704165739 -0.03756872720319312" rpy="0 0 0"/>
            <geometry>
                <box size="0.4744848464758834 0.3055024920527094 0.16187534962059702" />
            </geometry>
            <material name="Green">
                <color rgba="0.0 1.0 0.0 1.0"/>
            </material>
        </visual>
        <collision>
            <origin xyz="0.2372424232379417 -0.087085704165739 -0.03756872720319312" rpy="0 0 0"/>
            <geometry>
                <box size="0.4744848464758834 0.3055024920527094 0.16187534962059702" />
            </geometry>
        </collision>
    </link>
    <joint name="link3_link5" type="revolute">
       <parent link="link3"/>
       <child  link="link5"/>
       <origin rpy="0 0 0" xyz="0.7046681580916678 0.03391624206068434 -0.0054403185167092305" />
     <axis xyz="0 0 1"/>
       <limit effort="0.0" lower="-3.14159" upper="3.14159" velocity="0.0"/>
    </joint>
    <link name="link5">
        <inertial>
            <origin xyz="-0.10247067215553407 0.43192064260498875 -0.2253150259207331" rpy="0 0 0"/>
            <mass value="1" />
            <inertia ixx="100" ixy="0" ixz="0" iyy="100" iyz="0" izz="100" />
        </inertial>
        <visual>
            <origin xyz="-0.10247067215553407 0.43192064260498875 -0.2253150259207331" rpy="0 0 0"/>
            <geometry>
                <box size="0.5424950418172995 0.8638412852099775 0.6622798845730093" />
            </geometry>
            <material name="Green">
                <color rgba="0.0 1.0 0.0 1.0"/>
            </material>
        </visual>
        <collision>
            <origin xyz="-0.10247067215553407 0.43192064260498875 -0.2253150259207331" rpy="0 0 0"/>
            <geometry>
                <box size="0.5424950418172995 0.8638412852099775 0.6622798845730093" />
            </geometry>
        </collision>
    </link>
    <joint name="link1_link6" type="revolute">
       <parent link="link1"/>
       <child  link="link6"/>
       <origin rpy="0 0 0" xyz="0.0028283724594152376 -0.3264722141021861 0.8172166164441284" />
     <axis xyz="0 1 0"/>
       <limit effort="0.0" lower="-3.14159" upper="3.14159" velocity="0.0"/>
    </joint>
    <link name="link6">
        <inertial>
            <origin xyz="0.3105821381344845 -0.018720224345343595 0.04879758347117857" rpy="0 0 0"/>
            <mass value="1" />
            <inertia ixx="100" ixy="0" ixz="0" iyy="100" iyz="0" izz="100" />
        </inertial>
        <visual>
            <origin xyz="0.3105821381344845 -0.018720224345343595 0.04879758347117857" rpy="0 0 0"/>
            <geometry>
                <box size="0.7360142159182957 0.03744044869068719 0.43176735425211166" />
            </geometry>
            <material name="Green">
                <color rgba="0.0 1.0 0.0 1.0"/>
            </material>
        </visual>
        <collision>
            <origin xyz="0.3105821381344845 -0.018720224345343595 0.04879758347117857" rpy="0 0 0"/>
            <geometry>
                <box size="0.7360142159182957 0.03744044869068719 0.43176735425211166" />
            </geometry>
        </collision>
    </link>
</robot>