<robot name = "robot">
    <link name="link0">
        <inertial>
            <origin xyz="0 0 1" rpy="0 0 0"/>
            <mass value="1" />
            <inertia ixx="100" ixy="0" ixz="0" iyy="100" iyz="0" izz="100" />
        </inertial>
        <visual>
            <origin xyz="0 0 1" rpy="0 0 0"/>
            <geometry>
                <box size="0.5716300629017266 0.6498061356206976 0.30746108006904105" />
            </geometry>
            <material name="Cyan">
                <color rgba="0.0 1.0 1.0 1.0"/>
            </material>
        </visual>
        <collision>
            <origin xyz="0 0 1" rpy="0 0 0"/>
            <geometry>
                <box size="0.5716300629017266 0.6498061356206976 0.30746108006904105" />
            </geometry>
        </collision>
    </link>
    <joint name="link0_link1" type="revolute">
       <parent link="link0"/>
       <child  link="link1"/>
       <origin rpy="0 0 0" xyz="0.11868321959495971 0.3249030678103488 0.9683711553385661" />
     <axis xyz="0 0 1"/>
       <limit effort="0.0" lower="-3.14159" upper="3.14159" velocity="0.0"/>
    </joint>
    <link name="link1">
        <inertial>
            <origin xyz="0.18432905894515486 0.12883391284893708 -0.08997865506801439" rpy="0 0 0"/>
            <mass value="1" />
            <inertia ixx="100" ixy="0" ixz="0" iyy="100" iyz="0" izz="100" />
        </inertial>
        <visual>
            <origin xyz="0.18432905894515486 0.12883391284893708 -0.08997865506801439" rpy="0 0 0"/>
            <geometry>
                <box size="0.8147007445875001 0.25766782569787416 0.9114670552566074" />
            </geometry>
            <material name="Cyan">
                <color rgba="0.0 1.0 1.0 1.0"/>
            </material>
        </visual>
        <collision>
            <origin xyz="0.18432905894515486 0.12883391284893708 -0.08997865506801439" rpy="0 0 0"/>
            <geometry>
                <box size="0.8147007445875001 0.25766782569787416 0.9114670552566074" />
            </geometry>
        </collision>
    </link>
    <joint name="link1_link2" type="revolute">
       <parent link="link1"/>
       <child  link="link2"/>
       <origin rpy="0 0 0" xyz="-0.05990512600052303 0.03815569048611575 0.3657548725602893" />
     <axis xyz="0 1 0"/>
       <limit effort="0.0" lower="-3.14159" upper="3.14159" velocity="0.0"/>
    </joint>
    <link name="link2">
        <inertial>
            <origin xyz="0.014906378387999695 0.0715725051206357 0.06794038608551278" rpy="0 0 0"/>
            <mass value="1" />
            <inertia ixx="100" ixy="0" ixz="0" iyy="100" iyz="0" izz="100" />
        </inertial>
        <visual>
            <origin xyz="0.014906378387999695 0.0715725051206357 0.06794038608551278" rpy="0 0 0"/>
            <geometry>
                <box size="0.10492010281367714 0.22283060776838193 0.13588077217102557" />
            </geometry>
            <material name="Green">
                <color rgba="0.0 1.0 0.0 1.0"/>
            </material>
        </visual>
        <collision>
            <origin xyz="0.014906378387999695 0.0715725051206357 0.06794038608551278" rpy="0 0 0"/>
            <geometry>
                <box size="0.10492010281367714 0.22283060776838193 0.13588077217102557" />
            </geometry>
        </collision>
    </link>
    <joint name="link0_link3" type="revolute">
       <parent link="link0"/>
       <child  link="link3"/>
       <origin rpy="0 0 0" xyz="0.05401817614940195 -0.20330012915852272 1.1537305400345206" />
     <axis xyz="0 1 0"/>
       <limit effort="0.0" lower="-3.14159" upper="3.14159" velocity="0.0"/>
    </joint>
    <link name="link3">
        <inertial>
            <origin xyz="-0.2669446311535202 0.12040777130543508 0.43370274422626" rpy="0 0 0"/>
            <mass value="1" />
            <inertia ixx="100" ixy="0" ixz="0" iyy="100" iyz="0" izz="100" />
        </inertial>
        <visual>
            <origin xyz="-0.2669446311535202 0.12040777130543508 0.43370274422626" rpy="0 0 0"/>
            <geometry>
                <box size="0.77693064849458 0.9919127170363808 0.86740548845252" />
            </geometry>
            <material name="Cyan">
                <color rgba="0.0 1.0 1.0 1.0"/>
            </material>
        </visual>
        <collision>
            <origin xyz="-0.2669446311535202 0.12040777130543508 0.43370274422626" rpy="0 0 0"/>
            <geometry>
                <box size="0.77693064849458 0.9919127170363808 0.86740548845252" />
            </geometry>
        </collision>
    </link>
    <joint name="link2_link4" type="revolute">
       <parent link="link2"/>
       <child  link="link4"/>
       <origin rpy="0 0 0" xyz="0.048609156178267096 0.16037385642329027 0.13588077217102557" />
     <axis xyz="1 0 0"/>
       <limit effort="0.0" lower="-3.14159" upper="3.14159" velocity="0.0"/>
    </joint>
    <link name="link4">
        <inertial>
            <origin xyz="-0.20023857537073417 0.18428243952223794 0.29286471258540947" rpy="0 0 0"/>
            <mass value="1" />
            <inertia ixx="100" ixy="0" ixz="0" iyy="100" iyz="0" izz="100" />
        </inertial>
        <visual>
            <origin xyz="-0.20023857537073417 0.18428243952223794 0.29286471258540947" rpy="0 0 0"/>
            <geometry>
                <box size="0.5536531658080528 0.9390826381426045 0.5857294251708189" />
            </geometry>
            <material name="Green">
                <color rgba="0.0 1.0 0.0 1.0"/>
            </material>
        </visual>
        <collision>
            <origin xyz="-0.20023857537073417 0.18428243952223794 0.29286471258540947" rpy="0 0 0"/>
            <geometry>
                <box size="0.5536531658080528 0.9390826381426045 0.5857294251708189" />
            </geometry>
        </collision>
    </link>
    <joint name="link0_link5" type="revolute">
       <parent link="link0"/>
       <child  link="link5"/>
       <origin rpy="0 0 0" xyz="-0.2858150314508633 0.24267297471533117 0.9135593069799528" />
     <axis xyz="0 0 1"/>
       <limit effort="0.0" lower="-3.14159" upper="3.14159" velocity="0.0"/>
    </joint>
    <link name="link5">
        <inertial>
            <origin xyz="-0.16060057269928457 0.005994794200452605 -0.03642264314229101" rpy="0 0 0"/>
            <mass value="1" />
            <inertia ixx="100" ixy="0" ixz="0" iyy="100" iyz="0" izz="100" />
        </inertial>
        <visual>
            <origin xyz="-0.16060057269928457 0.005994794200452605 -0.03642264314229101" rpy="0 0 0"/>
            <geometry>
                <box size="0.32120114539856914 0.07953792661706327 0.3413446160899427" />
            </geometry>
            <material name="Green">
                <color rgba="0.0 1.0 0.0 1.0"/>
            </material>
        </visual>
        <collision>
            <origin xyz="-0.16060057269928457 0.005994794200452605 -0.03642264314229101" rpy="0 0 0"/>
            <geometry>
                <box size="0.32120114539856914 0.07953792661706327 0.3413446160899427" />
            </geometry>
        </collision>
    </link>
    <joint name="link2_link6" type="revolute">
       <parent link="link2"/>
       <child  link="link6"/>
       <origin rpy="0 0 0" xyz="0.02234224517418723 0.10212308309473624 0.13588077217102557" />
     <axis xyz="0 1 0"/>
       <limit effort="0.0" lower="-3.14159" upper="3.14159" velocity="0.0"/>
    </joint>
    <link name="link6">
        <inertial>
            <origin xyz="0.004988908959184419 -0.040854189827562296 0.07819909776549788" rpy="0 0 0"/>
            <mass value="1" />
            <inertia ixx="100" ixy="0" ixz="0" iyy="100" iyz="0" izz="100" />
        </inertial>
        <visual>
            <origin xyz="0.004988908959184419 -0.040854189827562296 0.07819909776549788" rpy="0 0 0"/>
            <geometry>
                <box size="0.013255498035075197 0.11544359060163756 0.15639819553099576" />
            </geometry>
            <material name="Cyan">
                <color rgba="0.0 1.0 1.0 1.0"/>
            </material>
        </visual>
        <collision>
            <origin xyz="0.004988908959184419 -0.040854189827562296 0.07819909776549788" rpy="0 0 0"/>
            <geometry>
                <box size="0.013255498035075197 0.11544359060163756 0.15639819553099576" />
            </geometry>
        </collision>
    </link>
    <joint name="link4_link7" type="revolute">
       <parent link="link4"/>
       <child  link="link7"/>
       <origin rpy="0 0 0" xyz="0.07658800753329223 0.38956186045703434 0.1992546177450832" />
     <axis xyz="0 0 1"/>
       <limit effort="0.0" lower="-3.14159" upper="3.14159" velocity="0.0"/>
    </joint>
    <link name="link7">
        <inertial>
            <origin xyz="0.238831779802114 -0.18391699750103313 0.14917859362030694" rpy="0 0 0"/>
            <mass value="1" />
            <inertia ixx="100" ixy="0" ixz="0" iyy="100" iyz="0" izz="100" />
        </inertial>
        <visual>
            <origin xyz="0.238831779802114 -0.18391699750103313 0.14917859362030694" rpy="0 0 0"/>
            <geometry>
                <box size="0.477663559604228 0.39818099519286143 0.34865729041192306" />
            </geometry>
            <material name="Cyan">
                <color rgba="0.0 1.0 1.0 1.0"/>
            </material>
        </visual>
        <collision>
            <origin xyz="0.238831779802114 -0.18391699750103313 0.14917859362030694" rpy="0 0 0"/>
            <geometry>
                <box size="0.477663559604228 0.39818099519286143 0.34865729041192306" />
            </geometry>
        </collision>
    </link>
    <joint name="link6_link8" type="revolute">
       <parent link="link6"/>
       <child  link="link8"/>
       <origin rpy="0 0 0" xyz="-0.0016388400583531798 -0.06895373543491255 0.1105708479681691" />
     <axis xyz="0 0 1"/>
       <limit effort="0.0" lower="-3.14159" upper="3.14159" velocity="0.0"/>
    </joint>
    <link name="link8">
        <inertial>
            <origin xyz="-0.4305215149854172 -0.14516665874199272 -0.08203739065335668" rpy="0 0 0"/>
            <mass value="1" />
            <inertia ixx="100" ixy="0" ixz="0" iyy="100" iyz="0" izz="100" />
        </inertial>
        <visual>
            <origin xyz="-0.4305215149854172 -0.14516665874199272 -0.08203739065335668" rpy="0 0 0"/>
            <geometry>
                <box size="0.8610430299708344 0.718266825920471 0.3394787473946076" />
            </geometry>
            <material name="Cyan">
                <color rgba="0.0 1.0 1.0 1.0"/>
            </material>
        </visual>
        <collision>
            <origin xyz="-0.4305215149854172 -0.14516665874199272 -0.08203739065335668" rpy="0 0 0"/>
            <geometry>
                <box size="0.8610430299708344 0.718266825920471 0.3394787473946076" />
            </geometry>
        </collision>
    </link>
</robot>