<robot name = "robot">
    <link name="link0">
        <inertial>
            <origin xyz="0 0 1" rpy="0 0 0"/>
            <mass value="1" />
            <inertia ixx="100" ixy="0" ixz="0" iyy="100" iyz="0" izz="100" />
        </inertial>
        <visual>
            <origin xyz="0 0 1" rpy="0 0 0"/>
            <geometry>
                <box size="0.4761236881474429 0.15477716448470624 0.16038066488003655" />
            </geometry>
            <material name="Cyan">
                <color rgba="0 1.0 1.0 1.0"/>
            </material>
        </visual>
        <collision>
            <origin xyz="0 0 1" rpy="0 0 0"/>
            <geometry>
                <box size="0.4761236881474429 0.15477716448470624 0.16038066488003655" />
            </geometry>
        </collision>
    </link>
    <joint name="link0_link1" type="revolute">
       <parent link="link0"/>
       <child  link="link1"/>
       <origin rpy="0 0 0" xyz="-0.040024701246442244 -0.07738858224235312 1.0059105441987122" />
     <axis xyz="1 0 0"/>
       <limit effort="0.0" lower="-3.14159" upper="3.14159" velocity="0.0"/>
    </joint>
    <link name="link1">
        <inertial>
            <origin xyz="-0.17620238207982356 -0.09783509997425399 -0.257542194506492" rpy="0 0 0"/>
            <mass value="1" />
            <inertia ixx="100" ixy="0" ixz="0" iyy="100" iyz="0" izz="100" />
        </inertial>
        <visual>
            <origin xyz="-0.17620238207982356 -0.09783509997425399 -0.257542194506492" rpy="0 0 0"/>
            <geometry>
                <box size="0.5402023593896198 0.19567019994850798 0.841759568743768" />
            </geometry>
            <material name="Cyan">
                <color rgba="0 1.0 1.0 1.0"/>
            </material>
        </visual>
        <collision>
            <origin xyz="-0.17620238207982356 -0.09783509997425399 -0.257542194506492" rpy="0 0 0"/>
            <geometry>
                <box size="0.5402023593896198 0.19567019994850798 0.841759568743768" />
            </geometry>
        </collision>
    </link>
    <joint name="link0_link2" type="revolute">
       <parent link="link0"/>
       <child  link="link2"/>
       <origin rpy="0 0 0" xyz="0.018560623328481837 0.040430678728360876 0.9198096675599817" />
     <axis xyz="0 0 1"/>
       <limit effort="0.0" lower="-3.14159" upper="3.14159" velocity="0.0"/>
    </joint>
    <link name="link2">
        <inertial>
            <origin xyz="0.26317519083939533 0.030347785274415447 -0.426651447135459" rpy="0 0 0"/>
            <mass value="1" />
            <inertia ixx="100" ixy="0" ixz="0" iyy="100" iyz="0" izz="100" />
        </inertial>
        <visual>
            <origin xyz="0.26317519083939533 0.030347785274415447 -0.426651447135459" rpy="0 0 0"/>
            <geometry>
                <box size="0.7601586761610978 0.26246550915692346 0.853302894270918" />
            </geometry>
            <material name="Cyan">
                <color rgba="0 1.0 1.0 1.0"/>
            </material>
        </visual>
        <collision>
            <origin xyz="0.26317519083939533 0.030347785274415447 -0.426651447135459" rpy="0 0 0"/>
            <geometry>
                <box size="0.7601586761610978 0.26246550915692346 0.853302894270918" />
            </geometry>
        </collision>
    </link>
    <joint name="link2_link3" type="revolute">
       <parent link="link2"/>
       <child  link="link3"/>
       <origin rpy="0 0 0" xyz="-0.11690414724115356 0.011548384967715031 -0.17009226096171642" />
     <axis xyz="0 0 1"/>
       <limit effort="0.0" lower="-3.14159" upper="3.14159" velocity="0.0"/>
    </joint>
    <link name="link3">
        <inertial>
            <origin xyz="-0.40842527572612697 0.008289406420550073 0.18983546602991613" rpy="0 0 0"/>
            <mass value="1" />
            <inertia ixx="100" ixy="0" ixz="0" iyy="100" iyz="0" izz="100" />
        </inertial>
        <visual>
            <origin xyz="-0.40842527572612697 0.008289406420550073 0.18983546602991613" rpy="0 0 0"/>
            <geometry>
                <box size="0.8168505514522539 0.18800759399070843 0.9239322108841793" />
            </geometry>
            <material name="Cyan">
                <color rgba="0 1.0 1.0 1.0"/>
            </material>
        </visual>
        <collision>
            <origin xyz="-0.40842527572612697 0.008289406420550073 0.18983546602991613" rpy="0 0 0"/>
            <geometry>
                <box size="0.8168505514522539 0.18800759399070843 0.9239322108841793" />
            </geometry>
        </collision>
    </link>
    <joint name="link1_link4" type="revolute">
       <parent link="link1"/>
       <child  link="link4"/>
       <origin rpy="0 0 0" xyz="-0.4463035617746335 -0.03809336640431829 -0.12930245870745022" />
     <axis xyz="0 0 1"/>
       <limit effort="0.0" lower="-3.14159" upper="3.14159" velocity="0.0"/>
    </joint>
    <link name="link4">
        <inertial>
            <origin xyz="-0.11394833709581864 -0.3364149914413146 -0.12658756196741228" rpy="0 0 0"/>
            <mass value="1" />
            <inertia ixx="100" ixy="0" ixz="0" iyy="100" iyz="0" izz="100" />
        </inertial>
        <visual>
            <origin xyz="-0.11394833709581864 -0.3364149914413146 -0.12658756196741228" rpy="0 0 0"/>
            <geometry>
                <box size="0.22789667419163728 0.8127167261552232 0.9891601839671934" />
            </geometry>
            <material name="Cyan">
                <color rgba="0 1.0 1.0 1.0"/>
            </material>
        </visual>
        <collision>
            <origin xyz="-0.11394833709581864 -0.3364149914413146 -0.12658756196741228" rpy="0 0 0"/>
            <geometry>
                <box size="0.22789667419163728 0.8127167261552232 0.9891601839671934" />
            </geometry>
        </collision>
    </link>
    <joint name="link0_link5" type="revolute">
       <parent link="link0"/>
       <child  link="link5"/>
       <origin rpy="0 0 0" xyz="-0.23806184407372144 -0.032945516136026386 0.9619582632717091" />
     <axis xyz="0 1 0"/>
       <limit effort="0.0" lower="-3.14159" upper="3.14159" velocity="0.0"/>
    </joint>
    <link name="link5">
        <inertial>
            <origin xyz="-0.0009000010532273506 -0.040390178399719194 0.020071882859322734" rpy="0 0 0"/>
            <mass value="1" />
            <inertia ixx="100" ixy="0" ixz="0" iyy="100" iyz="0" izz="100" />
        </inertial>
        <visual>
            <origin xyz="-0.0009000010532273506 -0.040390178399719194 0.020071882859322734" rpy="0 0 0"/>
            <geometry>
                <box size="0.0018000021064547012 0.293583621610646 0.12596897776559202" />
            </geometry>
            <material name="Cyan">
                <color rgba="0 1.0 1.0 1.0"/>
            </material>
        </visual>
        <collision>
            <origin xyz="-0.0009000010532273506 -0.040390178399719194 0.020071882859322734" rpy="0 0 0"/>
            <geometry>
                <box size="0.0018000021064547012 0.293583621610646 0.12596897776559202" />
            </geometry>
        </collision>
    </link>
    <joint name="link2_link6" type="revolute">
       <parent link="link2"/>
       <child  link="link6"/>
       <origin rpy="0 0 0" xyz="0.24724741221514074 -0.10088496930404628 -0.523982768159115" />
     <axis xyz="1 0 0"/>
       <limit effort="0.0" lower="-3.14159" upper="3.14159" velocity="0.0"/>
    </joint>
    <link name="link6">
        <inertial>
            <origin xyz="-0.02772103665217577 -0.10441930213038703 -0.0485401055334474" rpy="0 0 0"/>
            <mass value="1" />
            <inertia ixx="100" ixy="0" ixz="0" iyy="100" iyz="0" izz="100" />
        </inertial>
        <visual>
            <origin xyz="-0.02772103665217577 -0.10441930213038703 -0.0485401055334474" rpy="0 0 0"/>
            <geometry>
                <box size="0.4931575257279087 0.20883860426077405 0.13469091745029216" />
            </geometry>
            <material name="Cyan">
                <color rgba="0 1.0 1.0 1.0"/>
            </material>
        </visual>
        <collision>
            <origin xyz="-0.02772103665217577 -0.10441930213038703 -0.0485401055334474" rpy="0 0 0"/>
            <geometry>
                <box size="0.4931575257279087 0.20883860426077405 0.13469091745029216" />
            </geometry>
        </collision>
    </link>
</robot>