<robot name = "robot">
    <link name="link0">
        <inertial>
            <origin xyz="0 0 1" rpy="0 0 0"/>
            <mass value="1" />
            <inertia ixx="100" ixy="0" ixz="0" iyy="100" iyz="0" izz="100" />
        </inertial>
        <visual>
            <origin xyz="0 0 1" rpy="0 0 0"/>
            <geometry>
                <box size="0.8190402304261833 0.9981145113917321 0.6257408285558247" />
            </geometry>
            <material name="Cyan">
                <color rgba="0.0 1.0 1.0 1.0"/>
            </material>
        </visual>
        <collision>
            <origin xyz="0 0 1" rpy="0 0 0"/>
            <geometry>
                <box size="0.8190402304261833 0.9981145113917321 0.6257408285558247" />
            </geometry>
        </collision>
    </link>
    <joint name="link0_link1" type="revolute">
       <parent link="link0"/>
       <child  link="link1"/>
       <origin rpy="0 0 0" xyz="0.3473884056355175 -0.43371062682678946 1.3128704142779124" />
     <axis xyz="0 1 0"/>
       <limit effort="0.0" lower="-3.14159" upper="3.14159" velocity="0.0"/>
    </joint>
    <link name="link1">
        <inertial>
            <origin xyz="0.039428630236773045 -0.06647542829861774 0.2986901273128243" rpy="0 0 0"/>
            <mass value="1" />
            <inertia ixx="100" ixy="0" ixz="0" iyy="100" iyz="0" izz="100" />
        </inertial>
        <visual>
            <origin xyz="0.039428630236773045 -0.06647542829861774 0.2986901273128243" rpy="0 0 0"/>
            <geometry>
                <box size="0.6225737883992468 0.8147119455246457 0.5973802546256486" />
            </geometry>
            <material name="Green">
                <color rgba="0.0 1.0 0.0 1.0"/>
            </material>
        </visual>
        <collision>
            <origin xyz="0.039428630236773045 -0.06647542829861774 0.2986901273128243" rpy="0 0 0"/>
            <geometry>
                <box size="0.6225737883992468 0.8147119455246457 0.5973802546256486" />
            </geometry>
        </collision>
    </link>
    <joint name="link0_link2" type="revolute">
       <parent link="link0"/>
       <child  link="link2"/>
       <origin rpy="0 0 0" xyz="0.08657811018306538 -0.23523974729128086 1.3128704142779124" />
     <axis xyz="1 0 0"/>
       <limit effort="0.0" lower="-3.14159" upper="3.14159" velocity="0.0"/>
    </joint>
    <link name="link2">
        <inertial>
            <origin xyz="0.13116818270863392 -0.1432262142739606 0.3279504144468432" rpy="0 0 0"/>
            <mass value="1" />
            <inertia ixx="100" ixy="0" ixz="0" iyy="100" iyz="0" izz="100" />
        </inertial>
        <visual>
            <origin xyz="0.13116818270863392 -0.1432262142739606 0.3279504144468432" rpy="0 0 0"/>
            <geometry>
                <box size="0.6952393183794504 0.9266457741404723 0.6559008288936864" />
            </geometry>
            <material name="Green">
                <color rgba="0.0 1.0 0.0 1.0"/>
            </material>
        </visual>
        <collision>
            <origin xyz="0.13116818270863392 -0.1432262142739606 0.3279504144468432" rpy="0 0 0"/>
            <geometry>
                <box size="0.6952393183794504 0.9266457741404723 0.6559008288936864" />
            </geometry>
        </collision>
    </link>
    <joint name="link2_link3" type="revolute">
       <parent link="link2"/>
       <child  link="link3"/>
       <origin rpy="0 0 0" xyz="-0.17631870299434502 -0.6065491013441968 0.5424884543912631" />
     <axis xyz="0 0 1"/>
       <limit effort="0.0" lower="-3.14159" upper="3.14159" velocity="0.0"/>
    </joint>
    <link name="link3">
        <inertial>
            <origin xyz="0.01856528907367991 -0.4551411926660661 -0.0003745242035036863" rpy="0 0 0"/>
            <mass value="1" />
            <inertia ixx="100" ixy="0" ixz="0" iyy="100" iyz="0" izz="100" />
        </inertial>
        <visual>
            <origin xyz="0.01856528907367991 -0.4551411926660661 -0.0003745242035036863" rpy="0 0 0"/>
            <geometry>
                <box size="0.3618202010164351 0.9102823853321322 0.013504571001032861" />
            </geometry>
            <material name="Green">
                <color rgba="0.0 1.0 0.0 1.0"/>
            </material>
        </visual>
        <collision>
            <origin xyz="0.01856528907367991 -0.4551411926660661 -0.0003745242035036863" rpy="0 0 0"/>
            <geometry>
                <box size="0.3618202010164351 0.9102823853321322 0.013504571001032861" />
            </geometry>
        </collision>
    </link>
    <joint name="link2_link4" type="revolute">
       <parent link="link2"/>
       <child  link="link4"/>
       <origin rpy="0 0 0" xyz="0.20902460399215889 -0.6065491013441968 0.022841243794832544" />
     <axis xyz="1 0 0"/>
       <limit effort="0.0" lower="-3.14159" upper="3.14159" velocity="0.0"/>
    </joint>
    <link name="link4">
        <inertial>
            <origin xyz="0.4003923618015991 -0.011305745244253651 -0.26367884402933456" rpy="0 0 0"/>
            <mass value="1" />
            <inertia ixx="100" ixy="0" ixz="0" iyy="100" iyz="0" izz="100" />
        </inertial>
        <visual>
            <origin xyz="0.4003923618015991 -0.011305745244253651 -0.26367884402933456" rpy="0 0 0"/>
            <geometry>
                <box size="0.9793601035251867 0.022611490488507302 0.7738630147651886" />
            </geometry>
            <material name="Green">
                <color rgba="0.0 1.0 0.0 1.0"/>
            </material>
        </visual>
        <collision>
            <origin xyz="0.4003923618015991 -0.011305745244253651 -0.26367884402933456" rpy="0 0 0"/>
            <geometry>
                <box size="0.9793601035251867 0.022611490488507302 0.7738630147651886" />
            </geometry>
        </collision>
    </link>
    <joint name="link0_link5" type="revolute">
       <parent link="link0"/>
       <child  link="link5"/>
       <origin rpy="0 0 0" xyz="0.24067870995058263 -0.49905725569586606 0.9379544511047863" />
     <axis xyz="1 0 0"/>
       <limit effort="0.0" lower="-3.14159" upper="3.14159" velocity="0.0"/>
    </joint>
    <link name="link5">
        <inertial>
            <origin xyz="0.03134260105266844 -0.07102101858067505 -0.05934614532282515" rpy="0 0 0"/>
            <mass value="1" />
            <inertia ixx="100" ixy="0" ixz="0" iyy="100" iyz="0" izz="100" />
        </inertial>
        <visual>
            <origin xyz="0.03134260105266844 -0.07102101858067505 -0.05934614532282515" rpy="0 0 0"/>
            <geometry>
                <box size="0.12768922603639976 0.1420420371613501 0.2691086867051242" />
            </geometry>
            <material name="Green">
                <color rgba="0.0 1.0 0.0 1.0"/>
            </material>
        </visual>
        <collision>
            <origin xyz="0.03134260105266844 -0.07102101858067505 -0.05934614532282515" rpy="0 0 0"/>
            <geometry>
                <box size="0.12768922603639976 0.1420420371613501 0.2691086867051242" />
            </geometry>
        </collision>
    </link>
    <joint name="link3_link6" type="revolute">
       <parent link="link3"/>
       <child  link="link6"/>
       <origin rpy="0 0 0" xyz="0.07957976551693619 -0.9102823853321322 0.000979150614308438" />
     <axis xyz="0 1 0"/>
       <limit effort="0.0" lower="-3.14159" upper="3.14159" velocity="0.0"/>
    </joint>
    <link name="link6">
        <inertial>
            <origin xyz="0.2427551813583369 -0.14453413106463325 0.4315353012212265" rpy="0 0 0"/>
            <mass value="1" />
            <inertia ixx="100" ixy="0" ixz="0" iyy="100" iyz="0" izz="100" />
        </inertial>
        <visual>
            <origin xyz="0.2427551813583369 -0.14453413106463325 0.4315353012212265" rpy="0 0 0"/>
            <geometry>
                <box size="0.982863960456406 0.2890682621292665 0.8813299653201278" />
            </geometry>
            <material name="Green">
                <color rgba="0.0 1.0 0.0 1.0"/>
            </material>
        </visual>
        <collision>
            <origin xyz="0.2427551813583369 -0.14453413106463325 0.4315353012212265" rpy="0 0 0"/>
            <geometry>
                <box size="0.982863960456406 0.2890682621292665 0.8813299653201278" />
            </geometry>
        </collision>
    </link>
    <joint name="link0_link7" type="revolute">
       <parent link="link0"/>
       <child  link="link7"/>
       <origin rpy="0 0 0" xyz="-0.3002078981685136 0.49905725569586606 1.0221137331037717" />
     <axis xyz="0 1 0"/>
       <limit effort="0.0" lower="-3.14159" upper="3.14159" velocity="0.0"/>
    </joint>
    <link name="link7">
        <inertial>
            <origin xyz="-0.0031388804540613277 0.3423671350013793 0.00248715288321714" rpy="0 0 0"/>
            <mass value="1" />
            <inertia ixx="100" ixy="0" ixz="0" iyy="100" iyz="0" izz="100" />
        </inertial>
        <visual>
            <origin xyz="-0.0031388804540613277 0.3423671350013793 0.00248715288321714" rpy="0 0 0"/>
            <geometry>
                <box size="0.009293025476349803 0.6847342700027585 0.008943043994374289" />
            </geometry>
            <material name="Green">
                <color rgba="0.0 1.0 0.0 1.0"/>
            </material>
        </visual>
        <collision>
            <origin xyz="-0.0031388804540613277 0.3423671350013793 0.00248715288321714" rpy="0 0 0"/>
            <geometry>
                <box size="0.009293025476349803 0.6847342700027585 0.008943043994374289" />
            </geometry>
        </collision>
    </link>
    <joint name="link6_link8" type="revolute">
       <parent link="link6"/>
       <child  link="link8"/>
       <origin rpy="0 0 0" xyz="-0.038546655145333675 -0.2890682621292665 0.2259710012494859" />
     <axis xyz="1 0 0"/>
       <limit effort="0.0" lower="-3.14159" upper="3.14159" velocity="0.0"/>
    </joint>
    <link name="link8">
        <inertial>
            <origin xyz="-0.2758900733462604 -0.33076691042652545 -0.12602616942039857" rpy="0 0 0"/>
            <mass value="1" />
            <inertia ixx="100" ixy="0" ixz="0" iyy="100" iyz="0" izz="100" />
        </inertial>
        <visual>
            <origin xyz="-0.2758900733462604 -0.33076691042652545 -0.12602616942039857" rpy="0 0 0"/>
            <geometry>
                <box size="0.6974351753475226 0.6615338208530509 0.6643613364809736" />
            </geometry>
            <material name="Green">
                <color rgba="0.0 1.0 0.0 1.0"/>
            </material>
        </visual>
        <collision>
            <origin xyz="-0.2758900733462604 -0.33076691042652545 -0.12602616942039857" rpy="0 0 0"/>
            <geometry>
                <box size="0.6974351753475226 0.6615338208530509 0.6643613364809736" />
            </geometry>
        </collision>
    </link>
</robot>