<robot name = "robot">
    <link name="link0">
        <inertial>
            <origin xyz="0 0 1" rpy="0 0 0"/>
            <mass value="1" />
            <inertia ixx="100" ixy="0" ixz="0" iyy="100" iyz="0" izz="100" />
        </inertial>
        <visual>
            <origin xyz="0 0 1" rpy="0 0 0"/>
            <geometry>
                <box size="0.3227355504782078 0.8711049621156418 0.9252392212268591" />
            </geometry>
            <material name="Cyan">
                <color rgba="0.0 1.0 1.0 1.0"/>
            </material>
        </visual>
        <collision>
            <origin xyz="0 0 1" rpy="0 0 0"/>
            <geometry>
                <box size="0.3227355504782078 0.8711049621156418 0.9252392212268591" />
            </geometry>
        </collision>
    </link>
    <joint name="link0_link1" type="revolute">
       <parent link="link0"/>
       <child  link="link1"/>
       <origin rpy="0 0 0" xyz="0.0681022865712166 -0.061076828767252865 1.4626196106134295" />
     <axis xyz="0 1 0"/>
       <limit effort="0.0" lower="-3.14159" upper="3.14159" velocity="0.0"/>
    </joint>
    <link name="link1">
        <inertial>
            <origin xyz="-0.106452135225699 0.07691180880718063 0.3595199377875168" rpy="0 0 0"/>
            <mass value="1" />
            <inertia ixx="100" ixy="0" ixz="0" iyy="100" iyz="0" izz="100" />
        </inertial>
        <visual>
            <origin xyz="-0.106452135225699 0.07691180880718063 0.3595199377875168" rpy="0 0 0"/>
            <geometry>
                <box size="0.6319987270622902 0.39221665765634806 0.7190398755750336" />
            </geometry>
            <material name="Cyan">
                <color rgba="0.0 1.0 1.0 1.0"/>
            </material>
        </visual>
        <collision>
            <origin xyz="-0.106452135225699 0.07691180880718063 0.3595199377875168" rpy="0 0 0"/>
            <geometry>
                <box size="0.6319987270622902 0.39221665765634806 0.7190398755750336" />
            </geometry>
        </collision>
    </link>
    <joint name="link1_link2" type="revolute">
       <parent link="link1"/>
       <child  link="link2"/>
       <origin rpy="0 0 0" xyz="0.2095472283054461 0.11902987060585277 0.3890967781297961" />
     <axis xyz="0 0 1"/>
       <limit effort="0.0" lower="-3.14159" upper="3.14159" velocity="0.0"/>
    </joint>
    <link name="link2">
        <inertial>
            <origin xyz="0.3896918967795991 0.05752618415933061 -0.018806491651975794" rpy="0 0 0"/>
            <mass value="1" />
            <inertia ixx="100" ixy="0" ixz="0" iyy="100" iyz="0" izz="100" />
        </inertial>
        <visual>
            <origin xyz="0.3896918967795991 0.05752618415933061 -0.018806491651975794" rpy="0 0 0"/>
            <geometry>
                <box size="0.7793837935591982 0.36091401579588567 0.2709378599510347" />
            </geometry>
            <material name="Green">
                <color rgba="0.0 1.0 0.0 1.0"/>
            </material>
        </visual>
        <collision>
            <origin xyz="0.3896918967795991 0.05752618415933061 -0.018806491651975794" rpy="0 0 0"/>
            <geometry>
                <box size="0.7793837935591982 0.36091401579588567 0.2709378599510347" />
            </geometry>
        </collision>
    </link>
    <joint name="link2_link3" type="revolute">
       <parent link="link2"/>
       <child  link="link3"/>
       <origin rpy="0 0 0" xyz="0.7793837935591982 -0.030819978917347085 0.035312857341231456" />
     <axis xyz="0 1 0"/>
       <limit effort="0.0" lower="-3.14159" upper="3.14159" velocity="0.0"/>
    </joint>
    <link name="link3">
        <inertial>
            <origin xyz="0.13902651941710853 -0.2960955927595783 -0.11155711502353506" rpy="0 0 0"/>
            <mass value="1" />
            <inertia ixx="100" ixy="0" ixz="0" iyy="100" iyz="0" izz="100" />
        </inertial>
        <visual>
            <origin xyz="0.13902651941710853 -0.2960955927595783 -0.11155711502353506" rpy="0 0 0"/>
            <geometry>
                <box size="0.27805303883421706 0.9102006166690791 0.6894411200218985" />
            </geometry>
            <material name="Green">
                <color rgba="0.0 1.0 0.0 1.0"/>
            </material>
        </visual>
        <collision>
            <origin xyz="0.13902651941710853 -0.2960955927595783 -0.11155711502353506" rpy="0 0 0"/>
            <geometry>
                <box size="0.27805303883421706 0.9102006166690791 0.6894411200218985" />
            </geometry>
        </collision>
    </link>
    <joint name="link2_link4" type="revolute">
       <parent link="link2"/>
       <child  link="link4"/>
       <origin rpy="0 0 0" xyz="0.6084421900663695 0.002833897412988645 0.11666243832354156" />
     <axis xyz="0 0 1"/>
       <limit effort="0.0" lower="-3.14159" upper="3.14159" velocity="0.0"/>
    </joint>
    <link name="link4">
        <inertial>
            <origin xyz="0.4052868802175719 0.02445121510383893 0.18481709114200157" rpy="0 0 0"/>
            <mass value="1" />
            <inertia ixx="100" ixy="0" ixz="0" iyy="100" iyz="0" izz="100" />
        </inertial>
        <visual>
            <origin xyz="0.4052868802175719 0.02445121510383893 0.18481709114200157" rpy="0 0 0"/>
            <geometry>
                <box size="0.8402295863900969 0.8139699121755882 0.36963418228400313" />
            </geometry>
            <material name="Green">
                <color rgba="0.0 1.0 0.0 1.0"/>
            </material>
        </visual>
        <collision>
            <origin xyz="0.4052868802175719 0.02445121510383893 0.18481709114200157" rpy="0 0 0"/>
            <geometry>
                <box size="0.8402295863900969 0.8139699121755882 0.36963418228400313" />
            </geometry>
        </collision>
    </link>
    <joint name="link4_link5" type="revolute">
       <parent link="link4"/>
       <child  link="link5"/>
       <origin rpy="0 0 0" xyz="0.21575994733699938 -0.3825337409839552 0.0902634752610288" />
     <axis xyz="0 1 0"/>
       <limit effort="0.0" lower="-3.14159" upper="3.14159" velocity="0.0"/>
    </joint>
    <link name="link5">
        <inertial>
            <origin xyz="-0.001089636728481583 -0.44059592045345125 -0.029878782839596097" rpy="0 0 0"/>
            <mass value="1" />
            <inertia ixx="100" ixy="0" ixz="0" iyy="100" iyz="0" izz="100" />
        </inertial>
        <visual>
            <origin xyz="-0.001089636728481583 -0.44059592045345125 -0.029878782839596097" rpy="0 0 0"/>
            <geometry>
                <box size="0.032803480614995606 0.8811918409069025 0.34559728262879674" />
            </geometry>
            <material name="Green">
                <color rgba="0.0 1.0 0.0 1.0"/>
            </material>
        </visual>
        <collision>
            <origin xyz="-0.001089636728481583 -0.44059592045345125 -0.029878782839596097" rpy="0 0 0"/>
            <geometry>
                <box size="0.032803480614995606 0.8811918409069025 0.34559728262879674" />
            </geometry>
        </collision>
    </link>
    <joint name="link2_link6" type="revolute">
       <parent link="link2"/>
       <child  link="link6"/>
       <origin rpy="0 0 0" xyz="0.7793837935591982 0.10956393016104118 -0.11771634911386059" />
     <axis xyz="0 1 0"/>
       <limit effort="0.0" lower="-3.14159" upper="3.14159" velocity="0.0"/>
    </joint>
    <link name="link6">
        <inertial>
            <origin xyz="0.05770080014849999 -0.04572214969050642 0.025725913864443253" rpy="0 0 0"/>
            <mass value="1" />
            <inertia ixx="100" ixy="0" ixz="0" iyy="100" iyz="0" izz="100" />
        </inertial>
        <visual>
            <origin xyz="0.05770080014849999 -0.04572214969050642 0.025725913864443253" rpy="0 0 0"/>
            <geometry>
                <box size="0.11540160029699997 0.4106660725637483 0.08062550583789707" />
            </geometry>
            <material name="Cyan">
                <color rgba="0.0 1.0 1.0 1.0"/>
            </material>
        </visual>
        <collision>
            <origin xyz="0.05770080014849999 -0.04572214969050642 0.025725913864443253" rpy="0 0 0"/>
            <geometry>
                <box size="0.11540160029699997 0.4106660725637483 0.08062550583789707" />
            </geometry>
        </collision>
    </link>
    <joint name="link3_link7" type="revolute">
       <parent link="link3"/>
       <child  link="link7"/>
       <origin rpy="0 0 0" xyz="0.27805303883421706 -0.06537239503547404 -0.2898576366162594" />
     <axis xyz="1 0 0"/>
       <limit effort="0.0" lower="-3.14159" upper="3.14159" velocity="0.0"/>
    </joint>
    <link name="link7">
        <inertial>
            <origin xyz="0.4159528096301804 0.21809380199602701 0.11527425468744568" rpy="0 0 0"/>
            <mass value="1" />
            <inertia ixx="100" ixy="0" ixz="0" iyy="100" iyz="0" izz="100" />
        </inertial>
        <visual>
            <origin xyz="0.4159528096301804 0.21809380199602701 0.11527425468744568" rpy="0 0 0"/>
            <geometry>
                <box size="0.8319056192603608 0.6745940966240302 0.9485641853964666" />
            </geometry>
            <material name="Cyan">
                <color rgba="0.0 1.0 1.0 1.0"/>
            </material>
        </visual>
        <collision>
            <origin xyz="0.4159528096301804 0.21809380199602701 0.11527425468744568" rpy="0 0 0"/>
            <geometry>
                <box size="0.8319056192603608 0.6745940966240302 0.9485641853964666" />
            </geometry>
        </collision>
    </link>
    <joint name="link2_link8" type="revolute">
       <parent link="link2"/>
       <child  link="link8"/>
       <origin rpy="0 0 0" xyz="0.7793837935591982 0.21033973338374523 -0.02416018492065566" />
     <axis xyz="0 1 0"/>
       <limit effort="0.0" lower="-3.14159" upper="3.14159" velocity="0.0"/>
    </joint>
    <link name="link8">
        <inertial>
            <origin xyz="0.20381295221485224 -0.037944565456102086 0.0028033145190178273" rpy="0 0 0"/>
            <mass value="1" />
            <inertia ixx="100" ixy="0" ixz="0" iyy="100" iyz="0" izz="100" />
        </inertial>
        <visual>
            <origin xyz="0.20381295221485224 -0.037944565456102086 0.0028033145190178273" rpy="0 0 0"/>
            <geometry>
                <box size="0.4076259044297045 0.0835557153384705 0.5406951456213263" />
            </geometry>
            <material name="Green">
                <color rgba="0.0 1.0 0.0 1.0"/>
            </material>
        </visual>
        <collision>
            <origin xyz="0.20381295221485224 -0.037944565456102086 0.0028033145190178273" rpy="0 0 0"/>
            <geometry>
                <box size="0.4076259044297045 0.0835557153384705 0.5406951456213263" />
            </geometry>
        </collision>
    </link>
</robot>