<robot name = "robot">
    <link name="link0">
        <inertial>
            <origin xyz="0 0 1" rpy="0 0 0"/>
            <mass value="1" />
            <inertia ixx="100" ixy="0" ixz="0" iyy="100" iyz="0" izz="100" />
        </inertial>
        <visual>
            <origin xyz="0 0 1" rpy="0 0 0"/>
            <geometry>
                <box size="0.0920014149172661 0.32267948107034783 0.39636092900322384" />
            </geometry>
            <material name="Cyan">
                <color rgba="0.0 1.0 1.0 1.0"/>
            </material>
        </visual>
        <collision>
            <origin xyz="0 0 1" rpy="0 0 0"/>
            <geometry>
                <box size="0.0920014149172661 0.32267948107034783 0.39636092900322384" />
            </geometry>
        </collision>
    </link>
    <joint name="link0_link1" type="revolute">
       <parent link="link0"/>
       <child  link="link1"/>
       <origin rpy="0 0 0" xyz="-0.035336322724895675 0.062446420878248664 1.1981804645016119" />
     <axis xyz="0 0 1"/>
       <limit effort="0.0" lower="-3.14159" upper="3.14159" velocity="0.0"/>
    </joint>
    <link name="link1">
        <inertial>
            <origin xyz="-0.008583411144789171 -0.0008023076445923865 0.38096573613489315" rpy="0 0 0"/>
            <mass value="1" />
            <inertia ixx="100" ixy="0" ixz="0" iyy="100" iyz="0" izz="100" />
        </inertial>
        <visual>
            <origin xyz="-0.008583411144789171 -0.0008023076445923865 0.38096573613489315" rpy="0 0 0"/>
            <geometry>
                <box size="0.09820193480963502 0.012608888028625254 0.7619314722697863" />
            </geometry>
            <material name="Cyan">
                <color rgba="0.0 1.0 1.0 1.0"/>
            </material>
        </visual>
        <collision>
            <origin xyz="-0.008583411144789171 -0.0008023076445923865 0.38096573613489315" rpy="0 0 0"/>
            <geometry>
                <box size="0.09820193480963502 0.012608888028625254 0.7619314722697863" />
            </geometry>
        </collision>
    </link>
    <joint name="link0_link2" type="revolute">
       <parent link="link0"/>
       <child  link="link2"/>
       <origin rpy="0 0 0" xyz="0.007429879828668283 0.16133974053517391 0.9619042608740324" />
     <axis xyz="1 0 0"/>
       <limit effort="0.0" lower="-3.14159" upper="3.14159" velocity="0.0"/>
    </joint>
    <link name="link2">
        <inertial>
            <origin xyz="0.02096569431463252 0.31259604509449146 -0.04506433713980834" rpy="0 0 0"/>
            <mass value="1" />
            <inertia ixx="100" ixy="0" ixz="0" iyy="100" iyz="0" izz="100" />
        </inertial>
        <visual>
            <origin xyz="0.02096569431463252 0.31259604509449146 -0.04506433713980834" rpy="0 0 0"/>
            <geometry>
                <box size="0.16980186172138767 0.6251920901889829 0.5684915428449924" />
            </geometry>
            <material name="Cyan">
                <color rgba="0.0 1.0 1.0 1.0"/>
            </material>
        </visual>
        <collision>
            <origin xyz="0.02096569431463252 0.31259604509449146 -0.04506433713980834" rpy="0 0 0"/>
            <geometry>
                <box size="0.16980186172138767 0.6251920901889829 0.5684915428449924" />
            </geometry>
        </collision>
    </link>
    <joint name="link0_link3" type="revolute">
       <parent link="link0"/>
       <child  link="link3"/>
       <origin rpy="0 0 0" xyz="0.0454310027904899 0.16133974053517391 1.0590072888609974" />
     <axis xyz="0 1 0"/>
       <limit effort="0.0" lower="-3.14159" upper="3.14159" velocity="0.0"/>
    </joint>
    <link name="link3">
        <inertial>
            <origin xyz="0.13186834929343644 0.1728860693168235 0.013364368460304817" rpy="0 0 0"/>
            <mass value="1" />
            <inertia ixx="100" ixy="0" ixz="0" iyy="100" iyz="0" izz="100" />
        </inertial>
        <visual>
            <origin xyz="0.13186834929343644 0.1728860693168235 0.013364368460304817" rpy="0 0 0"/>
            <geometry>
                <box size="0.28170610590052947 0.345772138633647 0.43236703948415145" />
            </geometry>
            <material name="Green">
                <color rgba="0.0 1.0 0.0 1.0"/>
            </material>
        </visual>
        <collision>
            <origin xyz="0.13186834929343644 0.1728860693168235 0.013364368460304817" rpy="0 0 0"/>
            <geometry>
                <box size="0.28170610590052947 0.345772138633647 0.43236703948415145" />
            </geometry>
        </collision>
    </link>
    <joint name="link3_link4" type="revolute">
       <parent link="link3"/>
       <child  link="link4"/>
       <origin rpy="0 0 0" xyz="0.06087924552453085 0.19682712842882907 0.22954788820238053" />
     <axis xyz="0 0 1"/>
       <limit effort="0.0" lower="-3.14159" upper="3.14159" velocity="0.0"/>
    </joint>
    <link name="link4">
        <inertial>
            <origin xyz="-0.011828485167378578 -0.09035763490459904 0.31782426068487263" rpy="0 0 0"/>
            <mass value="1" />
            <inertia ixx="100" ixy="0" ixz="0" iyy="100" iyz="0" izz="100" />
        </inertial>
        <visual>
            <origin xyz="-0.011828485167378578 -0.09035763490459904 0.31782426068487263" rpy="0 0 0"/>
            <geometry>
                <box size="0.16454783180117527 0.18883905960339198 0.6356485213697453" />
            </geometry>
            <material name="Green">
                <color rgba="0.0 1.0 0.0 1.0"/>
            </material>
        </visual>
        <collision>
            <origin xyz="-0.011828485167378578 -0.09035763490459904 0.31782426068487263" rpy="0 0 0"/>
            <geometry>
                <box size="0.16454783180117527 0.18883905960339198 0.6356485213697453" />
            </geometry>
        </collision>
    </link>
    <joint name="link2_link5" type="revolute">
       <parent link="link2"/>
       <child  link="link5"/>
       <origin rpy="0 0 0" xyz="0.08332238194816882 0.0 -0.30900488043508323" />
     <axis xyz="1 0 0"/>
       <limit effort="0.0" lower="-3.14159" upper="3.14159" velocity="0.0"/>
    </joint>
    <link name="link5">
        <inertial>
            <origin xyz="0.17987080121583765 -0.04190809344073437 0.0013537282736424245" rpy="0 0 0"/>
            <mass value="1" />
            <inertia ixx="100" ixy="0" ixz="0" iyy="100" iyz="0" izz="100" />
        </inertial>
        <visual>
            <origin xyz="0.17987080121583765 -0.04190809344073437 0.0013537282736424245" rpy="0 0 0"/>
            <geometry>
                <box size="0.40145302262431304 0.08381618688146875 0.02746419834514835" />
            </geometry>
            <material name="Green">
                <color rgba="0.0 1.0 0.0 1.0"/>
            </material>
        </visual>
        <collision>
            <origin xyz="0.17987080121583765 -0.04190809344073437 0.0013537282736424245" rpy="0 0 0"/>
            <geometry>
                <box size="0.40145302262431304 0.08381618688146875 0.02746419834514835" />
            </geometry>
        </collision>
    </link>
    <joint name="link3_link6" type="revolute">
       <parent link="link3"/>
       <child  link="link6"/>
       <origin rpy="0 0 0" xyz="0.11038000491014878 0.0335111669986638 0.22954788820238053" />
     <axis xyz="1 0 0"/>
       <limit effort="0.0" lower="-3.14159" upper="3.14159" velocity="0.0"/>
    </joint>
    <link name="link6">
        <inertial>
            <origin xyz="0.0779907539065878 0.13079735680943147 0.4502500942482856" rpy="0 0 0"/>
            <mass value="1" />
            <inertia ixx="100" ixy="0" ixz="0" iyy="100" iyz="0" izz="100" />
        </inertial>
        <visual>
            <origin xyz="0.0779907539065878 0.13079735680943147 0.4502500942482856" rpy="0 0 0"/>
            <geometry>
                <box size="0.48112520496076305 0.3005807860923212 0.9005001884965712" />
            </geometry>
            <material name="Green">
                <color rgba="0.0 1.0 0.0 1.0"/>
            </material>
        </visual>
        <collision>
            <origin xyz="0.0779907539065878 0.13079735680943147 0.4502500942482856" rpy="0 0 0"/>
            <geometry>
                <box size="0.48112520496076305 0.3005807860923212 0.9005001884965712" />
            </geometry>
        </collision>
    </link>
    <joint name="link0_link7" type="revolute">
       <parent link="link0"/>
       <child  link="link7"/>
       <origin rpy="0 0 0" xyz="-0.04600070745863305 -0.08381381252880284 1.1333686927085027" />
     <axis xyz="0 1 0"/>
       <limit effort="0.0" lower="-3.14159" upper="3.14159" velocity="0.0"/>
    </joint>
    <link name="link7">
        <inertial>
            <origin xyz="-0.40334675377790785 0.12010567008067241 -0.3857783190574377" rpy="0 0 0"/>
            <mass value="1" />
            <inertia ixx="100" ixy="0" ixz="0" iyy="100" iyz="0" izz="100" />
        </inertial>
        <visual>
            <origin xyz="-0.40334675377790785 0.12010567008067241 -0.3857783190574377" rpy="0 0 0"/>
            <geometry>
                <box size="0.8066935075558157 0.9883907829639057 0.8138855681356223" />
            </geometry>
            <material name="Green">
                <color rgba="0.0 1.0 0.0 1.0"/>
            </material>
        </visual>
        <collision>
            <origin xyz="-0.40334675377790785 0.12010567008067241 -0.3857783190574377" rpy="0 0 0"/>
            <geometry>
                <box size="0.8066935075558157 0.9883907829639057 0.8138855681356223" />
            </geometry>
        </collision>
    </link>
    <joint name="link0_link8" type="revolute">
       <parent link="link0"/>
       <child  link="link8"/>
       <origin rpy="0 0 0" xyz="0.036356677739880765 -0.054019536564929756 1.1981804645016119" />
     <axis xyz="0 0 1"/>
       <limit effort="0.0" lower="-3.14159" upper="3.14159" velocity="0.0"/>
    </joint>
    <link name="link8">
        <inertial>
            <origin xyz="-0.392442963029592 0.1221711810576324 0.2956692759006481" rpy="0 0 0"/>
            <mass value="1" />
            <inertia ixx="100" ixy="0" ixz="0" iyy="100" iyz="0" izz="100" />
        </inertial>
        <visual>
            <origin xyz="-0.392442963029592 0.1221711810576324 0.2956692759006481" rpy="0 0 0"/>
            <geometry>
                <box size="0.929977157217159 0.590136551404954 0.5913385518012962" />
            </geometry>
            <material name="Green">
                <color rgba="0.0 1.0 0.0 1.0"/>
            </material>
        </visual>
        <collision>
            <origin xyz="-0.392442963029592 0.1221711810576324 0.2956692759006481" rpy="0 0 0"/>
            <geometry>
                <box size="0.929977157217159 0.590136551404954 0.5913385518012962" />
            </geometry>
        </collision>
    </link>
</robot>