<robot name = "robot">
    <link name="link0">
        <inertial>
            <origin xyz="0 0 1" rpy="0 0 0"/>
            <mass value="1" />
            <inertia ixx="100" ixy="0" ixz="0" iyy="100" iyz="0" izz="100" />
        </inertial>
        <visual>
            <origin xyz="0 0 1" rpy="0 0 0"/>
            <geometry>
                <box size="0.6864968847656281 0.3575414295165953 0.26612317493057636" />
            </geometry>
            <material name="Cyan">
                <color rgba="0.0 1.0 1.0 1.0"/>
            </material>
        </visual>
        <collision>
            <origin xyz="0 0 1" rpy="0 0 0"/>
            <geometry>
                <box size="0.6864968847656281 0.3575414295165953 0.26612317493057636" />
            </geometry>
        </collision>
    </link>
    <joint name="link0_link1" type="revolute">
       <parent link="link0"/>
       <child  link="link1"/>
       <origin rpy="0 0 0" xyz="0.1400925073086994 0.13585378704347983 1.133061587465288" />
     <axis xyz="1 0 0"/>
       <limit effort="0.0" lower="-3.14159" upper="3.14159" velocity="0.0"/>
    </joint>
    <link name="link1">
        <inertial>
            <origin xyz="0.058047128327697636 0.20657862331558666 0.15102525136668082" rpy="0 0 0"/>
            <mass value="1" />
            <inertia ixx="100" ixy="0" ixz="0" iyy="100" iyz="0" izz="100" />
        </inertial>
        <visual>
            <origin xyz="0.058047128327697636 0.20657862331558666 0.15102525136668082" rpy="0 0 0"/>
            <geometry>
                <box size="0.18978707358297997 0.44353524591790217 0.30205050273336165" />
            </geometry>
            <material name="Green">
                <color rgba="0.0 1.0 0.0 1.0"/>
            </material>
        </visual>
        <collision>
            <origin xyz="0.058047128327697636 0.20657862331558666 0.15102525136668082" rpy="0 0 0"/>
            <geometry>
                <box size="0.18978707358297997 0.44353524591790217 0.30205050273336165" />
            </geometry>
        </collision>
    </link>
    <joint name="link1_link2" type="revolute">
       <parent link="link1"/>
       <child  link="link2"/>
       <origin rpy="0 0 0" xyz="-0.03684640846379235 0.3668957556177934 0.22792571957657815" />
     <axis xyz="0 1 0"/>
       <limit effort="0.0" lower="-3.14159" upper="3.14159" velocity="0.0"/>
    </joint>
    <link name="link2">
        <inertial>
            <origin xyz="-0.4361250819841436 0.4369195134913875 0.13122353510012824" rpy="0 0 0"/>
            <mass value="1" />
            <inertia ixx="100" ixy="0" ixz="0" iyy="100" iyz="0" izz="100" />
        </inertial>
        <visual>
            <origin xyz="-0.4361250819841436 0.4369195134913875 0.13122353510012824" rpy="0 0 0"/>
            <geometry>
                <box size="0.8722501639682873 0.9719073917346774 0.2990376290232726" />
            </geometry>
            <material name="Green">
                <color rgba="0.0 1.0 0.0 1.0"/>
            </material>
        </visual>
        <collision>
            <origin xyz="-0.4361250819841436 0.4369195134913875 0.13122353510012824" rpy="0 0 0"/>
            <geometry>
                <box size="0.8722501639682873 0.9719073917346774 0.2990376290232726" />
            </geometry>
        </collision>
    </link>
    <joint name="link2_link3" type="revolute">
       <parent link="link2"/>
       <child  link="link3"/>
       <origin rpy="0 0 0" xyz="-0.03487644020957481 0.9228732093587262 0.24543768160385385" />
     <axis xyz="0 0 1"/>
       <limit effort="0.0" lower="-3.14159" upper="3.14159" velocity="0.0"/>
    </joint>
    <link name="link3">
        <inertial>
            <origin xyz="0.07077664256377804 0.16703936133132113 0.07870088920596904" rpy="0 0 0"/>
            <mass value="1" />
            <inertia ixx="100" ixy="0" ixz="0" iyy="100" iyz="0" izz="100" />
        </inertial>
        <visual>
            <origin xyz="0.07077664256377804 0.16703936133132113 0.07870088920596904" rpy="0 0 0"/>
            <geometry>
                <box size="0.23660509642642902 0.33407872266264227 0.8172859465633591" />
            </geometry>
            <material name="Green">
                <color rgba="0.0 1.0 0.0 1.0"/>
            </material>
        </visual>
        <collision>
            <origin xyz="0.07077664256377804 0.16703936133132113 0.07870088920596904" rpy="0 0 0"/>
            <geometry>
                <box size="0.23660509642642902 0.33407872266264227 0.8172859465633591" />
            </geometry>
        </collision>
    </link>
    <joint name="link1_link4" type="revolute">
       <parent link="link1"/>
       <child  link="link4"/>
       <origin rpy="0 0 0" xyz="0.15294066511918764 0.2791241554316679 0.018396119835437486" />
     <axis xyz="1 0 0"/>
       <limit effort="0.0" lower="-3.14159" upper="3.14159" velocity="0.0"/>
    </joint>
    <link name="link4">
        <inertial>
            <origin xyz="0.1974678489449102 -0.13252453509039497 0.12070438589431326" rpy="0 0 0"/>
            <mass value="1" />
            <inertia ixx="100" ixy="0" ixz="0" iyy="100" iyz="0" izz="100" />
        </inertial>
        <visual>
            <origin xyz="0.1974678489449102 -0.13252453509039497 0.12070438589431326" rpy="0 0 0"/>
            <geometry>
                <box size="0.3949356978898204 0.3422623784735841 0.2705146289520539" />
            </geometry>
            <material name="Green">
                <color rgba="0.0 1.0 0.0 1.0"/>
            </material>
        </visual>
        <collision>
            <origin xyz="0.1974678489449102 -0.13252453509039497 0.12070438589431326" rpy="0 0 0"/>
            <geometry>
                <box size="0.3949356978898204 0.3422623784735841 0.2705146289520539" />
            </geometry>
        </collision>
    </link>
    <joint name="link1_link5" type="revolute">
       <parent link="link1"/>
       <child  link="link5"/>
       <origin rpy="0 0 0" xyz="-0.03684640846379235 0.2184176284258986 0.09036900164814039" />
     <axis xyz="0 1 0"/>
       <limit effort="0.0" lower="-3.14159" upper="3.14159" velocity="0.0"/>
    </joint>
    <link name="link5">
        <inertial>
            <origin xyz="-0.4853111387140549 0.08635689584281049 0.0375763294451188" rpy="0 0 0"/>
            <mass value="1" />
            <inertia ixx="100" ixy="0" ixz="0" iyy="100" iyz="0" izz="100" />
        </inertial>
        <visual>
            <origin xyz="-0.4853111387140549 0.08635689584281049 0.0375763294451188" rpy="0 0 0"/>
            <geometry>
                <box size="0.9706222774281098 0.21579092095205976 0.09362845455069246" />
            </geometry>
            <material name="Green">
                <color rgba="0.0 1.0 0.0 1.0"/>
            </material>
        </visual>
        <collision>
            <origin xyz="-0.4853111387140549 0.08635689584281049 0.0375763294451188" rpy="0 0 0"/>
            <geometry>
                <box size="0.9706222774281098 0.21579092095205976 0.09362845455069246" />
            </geometry>
        </collision>
    </link>
    <joint name="link3_link6" type="revolute">
       <parent link="link3"/>
       <child  link="link6"/>
       <origin rpy="0 0 0" xyz="-0.02140610746076349 0.0 0.3397389516566822" />
     <axis xyz="0 1 0"/>
       <limit effort="0.0" lower="-3.14159" upper="3.14159" velocity="0.0"/>
    </joint>
    <link name="link6">
        <inertial>
            <origin xyz="-0.15236945559118623 -0.07425056023419813 0.43099407675592755" rpy="0 0 0"/>
            <mass value="1" />
            <inertia ixx="100" ixy="0" ixz="0" iyy="100" iyz="0" izz="100" />
        </inertial>
        <visual>
            <origin xyz="-0.15236945559118623 -0.07425056023419813 0.43099407675592755" rpy="0 0 0"/>
            <geometry>
                <box size="0.4131313279845501 0.14850112046839625 0.9037271533268888" />
            </geometry>
            <material name="Green">
                <color rgba="0.0 1.0 0.0 1.0"/>
            </material>
        </visual>
        <collision>
            <origin xyz="-0.15236945559118623 -0.07425056023419813 0.43099407675592755" rpy="0 0 0"/>
            <geometry>
                <box size="0.4131313279845501 0.14850112046839625 0.9037271533268888" />
            </geometry>
        </collision>
    </link>
    <joint name="link6_link7" type="revolute">
       <parent link="link6"/>
       <child  link="link7"/>
       <origin rpy="0 0 0" xyz="-0.35801308533564447 -0.14850112046839625 0.5489329841584057" />
     <axis xyz="0 0 1"/>
       <limit effort="0.0" lower="-3.14159" upper="3.14159" velocity="0.0"/>
    </joint>
    <link name="link7">
        <inertial>
            <origin xyz="-0.10381343192368797 -0.3584237812220525 -0.37638701843131517" rpy="0 0 0"/>
            <mass value="1" />
            <inertia ixx="100" ixy="0" ixz="0" iyy="100" iyz="0" izz="100" />
        </inertial>
        <visual>
            <origin xyz="-0.10381343192368797 -0.3584237812220525 -0.37638701843131517" rpy="0 0 0"/>
            <geometry>
                <box size="0.8981515729405122 0.716847562444105 0.8050923655491756" />
            </geometry>
            <material name="Green">
                <color rgba="0.0 1.0 0.0 1.0"/>
            </material>
        </visual>
        <collision>
            <origin xyz="-0.10381343192368797 -0.3584237812220525 -0.37638701843131517" rpy="0 0 0"/>
            <geometry>
                <box size="0.8981515729405122 0.716847562444105 0.8050923655491756" />
            </geometry>
        </collision>
    </link>
    <joint name="link0_link8" type="revolute">
       <parent link="link0"/>
       <child  link="link8"/>
       <origin rpy="0 0 0" xyz="0.18857540853597826 0.17877071475829764 1.0833391829195043" />
     <axis xyz="0 1 0"/>
       <limit effort="0.0" lower="-3.14159" upper="3.14159" velocity="0.0"/>
    </joint>
    <link name="link8">
        <inertial>
            <origin xyz="-0.04454991480453582 0.15122049028210477 -0.07242679560685536" rpy="0 0 0"/>
            <mass value="1" />
            <inertia ixx="100" ixy="0" ixz="0" iyy="100" iyz="0" izz="100" />
        </inertial>
        <visual>
            <origin xyz="-0.04454991480453582 0.15122049028210477 -0.07242679560685536" rpy="0 0 0"/>
            <geometry>
                <box size="0.2678793094637134 0.30244098056420954 0.9932326331897136" />
            </geometry>
            <material name="Green">
                <color rgba="0.0 1.0 0.0 1.0"/>
            </material>
        </visual>
        <collision>
            <origin xyz="-0.04454991480453582 0.15122049028210477 -0.07242679560685536" rpy="0 0 0"/>
            <geometry>
                <box size="0.2678793094637134 0.30244098056420954 0.9932326331897136" />
            </geometry>
        </collision>
    </link>
</robot>