<robot name = "robot">
    <link name="link0">
        <inertial>
            <origin xyz="0 0 1" rpy="0 0 0"/>
            <mass value="1" />
            <inertia ixx="100" ixy="0" ixz="0" iyy="100" iyz="0" izz="100" />
        </inertial>
        <visual>
            <origin xyz="0 0 1" rpy="0 0 0"/>
            <geometry>
                <box size="0.2657731708486626 0.7288233738045159 0.6439082583708522" />
            </geometry>
            <material name="Cyan">
                <color rgba="0.0 1.0 1.0 1.0"/>
            </material>
        </visual>
        <collision>
            <origin xyz="0 0 1" rpy="0 0 0"/>
            <geometry>
                <box size="0.2657731708486626 0.7288233738045159 0.6439082583708522" />
            </geometry>
        </collision>
    </link>
    <joint name="link0_link1" type="revolute">
       <parent link="link0"/>
       <child  link="link1"/>
       <origin rpy="0 0 0" xyz="-0.0806051533162016 0.36441168690225795 0.9263189692537698" />
     <axis xyz="0 0 1"/>
       <limit effort="0.0" lower="-3.14159" upper="3.14159" velocity="0.0"/>
    </joint>
    <link name="link1">
        <inertial>
            <origin xyz="0.005961796509503888 0.498082848146322 -0.007720820690501293" rpy="0 0 0"/>
            <mass value="1" />
            <inertia ixx="100" ixy="0" ixz="0" iyy="100" iyz="0" izz="100" />
        </inertial>
        <visual>
            <origin xyz="0.005961796509503888 0.498082848146322 -0.007720820690501293" rpy="0 0 0"/>
            <geometry>
                <box size="0.49498753343488777 0.996165696292644 0.4909796125307748" />
            </geometry>
            <material name="Green">
                <color rgba="0.0 1.0 0.0 1.0"/>
            </material>
        </visual>
        <collision>
            <origin xyz="0.005961796509503888 0.498082848146322 -0.007720820690501293" rpy="0 0 0"/>
            <geometry>
                <box size="0.49498753343488777 0.996165696292644 0.4909796125307748" />
            </geometry>
        </collision>
    </link>
</robot>