<robot name = "robot">
    <link name="link0">
        <inertial>
            <origin xyz="0 0 1" rpy="0 0 0"/>
            <mass value="1" />
            <inertia ixx="100" ixy="0" ixz="0" iyy="100" iyz="0" izz="100" />
        </inertial>
        <visual>
            <origin xyz="0 0 1" rpy="0 0 0"/>
            <geometry>
                <box size="0.6737880653275938 0.8750251961906392 0.5317970472449406" />
            </geometry>
            <material name="Cyan">
                <color rgba="0.0 1.0 1.0 1.0"/>
            </material>
        </visual>
        <collision>
            <origin xyz="0 0 1" rpy="0 0 0"/>
            <geometry>
                <box size="0.6737880653275938 0.8750251961906392 0.5317970472449406" />
            </geometry>
        </collision>
    </link>
    <joint name="link0_link1" type="revolute">
       <parent link="link0"/>
       <child  link="link1"/>
       <origin rpy="0 0 0" xyz="0.3368940326637969 0.3731667430017414 0.9425476542733087" />
     <axis xyz="0 0 1"/>
       <limit effort="0.0" lower="-3.14159" upper="3.14159" velocity="0.0"/>
    </joint>
    <link name="link1">
        <inertial>
            <origin xyz="0.3441614075821547 0.026704275895106055 -0.3276492382374965" rpy="0 0 0"/>
            <mass value="1" />
            <inertia ixx="100" ixy="0" ixz="0" iyy="100" iyz="0" izz="100" />
        </inertial>
        <visual>
            <origin xyz="0.3441614075821547 0.026704275895106055 -0.3276492382374965" rpy="0 0 0"/>
            <geometry>
                <box size="0.6883228151643094 0.07634567671931469 0.6886870841262481" />
            </geometry>
            <material name="Green">
                <color rgba="0.0 1.0 0.0 1.0"/>
            </material>
        </visual>
        <collision>
            <origin xyz="0.3441614075821547 0.026704275895106055 -0.3276492382374965" rpy="0 0 0"/>
            <geometry>
                <box size="0.6883228151643094 0.07634567671931469 0.6886870841262481" />
            </geometry>
        </collision>
    </link>
    <joint name="link1_link2" type="revolute">
       <parent link="link1"/>
       <child  link="link2"/>
       <origin rpy="0 0 0" xyz="0.6883228151643094 0.04055123707094235 -0.08198582162905477" />
     <axis xyz="0 0 1"/>
       <limit effort="0.0" lower="-3.14159" upper="3.14159" velocity="0.0"/>
    </joint>
    <link name="link2">
        <inertial>
            <origin xyz="0.18956123242818007 0.05914455123104242 -0.006365109772243666" rpy="0 0 0"/>
            <mass value="1" />
            <inertia ixx="100" ixy="0" ixz="0" iyy="100" iyz="0" izz="100" />
        </inertial>
        <visual>
            <origin xyz="0.18956123242818007 0.05914455123104242 -0.006365109772243666" rpy="0 0 0"/>
            <geometry>
                <box size="0.37912246485636014 0.4219481963139966 0.08342353983803019" />
            </geometry>
            <material name="Green">
                <color rgba="0.0 1.0 0.0 1.0"/>
            </material>
        </visual>
        <collision>
            <origin xyz="0.18956123242818007 0.05914455123104242 -0.006365109772243666" rpy="0 0 0"/>
            <geometry>
                <box size="0.37912246485636014 0.4219481963139966 0.08342353983803019" />
            </geometry>
        </collision>
    </link>
</robot>