<robot name = "robot">
    <link name="link0">
        <inertial>
            <origin xyz="0 0 1" rpy="0 0 0"/>
            <mass value="1" />
            <inertia ixx="100" ixy="0" ixz="0" iyy="100" iyz="0" izz="100" />
        </inertial>
        <visual>
            <origin xyz="0 0 1" rpy="0 0 0"/>
            <geometry>
                <box size="0.15029526638521018 0.610606587145538 0.23902373892360818" />
            </geometry>
            <material name="Cyan">
                <color rgba="0 1.0 1.0 1.0"/>
            </material>
        </visual>
        <collision>
            <origin xyz="0 0 1" rpy="0 0 0"/>
            <geometry>
                <box size="0.15029526638521018 0.610606587145538 0.23902373892360818" />
            </geometry>
        </collision>
    </link>
    <joint name="link0_link1" type="revolute">
       <parent link="link0"/>
       <child  link="link1"/>
       <origin rpy="0 0 0" xyz="-0.07514763319260509 -0.0598004417817319 1.0853860459296871" />
     <axis xyz="0 0 1"/>
       <limit effort="0.0" lower="-3.14159" upper="3.14159" velocity="0.0"/>
    </joint>
    <link name="link1">
        <inertial>
            <origin xyz="-0.3241773218315271 -0.20303390673169816 0.04740452417040468" rpy="0 0 0"/>
            <mass value="1" />
            <inertia ixx="100" ixy="0" ixz="0" iyy="100" iyz="0" izz="100" />
        </inertial>
        <visual>
            <origin xyz="-0.3241773218315271 -0.20303390673169816 0.04740452417040468" rpy="0 0 0"/>
            <geometry>
                <box size="0.6483546436630542 0.8375358269013204 0.8451516537896654" />
            </geometry>
            <material name="Cyan">
                <color rgba="0 1.0 1.0 1.0"/>
            </material>
        </visual>
        <collision>
            <origin xyz="-0.3241773218315271 -0.20303390673169816 0.04740452417040468" rpy="0 0 0"/>
            <geometry>
                <box size="0.6483546436630542 0.8375358269013204 0.8451516537896654" />
            </geometry>
        </collision>
    </link>
</robot>