<robot name = "robot">
    <link name="link0">
        <inertial>
            <origin xyz="0 0 1" rpy="0 0 0"/>
            <mass value="1" />
            <inertia ixx="100" ixy="0" ixz="0" iyy="100" iyz="0" izz="100" />
        </inertial>
        <visual>
            <origin xyz="0 0 1" rpy="0 0 0"/>
            <geometry>
                <box size="0.00671465885799849 0.13826792307169655 0.5200665854929661" />
            </geometry>
            <material name="Cyan">
                <color rgba="0.0 1.0 1.0 1.0"/>
            </material>
        </visual>
        <collision>
            <origin xyz="0 0 1" rpy="0 0 0"/>
            <geometry>
                <box size="0.00671465885799849 0.13826792307169655 0.5200665854929661" />
            </geometry>
        </collision>
    </link>
    <joint name="link0_link1" type="revolute">
       <parent link="link0"/>
       <child  link="link1"/>
       <origin rpy="0 0 0" xyz="-0.0013056055059394714 -0.059409826516488434 1.260033292746483" />
     <axis xyz="1 0 0"/>
       <limit effort="0.0" lower="-3.14159" upper="3.14159" velocity="0.0"/>
    </joint>
    <link name="link1">
        <inertial>
            <origin xyz="0.017847518560525067 -0.3805911328424104 0.1589144000343924" rpy="0 0 0"/>
            <mass value="1" />
            <inertia ixx="100" ixy="0" ixz="0" iyy="100" iyz="0" izz="100" />
        </inertial>
        <visual>
            <origin xyz="0.017847518560525067 -0.3805911328424104 0.1589144000343924" rpy="0 0 0"/>
            <geometry>
                <box size="0.7201720841724985 0.9347007853089172 0.3178288000687848" />
            </geometry>
            <material name="Green">
                <color rgba="0.0 1.0 0.0 1.0"/>
            </material>
        </visual>
        <collision>
            <origin xyz="0.017847518560525067 -0.3805911328424104 0.1589144000343924" rpy="0 0 0"/>
            <geometry>
                <box size="0.7201720841724985 0.9347007853089172 0.3178288000687848" />
            </geometry>
        </collision>
    </link>
</robot>