<robot name = "robot">
    <link name="link0">
        <inertial>
            <origin xyz="0 0 1" rpy="0 0 0"/>
            <mass value="1" />
            <inertia ixx="100" ixy="0" ixz="0" iyy="100" iyz="0" izz="100" />
        </inertial>
        <visual>
            <origin xyz="0 0 1" rpy="0 0 0"/>
            <geometry>
                <box size="0.2263539885962229 0.7837049053528578 0.9725800474861895" />
            </geometry>
            <material name="Cyan">
                <color rgba="0 1.0 1.0 1.0"/>
            </material>
        </visual>
        <collision>
            <origin xyz="0 0 1" rpy="0 0 0"/>
            <geometry>
                <box size="0.2263539885962229 0.7837049053528578 0.9725800474861895" />
            </geometry>
        </collision>
    </link>
    <joint name="link0_link1" type="revolute">
       <parent link="link0"/>
       <child  link="link1"/>
       <origin rpy="0 0 0" xyz="-0.04665842874378336 -0.22020620946381297 1.4862900237430947" />
     <axis xyz="0 1 0"/>
       <limit effort="0.0" lower="-3.14159" upper="3.14159" velocity="0.0"/>
    </joint>
    <link name="link1">
        <inertial>
            <origin xyz="-0.11092512757186532 -0.0019063851677320618 0.4444796172201291" rpy="0 0 0"/>
            <mass value="1" />
            <inertia ixx="100" ixy="0" ixz="0" iyy="100" iyz="0" izz="100" />
        </inertial>
        <visual>
            <origin xyz="-0.11092512757186532 -0.0019063851677320618 0.4444796172201291" rpy="0 0 0"/>
            <geometry>
                <box size="0.8667241869796026 0.08643242207869173 0.8889592344402582" />
            </geometry>
            <material name="Cyan">
                <color rgba="0 1.0 1.0 1.0"/>
            </material>
        </visual>
        <collision>
            <origin xyz="-0.11092512757186532 -0.0019063851677320618 0.4444796172201291" rpy="0 0 0"/>
            <geometry>
                <box size="0.8667241869796026 0.08643242207869173 0.8889592344402582" />
            </geometry>
        </collision>
    </link>
    <joint name="link0_link2" type="revolute">
       <parent link="link0"/>
       <child  link="link2"/>
       <origin rpy="0 0 0" xyz="0.06627645873488354 -0.3918524526764289 0.7381705956089519" />
     <axis xyz="0 0 1"/>
       <limit effort="0.0" lower="-3.14159" upper="3.14159" velocity="0.0"/>
    </joint>
    <link name="link2">
        <inertial>
            <origin xyz="-0.01724208324329604 -0.44382515246572346 0.3087490174764873" rpy="0 0 0"/>
            <mass value="1" />
            <inertia ixx="100" ixy="0" ixz="0" iyy="100" iyz="0" izz="100" />
        </inertial>
        <visual>
            <origin xyz="-0.01724208324329604 -0.44382515246572346 0.3087490174764873" rpy="0 0 0"/>
            <geometry>
                <box size="0.380282079050398 0.8876503049314469 0.9003252191301544" />
            </geometry>
            <material name="Cyan">
                <color rgba="0 1.0 1.0 1.0"/>
            </material>
        </visual>
        <collision>
            <origin xyz="-0.01724208324329604 -0.44382515246572346 0.3087490174764873" rpy="0 0 0"/>
            <geometry>
                <box size="0.380282079050398 0.8876503049314469 0.9003252191301544" />
            </geometry>
        </collision>
    </link>
    <joint name="link1_link3" type="revolute">
       <parent link="link1"/>
       <child  link="link3"/>
       <origin rpy="0 0 0" xyz="-0.3989475243434467 0.0413098258716138 0.3761877696164857" />
     <axis xyz="0 0 1"/>
       <limit effort="0.0" lower="-3.14159" upper="3.14159" velocity="0.0"/>
    </joint>
    <link name="link3">
        <inertial>
            <origin xyz="0.08614059660743208 0.37324639738081206 0.08162781519865601" rpy="0 0 0"/>
            <mass value="1" />
            <inertia ixx="100" ixy="0" ixz="0" iyy="100" iyz="0" izz="100" />
        </inertial>
        <visual>
            <origin xyz="0.08614059660743208 0.37324639738081206 0.08162781519865601" rpy="0 0 0"/>
            <geometry>
                <box size="0.330446098527013 0.7464927947616241 0.25749636916369545" />
            </geometry>
            <material name="Cyan">
                <color rgba="0 1.0 1.0 1.0"/>
            </material>
        </visual>
        <collision>
            <origin xyz="0.08614059660743208 0.37324639738081206 0.08162781519865601" rpy="0 0 0"/>
            <geometry>
                <box size="0.330446098527013 0.7464927947616241 0.25749636916369545" />
            </geometry>
        </collision>
    </link>
    <joint name="link0_link4" type="revolute">
       <parent link="link0"/>
       <child  link="link4"/>
       <origin rpy="0 0 0" xyz="0.026645684489141414 0.33029080113863635 1.4862900237430947" />
     <axis xyz="0 0 1"/>
       <limit effort="0.0" lower="-3.14159" upper="3.14159" velocity="0.0"/>
    </joint>
    <link name="link4">
        <inertial>
            <origin xyz="0.017577590718111973 0.07358846393423248 0.3900004915937318" rpy="0 0 0"/>
            <mass value="1" />
            <inertia ixx="100" ixy="0" ixz="0" iyy="100" iyz="0" izz="100" />
        </inertial>
        <visual>
            <origin xyz="0.017577590718111973 0.07358846393423248 0.3900004915937318" rpy="0 0 0"/>
            <geometry>
                <box size="0.2029652026109926 0.39538360136241557 0.7800009831874636" />
            </geometry>
            <material name="Cyan">
                <color rgba="0 1.0 1.0 1.0"/>
            </material>
        </visual>
        <collision>
            <origin xyz="0.017577590718111973 0.07358846393423248 0.3900004915937318" rpy="0 0 0"/>
            <geometry>
                <box size="0.2029652026109926 0.39538360136241557 0.7800009831874636" />
            </geometry>
        </collision>
    </link>
    <joint name="link4_link5" type="revolute">
       <parent link="link4"/>
       <child  link="link5"/>
       <origin rpy="0 0 0" xyz="-0.02468492972600057 0.27128026461544025 0.18100482289270747" />
     <axis xyz="0 0 1"/>
       <limit effort="0.0" lower="-3.14159" upper="3.14159" velocity="0.0"/>
    </joint>
    <link name="link5">
        <inertial>
            <origin xyz="0.06928849360183753 0.34424699641342643 0.09507417412303748" rpy="0 0 0"/>
            <mass value="1" />
            <inertia ixx="100" ixy="0" ixz="0" iyy="100" iyz="0" izz="100" />
        </inertial>
        <visual>
            <origin xyz="0.06928849360183753 0.34424699641342643 0.09507417412303748" rpy="0 0 0"/>
            <geometry>
                <box size="0.1835500726823842 0.6884939928268529 0.3610522260688549" />
            </geometry>
            <material name="Cyan">
                <color rgba="0 1.0 1.0 1.0"/>
            </material>
        </visual>
        <collision>
            <origin xyz="0.06928849360183753 0.34424699641342643 0.09507417412303748" rpy="0 0 0"/>
            <geometry>
                <box size="0.1835500726823842 0.6884939928268529 0.3610522260688549" />
            </geometry>
        </collision>
    </link>
    <joint name="link2_link6" type="revolute">
       <parent link="link2"/>
       <child  link="link6"/>
       <origin rpy="0 0 0" xyz="-0.13656543907520338 -0.13833089443348345 0.7589116270415646" />
     <axis xyz="0 0 1"/>
       <limit effort="0.0" lower="-3.14159" upper="3.14159" velocity="0.0"/>
    </joint>
    <link name="link6">
        <inertial>
            <origin xyz="0.06582426245389966 0.07043817677817665 0.3507099510009984" rpy="0 0 0"/>
            <mass value="1" />
            <inertia ixx="100" ixy="0" ixz="0" iyy="100" iyz="0" izz="100" />
        </inertial>
        <visual>
            <origin xyz="0.06582426245389966 0.07043817677817665 0.3507099510009984" rpy="0 0 0"/>
            <geometry>
                <box size="0.8278506877117867 0.39645505071974674 0.7014199020019968" />
            </geometry>
            <material name="Cyan">
                <color rgba="0 1.0 1.0 1.0"/>
            </material>
        </visual>
        <collision>
            <origin xyz="0.06582426245389966 0.07043817677817665 0.3507099510009984" rpy="0 0 0"/>
            <geometry>
                <box size="0.8278506877117867 0.39645505071974674 0.7014199020019968" />
            </geometry>
        </collision>
    </link>
    <joint name="link5_link7" type="revolute">
       <parent link="link5"/>
       <child  link="link7"/>
       <origin rpy="0 0 0" xyz="0.0931735138121357 0.0 0.22176016134207072" />
     <axis xyz="0 0 1"/>
       <limit effort="0.0" lower="-3.14159" upper="3.14159" velocity="0.0"/>
    </joint>
    <link name="link7">
        <inertial>
            <origin xyz="-0.15728564576560292 -0.17725796843691466 -0.0788739187412037" rpy="0 0 0"/>
            <mass value="1" />
            <inertia ixx="100" ixy="0" ixz="0" iyy="100" iyz="0" izz="100" />
        </inertial>
        <visual>
            <origin xyz="-0.15728564576560292 -0.17725796843691466 -0.0788739187412037" rpy="0 0 0"/>
            <geometry>
                <box size="0.9980032453819042 0.3545159368738293 0.1663547595673195" />
            </geometry>
            <material name="Cyan">
                <color rgba="0 1.0 1.0 1.0"/>
            </material>
        </visual>
        <collision>
            <origin xyz="-0.15728564576560292 -0.17725796843691466 -0.0788739187412037" rpy="0 0 0"/>
            <geometry>
                <box size="0.9980032453819042 0.3545159368738293 0.1663547595673195" />
            </geometry>
        </collision>
    </link>
    <joint name="link6_link8" type="revolute">
       <parent link="link6"/>
       <child  link="link8"/>
       <origin rpy="0 0 0" xyz="-0.23922169903579138 0.26866570213805 0.4388055041862169" />
     <axis xyz="0 1 0"/>
       <limit effort="0.0" lower="-3.14159" upper="3.14159" velocity="0.0"/>
    </joint>
    <link name="link8">
        <inertial>
            <origin xyz="0.047816375099037384 0.44106132795957376 -0.06263610920997628" rpy="0 0 0"/>
            <mass value="1" />
            <inertia ixx="100" ixy="0" ixz="0" iyy="100" iyz="0" izz="100" />
        </inertial>
        <visual>
            <origin xyz="0.047816375099037384 0.44106132795957376 -0.06263610920997628" rpy="0 0 0"/>
            <geometry>
                <box size="0.7380645703198166 0.8821226559191475 0.32431364867465284" />
            </geometry>
            <material name="Cyan">
                <color rgba="0 1.0 1.0 1.0"/>
            </material>
        </visual>
        <collision>
            <origin xyz="0.047816375099037384 0.44106132795957376 -0.06263610920997628" rpy="0 0 0"/>
            <geometry>
                <box size="0.7380645703198166 0.8821226559191475 0.32431364867465284" />
            </geometry>
        </collision>
    </link>
    <joint name="link4_link9" type="revolute">
       <parent link="link4"/>
       <child  link="link9"/>
       <origin rpy="0 0 0" xyz="0.11906019202360828 0.21301050545357514 0.319483763125442" />
     <axis xyz="0 1 0"/>
       <limit effort="0.0" lower="-3.14159" upper="3.14159" velocity="0.0"/>
    </joint>
    <link name="link9">
        <inertial>
            <origin xyz="0.2389147395162986 0.11186435549466633 0.167516728558704" rpy="0 0 0"/>
            <mass value="1" />
            <inertia ixx="100" ixy="0" ixz="0" iyy="100" iyz="0" izz="100" />
        </inertial>
        <visual>
            <origin xyz="0.2389147395162986 0.11186435549466633 0.167516728558704" rpy="0 0 0"/>
            <geometry>
                <box size="0.4778294790325972 0.49631983437180804 0.853698499378811" />
            </geometry>
            <material name="Cyan">
                <color rgba="0 1.0 1.0 1.0"/>
            </material>
        </visual>
        <collision>
            <origin xyz="0.2389147395162986 0.11186435549466633 0.167516728558704" rpy="0 0 0"/>
            <geometry>
                <box size="0.4778294790325972 0.49631983437180804 0.853698499378811" />
            </geometry>
        </collision>
    </link>
    <joint name="link8_link10" type="revolute">
       <parent link="link8"/>
       <child  link="link10"/>
       <origin rpy="0 0 0" xyz="-0.3212159100608709 0.4123623420714393 -0.15715892133896642" />
     <axis xyz="0 0 1"/>
       <limit effort="0.0" lower="-3.14159" upper="3.14159" velocity="0.0"/>
    </joint>
    <link name="link10">
        <inertial>
            <origin xyz="-0.18167788686717612 0.1002377866766163 -0.0927882689555653" rpy="0 0 0"/>
            <mass value="1" />
            <inertia ixx="100" ixy="0" ixz="0" iyy="100" iyz="0" izz="100" />
        </inertial>
        <visual>
            <origin xyz="-0.18167788686717612 0.1002377866766163 -0.0927882689555653" rpy="0 0 0"/>
            <geometry>
                <box size="0.36335577373435224 0.26519219306845776 0.32669682291133384" />
            </geometry>
            <material name="Cyan">
                <color rgba="0 1.0 1.0 1.0"/>
            </material>
        </visual>
        <collision>
            <origin xyz="-0.18167788686717612 0.1002377866766163 -0.0927882689555653" rpy="0 0 0"/>
            <geometry>
                <box size="0.36335577373435224 0.26519219306845776 0.32669682291133384" />
            </geometry>
        </collision>
    </link>
</robot>