<robot name = "robot">
    <link name="link0">
        <inertial>
            <origin xyz="0 0 1" rpy="0 0 0"/>
            <mass value="1" />
            <inertia ixx="100" ixy="0" ixz="0" iyy="100" iyz="0" izz="100" />
        </inertial>
        <visual>
            <origin xyz="0 0 1" rpy="0 0 0"/>
            <geometry>
                <box size="0.2512384480304639 0.8633299316669261 0.7828926962369672" />
            </geometry>
            <material name="Cyan">
                <color rgba="0 1.0 1.0 1.0"/>
            </material>
        </visual>
        <collision>
            <origin xyz="0 0 1" rpy="0 0 0"/>
            <geometry>
                <box size="0.2512384480304639 0.8633299316669261 0.7828926962369672" />
            </geometry>
        </collision>
    </link>
    <joint name="link0_link1" type="revolute">
       <parent link="link0"/>
       <child  link="link1"/>
       <origin rpy="0 0 0" xyz="0.05560319492873347 0.43166496583346303 0.7372343418836862" />
     <axis xyz="1 0 0"/>
       <limit effort="0.0" lower="-3.14159" upper="3.14159" velocity="0.0"/>
    </joint>
    <link name="link1">
        <inertial>
            <origin xyz="0.12204133076707878 0.08151316511299994 0.04940535225295914" rpy="0 0 0"/>
            <mass value="1" />
            <inertia ixx="100" ixy="0" ixz="0" iyy="100" iyz="0" izz="100" />
        </inertial>
        <visual>
            <origin xyz="0.12204133076707878 0.08151316511299994 0.04940535225295914" rpy="0 0 0"/>
            <geometry>
                <box size="0.84459357041856 0.16302633022599988 0.28122602094003757" />
            </geometry>
            <material name="Cyan">
                <color rgba="0 1.0 1.0 1.0"/>
            </material>
        </visual>
        <collision>
            <origin xyz="0.12204133076707878 0.08151316511299994 0.04940535225295914" rpy="0 0 0"/>
            <geometry>
                <box size="0.84459357041856 0.16302633022599988 0.28122602094003757" />
            </geometry>
        </collision>
    </link>
    <joint name="link0_link2" type="revolute">
       <parent link="link0"/>
       <child  link="link2"/>
       <origin rpy="0 0 0" xyz="-0.12561922401523196 -0.39884938185676805 1.123572320265224" />
     <axis xyz="1 0 0"/>
       <limit effort="0.0" lower="-3.14159" upper="3.14159" velocity="0.0"/>
    </joint>
    <link name="link2">
        <inertial>
            <origin xyz="-0.3273608369349308 -0.003913148272753923 0.42194973711909145" rpy="0 0 0"/>
            <mass value="1" />
            <inertia ixx="100" ixy="0" ixz="0" iyy="100" iyz="0" izz="100" />
        </inertial>
        <visual>
            <origin xyz="-0.3273608369349308 -0.003913148272753923 0.42194973711909145" rpy="0 0 0"/>
            <geometry>
                <box size="0.6547216738698616 0.0281084778891747 0.9163995729886145" />
            </geometry>
            <material name="Cyan">
                <color rgba="0 1.0 1.0 1.0"/>
            </material>
        </visual>
        <collision>
            <origin xyz="-0.3273608369349308 -0.003913148272753923 0.42194973711909145" rpy="0 0 0"/>
            <geometry>
                <box size="0.6547216738698616 0.0281084778891747 0.9163995729886145" />
            </geometry>
        </collision>
    </link>
    <joint name="link1_link3" type="revolute">
       <parent link="link1"/>
       <child  link="link3"/>
       <origin rpy="0 0 0" xyz="-0.10785477368616235 0.16302633022599988 0.16465345733939074" />
     <axis xyz="0 0 1"/>
       <limit effort="0.0" lower="-3.14159" upper="3.14159" velocity="0.0"/>
    </joint>
    <link name="link3">
        <inertial>
            <origin xyz="0.07164910783389386 0.1110665899863344 -0.00551729248252914" rpy="0 0 0"/>
            <mass value="1" />
            <inertia ixx="100" ixy="0" ixz="0" iyy="100" iyz="0" izz="100" />
        </inertial>
        <visual>
            <origin xyz="0.07164910783389386 0.1110665899863344 -0.00551729248252914" rpy="0 0 0"/>
            <geometry>
                <box size="0.5088143076001332 0.2221331799726688 0.08303806923529178" />
            </geometry>
            <material name="Cyan">
                <color rgba="0 1.0 1.0 1.0"/>
            </material>
        </visual>
        <collision>
            <origin xyz="0.07164910783389386 0.1110665899863344 -0.00551729248252914" rpy="0 0 0"/>
            <geometry>
                <box size="0.5088143076001332 0.2221331799726688 0.08303806923529178" />
            </geometry>
        </collision>
    </link>
    <joint name="link3_link4" type="revolute">
       <parent link="link3"/>
       <child  link="link4"/>
       <origin rpy="0 0 0" xyz="0.3260562616339605 0.16389879125451126 0.024892032122015684" />
     <axis xyz="1 0 0"/>
       <limit effort="0.0" lower="-3.14159" upper="3.14159" velocity="0.0"/>
    </joint>
    <link name="link4">
        <inertial>
            <origin xyz="0.3948083203169166 -0.06891640551927015 0.14461782986029947" rpy="0 0 0"/>
            <mass value="1" />
            <inertia ixx="100" ixy="0" ixz="0" iyy="100" iyz="0" izz="100" />
        </inertial>
        <visual>
            <origin xyz="0.3948083203169166 -0.06891640551927015 0.14461782986029947" rpy="0 0 0"/>
            <geometry>
                <box size="0.7896166406338332 0.7078904931814987 0.7122126107470963" />
            </geometry>
            <material name="Cyan">
                <color rgba="0 1.0 1.0 1.0"/>
            </material>
        </visual>
        <collision>
            <origin xyz="0.3948083203169166 -0.06891640551927015 0.14461782986029947" rpy="0 0 0"/>
            <geometry>
                <box size="0.7896166406338332 0.7078904931814987 0.7122126107470963" />
            </geometry>
        </collision>
    </link>
</robot>