<robot name = "robot">
    <link name="link0">
        <inertial>
            <origin xyz="0 0 1" rpy="0 0 0"/>
            <mass value="1" />
            <inertia ixx="100" ixy="0" ixz="0" iyy="100" iyz="0" izz="100" />
        </inertial>
        <visual>
            <origin xyz="0 0 1" rpy="0 0 0"/>
            <geometry>
                <box size="0.7221679346255782 0.13644631783190253 0.4180960455468621" />
            </geometry>
            <material name="Cyan">
                <color rgba="0 1.0 1.0 1.0"/>
            </material>
        </visual>
        <collision>
            <origin xyz="0 0 1" rpy="0 0 0"/>
            <geometry>
                <box size="0.7221679346255782 0.13644631783190253 0.4180960455468621" />
            </geometry>
        </collision>
    </link>
    <joint name="link0_link1" type="revolute">
       <parent link="link0"/>
       <child  link="link1"/>
       <origin rpy="0 0 0" xyz="-0.2427937471264354 -0.06822315891595127 0.8636065898031615" />
     <axis xyz="1 0 0"/>
       <limit effort="0.0" lower="-3.14159" upper="3.14159" velocity="0.0"/>
    </joint>
    <link name="link1">
        <inertial>
            <origin xyz="0.09333159554566693 -0.23941475801369394 0.07155005983658823" rpy="0 0 0"/>
            <mass value="1" />
            <inertia ixx="100" ixy="0" ixz="0" iyy="100" iyz="0" izz="100" />
        </inertial>
        <visual>
            <origin xyz="0.09333159554566693 -0.23941475801369394 0.07155005983658823" rpy="0 0 0"/>
            <geometry>
                <box size="0.8894476183556619 0.4788295160273879 0.29213527096955927" />
            </geometry>
            <material name="Cyan">
                <color rgba="0 1.0 1.0 1.0"/>
            </material>
        </visual>
        <collision>
            <origin xyz="0.09333159554566693 -0.23941475801369394 0.07155005983658823" rpy="0 0 0"/>
            <geometry>
                <box size="0.8894476183556619 0.4788295160273879 0.29213527096955927" />
            </geometry>
        </collision>
    </link>
    <joint name="link0_link2" type="revolute">
       <parent link="link0"/>
       <child  link="link2"/>
       <origin rpy="0 0 0" xyz="0.3610839673127891 -0.025578148557766682 1.208702766041325" />
     <axis xyz="1 0 0"/>
       <limit effort="0.0" lower="-3.14159" upper="3.14159" velocity="0.0"/>
    </joint>
    <link name="link2">
        <inertial>
            <origin xyz="0.23526390485747894 -0.40843759192074264 0.09739232452033003" rpy="0 0 0"/>
            <mass value="1" />
            <inertia ixx="100" ixy="0" ixz="0" iyy="100" iyz="0" izz="100" />
        </inertial>
        <visual>
            <origin xyz="0.23526390485747894 -0.40843759192074264 0.09739232452033003" rpy="0 0 0"/>
            <geometry>
                <box size="0.4705278097149579 0.9493063658273203 0.24167815457534558" />
            </geometry>
            <material name="Cyan">
                <color rgba="0 1.0 1.0 1.0"/>
            </material>
        </visual>
        <collision>
            <origin xyz="0.23526390485747894 -0.40843759192074264 0.09739232452033003" rpy="0 0 0"/>
            <geometry>
                <box size="0.4705278097149579 0.9493063658273203 0.24167815457534558" />
            </geometry>
        </collision>
    </link>
    <joint name="link2_link3" type="revolute">
       <parent link="link2"/>
       <child  link="link3"/>
       <origin rpy="0 0 0" xyz="0.04110506599360822 -0.6584445569050777 -0.02344675276734276" />
     <axis xyz="0 1 0"/>
       <limit effort="0.0" lower="-3.14159" upper="3.14159" velocity="0.0"/>
    </joint>
    <link name="link3">
        <inertial>
            <origin xyz="-0.22771693534990872 0.06421971606881348 -0.036362764733089026" rpy="0 0 0"/>
            <mass value="1" />
            <inertia ixx="100" ixy="0" ixz="0" iyy="100" iyz="0" izz="100" />
        </inertial>
        <visual>
            <origin xyz="-0.22771693534990872 0.06421971606881348 -0.036362764733089026" rpy="0 0 0"/>
            <geometry>
                <box size="0.4698127986339453 0.42893208179342834 0.07272552946617805" />
            </geometry>
            <material name="Cyan">
                <color rgba="0 1.0 1.0 1.0"/>
            </material>
        </visual>
        <collision>
            <origin xyz="-0.22771693534990872 0.06421971606881348 -0.036362764733089026" rpy="0 0 0"/>
            <geometry>
                <box size="0.4698127986339453 0.42893208179342834 0.07272552946617805" />
            </geometry>
        </collision>
    </link>
    <joint name="link3_link4" type="revolute">
       <parent link="link3"/>
       <child  link="link4"/>
       <origin rpy="0 0 0" xyz="-0.17185042083136226 0.06417657842156466 0.0" />
     <axis xyz="0 1 0"/>
       <limit effort="0.0" lower="-3.14159" upper="3.14159" velocity="0.0"/>
    </joint>
    <link name="link4">
        <inertial>
            <origin xyz="0.1755909189136234 -0.084417777867977 0.10714035445654413" rpy="0 0 0"/>
            <mass value="1" />
            <inertia ixx="100" ixy="0" ixz="0" iyy="100" iyz="0" izz="100" />
        </inertial>
        <visual>
            <origin xyz="0.1755909189136234 -0.084417777867977 0.10714035445654413" rpy="0 0 0"/>
            <geometry>
                <box size="0.601054027411782 0.2137456560663552 0.21428070891308826" />
            </geometry>
            <material name="Cyan">
                <color rgba="0 1.0 1.0 1.0"/>
            </material>
        </visual>
        <collision>
            <origin xyz="0.1755909189136234 -0.084417777867977 0.10714035445654413" rpy="0 0 0"/>
            <geometry>
                <box size="0.601054027411782 0.2137456560663552 0.21428070891308826" />
            </geometry>
        </collision>
    </link>
    <joint name="link1_link5" type="revolute">
       <parent link="link1"/>
       <child  link="link5"/>
       <origin rpy="0 0 0" xyz="0.140611583838153 -0.4788295160273879 0.15246449027503614" />
     <axis xyz="0 0 1"/>
       <limit effort="0.0" lower="-3.14159" upper="3.14159" velocity="0.0"/>
    </joint>
    <link name="link5">
        <inertial>
            <origin xyz="-0.05455486475955772 -0.1266100891966977 0.241336910363166" rpy="0 0 0"/>
            <mass value="1" />
            <inertia ixx="100" ixy="0" ixz="0" iyy="100" iyz="0" izz="100" />
        </inertial>
        <visual>
            <origin xyz="-0.05455486475955772 -0.1266100891966977 0.241336910363166" rpy="0 0 0"/>
            <geometry>
                <box size="0.4095373792455749 0.2532201783933954 0.7469486800098142" />
            </geometry>
            <material name="Cyan">
                <color rgba="0 1.0 1.0 1.0"/>
            </material>
        </visual>
        <collision>
            <origin xyz="-0.05455486475955772 -0.1266100891966977 0.241336910363166" rpy="0 0 0"/>
            <geometry>
                <box size="0.4095373792455749 0.2532201783933954 0.7469486800098142" />
            </geometry>
        </collision>
    </link>
    <joint name="link4_link6" type="revolute">
       <parent link="link4"/>
       <child  link="link6"/>
       <origin rpy="0 0 0" xyz="0.45208275218693383 -0.168656539021598 0.0" />
     <axis xyz="1 0 0"/>
       <limit effort="0.0" lower="-3.14159" upper="3.14159" velocity="0.0"/>
    </joint>
    <link name="link6">
        <inertial>
            <origin xyz="-0.09506915418267738 -0.040991994785989735 -0.261024383271581" rpy="0 0 0"/>
            <mass value="1" />
            <inertia ixx="100" ixy="0" ixz="0" iyy="100" iyz="0" izz="100" />
        </inertial>
        <visual>
            <origin xyz="-0.09506915418267738 -0.040991994785989735 -0.261024383271581" rpy="0 0 0"/>
            <geometry>
                <box size="0.21679110696189108 0.20196346159260903 0.522048766543162" />
            </geometry>
            <material name="Cyan">
                <color rgba="0 1.0 1.0 1.0"/>
            </material>
        </visual>
        <collision>
            <origin xyz="-0.09506915418267738 -0.040991994785989735 -0.261024383271581" rpy="0 0 0"/>
            <geometry>
                <box size="0.21679110696189108 0.20196346159260903 0.522048766543162" />
            </geometry>
        </collision>
    </link>
    <joint name="link6_link7" type="revolute">
       <parent link="link6"/>
       <child  link="link7"/>
       <origin rpy="0 0 0" xyz="0.013326399298268163 -0.06608962522146639 -0.2803029777844097" />
     <axis xyz="0 0 1"/>
       <limit effort="0.0" lower="-3.14159" upper="3.14159" velocity="0.0"/>
    </joint>
    <link name="link7">
        <inertial>
            <origin xyz="0.09591569408572614 -0.27004203257148635 -0.13426591701264046" rpy="0 0 0"/>
            <mass value="1" />
            <inertia ixx="100" ixy="0" ixz="0" iyy="100" iyz="0" izz="100" />
        </inertial>
        <visual>
            <origin xyz="0.09591569408572614 -0.27004203257148635 -0.13426591701264046" rpy="0 0 0"/>
            <geometry>
                <box size="0.1918313881714523 0.8020735981074267 0.6666853046081693" />
            </geometry>
            <material name="Cyan">
                <color rgba="0 1.0 1.0 1.0"/>
            </material>
        </visual>
        <collision>
            <origin xyz="0.09591569408572614 -0.27004203257148635 -0.13426591701264046" rpy="0 0 0"/>
            <geometry>
                <box size="0.1918313881714523 0.8020735981074267 0.6666853046081693" />
            </geometry>
        </collision>
    </link>
    <joint name="link1_link8" type="revolute">
       <parent link="link1"/>
       <child  link="link8"/>
       <origin rpy="0 0 0" xyz="-0.20448032105039138 -0.17443762936515245 -0.0745175756481914" />
     <axis xyz="0 1 0"/>
       <limit effort="0.0" lower="-3.14159" upper="3.14159" velocity="0.0"/>
    </joint>
    <link name="link8">
        <inertial>
            <origin xyz="-0.1289407897341219 -0.0003305364448308577 -0.21697641365519" rpy="0 0 0"/>
            <mass value="1" />
            <inertia ixx="100" ixy="0" ixz="0" iyy="100" iyz="0" izz="100" />
        </inertial>
        <visual>
            <origin xyz="-0.1289407897341219 -0.0003305364448308577 -0.21697641365519" rpy="0 0 0"/>
            <geometry>
                <box size="0.8879410273662185 0.2307882959609131 0.43395282731038" />
            </geometry>
            <material name="Cyan">
                <color rgba="0 1.0 1.0 1.0"/>
            </material>
        </visual>
        <collision>
            <origin xyz="-0.1289407897341219 -0.0003305364448308577 -0.21697641365519" rpy="0 0 0"/>
            <geometry>
                <box size="0.8879410273662185 0.2307882959609131 0.43395282731038" />
            </geometry>
        </collision>
    </link>
    <joint name="link3_link9" type="revolute">
       <parent link="link3"/>
       <child  link="link9"/>
       <origin rpy="0 0 0" xyz="0.0016865885439316108 0.04241239944703133 -0.07272552946617805" />
     <axis xyz="1 0 0"/>
       <limit effort="0.0" lower="-3.14159" upper="3.14159" velocity="0.0"/>
    </joint>
    <link name="link9">
        <inertial>
            <origin xyz="0.4029214177370165 0.009464959088571314 -0.2875449200091153" rpy="0 0 0"/>
            <mass value="1" />
            <inertia ixx="100" ixy="0" ixz="0" iyy="100" iyz="0" izz="100" />
        </inertial>
        <visual>
            <origin xyz="0.4029214177370165 0.009464959088571314 -0.2875449200091153" rpy="0 0 0"/>
            <geometry>
                <box size="0.9430970206247319 0.12229604681041517 0.5750898400182306" />
            </geometry>
            <material name="Cyan">
                <color rgba="0 1.0 1.0 1.0"/>
            </material>
        </visual>
        <collision>
            <origin xyz="0.4029214177370165 0.009464959088571314 -0.2875449200091153" rpy="0 0 0"/>
            <geometry>
                <box size="0.9430970206247319 0.12229604681041517 0.5750898400182306" />
            </geometry>
        </collision>
    </link>
    <joint name="link9_link10" type="revolute">
       <parent link="link9"/>
       <child  link="link10"/>
       <origin rpy="0 0 0" xyz="-0.045260985379432794 0.0706129824937789 -0.0902812585415298" />
     <axis xyz="0 1 0"/>
       <limit effort="0.0" lower="-3.14159" upper="3.14159" velocity="0.0"/>
    </joint>
    <link name="link10">
        <inertial>
            <origin xyz="-0.17922185690961728 0.16613893974152566 0.26102762360149584" rpy="0 0 0"/>
            <mass value="1" />
            <inertia ixx="100" ixy="0" ixz="0" iyy="100" iyz="0" izz="100" />
        </inertial>
        <visual>
            <origin xyz="-0.17922185690961728 0.16613893974152566 0.26102762360149584" rpy="0 0 0"/>
            <geometry>
                <box size="0.6714771918230633 0.3322778794830513 0.683953713180711" />
            </geometry>
            <material name="Cyan">
                <color rgba="0 1.0 1.0 1.0"/>
            </material>
        </visual>
        <collision>
            <origin xyz="-0.17922185690961728 0.16613893974152566 0.26102762360149584" rpy="0 0 0"/>
            <geometry>
                <box size="0.6714771918230633 0.3322778794830513 0.683953713180711" />
            </geometry>
        </collision>
    </link>
</robot>