<robot name = "robot">
    <link name="link0">
        <inertial>
            <origin xyz="0 0 1" rpy="0 0 0"/>
            <mass value="1" />
            <inertia ixx="100" ixy="0" ixz="0" iyy="100" iyz="0" izz="100" />
        </inertial>
        <visual>
            <origin xyz="0 0 1" rpy="0 0 0"/>
            <geometry>
                <box size="0.1916584905190335 0.3621892711602517 0.2912792712442793" />
            </geometry>
            <material name="Cyan">
                <color rgba="0 1.0 1.0 1.0"/>
            </material>
        </visual>
        <collision>
            <origin xyz="0 0 1" rpy="0 0 0"/>
            <geometry>
                <box size="0.1916584905190335 0.3621892711602517 0.2912792712442793" />
            </geometry>
        </collision>
    </link>
    <joint name="link0_link1" type="revolute">
       <parent link="link0"/>
       <child  link="link1"/>
       <origin rpy="0 0 0" xyz="0.07878749237867225 -0.18109463558012584 1.09638551840289" />
     <axis xyz="1 0 0"/>
       <limit effort="0.0" lower="-3.14159" upper="3.14159" velocity="0.0"/>
    </joint>
    <link name="link1">
        <inertial>
            <origin xyz="0.05337333585564154 -0.21136710143975673 0.0299620512650554" rpy="0 0 0"/>
            <mass value="1" />
            <inertia ixx="100" ixy="0" ixz="0" iyy="100" iyz="0" izz="100" />
        </inertial>
        <visual>
            <origin xyz="0.05337333585564154 -0.21136710143975673 0.0299620512650554" rpy="0 0 0"/>
            <geometry>
                <box size="0.19922090084004762 0.42273420287951347 0.15244337546115272" />
            </geometry>
            <material name="Cyan">
                <color rgba="0 1.0 1.0 1.0"/>
            </material>
        </visual>
        <collision>
            <origin xyz="0.05337333585564154 -0.21136710143975673 0.0299620512650554" rpy="0 0 0"/>
            <geometry>
                <box size="0.19922090084004762 0.42273420287951347 0.15244337546115272" />
            </geometry>
        </collision>
    </link>
    <joint name="link0_link2" type="revolute">
       <parent link="link0"/>
       <child  link="link2"/>
       <origin rpy="0 0 0" xyz="-0.05051596225979666 0.18109463558012584 0.9368955893362634" />
     <axis xyz="0 0 1"/>
       <limit effort="0.0" lower="-3.14159" upper="3.14159" velocity="0.0"/>
    </joint>
    <link name="link2">
        <inertial>
            <origin xyz="0.20936924398243503 0.1683372044807862 -0.05962048555727598" rpy="0 0 0"/>
            <mass value="1" />
            <inertia ixx="100" ixy="0" ixz="0" iyy="100" iyz="0" izz="100" />
        </inertial>
        <visual>
            <origin xyz="0.20936924398243503 0.1683372044807862 -0.05962048555727598" rpy="0 0 0"/>
            <geometry>
                <box size="0.6027904815697199 0.3366744089615724 0.23920575880727912" />
            </geometry>
            <material name="Cyan">
                <color rgba="0 1.0 1.0 1.0"/>
            </material>
        </visual>
        <collision>
            <origin xyz="0.20936924398243503 0.1683372044807862 -0.05962048555727598" rpy="0 0 0"/>
            <geometry>
                <box size="0.6027904815697199 0.3366744089615724 0.23920575880727912" />
            </geometry>
        </collision>
    </link>
    <joint name="link1_link3" type="revolute">
       <parent link="link1"/>
       <child  link="link3"/>
       <origin rpy="0 0 0" xyz="0.15298378627566533 -0.26914700844685047 0.055262955529354243" />
     <axis xyz="1 0 0"/>
       <limit effort="0.0" lower="-3.14159" upper="3.14159" velocity="0.0"/>
    </joint>
    <link name="link3">
        <inertial>
            <origin xyz="0.014781253202184375 0.05233230752397406 0.029625124654238843" rpy="0 0 0"/>
            <mass value="1" />
            <inertia ixx="100" ixy="0" ixz="0" iyy="100" iyz="0" izz="100" />
        </inertial>
        <visual>
            <origin xyz="0.014781253202184375 0.05233230752397406 0.029625124654238843" rpy="0 0 0"/>
            <geometry>
                <box size="0.02956250640436875 0.27365864913506943 0.5996619515483016" />
            </geometry>
            <material name="Cyan">
                <color rgba="0 1.0 1.0 1.0"/>
            </material>
        </visual>
        <collision>
            <origin xyz="0.014781253202184375 0.05233230752397406 0.029625124654238843" rpy="0 0 0"/>
            <geometry>
                <box size="0.02956250640436875 0.27365864913506943 0.5996619515483016" />
            </geometry>
        </collision>
    </link>
    <joint name="link0_link4" type="revolute">
       <parent link="link0"/>
       <child  link="link4"/>
       <origin rpy="0 0 0" xyz="0.017792971875379242 0.1368996152860982 0.8543603643778603" />
     <axis xyz="1 0 0"/>
       <limit effort="0.0" lower="-3.14159" upper="3.14159" velocity="0.0"/>
    </joint>
    <link name="link4">
        <inertial>
            <origin xyz="-0.049414638057530776 -0.04886780095680013 -0.3569355568723432" rpy="0 0 0"/>
            <mass value="1" />
            <inertia ixx="100" ixy="0" ixz="0" iyy="100" iyz="0" izz="100" />
        </inertial>
        <visual>
            <origin xyz="-0.049414638057530776 -0.04886780095680013 -0.3569355568723432" rpy="0 0 0"/>
            <geometry>
                <box size="0.1988248937426611 0.9710518209178581 0.7138711137446864" />
            </geometry>
            <material name="Cyan">
                <color rgba="0 1.0 1.0 1.0"/>
            </material>
        </visual>
        <collision>
            <origin xyz="-0.049414638057530776 -0.04886780095680013 -0.3569355568723432" rpy="0 0 0"/>
            <geometry>
                <box size="0.1988248937426611 0.9710518209178581 0.7138711137446864" />
            </geometry>
        </collision>
    </link>
</robot>