<robot name = "robot">
    <link name="link0">
        <inertial>
            <origin xyz="0 0 1" rpy="0 0 0"/>
            <mass value="1" />
            <inertia ixx="100" ixy="0" ixz="0" iyy="100" iyz="0" izz="100" />
        </inertial>
        <visual>
            <origin xyz="0 0 1" rpy="0 0 0"/>
            <geometry>
                <box size="0.15836440423708653 0.1817167421191651 0.6109207068343592" />
            </geometry>
            <material name="Cyan">
                <color rgba="0.0 1.0 1.0 1.0"/>
            </material>
        </visual>
        <collision>
            <origin xyz="0 0 1" rpy="0 0 0"/>
            <geometry>
                <box size="0.15836440423708653 0.1817167421191651 0.6109207068343592" />
            </geometry>
        </collision>
    </link>
    <joint name="link0_link1" type="revolute">
       <parent link="link0"/>
       <child  link="link1"/>
       <origin rpy="0 0 0" xyz="-0.07918220211854327 0.029860561072494102 1.2017151026887516" />
     <axis xyz="0 1 0"/>
       <limit effort="0.0" lower="-3.14159" upper="3.14159" velocity="0.0"/>
    </joint>
    <link name="link1">
        <inertial>
            <origin xyz="-0.30845765466991554 -0.38180809501073637 0.12045290281749987" rpy="0 0 0"/>
            <mass value="1" />
            <inertia ixx="100" ixy="0" ixz="0" iyy="100" iyz="0" izz="100" />
        </inertial>
        <visual>
            <origin xyz="-0.30845765466991554 -0.38180809501073637 0.12045290281749987" rpy="0 0 0"/>
            <geometry>
                <box size="0.6169153093398311 0.8024830841650932 0.2698692750819792" />
            </geometry>
            <material name="Cyan">
                <color rgba="0.0 1.0 1.0 1.0"/>
            </material>
        </visual>
        <collision>
            <origin xyz="-0.30845765466991554 -0.38180809501073637 0.12045290281749987" rpy="0 0 0"/>
            <geometry>
                <box size="0.6169153093398311 0.8024830841650932 0.2698692750819792" />
            </geometry>
        </collision>
    </link>
    <joint name="link1_link2" type="revolute">
       <parent link="link1"/>
       <child  link="link2"/>
       <origin rpy="0 0 0" xyz="0.0 -0.4243499289204424 0.19212581941551368" />
     <axis xyz="0 0 1"/>
       <limit effort="0.0" lower="-3.14159" upper="3.14159" velocity="0.0"/>
    </joint>
    <link name="link2">
        <inertial>
            <origin xyz="0.3170735720152749 0.2848508232784547 0.046794674272399694" rpy="0 0 0"/>
            <mass value="1" />
            <inertia ixx="100" ixy="0" ixz="0" iyy="100" iyz="0" izz="100" />
        </inertial>
        <visual>
            <origin xyz="0.3170735720152749 0.2848508232784547 0.046794674272399694" rpy="0 0 0"/>
            <geometry>
                <box size="0.6341471440305498 0.7621928082889454 0.10793299914631538" />
            </geometry>
            <material name="Green">
                <color rgba="0.0 1.0 0.0 1.0"/>
            </material>
        </visual>
        <collision>
            <origin xyz="0.3170735720152749 0.2848508232784547 0.046794674272399694" rpy="0 0 0"/>
            <geometry>
                <box size="0.6341471440305498 0.7621928082889454 0.10793299914631538" />
            </geometry>
        </collision>
    </link>
    <joint name="link1_link3" type="revolute">
       <parent link="link1"/>
       <child  link="link3"/>
       <origin rpy="0 0 0" xyz="-0.6169153093398311 -0.35034565690899167 0.13321698500105034" />
     <axis xyz="1 0 0"/>
       <limit effort="0.0" lower="-3.14159" upper="3.14159" velocity="0.0"/>
    </joint>
    <link name="link3">
        <inertial>
            <origin xyz="-0.3408366871048493 -0.2684438749497398 -0.06341274471241908" rpy="0 0 0"/>
            <mass value="1" />
            <inertia ixx="100" ixy="0" ixz="0" iyy="100" iyz="0" izz="100" />
        </inertial>
        <visual>
            <origin xyz="-0.3408366871048493 -0.2684438749497398 -0.06341274471241908" rpy="0 0 0"/>
            <geometry>
                <box size="0.6816733742096986 0.5688236353001958 0.4609639843970894" />
            </geometry>
            <material name="Cyan">
                <color rgba="0.0 1.0 1.0 1.0"/>
            </material>
        </visual>
        <collision>
            <origin xyz="-0.3408366871048493 -0.2684438749497398 -0.06341274471241908" rpy="0 0 0"/>
            <geometry>
                <box size="0.6816733742096986 0.5688236353001958 0.4609639843970894" />
            </geometry>
        </collision>
    </link>
    <joint name="link3_link4" type="revolute">
       <parent link="link3"/>
       <child  link="link4"/>
       <origin rpy="0 0 0" xyz="0.0 -0.3989745849147487 -0.13992767383057825" />
     <axis xyz="1 0 0"/>
       <limit effort="0.0" lower="-3.14159" upper="3.14159" velocity="0.0"/>
    </joint>
    <link name="link4">
        <inertial>
            <origin xyz="0.3020122865047679 -0.003586441787670853 0.11232613086779829" rpy="0 0 0"/>
            <mass value="1" />
            <inertia ixx="100" ixy="0" ixz="0" iyy="100" iyz="0" izz="100" />
        </inertial>
        <visual>
            <origin xyz="0.3020122865047679 -0.003586441787670853 0.11232613086779829" rpy="0 0 0"/>
            <geometry>
                <box size="0.6040245730095358 0.09883718750304515 0.26176954831706256" />
            </geometry>
            <material name="Green">
                <color rgba="0.0 1.0 0.0 1.0"/>
            </material>
        </visual>
        <collision>
            <origin xyz="0.3020122865047679 -0.003586441787670853 0.11232613086779829" rpy="0 0 0"/>
            <geometry>
                <box size="0.6040245730095358 0.09883718750304515 0.26176954831706256" />
            </geometry>
        </collision>
    </link>
    <joint name="link4_link5" type="revolute">
       <parent link="link4"/>
       <child  link="link5"/>
       <origin rpy="0 0 0" xyz="0.6040245730095358 0.022663905815688 0.21443367903990912" />
     <axis xyz="0 1 0"/>
       <limit effort="0.0" lower="-3.14159" upper="3.14159" velocity="0.0"/>
    </joint>
    <link name="link5">
        <inertial>
            <origin xyz="0.09556159729941721 0.20026148503844937 0.16169015821106658" rpy="0 0 0"/>
            <mass value="1" />
            <inertia ixx="100" ixy="0" ixz="0" iyy="100" iyz="0" izz="100" />
        </inertial>
        <visual>
            <origin xyz="0.09556159729941721 0.20026148503844937 0.16169015821106658" rpy="0 0 0"/>
            <geometry>
                <box size="0.19112319459883442 0.6848251192909625 0.8523625449969232" />
            </geometry>
            <material name="Cyan">
                <color rgba="0.0 1.0 1.0 1.0"/>
            </material>
        </visual>
        <collision>
            <origin xyz="0.09556159729941721 0.20026148503844937 0.16169015821106658" rpy="0 0 0"/>
            <geometry>
                <box size="0.19112319459883442 0.6848251192909625 0.8523625449969232" />
            </geometry>
        </collision>
    </link>
    <joint name="link3_link6" type="revolute">
       <parent link="link3"/>
       <child  link="link6"/>
       <origin rpy="0 0 0" xyz="-0.03939390926690345 0.005312874841673698 0.16706924748612562" />
     <axis xyz="0 1 0"/>
       <limit effort="0.0" lower="-3.14159" upper="3.14159" velocity="0.0"/>
    </joint>
    <link name="link6">
        <inertial>
            <origin xyz="-0.2223136163216337 0.23362498383398492 0.12542519166479643" rpy="0 0 0"/>
            <mass value="1" />
            <inertia ixx="100" ixy="0" ixz="0" iyy="100" iyz="0" izz="100" />
        </inertial>
        <visual>
            <origin xyz="-0.2223136163216337 0.23362498383398492 0.12542519166479643" rpy="0 0 0"/>
            <geometry>
                <box size="0.9380112848607758 0.6456094009529856 0.25085038332959286" />
            </geometry>
            <material name="Green">
                <color rgba="0.0 1.0 0.0 1.0"/>
            </material>
        </visual>
        <collision>
            <origin xyz="-0.2223136163216337 0.23362498383398492 0.12542519166479643" rpy="0 0 0"/>
            <geometry>
                <box size="0.9380112848607758 0.6456094009529856 0.25085038332959286" />
            </geometry>
        </collision>
    </link>
    <joint name="link6_link7" type="revolute">
       <parent link="link6"/>
       <child  link="link7"/>
       <origin rpy="0 0 0" xyz="0.11573214599357945 0.5248520984440255 0.25085038332959286" />
     <axis xyz="0 1 0"/>
       <limit effort="0.0" lower="-3.14159" upper="3.14159" velocity="0.0"/>
    </joint>
    <link name="link7">
        <inertial>
            <origin xyz="-0.08706322670435546 -0.3282212670564256 0.328510808914051" rpy="0 0 0"/>
            <mass value="1" />
            <inertia ixx="100" ixy="0" ixz="0" iyy="100" iyz="0" izz="100" />
        </inertial>
        <visual>
            <origin xyz="-0.08706322670435546 -0.3282212670564256 0.328510808914051" rpy="0 0 0"/>
            <geometry>
                <box size="0.36987984658034134 0.6968944827850752 0.657021617828102" />
            </geometry>
            <material name="Green">
                <color rgba="0.0 1.0 0.0 1.0"/>
            </material>
        </visual>
        <collision>
            <origin xyz="-0.08706322670435546 -0.3282212670564256 0.328510808914051" rpy="0 0 0"/>
            <geometry>
                <box size="0.36987984658034134 0.6968944827850752 0.657021617828102" />
            </geometry>
        </collision>
    </link>
</robot>