<robot name = "robot">
    <link name="link0">
        <inertial>
            <origin xyz="0 0 1" rpy="0 0 0"/>
            <mass value="1" />
            <inertia ixx="100" ixy="0" ixz="0" iyy="100" iyz="0" izz="100" />
        </inertial>
        <visual>
            <origin xyz="0 0 1" rpy="0 0 0"/>
            <geometry>
                <box size="0.16381015729716586 0.06259298043798955 0.30100249848651617" />
            </geometry>
            <material name="Cyan">
                <color rgba="0.0 1.0 1.0 1.0"/>
            </material>
        </visual>
        <collision>
            <origin xyz="0 0 1" rpy="0 0 0"/>
            <geometry>
                <box size="0.16381015729716586 0.06259298043798955 0.30100249848651617" />
            </geometry>
        </collision>
    </link>
    <joint name="link0_link1" type="revolute">
       <parent link="link0"/>
       <child  link="link1"/>
       <origin rpy="0 0 0" xyz="0.03571007456960271 0.03129649021899478 0.9961592688788099" />
     <axis xyz="0 0 1"/>
       <limit effort="0.0" lower="-3.14159" upper="3.14159" velocity="0.0"/>
    </joint>
    <link name="link1">
        <inertial>
            <origin xyz="-0.18542066678475183 0.16739887716186475 -0.14033407675164383" rpy="0 0 0"/>
            <mass value="1" />
            <inertia ixx="100" ixy="0" ixz="0" iyy="100" iyz="0" izz="100" />
        </inertial>
        <visual>
            <origin xyz="-0.18542066678475183 0.16739887716186475 -0.14033407675164383" rpy="0 0 0"/>
            <geometry>
                <box size="0.8140403485984378 0.3347977543237295 0.3896137182665733" />
            </geometry>
            <material name="Green">
                <color rgba="0.0 1.0 0.0 1.0"/>
            </material>
        </visual>
        <collision>
            <origin xyz="-0.18542066678475183 0.16739887716186475 -0.14033407675164383" rpy="0 0 0"/>
            <geometry>
                <box size="0.8140403485984378 0.3347977543237295 0.3896137182665733" />
            </geometry>
        </collision>
    </link>
    <joint name="link1_link2" type="revolute">
       <parent link="link1"/>
       <child  link="link2"/>
       <origin rpy="0 0 0" xyz="-0.43514293246039715 0.3347977543237295 0.022778422210774196" />
     <axis xyz="1 0 0"/>
       <limit effort="0.0" lower="-3.14159" upper="3.14159" velocity="0.0"/>
    </joint>
    <link name="link2">
        <inertial>
            <origin xyz="0.0821371591314691 0.16782766832407214 -0.34143749836792525" rpy="0 0 0"/>
            <mass value="1" />
            <inertia ixx="100" ixy="0" ixz="0" iyy="100" iyz="0" izz="100" />
        </inertial>
        <visual>
            <origin xyz="0.0821371591314691 0.16782766832407214 -0.34143749836792525" rpy="0 0 0"/>
            <geometry>
                <box size="0.17434350364362983 0.3356553366481443 0.8395073541808395" />
            </geometry>
            <material name="Green">
                <color rgba="0.0 1.0 0.0 1.0"/>
            </material>
        </visual>
        <collision>
            <origin xyz="0.0821371591314691 0.16782766832407214 -0.34143749836792525" rpy="0 0 0"/>
            <geometry>
                <box size="0.17434350364362983 0.3356553366481443 0.8395073541808395" />
            </geometry>
        </collision>
    </link>
    <joint name="link2_link3" type="revolute">
       <parent link="link2"/>
       <child  link="link3"/>
       <origin rpy="0 0 0" xyz="0.06596472473228357 0.3356553366481443 -0.3034338017003715" />
     <axis xyz="1 0 0"/>
       <limit effort="0.0" lower="-3.14159" upper="3.14159" velocity="0.0"/>
    </joint>
    <link name="link3">
        <inertial>
            <origin xyz="0.021313455226253088 0.2309661432613342 -0.21192775170961137" rpy="0 0 0"/>
            <mass value="1" />
            <inertia ixx="100" ixy="0" ixz="0" iyy="100" iyz="0" izz="100" />
        </inertial>
        <visual>
            <origin xyz="0.021313455226253088 0.2309661432613342 -0.21192775170961137" rpy="0 0 0"/>
            <geometry>
                <box size="0.3970802000693848 0.4619322865226684 0.48033175583116805" />
            </geometry>
            <material name="Cyan">
                <color rgba="0.0 1.0 1.0 1.0"/>
            </material>
        </visual>
        <collision>
            <origin xyz="0.021313455226253088 0.2309661432613342 -0.21192775170961137" rpy="0 0 0"/>
            <geometry>
                <box size="0.3970802000693848 0.4619322865226684 0.48033175583116805" />
            </geometry>
        </collision>
    </link>
</robot>