<robot name = "robot">
    <link name="link0">
        <inertial>
            <origin xyz="0 0 1" rpy="0 0 0"/>
            <mass value="1" />
            <inertia ixx="100" ixy="0" ixz="0" iyy="100" iyz="0" izz="100" />
        </inertial>
        <visual>
            <origin xyz="0 0 1" rpy="0 0 0"/>
            <geometry>
                <box size="0.6097351751279089 0.6499408682978244 0.8905179485988264" />
            </geometry>
            <material name="Cyan">
                <color rgba="0.0 1.0 1.0 1.0"/>
            </material>
        </visual>
        <collision>
            <origin xyz="0 0 1" rpy="0 0 0"/>
            <geometry>
                <box size="0.6097351751279089 0.6499408682978244 0.8905179485988264" />
            </geometry>
        </collision>
    </link>
    <joint name="link0_link1" type="revolute">
       <parent link="link0"/>
       <child  link="link1"/>
       <origin rpy="0 0 0" xyz="0.30486758756395443 0.1236480774539795 0.6832499472552622" />
     <axis xyz="0 1 0"/>
       <limit effort="0.0" lower="-3.14159" upper="3.14159" velocity="0.0"/>
    </joint>
    <link name="link1">
        <inertial>
            <origin xyz="0.43795171039115993 0.0012200600915893514 -0.1769660001235387" rpy="0 0 0"/>
            <mass value="1" />
            <inertia ixx="100" ixy="0" ixz="0" iyy="100" iyz="0" izz="100" />
        </inertial>
        <visual>
            <origin xyz="0.43795171039115993 0.0012200600915893514 -0.1769660001235387" rpy="0 0 0"/>
            <geometry>
                <box size="0.8759034207823199 0.24014844863517992 0.3732542051808143" />
            </geometry>
            <material name="Green">
                <color rgba="0.0 1.0 0.0 1.0"/>
            </material>
        </visual>
        <collision>
            <origin xyz="0.43795171039115993 0.0012200600915893514 -0.1769660001235387" rpy="0 0 0"/>
            <geometry>
                <box size="0.8759034207823199 0.24014844863517992 0.3732542051808143" />
            </geometry>
        </collision>
    </link>
    <joint name="link1_link2" type="revolute">
       <parent link="link1"/>
       <child  link="link2"/>
       <origin rpy="0 0 0" xyz="0.8710476333637653 -0.08890033689286632 0.009661102466868465" />
     <axis xyz="0 0 1"/>
       <limit effort="0.0" lower="-3.14159" upper="3.14159" velocity="0.0"/>
    </joint>
    <link name="link2">
        <inertial>
            <origin xyz="0.048075123372111124 0.12805394770049236 0.019534388671064384" rpy="0 0 0"/>
            <mass value="1" />
            <inertia ixx="100" ixy="0" ixz="0" iyy="100" iyz="0" izz="100" />
        </inertial>
        <visual>
            <origin xyz="0.048075123372111124 0.12805394770049236 0.019534388671064384" rpy="0 0 0"/>
            <geometry>
                <box size="0.47581757202872277 0.38453937142033223 0.03906877734212877" />
            </geometry>
            <material name="Cyan">
                <color rgba="0.0 1.0 1.0 1.0"/>
            </material>
        </visual>
        <collision>
            <origin xyz="0.048075123372111124 0.12805394770049236 0.019534388671064384" rpy="0 0 0"/>
            <geometry>
                <box size="0.47581757202872277 0.38453937142033223 0.03906877734212877" />
            </geometry>
        </collision>
    </link>
    <joint name="link2_link3" type="revolute">
       <parent link="link2"/>
       <child  link="link3"/>
       <origin rpy="0 0 0" xyz="-0.18983366264225027 0.25162893544924375 0.01982166853114053" />
     <axis xyz="0 1 0"/>
       <limit effort="0.0" lower="-3.14159" upper="3.14159" velocity="0.0"/>
    </joint>
    <link name="link3">
        <inertial>
            <origin xyz="-0.41611978310217834 -0.2756391674542164 -0.019094508810503487" rpy="0 0 0"/>
            <mass value="1" />
            <inertia ixx="100" ixy="0" ixz="0" iyy="100" iyz="0" izz="100" />
        </inertial>
        <visual>
            <origin xyz="-0.41611978310217834 -0.2756391674542164 -0.019094508810503487" rpy="0 0 0"/>
            <geometry>
                <box size="0.8322395662043567 0.6553866987044642 0.22931038166748452" />
            </geometry>
            <material name="Green">
                <color rgba="0.0 1.0 0.0 1.0"/>
            </material>
        </visual>
        <collision>
            <origin xyz="-0.41611978310217834 -0.2756391674542164 -0.019094508810503487" rpy="0 0 0"/>
            <geometry>
                <box size="0.8322395662043567 0.6553866987044642 0.22931038166748452" />
            </geometry>
        </collision>
    </link>
    <joint name="link0_link4" type="revolute">
       <parent link="link0"/>
       <child  link="link4"/>
       <origin rpy="0 0 0" xyz="0.30486758756395443 -0.003357664851099903 1.147278503444354" />
     <axis xyz="1 0 0"/>
       <limit effort="0.0" lower="-3.14159" upper="3.14159" velocity="0.0"/>
    </joint>
    <link name="link4">
        <inertial>
            <origin xyz="0.17989826415721438 0.01897157964573244 -0.0892906402577789" rpy="0 0 0"/>
            <mass value="1" />
            <inertia ixx="100" ixy="0" ixz="0" iyy="100" iyz="0" izz="100" />
        </inertial>
        <visual>
            <origin xyz="0.17989826415721438 0.01897157964573244 -0.0892906402577789" rpy="0 0 0"/>
            <geometry>
                <box size="0.35979652831442877 0.07548329440390622 0.4887176347367982" />
            </geometry>
            <material name="Green">
                <color rgba="0.0 1.0 0.0 1.0"/>
            </material>
        </visual>
        <collision>
            <origin xyz="0.17989826415721438 0.01897157964573244 -0.0892906402577789" rpy="0 0 0"/>
            <geometry>
                <box size="0.35979652831442877 0.07548329440390622 0.4887176347367982" />
            </geometry>
        </collision>
    </link>
</robot>