<robot name = "robot">
    <link name="link0">
        <inertial>
            <origin xyz="0 0 1" rpy="0 0 0"/>
            <mass value="1" />
            <inertia ixx="100" ixy="0" ixz="0" iyy="100" iyz="0" izz="100" />
        </inertial>
        <visual>
            <origin xyz="0 0 1" rpy="0 0 0"/>
            <geometry>
                <box size="0.5334293038997017 0.6958477221874614 0.8685876433975955" />
            </geometry>
            <material name="Cyan">
                <color rgba="0 1.0 1.0 1.0"/>
            </material>
        </visual>
        <collision>
            <origin xyz="0 0 1" rpy="0 0 0"/>
            <geometry>
                <box size="0.5334293038997017 0.6958477221874614 0.8685876433975955" />
            </geometry>
        </collision>
    </link>
    <joint name="link0_link1" type="revolute">
       <parent link="link0"/>
       <child  link="link1"/>
       <origin rpy="0 0 0" xyz="-0.26671465194985083 0.24579322235463277 1.3351147939979078" />
     <axis xyz="1 0 0"/>
       <limit effort="0.0" lower="-3.14159" upper="3.14159" velocity="0.0"/>
    </joint>
    <link name="link1">
        <inertial>
            <origin xyz="-0.1378638554976861 -0.08771601902659774 0.020460591894083772" rpy="0 0 0"/>
            <mass value="1" />
            <inertia ixx="100" ixy="0" ixz="0" iyy="100" iyz="0" izz="100" />
        </inertial>
        <visual>
            <origin xyz="-0.1378638554976861 -0.08771601902659774 0.020460591894083772" rpy="0 0 0"/>
            <geometry>
                <box size="0.2757277109953722 0.9587029879223904 0.6281167191154183" />
            </geometry>
            <material name="Cyan">
                <color rgba="0 1.0 1.0 1.0"/>
            </material>
        </visual>
        <collision>
            <origin xyz="-0.1378638554976861 -0.08771601902659774 0.020460591894083772" rpy="0 0 0"/>
            <geometry>
                <box size="0.2757277109953722 0.9587029879223904 0.6281167191154183" />
            </geometry>
        </collision>
    </link>
</robot>