<robot name = "robot">
    <link name="link0">
        <inertial>
            <origin xyz="0 0 1" rpy="0 0 0"/>
            <mass value="1" />
            <inertia ixx="100" ixy="0" ixz="0" iyy="100" iyz="0" izz="100" />
        </inertial>
        <visual>
            <origin xyz="0 0 1" rpy="0 0 0"/>
            <geometry>
                <box size="0.8694535684025476 0.9060421634838117 0.23179814634224738" />
            </geometry>
            <material name="Cyan">
                <color rgba="0.0 1.0 1.0 1.0"/>
            </material>
        </visual>
        <collision>
            <origin xyz="0 0 1" rpy="0 0 0"/>
            <geometry>
                <box size="0.8694535684025476 0.9060421634838117 0.23179814634224738" />
            </geometry>
        </collision>
    </link>
    <joint name="link0_link1" type="revolute">
       <parent link="link0"/>
       <child  link="link1"/>
       <origin rpy="0 0 0" xyz="-0.10548277746637498 -0.45302108174190586 1.0381313234738427" />
     <axis xyz="1 0 0"/>
       <limit effort="0.0" lower="-3.14159" upper="3.14159" velocity="0.0"/>
    </joint>
    <link name="link1">
        <inertial>
            <origin xyz="0.09478068945086418 -0.0177888702064134 -0.16655268119913452" rpy="0 0 0"/>
            <mass value="1" />
            <inertia ixx="100" ixy="0" ixz="0" iyy="100" iyz="0" izz="100" />
        </inertial>
        <visual>
            <origin xyz="0.09478068945086418 -0.0177888702064134 -0.16655268119913452" rpy="0 0 0"/>
            <geometry>
                <box size="0.2501297423369855 0.0355777404128268 0.8369778337392951" />
            </geometry>
            <material name="Green">
                <color rgba="0.0 1.0 0.0 1.0"/>
            </material>
        </visual>
        <collision>
            <origin xyz="0.09478068945086418 -0.0177888702064134 -0.16655268119913452" rpy="0 0 0"/>
            <geometry>
                <box size="0.2501297423369855 0.0355777404128268 0.8369778337392951" />
            </geometry>
        </collision>
    </link>
</robot>