<robot name = "robot">
    <link name="link0">
        <inertial>
            <origin xyz="0 0 1" rpy="0 0 0"/>
            <mass value="1" />
            <inertia ixx="100" ixy="0" ixz="0" iyy="100" iyz="0" izz="100" />
        </inertial>
        <visual>
            <origin xyz="0 0 1" rpy="0 0 0"/>
            <geometry>
                <box size="0.6569754841085549 0.5283361009084455 0.7929013910290953" />
            </geometry>
            <material name="Cyan">
                <color rgba="0.0 1.0 1.0 1.0"/>
            </material>
        </visual>
        <collision>
            <origin xyz="0 0 1" rpy="0 0 0"/>
            <geometry>
                <box size="0.6569754841085549 0.5283361009084455 0.7929013910290953" />
            </geometry>
        </collision>
    </link>
    <joint name="link0_link1" type="revolute">
       <parent link="link0"/>
       <child  link="link1"/>
       <origin rpy="0 0 0" xyz="-0.32848774205427744 0.12528099196433645 1.3287705616161063" />
     <axis xyz="0 0 1"/>
       <limit effort="0.0" lower="-3.14159" upper="3.14159" velocity="0.0"/>
    </joint>
    <link name="link1">
        <inertial>
            <origin xyz="-0.20475412141616167 0.0034046385194098465 0.0950269745209185" rpy="0 0 0"/>
            <mass value="1" />
            <inertia ixx="100" ixy="0" ixz="0" iyy="100" iyz="0" izz="100" />
        </inertial>
        <visual>
            <origin xyz="-0.20475412141616167 0.0034046385194098465 0.0950269745209185" rpy="0 0 0"/>
            <geometry>
                <box size="0.40950824283232334 0.15447209418261365 0.1900874552634293" />
            </geometry>
            <material name="Green">
                <color rgba="0.0 1.0 0.0 1.0"/>
            </material>
        </visual>
        <collision>
            <origin xyz="-0.20475412141616167 0.0034046385194098465 0.0950269745209185" rpy="0 0 0"/>
            <geometry>
                <box size="0.40950824283232334 0.15447209418261365 0.1900874552634293" />
            </geometry>
        </collision>
    </link>
</robot>