<robot name = "robot">
    <link name="link0">
        <inertial>
            <origin xyz="0 0 1" rpy="0 0 0"/>
            <mass value="1" />
            <inertia ixx="100" ixy="0" ixz="0" iyy="100" iyz="0" izz="100" />
        </inertial>
        <visual>
            <origin xyz="0 0 1" rpy="0 0 0"/>
            <geometry>
                <box size="0.5284675084029056 0.01632721611831145 0.45749101518682644" />
            </geometry>
            <material name="Cyan">
                <color rgba="0.0 1.0 1.0 1.0"/>
            </material>
        </visual>
        <collision>
            <origin xyz="0 0 1" rpy="0 0 0"/>
            <geometry>
                <box size="0.5284675084029056 0.01632721611831145 0.45749101518682644" />
            </geometry>
        </collision>
    </link>
    <joint name="link0_link1" type="revolute">
       <parent link="link0"/>
       <child  link="link1"/>
       <origin rpy="0 0 0" xyz="-0.2642337542014528 -0.0006836506902563581 0.8578579848543626" />
     <axis xyz="1 0 0"/>
       <limit effort="0.0" lower="-3.14159" upper="3.14159" velocity="0.0"/>
    </joint>
    <link name="link1">
        <inertial>
            <origin xyz="-0.46874490258499496 -0.19724927789481692 0.11485048723132274" rpy="0 0 0"/>
            <mass value="1" />
            <inertia ixx="100" ixy="0" ixz="0" iyy="100" iyz="0" izz="100" />
        </inertial>
        <visual>
            <origin xyz="-0.46874490258499496 -0.19724927789481692 0.11485048723132274" rpy="0 0 0"/>
            <geometry>
                <box size="0.9374898051699899 0.4196511343987842 0.9304056475660021" />
            </geometry>
            <material name="Green">
                <color rgba="0.0 1.0 0.0 1.0"/>
            </material>
        </visual>
        <collision>
            <origin xyz="-0.46874490258499496 -0.19724927789481692 0.11485048723132274" rpy="0 0 0"/>
            <geometry>
                <box size="0.9374898051699899 0.4196511343987842 0.9304056475660021" />
            </geometry>
        </collision>
    </link>
    <joint name="link0_link2" type="revolute">
       <parent link="link0"/>
       <child  link="link2"/>
       <origin rpy="0 0 0" xyz="-0.13843313885959505 0.005233198503499948 1.2287455075934133" />
     <axis xyz="0 0 1"/>
       <limit effort="0.0" lower="-3.14159" upper="3.14159" velocity="0.0"/>
    </joint>
    <link name="link2">
        <inertial>
            <origin xyz="-0.19195558252162395 -0.24718213351842702 0.23094158568525813" rpy="0 0 0"/>
            <mass value="1" />
            <inertia ixx="100" ixy="0" ixz="0" iyy="100" iyz="0" izz="100" />
        </inertial>
        <visual>
            <origin xyz="-0.19195558252162395 -0.24718213351842702 0.23094158568525813" rpy="0 0 0"/>
            <geometry>
                <box size="0.9870792211517081 0.9783035710470885 0.46188317137051627" />
            </geometry>
            <material name="Green">
                <color rgba="0.0 1.0 0.0 1.0"/>
            </material>
        </visual>
        <collision>
            <origin xyz="-0.19195558252162395 -0.24718213351842702 0.23094158568525813" rpy="0 0 0"/>
            <geometry>
                <box size="0.9870792211517081 0.9783035710470885 0.46188317137051627" />
            </geometry>
        </collision>
    </link>
    <joint name="link2_link3" type="revolute">
       <parent link="link2"/>
       <child  link="link3"/>
       <origin rpy="0 0 0" xyz="-0.34281727535174067 -0.5091743548384243 0.46188317137051627" />
     <axis xyz="0 0 1"/>
       <limit effort="0.0" lower="-3.14159" upper="3.14159" velocity="0.0"/>
    </joint>
    <link name="link3">
        <inertial>
            <origin xyz="-0.24215249588922122 0.013822099483711757 0.2781732982842878" rpy="0 0 0"/>
            <mass value="1" />
            <inertia ixx="100" ixy="0" ixz="0" iyy="100" iyz="0" izz="100" />
        </inertial>
        <visual>
            <origin xyz="-0.24215249588922122 0.013822099483711757 0.2781732982842878" rpy="0 0 0"/>
            <geometry>
                <box size="0.678398667822429 0.20281737982155668 0.5563465965685755" />
            </geometry>
            <material name="Green">
                <color rgba="0.0 1.0 0.0 1.0"/>
            </material>
        </visual>
        <collision>
            <origin xyz="-0.24215249588922122 0.013822099483711757 0.2781732982842878" rpy="0 0 0"/>
            <geometry>
                <box size="0.678398667822429 0.20281737982155668 0.5563465965685755" />
            </geometry>
        </collision>
    </link>
    <joint name="link1_link4" type="revolute">
       <parent link="link1"/>
       <child  link="link4"/>
       <origin rpy="0 0 0" xyz="-0.6328239394565889 -0.07879006652914754 0.5800533110143238" />
     <axis xyz="0 1 0"/>
       <limit effort="0.0" lower="-3.14159" upper="3.14159" velocity="0.0"/>
    </joint>
    <link name="link4">
        <inertial>
            <origin xyz="0.36395158611498235 -0.03981737708793918 0.17466633468685278" rpy="0 0 0"/>
            <mass value="1" />
            <inertia ixx="100" ixy="0" ixz="0" iyy="100" iyz="0" izz="100" />
        </inertial>
        <visual>
            <origin xyz="0.36395158611498235 -0.03981737708793918 0.17466633468685278" rpy="0 0 0"/>
            <geometry>
                <box size="0.8707011875944869 0.21073003651552968 0.34933266937370555" />
            </geometry>
            <material name="Green">
                <color rgba="0.0 1.0 0.0 1.0"/>
            </material>
        </visual>
        <collision>
            <origin xyz="0.36395158611498235 -0.03981737708793918 0.17466633468685278" rpy="0 0 0"/>
            <geometry>
                <box size="0.8707011875944869 0.21073003651552968 0.34933266937370555" />
            </geometry>
        </collision>
    </link>
</robot>