<robot name = "robot">
    <link name="link0">
        <inertial>
            <origin xyz="0 0 1" rpy="0 0 0"/>
            <mass value="1" />
            <inertia ixx="100" ixy="0" ixz="0" iyy="100" iyz="0" izz="100" />
        </inertial>
        <visual>
            <origin xyz="0 0 1" rpy="0 0 0"/>
            <geometry>
                <box size="0.9399153724639688 0.38481517273176336 0.9343520917754992" />
            </geometry>
            <material name="Cyan">
                <color rgba="0 1.0 1.0 1.0"/>
            </material>
        </visual>
        <collision>
            <origin xyz="0 0 1" rpy="0 0 0"/>
            <geometry>
                <box size="0.9399153724639688 0.38481517273176336 0.9343520917754992" />
            </geometry>
        </collision>
    </link>
    <joint name="link0_link1" type="revolute">
       <parent link="link0"/>
       <child  link="link1"/>
       <origin rpy="0 0 0" xyz="0.06266713871799347 0.19240758636588168 0.9872894494674987" />
     <axis xyz="0 1 0"/>
       <limit effort="0.0" lower="-3.14159" upper="3.14159" velocity="0.0"/>
    </joint>
    <link name="link1">
        <inertial>
            <origin xyz="0.11500826789934196 0.2169629391918822 0.04650846454475884" rpy="0 0 0"/>
            <mass value="1" />
            <inertia ixx="100" ixy="0" ixz="0" iyy="100" iyz="0" izz="100" />
        </inertial>
        <visual>
            <origin xyz="0.11500826789934196 0.2169629391918822 0.04650846454475884" rpy="0 0 0"/>
            <geometry>
                <box size="0.23196473173685928 0.4339258783837644 0.8520260890307917" />
            </geometry>
            <material name="Cyan">
                <color rgba="0 1.0 1.0 1.0"/>
            </material>
        </visual>
        <collision>
            <origin xyz="0.11500826789934196 0.2169629391918822 0.04650846454475884" rpy="0 0 0"/>
            <geometry>
                <box size="0.23196473173685928 0.4339258783837644 0.8520260890307917" />
            </geometry>
        </collision>
    </link>
    <joint name="link1_link2" type="revolute">
       <parent link="link1"/>
       <child  link="link2"/>
       <origin rpy="0 0 0" xyz="-0.0009740979690876783 0.12257824595784668 0.24152499987591802" />
     <axis xyz="0 1 0"/>
       <limit effort="0.0" lower="-3.14159" upper="3.14159" velocity="0.0"/>
    </joint>
    <link name="link2">
        <inertial>
            <origin xyz="-0.028306430214501133 -0.05600557999314588 -0.08257288695728868" rpy="0 0 0"/>
            <mass value="1" />
            <inertia ixx="100" ixy="0" ixz="0" iyy="100" iyz="0" izz="100" />
        </inertial>
        <visual>
            <origin xyz="-0.028306430214501133 -0.05600557999314588 -0.08257288695728868" rpy="0 0 0"/>
            <geometry>
                <box size="0.056612860429002265 0.4426493250012348 0.4042420249871632" />
            </geometry>
            <material name="Cyan">
                <color rgba="0 1.0 1.0 1.0"/>
            </material>
        </visual>
        <collision>
            <origin xyz="-0.028306430214501133 -0.05600557999314588 -0.08257288695728868" rpy="0 0 0"/>
            <geometry>
                <box size="0.056612860429002265 0.4426493250012348 0.4042420249871632" />
            </geometry>
        </collision>
    </link>
    <joint name="link1_link3" type="revolute">
       <parent link="link1"/>
       <child  link="link3"/>
       <origin rpy="0 0 0" xyz="0.2309906337677716 0.17787385476777792 0.26398909298451523" />
     <axis xyz="1 0 0"/>
       <limit effort="0.0" lower="-3.14159" upper="3.14159" velocity="0.0"/>
    </joint>
    <link name="link3">
        <inertial>
            <origin xyz="0.08364598288642766 -0.40524483474060496 -0.03958830830365841" rpy="0 0 0"/>
            <mass value="1" />
            <inertia ixx="100" ixy="0" ixz="0" iyy="100" iyz="0" izz="100" />
        </inertial>
        <visual>
            <origin xyz="0.08364598288642766 -0.40524483474060496 -0.03958830830365841" rpy="0 0 0"/>
            <geometry>
                <box size="0.16729196577285532 0.8156967617995734 0.1556691197239347" />
            </geometry>
            <material name="Cyan">
                <color rgba="0 1.0 1.0 1.0"/>
            </material>
        </visual>
        <collision>
            <origin xyz="0.08364598288642766 -0.40524483474060496 -0.03958830830365841" rpy="0 0 0"/>
            <geometry>
                <box size="0.16729196577285532 0.8156967617995734 0.1556691197239347" />
            </geometry>
        </collision>
    </link>
    <joint name="link1_link4" type="revolute">
       <parent link="link1"/>
       <child  link="link4"/>
       <origin rpy="0 0 0" xyz="0.04089522855109341 0.1892112168496738 -0.379504579970637" />
     <axis xyz="1 0 0"/>
       <limit effort="0.0" lower="-3.14159" upper="3.14159" velocity="0.0"/>
    </joint>
    <link name="link4">
        <inertial>
            <origin xyz="0.025574018467627392 0.15062205818515975 -0.4352528226545521" rpy="0 0 0"/>
            <mass value="1" />
            <inertia ixx="100" ixy="0" ixz="0" iyy="100" iyz="0" izz="100" />
        </inertial>
        <visual>
            <origin xyz="0.025574018467627392 0.15062205818515975 -0.4352528226545521" rpy="0 0 0"/>
            <geometry>
                <box size="0.17116763034820803 0.7381902181228548 0.8705056453091042" />
            </geometry>
            <material name="Cyan">
                <color rgba="0 1.0 1.0 1.0"/>
            </material>
        </visual>
        <collision>
            <origin xyz="0.025574018467627392 0.15062205818515975 -0.4352528226545521" rpy="0 0 0"/>
            <geometry>
                <box size="0.17116763034820803 0.7381902181228548 0.8705056453091042" />
            </geometry>
        </collision>
    </link>
    <joint name="link2_link5" type="revolute">
       <parent link="link2"/>
       <child  link="link5"/>
       <origin rpy="0 0 0" xyz="-0.02163986115612531 0.10962764650020532 -0.2846938994508703" />
     <axis xyz="1 0 0"/>
       <limit effort="0.0" lower="-3.14159" upper="3.14159" velocity="0.0"/>
    </joint>
    <link name="link5">
        <inertial>
            <origin xyz="-0.2625821856045841 0.14416318313234983 -0.3453583558213603" rpy="0 0 0"/>
            <mass value="1" />
            <inertia ixx="100" ixy="0" ixz="0" iyy="100" iyz="0" izz="100" />
        </inertial>
        <visual>
            <origin xyz="-0.2625821856045841 0.14416318313234983 -0.3453583558213603" rpy="0 0 0"/>
            <geometry>
                <box size="0.8678210263846924 0.756071451954806 0.6907167116427206" />
            </geometry>
            <material name="Cyan">
                <color rgba="0 1.0 1.0 1.0"/>
            </material>
        </visual>
        <collision>
            <origin xyz="-0.2625821856045841 0.14416318313234983 -0.3453583558213603" rpy="0 0 0"/>
            <geometry>
                <box size="0.8678210263846924 0.756071451954806 0.6907167116427206" />
            </geometry>
        </collision>
    </link>
    <joint name="link1_link6" type="revolute">
       <parent link="link1"/>
       <child  link="link6"/>
       <origin rpy="0 0 0" xyz="0.2309906337677716 0.02668043175159024 -0.1936844582496334" />
     <axis xyz="1 0 0"/>
       <limit effort="0.0" lower="-3.14159" upper="3.14159" velocity="0.0"/>
    </joint>
    <link name="link6">
        <inertial>
            <origin xyz="0.13427678780826163 0.20157307322446502 0.0901133543504428" rpy="0 0 0"/>
            <mass value="1" />
            <inertia ixx="100" ixy="0" ixz="0" iyy="100" iyz="0" izz="100" />
        </inertial>
        <visual>
            <origin xyz="0.13427678780826163 0.20157307322446502 0.0901133543504428" rpy="0 0 0"/>
            <geometry>
                <box size="0.26855357561652327 0.6445460888240707 0.30252535318102103" />
            </geometry>
            <material name="Cyan">
                <color rgba="0 1.0 1.0 1.0"/>
            </material>
        </visual>
        <collision>
            <origin xyz="0.13427678780826163 0.20157307322446502 0.0901133543504428" rpy="0 0 0"/>
            <geometry>
                <box size="0.26855357561652327 0.6445460888240707 0.30252535318102103" />
            </geometry>
        </collision>
    </link>
    <joint name="link5_link7" type="revolute">
       <parent link="link5"/>
       <child  link="link7"/>
       <origin rpy="0 0 0" xyz="-0.17579734611784836 -0.23387254284505316 -0.4333266002449215" />
     <axis xyz="0 1 0"/>
       <limit effort="0.0" lower="-3.14159" upper="3.14159" velocity="0.0"/>
    </joint>
    <link name="link7">
        <inertial>
            <origin xyz="0.1582267528111011 -0.09672979612220378 0.02397104920507897" rpy="0 0 0"/>
            <mass value="1" />
            <inertia ixx="100" ixy="0" ixz="0" iyy="100" iyz="0" izz="100" />
        </inertial>
        <visual>
            <origin xyz="0.1582267528111011 -0.09672979612220378 0.02397104920507897" rpy="0 0 0"/>
            <geometry>
                <box size="0.7495306792365102 0.19345959224440756 0.203790421029994" />
            </geometry>
            <material name="Cyan">
                <color rgba="0 1.0 1.0 1.0"/>
            </material>
        </visual>
        <collision>
            <origin xyz="0.1582267528111011 -0.09672979612220378 0.02397104920507897" rpy="0 0 0"/>
            <geometry>
                <box size="0.7495306792365102 0.19345959224440756 0.203790421029994" />
            </geometry>
        </collision>
    </link>
    <joint name="link7_link8" type="revolute">
       <parent link="link7"/>
       <child  link="link8"/>
       <origin rpy="0 0 0" xyz="0.07503367158946801 -0.01954736801161705 0.12586625972007598" />
     <axis xyz="0 0 1"/>
       <limit effort="0.0" lower="-3.14159" upper="3.14159" velocity="0.0"/>
    </joint>
    <link name="link8">
        <inertial>
            <origin xyz="0.43526398265846267 -0.06612388404664486 0.14544974587078546" rpy="0 0 0"/>
            <mass value="1" />
            <inertia ixx="100" ixy="0" ixz="0" iyy="100" iyz="0" izz="100" />
        </inertial>
        <visual>
            <origin xyz="0.43526398265846267 -0.06612388404664486 0.14544974587078546" rpy="0 0 0"/>
            <geometry>
                <box size="0.9448040471476704 0.676214678766079 0.2908994917415709" />
            </geometry>
            <material name="Cyan">
                <color rgba="0 1.0 1.0 1.0"/>
            </material>
        </visual>
        <collision>
            <origin xyz="0.43526398265846267 -0.06612388404664486 0.14544974587078546" rpy="0 0 0"/>
            <geometry>
                <box size="0.9448040471476704 0.676214678766079 0.2908994917415709" />
            </geometry>
        </collision>
    </link>
    <joint name="link4_link9" type="revolute">
       <parent link="link4"/>
       <child  link="link9"/>
       <origin rpy="0 0 0" xyz="-0.007567639442469798 0.28956786188253314 -0.8705056453091042" />
     <axis xyz="0 1 0"/>
       <limit effort="0.0" lower="-3.14159" upper="3.14159" velocity="0.0"/>
    </joint>
    <link name="link9">
        <inertial>
            <origin xyz="-0.01039355765555932 0.13044578839810558 -0.15813823274609434" rpy="0 0 0"/>
            <mass value="1" />
            <inertia ixx="100" ixy="0" ixz="0" iyy="100" iyz="0" izz="100" />
        </inertial>
        <visual>
            <origin xyz="-0.01039355765555932 0.13044578839810558 -0.15813823274609434" rpy="0 0 0"/>
            <geometry>
                <box size="0.028526718878570057 0.26572156114653156 0.3162764654921887" />
            </geometry>
            <material name="Cyan">
                <color rgba="0 1.0 1.0 1.0"/>
            </material>
        </visual>
        <collision>
            <origin xyz="-0.01039355765555932 0.13044578839810558 -0.15813823274609434" rpy="0 0 0"/>
            <geometry>
                <box size="0.028526718878570057 0.26572156114653156 0.3162764654921887" />
            </geometry>
        </collision>
    </link>
</robot>