<robot name = "robot">
    <link name="link0">
        <inertial>
            <origin xyz="0 0 1" rpy="0 0 0"/>
            <mass value="1" />
            <inertia ixx="100" ixy="0" ixz="0" iyy="100" iyz="0" izz="100" />
        </inertial>
        <visual>
            <origin xyz="0 0 1" rpy="0 0 0"/>
            <geometry>
                <box size="0.4905285840483832 0.6589235012464228 0.3357839458661711" />
            </geometry>
            <material name="Cyan">
                <color rgba="0 1.0 1.0 1.0"/>
            </material>
        </visual>
        <collision>
            <origin xyz="0 0 1" rpy="0 0 0"/>
            <geometry>
                <box size="0.4905285840483832 0.6589235012464228 0.3357839458661711" />
            </geometry>
        </collision>
    </link>
    <joint name="link0_link1" type="revolute">
       <parent link="link0"/>
       <child  link="link1"/>
       <origin rpy="0 0 0" xyz="-0.14263230018548123 -0.16566785739010834 0.8321080270669144" />
     <axis xyz="0 0 1"/>
       <limit effort="0.0" lower="-3.14159" upper="3.14159" velocity="0.0"/>
    </joint>
    <link name="link1">
        <inertial>
            <origin xyz="-0.2193626886019079 0.04842538601846532 -0.4072895123553169" rpy="0 0 0"/>
            <mass value="1" />
            <inertia ixx="100" ixy="0" ixz="0" iyy="100" iyz="0" izz="100" />
        </inertial>
        <visual>
            <origin xyz="-0.2193626886019079 0.04842538601846532 -0.4072895123553169" rpy="0 0 0"/>
            <geometry>
                <box size="0.4907543238413754 0.1726207920509638 0.8145790247106338" />
            </geometry>
            <material name="Cyan">
                <color rgba="0 1.0 1.0 1.0"/>
            </material>
        </visual>
        <collision>
            <origin xyz="-0.2193626886019079 0.04842538601846532 -0.4072895123553169" rpy="0 0 0"/>
            <geometry>
                <box size="0.4907543238413754 0.1726207920509638 0.8145790247106338" />
            </geometry>
        </collision>
    </link>
    <joint name="link1_link2" type="revolute">
       <parent link="link1"/>
       <child  link="link2"/>
       <origin rpy="0 0 0" xyz="-0.11754467553258674 -0.037885010007016585 -0.5225105730307507" />
     <axis xyz="0 1 0"/>
       <limit effort="0.0" lower="-3.14159" upper="3.14159" velocity="0.0"/>
    </joint>
    <link name="link2">
        <inertial>
            <origin xyz="0.1633739166881152 -0.09657462343357903 0.052175180118200826" rpy="0 0 0"/>
            <mass value="1" />
            <inertia ixx="100" ixy="0" ixz="0" iyy="100" iyz="0" izz="100" />
        </inertial>
        <visual>
            <origin xyz="0.1633739166881152 -0.09657462343357903 0.052175180118200826" rpy="0 0 0"/>
            <geometry>
                <box size="0.6648856275198118 0.19314924686715806 0.8381595120329992" />
            </geometry>
            <material name="Cyan">
                <color rgba="0 1.0 1.0 1.0"/>
            </material>
        </visual>
        <collision>
            <origin xyz="0.1633739166881152 -0.09657462343357903 0.052175180118200826" rpy="0 0 0"/>
            <geometry>
                <box size="0.6648856275198118 0.19314924686715806 0.8381595120329992" />
            </geometry>
        </collision>
    </link>
    <joint name="link1_link3" type="revolute">
       <parent link="link1"/>
       <child  link="link3"/>
       <origin rpy="0 0 0" xyz="-0.22847032972823564 0.13473578204394723 -0.03699408788312941" />
     <axis xyz="0 1 0"/>
       <limit effort="0.0" lower="-3.14159" upper="3.14159" velocity="0.0"/>
    </joint>
    <link name="link3">
        <inertial>
            <origin xyz="0.01770688879112795 0.43079073779186366 -0.2463209287792524" rpy="0 0 0"/>
            <mass value="1" />
            <inertia ixx="100" ixy="0" ixz="0" iyy="100" iyz="0" izz="100" />
        </inertial>
        <visual>
            <origin xyz="0.01770688879112795 0.43079073779186366 -0.2463209287792524" rpy="0 0 0"/>
            <geometry>
                <box size="0.3357904424910343 0.8615814755837273 0.6539142912523589" />
            </geometry>
            <material name="Cyan">
                <color rgba="0 1.0 1.0 1.0"/>
            </material>
        </visual>
        <collision>
            <origin xyz="0.01770688879112795 0.43079073779186366 -0.2463209287792524" rpy="0 0 0"/>
            <geometry>
                <box size="0.3357904424910343 0.8615814755837273 0.6539142912523589" />
            </geometry>
        </collision>
    </link>
    <joint name="link0_link4" type="revolute">
       <parent link="link0"/>
       <child  link="link4"/>
       <origin rpy="0 0 0" xyz="-0.12848625354635643 -0.16076032601368295 0.8321080270669144" />
     <axis xyz="0 1 0"/>
       <limit effort="0.0" lower="-3.14159" upper="3.14159" velocity="0.0"/>
    </joint>
    <link name="link4">
        <inertial>
            <origin xyz="0.3255582699703081 0.011892238320689074 -0.2250876611473036" rpy="0 0 0"/>
            <mass value="1" />
            <inertia ixx="100" ixy="0" ixz="0" iyy="100" iyz="0" izz="100" />
        </inertial>
        <visual>
            <origin xyz="0.3255582699703081 0.011892238320689074 -0.2250876611473036" rpy="0 0 0"/>
            <geometry>
                <box size="0.8101073936031297 0.30156932093997446 0.4501753222946072" />
            </geometry>
            <material name="Cyan">
                <color rgba="0 1.0 1.0 1.0"/>
            </material>
        </visual>
        <collision>
            <origin xyz="0.3255582699703081 0.011892238320689074 -0.2250876611473036" rpy="0 0 0"/>
            <geometry>
                <box size="0.8101073936031297 0.30156932093997446 0.4501753222946072" />
            </geometry>
        </collision>
    </link>
    <joint name="link3_link5" type="revolute">
       <parent link="link3"/>
       <child  link="link5"/>
       <origin rpy="0 0 0" xyz="0.128084090421373 0.8615814755837273 -0.42158721260840015" />
     <axis xyz="1 0 0"/>
       <limit effort="0.0" lower="-3.14159" upper="3.14159" velocity="0.0"/>
    </joint>
    <link name="link5">
        <inertial>
            <origin xyz="-0.07072239573522893 0.42675724529500675 -0.03818054870667821" rpy="0 0 0"/>
            <mass value="1" />
            <inertia ixx="100" ixy="0" ixz="0" iyy="100" iyz="0" izz="100" />
        </inertial>
        <visual>
            <origin xyz="-0.07072239573522893 0.42675724529500675 -0.03818054870667821" rpy="0 0 0"/>
            <geometry>
                <box size="0.9774961178801364 0.8535144905900135 0.8836136016043651" />
            </geometry>
            <material name="Cyan">
                <color rgba="0 1.0 1.0 1.0"/>
            </material>
        </visual>
        <collision>
            <origin xyz="-0.07072239573522893 0.42675724529500675 -0.03818054870667821" rpy="0 0 0"/>
            <geometry>
                <box size="0.9774961178801364 0.8535144905900135 0.8836136016043651" />
            </geometry>
        </collision>
    </link>
    <joint name="link3_link6" type="revolute">
       <parent link="link3"/>
       <child  link="link6"/>
       <origin rpy="0 0 0" xyz="-0.10067510221782482 0.0 -0.3304726775763198" />
     <axis xyz="0 1 0"/>
       <limit effort="0.0" lower="-3.14159" upper="3.14159" velocity="0.0"/>
    </joint>
    <link name="link6">
        <inertial>
            <origin xyz="0.004843965260230421 -0.06089046157166483 0.008025433770115931" rpy="0 0 0"/>
            <mass value="1" />
            <inertia ixx="100" ixy="0" ixz="0" iyy="100" iyz="0" izz="100" />
        </inertial>
        <visual>
            <origin xyz="0.004843965260230421 -0.06089046157166483 0.008025433770115931" rpy="0 0 0"/>
            <geometry>
                <box size="0.017896934169012946 0.12178092314332967 0.034074174363170284" />
            </geometry>
            <material name="Cyan">
                <color rgba="0 1.0 1.0 1.0"/>
            </material>
        </visual>
        <collision>
            <origin xyz="0.004843965260230421 -0.06089046157166483 0.008025433770115931" rpy="0 0 0"/>
            <geometry>
                <box size="0.017896934169012946 0.12178092314332967 0.034074174363170284" />
            </geometry>
        </collision>
    </link>
    <joint name="link5_link7" type="revolute">
       <parent link="link5"/>
       <child  link="link7"/>
       <origin rpy="0 0 0" xyz="-0.3307328407152468 0.023857235607290972 -0.47998734950886074" />
     <axis xyz="0 1 0"/>
       <limit effort="0.0" lower="-3.14159" upper="3.14159" velocity="0.0"/>
    </joint>
    <link name="link7">
        <inertial>
            <origin xyz="0.011250223386853246 -0.4049789239338127 -0.21251368135610116" rpy="0 0 0"/>
            <mass value="1" />
            <inertia ixx="100" ixy="0" ixz="0" iyy="100" iyz="0" izz="100" />
        </inertial>
        <visual>
            <origin xyz="0.011250223386853246 -0.4049789239338127 -0.21251368135610116" rpy="0 0 0"/>
            <geometry>
                <box size="0.12155580926584797 0.8855487003733618 0.4250273627122023" />
            </geometry>
            <material name="Cyan">
                <color rgba="0 1.0 1.0 1.0"/>
            </material>
        </visual>
        <collision>
            <origin xyz="0.011250223386853246 -0.4049789239338127 -0.21251368135610116" rpy="0 0 0"/>
            <geometry>
                <box size="0.12155580926584797 0.8855487003733618 0.4250273627122023" />
            </geometry>
        </collision>
    </link>
</robot>