<robot name = "robot">
    <link name="link0">
        <inertial>
            <origin xyz="0 0 1" rpy="0 0 0"/>
            <mass value="1" />
            <inertia ixx="100" ixy="0" ixz="0" iyy="100" iyz="0" izz="100" />
        </inertial>
        <visual>
            <origin xyz="0 0 1" rpy="0 0 0"/>
            <geometry>
                <box size="0.719431948264419 0.32531222363614654 0.16175446656763992" />
            </geometry>
            <material name="Cyan">
                <color rgba="0.0 1.0 1.0 1.0"/>
            </material>
        </visual>
        <collision>
            <origin xyz="0 0 1" rpy="0 0 0"/>
            <geometry>
                <box size="0.719431948264419 0.32531222363614654 0.16175446656763992" />
            </geometry>
        </collision>
    </link>
    <joint name="link0_link1" type="revolute">
       <parent link="link0"/>
       <child  link="link1"/>
       <origin rpy="0 0 0" xyz="0.3597159741322095 0.14838011406492904 1.0436214838457225" />
     <axis xyz="0 0 1"/>
       <limit effort="0.0" lower="-3.14159" upper="3.14159" velocity="0.0"/>
    </joint>
    <link name="link1">
        <inertial>
            <origin xyz="0.010707128142483369 0.010179605213958677 -0.004739613186718172" rpy="0 0 0"/>
            <mass value="1" />
            <inertia ixx="100" ixy="0" ixz="0" iyy="100" iyz="0" izz="100" />
        </inertial>
        <visual>
            <origin xyz="0.010707128142483369 0.010179605213958677 -0.004739613186718172" rpy="0 0 0"/>
            <geometry>
                <box size="0.021414256284966737 0.0553671561700122 0.18640297250402338" />
            </geometry>
            <material name="Green">
                <color rgba="0.0 1.0 0.0 1.0"/>
            </material>
        </visual>
        <collision>
            <origin xyz="0.010707128142483369 0.010179605213958677 -0.004739613186718172" rpy="0 0 0"/>
            <geometry>
                <box size="0.021414256284966737 0.0553671561700122 0.18640297250402338" />
            </geometry>
        </collision>
    </link>
    <joint name="link1_link2" type="revolute">
       <parent link="link1"/>
       <child  link="link2"/>
       <origin rpy="0 0 0" xyz="0.008405429722881105 -0.006100714372834723 0.08846187306529352" />
     <axis xyz="1 0 0"/>
       <limit effort="0.0" lower="-3.14159" upper="3.14159" velocity="0.0"/>
    </joint>
    <link name="link2">
        <inertial>
            <origin xyz="0.02428492010348264 -0.16401183711525083 0.15813295416145146" rpy="0 0 0"/>
            <mass value="1" />
            <inertia ixx="100" ixy="0" ixz="0" iyy="100" iyz="0" izz="100" />
        </inertial>
        <visual>
            <origin xyz="0.02428492010348264 -0.16401183711525083 0.15813295416145146" rpy="0 0 0"/>
            <geometry>
                <box size="0.08697758702031355 0.570908321324297 0.3162659083229029" />
            </geometry>
            <material name="Green">
                <color rgba="0.0 1.0 0.0 1.0"/>
            </material>
        </visual>
        <collision>
            <origin xyz="0.02428492010348264 -0.16401183711525083 0.15813295416145146" rpy="0 0 0"/>
            <geometry>
                <box size="0.08697758702031355 0.570908321324297 0.3162659083229029" />
            </geometry>
        </collision>
    </link>
    <joint name="link0_link3" type="revolute">
       <parent link="link0"/>
       <child  link="link3"/>
       <origin rpy="0 0 0" xyz="-0.08536782589866207 -0.1098874629601173 1.08087723328382" />
     <axis xyz="1 0 0"/>
       <limit effort="0.0" lower="-3.14159" upper="3.14159" velocity="0.0"/>
    </joint>
    <link name="link3">
        <inertial>
            <origin xyz="0.1764518504411173 0.3274596946679998 0.4644774102491692" rpy="0 0 0"/>
            <mass value="1" />
            <inertia ixx="100" ixy="0" ixz="0" iyy="100" iyz="0" izz="100" />
        </inertial>
        <visual>
            <origin xyz="0.1764518504411173 0.3274596946679998 0.4644774102491692" rpy="0 0 0"/>
            <geometry>
                <box size="0.628039976818542 0.8696243318465903 0.9289548204983384" />
            </geometry>
            <material name="Green">
                <color rgba="0.0 1.0 0.0 1.0"/>
            </material>
        </visual>
        <collision>
            <origin xyz="0.1764518504411173 0.3274596946679998 0.4644774102491692" rpy="0 0 0"/>
            <geometry>
                <box size="0.628039976818542 0.8696243318465903 0.9289548204983384" />
            </geometry>
        </collision>
    </link>
    <joint name="link2_link4" type="revolute">
       <parent link="link2"/>
       <child  link="link4"/>
       <origin rpy="0 0 0" xyz="0.056023423964245825 -0.4494659977773994 0.08102552662299112" />
     <axis xyz="1 0 0"/>
       <limit effort="0.0" lower="-3.14159" upper="3.14159" velocity="0.0"/>
    </joint>
    <link name="link4">
        <inertial>
            <origin xyz="0.27429765596517736 -0.21448791074528778 -0.08589836420109373" rpy="0 0 0"/>
            <mass value="1" />
            <inertia ixx="100" ixy="0" ixz="0" iyy="100" iyz="0" izz="100" />
        </inertial>
        <visual>
            <origin xyz="0.27429765596517736 -0.21448791074528778 -0.08589836420109373" rpy="0 0 0"/>
            <geometry>
                <box size="0.6058400852850304 0.42897582149057556 0.5907986247858112" />
            </geometry>
            <material name="Green">
                <color rgba="0.0 1.0 0.0 1.0"/>
            </material>
        </visual>
        <collision>
            <origin xyz="0.27429765596517736 -0.21448791074528778 -0.08589836420109373" rpy="0 0 0"/>
            <geometry>
                <box size="0.6058400852850304 0.42897582149057556 0.5907986247858112" />
            </geometry>
        </collision>
    </link>
    <joint name="link4_link5" type="revolute">
       <parent link="link4"/>
       <child  link="link5"/>
       <origin rpy="0 0 0" xyz="0.4089011702301413 -0.1313464378213301 0.2095009481918119" />
     <axis xyz="1 0 0"/>
       <limit effort="0.0" lower="-3.14159" upper="3.14159" velocity="0.0"/>
    </joint>
    <link name="link5">
        <inertial>
            <origin xyz="0.02666999857102647 -0.09310283708225695 0.3695526072100089" rpy="0 0 0"/>
            <mass value="1" />
            <inertia ixx="100" ixy="0" ixz="0" iyy="100" iyz="0" izz="100" />
        </inertial>
        <visual>
            <origin xyz="0.02666999857102647 -0.09310283708225695 0.3695526072100089" rpy="0 0 0"/>
            <geometry>
                <box size="0.5070653142139382 0.37956607231002426 0.7391052144200178" />
            </geometry>
            <material name="Green">
                <color rgba="0.0 1.0 0.0 1.0"/>
            </material>
        </visual>
        <collision>
            <origin xyz="0.02666999857102647 -0.09310283708225695 0.3695526072100089" rpy="0 0 0"/>
            <geometry>
                <box size="0.5070653142139382 0.37956607231002426 0.7391052144200178" />
            </geometry>
        </collision>
    </link>
    <joint name="link1_link6" type="revolute">
       <parent link="link1"/>
       <child  link="link6"/>
       <origin rpy="0 0 0" xyz="0.018932178024003064 5.783024016495393e-05 0.08846187306529352" />
     <axis xyz="0 1 0"/>
       <limit effort="0.0" lower="-3.14159" upper="3.14159" velocity="0.0"/>
    </joint>
    <link name="link6">
        <inertial>
            <origin xyz="0.0010621875712453486 0.017897292825473584 0.19492133701936742" rpy="0 0 0"/>
            <mass value="1" />
            <inertia ixx="100" ixy="0" ixz="0" iyy="100" iyz="0" izz="100" />
        </inertial>
        <visual>
            <origin xyz="0.0010621875712453486 0.017897292825473584 0.19492133701936742" rpy="0 0 0"/>
            <geometry>
                <box size="0.034288819819018324 0.14665258354518174 0.38984267403873485" />
            </geometry>
            <material name="Cyan">
                <color rgba="0.0 1.0 1.0 1.0"/>
            </material>
        </visual>
        <collision>
            <origin xyz="0.0010621875712453486 0.017897292825473584 0.19492133701936742" rpy="0 0 0"/>
            <geometry>
                <box size="0.034288819819018324 0.14665258354518174 0.38984267403873485" />
            </geometry>
        </collision>
    </link>
    <joint name="link3_link7" type="revolute">
       <parent link="link3"/>
       <child  link="link7"/>
       <origin rpy="0 0 0" xyz="-0.13756813796815368 0.44683696975774756 0.5712614464061816" />
     <axis xyz="0 0 1"/>
       <limit effort="0.0" lower="-3.14159" upper="3.14159" velocity="0.0"/>
    </joint>
    <link name="link7">
        <inertial>
            <origin xyz="-0.37292601318123514 -0.006126563733353912 0.05288228428687836" rpy="0 0 0"/>
            <mass value="1" />
            <inertia ixx="100" ixy="0" ixz="0" iyy="100" iyz="0" izz="100" />
        </inertial>
        <visual>
            <origin xyz="-0.37292601318123514 -0.006126563733353912 0.05288228428687836" rpy="0 0 0"/>
            <geometry>
                <box size="0.7458520263624703 0.056693761680462695 0.11635983241037917" />
            </geometry>
            <material name="Cyan">
                <color rgba="0.0 1.0 1.0 1.0"/>
            </material>
        </visual>
        <collision>
            <origin xyz="-0.37292601318123514 -0.006126563733353912 0.05288228428687836" rpy="0 0 0"/>
            <geometry>
                <box size="0.7458520263624703 0.056693761680462695 0.11635983241037917" />
            </geometry>
        </collision>
    </link>
    <joint name="link4_link8" type="revolute">
       <parent link="link4"/>
       <child  link="link8"/>
       <origin rpy="0 0 0" xyz="0.1342790897628068 -0.42897582149057556 0.20012879143251464" />
     <axis xyz="0 1 0"/>
       <limit effort="0.0" lower="-3.14159" upper="3.14159" velocity="0.0"/>
    </joint>
    <link name="link8">
        <inertial>
            <origin xyz="0.1993491504637032 -0.34094376210748284 0.14449478405141972" rpy="0 0 0"/>
            <mass value="1" />
            <inertia ixx="100" ixy="0" ixz="0" iyy="100" iyz="0" izz="100" />
        </inertial>
        <visual>
            <origin xyz="0.1993491504637032 -0.34094376210748284 0.14449478405141972" rpy="0 0 0"/>
            <geometry>
                <box size="0.41717365279189 0.6818875242149657 0.4039605129289814" />
            </geometry>
            <material name="Green">
                <color rgba="0.0 1.0 0.0 1.0"/>
            </material>
        </visual>
        <collision>
            <origin xyz="0.1993491504637032 -0.34094376210748284 0.14449478405141972" rpy="0 0 0"/>
            <geometry>
                <box size="0.41717365279189 0.6818875242149657 0.4039605129289814" />
            </geometry>
        </collision>
    </link>
    <joint name="link0_link9" type="revolute">
       <parent link="link0"/>
       <child  link="link9"/>
       <origin rpy="0 0 0" xyz="-0.06823284548222082 -0.13410048023713458 1.08087723328382" />
     <axis xyz="0 1 0"/>
       <limit effort="0.0" lower="-3.14159" upper="3.14159" velocity="0.0"/>
    </joint>
    <link name="link9">
        <inertial>
            <origin xyz="-0.08456916121330799 -0.09486992872440377 0.37910851369023846" rpy="0 0 0"/>
            <mass value="1" />
            <inertia ixx="100" ixy="0" ixz="0" iyy="100" iyz="0" izz="100" />
        </inertial>
        <visual>
            <origin xyz="-0.08456916121330799 -0.09486992872440377 0.37910851369023846" rpy="0 0 0"/>
            <geometry>
                <box size="0.2999698719188477 0.6026983911306787 0.7582170273804769" />
            </geometry>
            <material name="Green">
                <color rgba="0.0 1.0 0.0 1.0"/>
            </material>
        </visual>
        <collision>
            <origin xyz="-0.08456916121330799 -0.09486992872440377 0.37910851369023846" rpy="0 0 0"/>
            <geometry>
                <box size="0.2999698719188477 0.6026983911306787 0.7582170273804769" />
            </geometry>
        </collision>
    </link>
</robot>