<robot name = "robot">
    <link name="link0">
        <inertial>
            <origin xyz="0 0 1" rpy="0 0 0"/>
            <mass value="1" />
            <inertia ixx="100" ixy="0" ixz="0" iyy="100" iyz="0" izz="100" />
        </inertial>
        <visual>
            <origin xyz="0 0 1" rpy="0 0 0"/>
            <geometry>
                <box size="0.2828608767605745 0.44196470161678714 0.9587848005002417" />
            </geometry>
            <material name="Cyan">
                <color rgba="0.0 1.0 1.0 1.0"/>
            </material>
        </visual>
        <collision>
            <origin xyz="0 0 1" rpy="0 0 0"/>
            <geometry>
                <box size="0.2828608767605745 0.44196470161678714 0.9587848005002417" />
            </geometry>
        </collision>
    </link>
    <joint name="link0_link1" type="revolute">
       <parent link="link0"/>
       <child  link="link1"/>
       <origin rpy="0 0 0" xyz="0.1379008402898661 0.22098235080839357 0.7268774561523879" />
     <axis xyz="0 1 0"/>
       <limit effort="0.0" lower="-3.14159" upper="3.14159" velocity="0.0"/>
    </joint>
    <link name="link1">
        <inertial>
            <origin xyz="0.33783692429147216 0.29337176932251163 -0.010497396917987687" rpy="0 0 0"/>
            <mass value="1" />
            <inertia ixx="100" ixy="0" ixz="0" iyy="100" iyz="0" izz="100" />
        </inertial>
        <visual>
            <origin xyz="0.33783692429147216 0.29337176932251163 -0.010497396917987687" rpy="0 0 0"/>
            <geometry>
                <box size="0.7479808877057695 0.5867435386450233 0.18751341585460035" />
            </geometry>
            <material name="Cyan">
                <color rgba="0.0 1.0 1.0 1.0"/>
            </material>
        </visual>
        <collision>
            <origin xyz="0.33783692429147216 0.29337176932251163 -0.010497396917987687" rpy="0 0 0"/>
            <geometry>
                <box size="0.7479808877057695 0.5867435386450233 0.18751341585460035" />
            </geometry>
        </collision>
    </link>
    <joint name="link0_link2" type="revolute">
       <parent link="link0"/>
       <child  link="link2"/>
       <origin rpy="0 0 0" xyz="0.027067615512948017 -0.04095780752165345 1.4793924002501209" />
     <axis xyz="0 0 1"/>
       <limit effort="0.0" lower="-3.14159" upper="3.14159" velocity="0.0"/>
    </joint>
    <link name="link2">
        <inertial>
            <origin xyz="-0.019337536701868482 0.315550150932046 0.47474822094807867" rpy="0 0 0"/>
            <mass value="1" />
            <inertia ixx="100" ixy="0" ixz="0" iyy="100" iyz="0" izz="100" />
        </inertial>
        <visual>
            <origin xyz="-0.019337536701868482 0.315550150932046 0.47474822094807867" rpy="0 0 0"/>
            <geometry>
                <box size="0.3167992854692281 0.6787272694944397 0.9494964418961573" />
            </geometry>
            <material name="Green">
                <color rgba="0.0 1.0 0.0 1.0"/>
            </material>
        </visual>
        <collision>
            <origin xyz="-0.019337536701868482 0.315550150932046 0.47474822094807867" rpy="0 0 0"/>
            <geometry>
                <box size="0.3167992854692281 0.6787272694944397 0.9494964418961573" />
            </geometry>
        </collision>
    </link>
    <joint name="link1_link3" type="revolute">
       <parent link="link1"/>
       <child  link="link3"/>
       <origin rpy="0 0 0" xyz="0.711827368144357 0.20620884632799957 0.06456673768965084" />
     <axis xyz="0 1 0"/>
       <limit effort="0.0" lower="-3.14159" upper="3.14159" velocity="0.0"/>
    </joint>
    <link name="link3">
        <inertial>
            <origin xyz="0.3341916256647571 -0.38740737512117274 -0.007585042222822876" rpy="0 0 0"/>
            <mass value="1" />
            <inertia ixx="100" ixy="0" ixz="0" iyy="100" iyz="0" izz="100" />
        </inertial>
        <visual>
            <origin xyz="0.3341916256647571 -0.38740737512117274 -0.007585042222822876" rpy="0 0 0"/>
            <geometry>
                <box size="0.6683832513295141 0.8565076569753318 0.02194427841236557" />
            </geometry>
            <material name="Green">
                <color rgba="0.0 1.0 0.0 1.0"/>
            </material>
        </visual>
        <collision>
            <origin xyz="0.3341916256647571 -0.38740737512117274 -0.007585042222822876" rpy="0 0 0"/>
            <geometry>
                <box size="0.6683832513295141 0.8565076569753318 0.02194427841236557" />
            </geometry>
        </collision>
    </link>
    <joint name="link3_link4" type="revolute">
       <parent link="link3"/>
       <child  link="link4"/>
       <origin rpy="0 0 0" xyz="0.0 -0.4330567024409903 0.00020838221368740285" />
     <axis xyz="0 1 0"/>
       <limit effort="0.0" lower="-3.14159" upper="3.14159" velocity="0.0"/>
    </joint>
    <link name="link4">
        <inertial>
            <origin xyz="-0.3883094987949441 -0.24148694990891367 0.2719054016594574" rpy="0 0 0"/>
            <mass value="1" />
            <inertia ixx="100" ixy="0" ixz="0" iyy="100" iyz="0" izz="100" />
        </inertial>
        <visual>
            <origin xyz="-0.3883094987949441 -0.24148694990891367 0.2719054016594574" rpy="0 0 0"/>
            <geometry>
                <box size="0.7766189975898882 0.9894531588937912 0.9878970960882772" />
            </geometry>
            <material name="Cyan">
                <color rgba="0.0 1.0 1.0 1.0"/>
            </material>
        </visual>
        <collision>
            <origin xyz="-0.3883094987949441 -0.24148694990891367 0.2719054016594574" rpy="0 0 0"/>
            <geometry>
                <box size="0.7766189975898882 0.9894531588937912 0.9878970960882772" />
            </geometry>
        </collision>
    </link>
    <joint name="link4_link5" type="revolute">
       <parent link="link4"/>
       <child  link="link5"/>
       <origin rpy="0 0 0" xyz="-0.7766189975898882 0.08992063714857629 0.439496988060929" />
     <axis xyz="0 1 0"/>
       <limit effort="0.0" lower="-3.14159" upper="3.14159" velocity="0.0"/>
    </joint>
    <link name="link5">
        <inertial>
            <origin xyz="-0.1035931492159653 -0.1551269868403409 0.018310285829901934" rpy="0 0 0"/>
            <mass value="1" />
            <inertia ixx="100" ixy="0" ixz="0" iyy="100" iyz="0" izz="100" />
        </inertial>
        <visual>
            <origin xyz="-0.1035931492159653 -0.1551269868403409 0.018310285829901934" rpy="0 0 0"/>
            <geometry>
                <box size="0.2071862984319306 0.7041331777627211 0.04395346305142922" />
            </geometry>
            <material name="Green">
                <color rgba="0.0 1.0 0.0 1.0"/>
            </material>
        </visual>
        <collision>
            <origin xyz="-0.1035931492159653 -0.1551269868403409 0.018310285829901934" rpy="0 0 0"/>
            <geometry>
                <box size="0.2071862984319306 0.7041331777627211 0.04395346305142922" />
            </geometry>
        </collision>
    </link>
    <joint name="link2_link6" type="revolute">
       <parent link="link2"/>
       <child  link="link6"/>
       <origin rpy="0 0 0" xyz="-0.17773717943648254 0.29806912220525783 0.03966549717582263" />
     <axis xyz="1 0 0"/>
       <limit effort="0.0" lower="-3.14159" upper="3.14159" velocity="0.0"/>
    </joint>
    <link name="link6">
        <inertial>
            <origin xyz="-0.45101511550304185 -0.03335767243189848 0.4050585014172401" rpy="0 0 0"/>
            <mass value="1" />
            <inertia ixx="100" ixy="0" ixz="0" iyy="100" iyz="0" izz="100" />
        </inertial>
        <visual>
            <origin xyz="-0.45101511550304185 -0.03335767243189848 0.4050585014172401" rpy="0 0 0"/>
            <geometry>
                <box size="0.9020302310060837 0.1728237920509329 0.8742946030090257" />
            </geometry>
            <material name="Green">
                <color rgba="0.0 1.0 0.0 1.0"/>
            </material>
        </visual>
        <collision>
            <origin xyz="-0.45101511550304185 -0.03335767243189848 0.4050585014172401" rpy="0 0 0"/>
            <geometry>
                <box size="0.9020302310060837 0.1728237920509329 0.8742946030090257" />
            </geometry>
        </collision>
    </link>
    <joint name="link0_link7" type="revolute">
       <parent link="link0"/>
       <child  link="link7"/>
       <origin rpy="0 0 0" xyz="-0.01268947200540685 -0.22098235080839357 0.9892263924099405" />
     <axis xyz="1 0 0"/>
       <limit effort="0.0" lower="-3.14159" upper="3.14159" velocity="0.0"/>
    </joint>
    <link name="link7">
        <inertial>
            <origin xyz="-0.05065563888296166 -0.05921466773668416 -0.16173305957537962" rpy="0 0 0"/>
            <mass value="1" />
            <inertia ixx="100" ixy="0" ixz="0" iyy="100" iyz="0" izz="100" />
        </inertial>
        <visual>
            <origin xyz="-0.05065563888296166 -0.05921466773668416 -0.16173305957537962" rpy="0 0 0"/>
            <geometry>
                <box size="0.6302331953978693 0.11842933547336831 0.43943706001862026" />
            </geometry>
            <material name="Green">
                <color rgba="0.0 1.0 0.0 1.0"/>
            </material>
        </visual>
        <collision>
            <origin xyz="-0.05065563888296166 -0.05921466773668416 -0.16173305957537962" rpy="0 0 0"/>
            <geometry>
                <box size="0.6302331953978693 0.11842933547336831 0.43943706001862026" />
            </geometry>
        </collision>
    </link>
    <joint name="link1_link8" type="revolute">
       <parent link="link1"/>
       <child  link="link8"/>
       <origin rpy="0 0 0" xyz="-0.036153519561412606 0.06731580774789056 -0.01805407894118069" />
     <axis xyz="0 1 0"/>
       <limit effort="0.0" lower="-3.14159" upper="3.14159" velocity="0.0"/>
    </joint>
    <link name="link8">
        <inertial>
            <origin xyz="-0.3085801606396483 -0.005859191637385795 -0.2006059604630457" rpy="0 0 0"/>
            <mass value="1" />
            <inertia ixx="100" ixy="0" ixz="0" iyy="100" iyz="0" izz="100" />
        </inertial>
        <visual>
            <origin xyz="-0.3085801606396483 -0.005859191637385795 -0.2006059604630457" rpy="0 0 0"/>
            <geometry>
                <box size="0.6171603212792967 0.01286501042136956 0.9371646478065622" />
            </geometry>
            <material name="Green">
                <color rgba="0.0 1.0 0.0 1.0"/>
            </material>
        </visual>
        <collision>
            <origin xyz="-0.3085801606396483 -0.005859191637385795 -0.2006059604630457" rpy="0 0 0"/>
            <geometry>
                <box size="0.6171603212792967 0.01286501042136956 0.9371646478065622" />
            </geometry>
        </collision>
    </link>
    <joint name="link4_link9" type="revolute">
       <parent link="link4"/>
       <child  link="link9"/>
       <origin rpy="0 0 0" xyz="-0.6812505888625607 0.2532396295379819 0.7499056480934085" />
     <axis xyz="1 0 0"/>
       <limit effort="0.0" lower="-3.14159" upper="3.14159" velocity="0.0"/>
    </joint>
    <link name="link9">
        <inertial>
            <origin xyz="0.07456544351197289 0.44433581010793255 0.45208586737592754" rpy="0 0 0"/>
            <mass value="1" />
            <inertia ixx="100" ixy="0" ixz="0" iyy="100" iyz="0" izz="100" />
        </inertial>
        <visual>
            <origin xyz="0.07456544351197289 0.44433581010793255 0.45208586737592754" rpy="0 0 0"/>
            <geometry>
                <box size="0.49855534785782574 0.8886716202158651 0.9727482268783032" />
            </geometry>
            <material name="Green">
                <color rgba="0.0 1.0 0.0 1.0"/>
            </material>
        </visual>
        <collision>
            <origin xyz="0.07456544351197289 0.44433581010793255 0.45208586737592754" rpy="0 0 0"/>
            <geometry>
                <box size="0.49855534785782574 0.8886716202158651 0.9727482268783032" />
            </geometry>
        </collision>
    </link>
</robot>