<robot name = "robot">
    <link name="link0">
        <inertial>
            <origin xyz="0 0 1" rpy="0 0 0"/>
            <mass value="1" />
            <inertia ixx="100" ixy="0" ixz="0" iyy="100" iyz="0" izz="100" />
        </inertial>
        <visual>
            <origin xyz="0 0 1" rpy="0 0 0"/>
            <geometry>
                <box size="0.7889438026836662 0.19551724769644951 0.2923406821953972" />
            </geometry>
            <material name="Cyan">
                <color rgba="0 1.0 1.0 1.0"/>
            </material>
        </visual>
        <collision>
            <origin xyz="0 0 1" rpy="0 0 0"/>
            <geometry>
                <box size="0.7889438026836662 0.19551724769644951 0.2923406821953972" />
            </geometry>
        </collision>
    </link>
    <joint name="link0_link1" type="revolute">
       <parent link="link0"/>
       <child  link="link1"/>
       <origin rpy="0 0 0" xyz="-0.0654531046123165 -0.009204091328227405 0.8538296589023013" />
     <axis xyz="1 0 0"/>
       <limit effort="0.0" lower="-3.14159" upper="3.14159" velocity="0.0"/>
    </joint>
    <link name="link1">
        <inertial>
            <origin xyz="-0.011340492255894957 0.020386555928838316 -0.025323718383067906" rpy="0 0 0"/>
            <mass value="1" />
            <inertia ixx="100" ixy="0" ixz="0" iyy="100" iyz="0" izz="100" />
        </inertial>
        <visual>
            <origin xyz="-0.011340492255894957 0.020386555928838316 -0.025323718383067906" rpy="0 0 0"/>
            <geometry>
                <box size="0.24810824545868904 0.8053181475540715 0.05064743676613581" />
            </geometry>
            <material name="Cyan">
                <color rgba="0 1.0 1.0 1.0"/>
            </material>
        </visual>
        <collision>
            <origin xyz="-0.011340492255894957 0.020386555928838316 -0.025323718383067906" rpy="0 0 0"/>
            <geometry>
                <box size="0.24810824545868904 0.8053181475540715 0.05064743676613581" />
            </geometry>
        </collision>
    </link>
    <joint name="link1_link2" type="revolute">
       <parent link="link1"/>
       <child  link="link2"/>
       <origin rpy="0 0 0" xyz="-0.11892857225568801 -0.3786289626007308 0.0" />
     <axis xyz="0 0 1"/>
       <limit effort="0.0" lower="-3.14159" upper="3.14159" velocity="0.0"/>
    </joint>
    <link name="link2">
        <inertial>
            <origin xyz="-0.00823919004005294 0.05607799791405293 0.1952819727897901" rpy="0 0 0"/>
            <mass value="1" />
            <inertia ixx="100" ixy="0" ixz="0" iyy="100" iyz="0" izz="100" />
        </inertial>
        <visual>
            <origin xyz="-0.00823919004005294 0.05607799791405293 0.1952819727897901" rpy="0 0 0"/>
            <geometry>
                <box size="0.05198610966903239 0.42242628011943717 0.3905639455795802" />
            </geometry>
            <material name="Cyan">
                <color rgba="0 1.0 1.0 1.0"/>
            </material>
        </visual>
        <collision>
            <origin xyz="-0.00823919004005294 0.05607799791405293 0.1952819727897901" rpy="0 0 0"/>
            <geometry>
                <box size="0.05198610966903239 0.42242628011943717 0.3905639455795802" />
            </geometry>
        </collision>
    </link>
    <joint name="link1_link3" type="revolute">
       <parent link="link1"/>
       <child  link="link3"/>
       <origin rpy="0 0 0" xyz="-0.13539461498523947 0.39238080546831955 -0.027835707022110755" />
     <axis xyz="1 0 0"/>
       <limit effort="0.0" lower="-3.14159" upper="3.14159" velocity="0.0"/>
    </joint>
    <link name="link3">
        <inertial>
            <origin xyz="-7.802639698739622e-05 0.0840412752783878 -0.050778809374238315" rpy="0 0 0"/>
            <mass value="1" />
            <inertia ixx="100" ixy="0" ixz="0" iyy="100" iyz="0" izz="100" />
        </inertial>
        <visual>
            <origin xyz="-7.802639698739622e-05 0.0840412752783878 -0.050778809374238315" rpy="0 0 0"/>
            <geometry>
                <box size="0.00015605279397479244 0.6405547993463927 0.12053862645979607" />
            </geometry>
            <material name="Cyan">
                <color rgba="0 1.0 1.0 1.0"/>
            </material>
        </visual>
        <collision>
            <origin xyz="-7.802639698739622e-05 0.0840412752783878 -0.050778809374238315" rpy="0 0 0"/>
            <geometry>
                <box size="0.00015605279397479244 0.6405547993463927 0.12053862645979607" />
            </geometry>
        </collision>
    </link>
    <joint name="link3_link4" type="revolute">
       <parent link="link3"/>
       <child  link="link4"/>
       <origin rpy="0 0 0" xyz="-8.165816693184328e-05 0.40431867495158413 -0.10228482549102079" />
     <axis xyz="0 1 0"/>
       <limit effort="0.0" lower="-3.14159" upper="3.14159" velocity="0.0"/>
    </joint>
    <link name="link4">
        <inertial>
            <origin xyz="-0.30127618653882904 0.3830965089575324 0.018568571475833684" rpy="0 0 0"/>
            <mass value="1" />
            <inertia ixx="100" ixy="0" ixz="0" iyy="100" iyz="0" izz="100" />
        </inertial>
        <visual>
            <origin xyz="-0.30127618653882904 0.3830965089575324 0.018568571475833684" rpy="0 0 0"/>
            <geometry>
                <box size="0.8069381406079928 0.7661930179150648 0.2588209489295824" />
            </geometry>
            <material name="Cyan">
                <color rgba="0 1.0 1.0 1.0"/>
            </material>
        </visual>
        <collision>
            <origin xyz="-0.30127618653882904 0.3830965089575324 0.018568571475833684" rpy="0 0 0"/>
            <geometry>
                <box size="0.8069381406079928 0.7661930179150648 0.2588209489295824" />
            </geometry>
        </collision>
    </link>
    <joint name="link0_link5" type="revolute">
       <parent link="link0"/>
       <child  link="link5"/>
       <origin rpy="0 0 0" xyz="-0.3944719013418331 -0.0645893990674796 1.1001182286251667" />
     <axis xyz="1 0 0"/>
       <limit effort="0.0" lower="-3.14159" upper="3.14159" velocity="0.0"/>
    </joint>
    <link name="link5">
        <inertial>
            <origin xyz="-0.4804022267348387 0.22311886707660775 0.12927540094537196" rpy="0 0 0"/>
            <mass value="1" />
            <inertia ixx="100" ixy="0" ixz="0" iyy="100" iyz="0" izz="100" />
        </inertial>
        <visual>
            <origin xyz="-0.4804022267348387 0.22311886707660775 0.12927540094537196" rpy="0 0 0"/>
            <geometry>
                <box size="0.9608044534696774 0.7318035533249858 0.267835641658543" />
            </geometry>
            <material name="Cyan">
                <color rgba="0 1.0 1.0 1.0"/>
            </material>
        </visual>
        <collision>
            <origin xyz="-0.4804022267348387 0.22311886707660775 0.12927540094537196" rpy="0 0 0"/>
            <geometry>
                <box size="0.9608044534696774 0.7318035533249858 0.267835641658543" />
            </geometry>
        </collision>
    </link>
    <joint name="link2_link6" type="revolute">
       <parent link="link2"/>
       <child  link="link6"/>
       <origin rpy="0 0 0" xyz="-0.034232244874569134 0.1252506303984849 0.20205608270594044" />
     <axis xyz="0 1 0"/>
       <limit effort="0.0" lower="-3.14159" upper="3.14159" velocity="0.0"/>
    </joint>
    <link name="link6">
        <inertial>
            <origin xyz="-0.4301686161936505 -0.16503477202560748 0.043154350264599" rpy="0 0 0"/>
            <mass value="1" />
            <inertia ixx="100" ixy="0" ixz="0" iyy="100" iyz="0" izz="100" />
        </inertial>
        <visual>
            <origin xyz="-0.4301686161936505 -0.16503477202560748 0.043154350264599" rpy="0 0 0"/>
            <geometry>
                <box size="0.860337232387301 0.9739350988878919 0.09915655343779817" />
            </geometry>
            <material name="Cyan">
                <color rgba="0 1.0 1.0 1.0"/>
            </material>
        </visual>
        <collision>
            <origin xyz="-0.4301686161936505 -0.16503477202560748 0.043154350264599" rpy="0 0 0"/>
            <geometry>
                <box size="0.860337232387301 0.9739350988878919 0.09915655343779817" />
            </geometry>
        </collision>
    </link>
</robot>