<robot name = "robot">
    <link name="link0">
        <inertial>
            <origin xyz="0 0 1" rpy="0 0 0"/>
            <mass value="1" />
            <inertia ixx="100" ixy="0" ixz="0" iyy="100" iyz="0" izz="100" />
        </inertial>
        <visual>
            <origin xyz="0 0 1" rpy="0 0 0"/>
            <geometry>
                <box size="0.45554610264060114 0.2991771428509574 0.6376025527393043" />
            </geometry>
            <material name="Cyan">
                <color rgba="0 1.0 1.0 1.0"/>
            </material>
        </visual>
        <collision>
            <origin xyz="0 0 1" rpy="0 0 0"/>
            <geometry>
                <box size="0.45554610264060114 0.2991771428509574 0.6376025527393043" />
            </geometry>
        </collision>
    </link>
    <joint name="link0_link1" type="revolute">
       <parent link="link0"/>
       <child  link="link1"/>
       <origin rpy="0 0 0" xyz="-0.11901301363540542 -0.1495885714254787 1.2861822301970935" />
     <axis xyz="0 0 1"/>
       <limit effort="0.0" lower="-3.14159" upper="3.14159" velocity="0.0"/>
    </joint>
    <link name="link1">
        <inertial>
            <origin xyz="-0.23802241380290326 -0.07771373669839127 0.009125844491532717" rpy="0 0 0"/>
            <mass value="1" />
            <inertia ixx="100" ixy="0" ixz="0" iyy="100" iyz="0" izz="100" />
        </inertial>
        <visual>
            <origin xyz="-0.23802241380290326 -0.07771373669839127 0.009125844491532717" rpy="0 0 0"/>
            <geometry>
                <box size="0.9800719295072307 0.15542747339678253 0.7032312072331576" />
            </geometry>
            <material name="Cyan">
                <color rgba="0 1.0 1.0 1.0"/>
            </material>
        </visual>
        <collision>
            <origin xyz="-0.23802241380290326 -0.07771373669839127 0.009125844491532717" rpy="0 0 0"/>
            <geometry>
                <box size="0.9800719295072307 0.15542747339678253 0.7032312072331576" />
            </geometry>
        </collision>
    </link>
    <joint name="link0_link2" type="revolute">
       <parent link="link0"/>
       <child  link="link2"/>
       <origin rpy="0 0 0" xyz="0.08919588701259182 0.1495885714254787 0.9832988831095963" />
     <axis xyz="1 0 0"/>
       <limit effort="0.0" lower="-3.14159" upper="3.14159" velocity="0.0"/>
    </joint>
    <link name="link2">
        <inertial>
            <origin xyz="0.428184217461119 0.19860827701769895 0.03168787488537843" rpy="0 0 0"/>
            <mass value="1" />
            <inertia ixx="100" ixy="0" ixz="0" iyy="100" iyz="0" izz="100" />
        </inertial>
        <visual>
            <origin xyz="0.428184217461119 0.19860827701769895 0.03168787488537843" rpy="0 0 0"/>
            <geometry>
                <box size="0.8976035014334485 0.3972165540353979 0.06690324173181494" />
            </geometry>
            <material name="Cyan">
                <color rgba="0 1.0 1.0 1.0"/>
            </material>
        </visual>
        <collision>
            <origin xyz="0.428184217461119 0.19860827701769895 0.03168787488537843" rpy="0 0 0"/>
            <geometry>
                <box size="0.8976035014334485 0.3972165540353979 0.06690324173181494" />
            </geometry>
        </collision>
    </link>
</robot>